Workbook
Name \p: #REF!
Name __atn1: #REF!
Name __atn10: #REF!
Name __atn2: #REF!
Name __atn3: #REF!
Name __atn4: #REF!
Name __atn5: #REF!
Name __atn6: #REF!
Name __atn7: #REF!
Name __atn8: #REF!
Name __atn9: #REF!
Name __boi1: #REF!
Name __boi2: #REF!
Name __CON1: #REF!
Name __CON2: #REF!
Name __cpd1: #REF!
Name __cpd2: #REF!
Name __deo1: #REF!
Name __deo10: #REF!
Name __deo2: #REF!
Name __deo3: #REF!
Name __deo4: #REF!
Name __deo5: #REF!
Name __deo6: #REF!
Name __deo7: #REF!
Name __deo8: #REF!
Name __deo9: #REF!
Name __lap1: #REF!
Name __lap2: #REF!
Name __nc151: #REF!
Name __NET2: #REF!
Name __SHR1: #REF!
Name __SHR2: #REF!
Name __tax1: #REF!
Name __tax2: #REF!
Name __tax3: #REF!
Name __tax4: #REF!
Name __tct5: #REF!
Name __tg427: #REF!
Name __TH20: #REF!
Name _1: #REF!
Name _1000A01: #REF!
Name _2: #REF!
Name _atn2: #REF!
Name _atn3: #REF!
Name _atn4: #REF!
Name _atn5: #REF!
Name _atn6: #REF!
Name _atn7: #REF!
Name _atn8: #REF!
Name _atn9: #REF!
Name _ATT_REG_DCOM_3G: #REF!
Name _ATT_REG_MI_3G: #REF!
Name _ATT_REG_voice_2G: #REF!
Name _ATT_REG_voice_3G: #REF!
Name _boi1: #REF!
Name _boi2: #REF!
Name _C_Lphi_4ab: #REF!
Name _chk1: #REF!
Name _CON1: #REF!

Sheet PL1.1 ML2027-2028
A1: PHỤ LỤC 1.1: BẢNG TỔNG HỢP CHI TIẾT NHU CẦU ĐẦU TƯ, MUA SẮM THEO QHĐC NĂM 2027-2028 (Ban hành kèm theo Tờ trình số của Tập đoàn CNVTQĐ) | P1: Ghi chú
G3: KHÔNG XÓA | J3: KHÔNG XÓA
A4: TT | B4: Nội dung/ hạng mục đầu tư, mua sắm | C4: Đơn vị tính | D4: Khối lượng | F4: Đơn giá dự kiến | G4: Thành tiền dự kiến (VNĐ) | I4: Dự kiến đơn vị đầu tư, mua sắm | J4: Mã mảng | K4: Mã DV | L4: Mã loại
D6: 2027 | E6: 2028 | F6: USD | G6: 2027 | H6: 2028
C7: 6 | F7: 7 | G7: =SUBTOTAL(9,G8:G2592) -> 1.2335528e+08 | H7: =SUBTOTAL(9,H8:H2592) -> 1.0102088e+08
B8: TỔNG ĐẦU TƯ VTTB VÀ XÂY LẮP 2027-2028 | G8: =SUBTOTAL(9,G9:G2592) -> 1.2335528e+08 | H8: =SUBTOTAL(9,H9:H2592) -> 1.0102088e+08
A9: P1 | B9: TỔNG ĐẦU TƯ VTTB 2027-2028 | G9: =SUBTOTAL(9,G10:G2053) -> 1.1274853e+08 | H9: =SUBTOTAL(9,H10:H2053) -> 94869816
A10: A | B10: VÔ TUYẾN | G10: =SUBTOTAL(9,G11:G92) -> 41358286 | H10: =SUBTOTAL(9,H11:H92) -> 26886814
A11: A1 | B11: Mạng 5G | G11: =SUBTOTAL(9,G12:G21) -> 0 | H11: =SUBTOTAL(9,H12:H21) -> 0 | P11: Cosite trên 802 vị trí triển khai 4G DL
A12: 1 | B12: Thiết bị macro 5G
A13: - | B13: Bộ Gá đa năng (gồm 3 gá đơn lẻ và các phụ kiện) | C13: Bộ | D13: 622 | E13: 458 | G13: =F13*D13 -> 0 | H13: =F13*E13 -> 0 | J13: VT | K13: 5G | L13: VTTB | P13: Tính trong DL 4G
A14: - | B14: NodeB Massive MIMO 2.6GHz+3.5GHz | C14: Tủ | D14: 622 | E14: 458 | G14: =F14*D14 -> 0 | H14: =F14*E14 -> 0 | J14: VT | K14: 5G | L14: VTTB | P14: Tính trong DL 4G
A15: 2 | B15: Thiết bị RRU 5G
A16: - | B16: RRU 5G triển khai IBD | C16: Chiếc | G16: =F16*D16 -> 0 | H16: =F16*E16 -> 0 | J16: VT | K16: 5G | L16: VTTB
A17: 3 | B17: Thiết bị smallcell 5G
A18: - | B18: Thiết bị vô tuyến 5G 4T4R | C18: Chiếc | G18: =F18*D18 -> 0 | H18: =F18*E18 -> 0 | J18: VT | K18: 5G | L18: VTTB
A19: 4 | B19: Card Baseband
A20: - | B20: Card Baseband cho 5G | C20: Chiếc | G20: =F20*D20 -> 0 | H20: =F20*E20 -> 0 | J20: VT | K20: 5G | L20: VTTB
A21: 5 | B21: Nâng cấp hệ thống Inbuilding lên 5G
A22: A2 | B22: Mạng 2/3/4G | G22: =SUBTOTAL(9,G23:G44) -> 4178882 | H22: =SUBTOTAL(9,H23:H44) -> 3876778
A23: I | B23: Vùng phủ | G23: =SUBTOTAL(9,G24:G44) -> 4178882 | H23: =SUBTOTAL(9,H24:H44) -> 3876778 | P23: Triển khai 208 vị trí triển khai vùng phủ mới cho 4G kết hợp cosite 2G, tổng chi phí dự kiến 3.5M USD
A24: 1 | B24: Thiết bị 4G | G24: =SUBTOTAL(9,G25:G31) -> 4178882 | H24: =SUBTOTAL(9,H25:H31) -> 3876778
A25: - | B25: Mixmode 2G 4G 800/900_Huawei | C25: Tủ | D25: 182 | E25: 178 | F25: 14893 | G25: =F25*D25 -> 2710526 | H25: =F25*E25 -> 2650954 | J25: VT | K25: VPDĐ | L25: VTTB
A26: - | B26: BTS 2G 900MHz 4T4R 4*40W (3 RRU 4T4R, S4/4/4) _ ZTE | C26: Tủ | D26: 93 | E26: 72 | F26: 8692 | G26: =F26*D26 -> 808356 | H26: =F26*E26 -> 625824 | J26: VT | K26: VPDĐ | L26: VTTB
A27: - | B27: eNodeB 800MHz@10MHz 4T4R 4*40W (3 RRU 4T4R, 3 cell 10MHz) Huawei | C27: Tủ | D27: 0 | E27: 0 | F27: 9064 | G27: =F27*D27 -> 0 | H27: =F27*E27 -> 0 | J27: VT | K27: VPDĐ | L27: VTTB
A28: - | B28: Diplexer 800-900 | C28: Chiếc | D28: 0 | E28: 0 | F28: 100 | G28: =F28*D28 -> 0 | H28: =F28*E28 -> 0 | J28: VT | K28: VPDĐ | L28: VTTB
A29: - | B29: Anten đa băng | C29: Chiếc | D29: 825 | E29: 750 | F29: 650 | G29: =F29*D29 -> 536250 | H29: =F29*E29 -> 487500 | J29: VT | K29: VPDĐ | L29: VTTB
A30: - | B30: Jumper | C30: Chiếc | D30: 3300 | E30: 3000 | F30: 20 | G30: =F30*D30 -> 66000 | H30: =F30*E30 -> 60000 | J30: VT | K30: VPDĐ | L30: VTTB
A31: - | B31: Bộ Gá đa năng (gồm 3 gá đơn lẻ và các phụ kiện) | C31: Chiếc | D31: 275 | E31: 250 | F31: 210 | G31: =F31*D31 -> 57750 | H31: =F31*E31 -> 52500 | J31: VT | K31: VPDĐ | L31: VTTB
A32: 2 | B32: Thiết bị 3G | G32: =SUBTOTAL(9,G33:G39) -> 0 | H32: =SUBTOTAL(9,H33:H39) -> 0
A33: - | B33: NodeB 3G dualband_Cosite | C33: Tủ | G33: =F33*D33 -> 0 | H33: =F33*E33 -> 0 | J33: VT | K33: VPDĐ | L33: VTTB
A34: - | B34: NodeB 3G dualband_New site | C34: Tủ | G34: =F34*D34 -> 0 | H34: =F34*E34 -> 0 | J34: VT | K34: VPDĐ | L34: VTTB
A35: - | B35: Card baseband | C35: Chiếc | G35: =F35*D35 -> 0 | H35: =F35*E35 -> 0 | J35: VT | K35: VPDĐ | L35: VTTB
A36: - | B36: Anten đa băng | C36: Chiếc | G36: =F36*D36 -> 0 | H36: =F36*E36 -> 0 | J36: VT | K36: VPDĐ | L36: VTTB
A37: - | B37: Jumper | C37: Chiếc | G37: =F37*D37 -> 0 | H37: =F37*E37 -> 0 | J37: VT | K37: VPDĐ | L37: VTTB
A38: - | B38: Bộ Gá đa năng (gồm 3 gá đơn lẻ và các phụ kiện) | C38: Chiếc | G38: =F38*D38 -> 0 | H38: =F38*E38 -> 0 | J38: VT | K38: VPDĐ | L38: VTTB
A39: 3 | B39: Thiết bị 2G | G39: =SUBTOTAL(9,G40:G46) -> 0 | H39: =SUBTOTAL(9,H40:H46) -> 0
A40: - | B40: BTS 2G dualband_Cosite | C40: Tủ | G40: =F40*D40 -> 0 | H40: =F40*E40 -> 0 | J40: VT | K40: VPDĐ | L40: VTTB
A41: - | B41: BTS 2G dualband_New site 2G | C41: Tủ | G41: =F41*D41 -> 0 | H41: =F41*E41 -> 0 | J41: VT | K41: VPDĐ | L41: VTTB
A42: - | B42: Anten đa băng | C42: Chiếc | G42: =F42*D42 -> 0 | H42: =F42*E42 -> 0 | J42: VT | K42: VPDĐ | L42: VTTB
...

Sheet TH theo dich vu
D1: 1000000
A2: STT | B2: Nội dung | C2: Ko xóa | D2: 2027 (triệu USD) | O2: 2028 (triệu USD) | Z2: 2027-2028 (triệu USD) | AJ2: Tỷ trọng theo dịch vụ
B3: Mảng | C3: Mã DV | D3: VT | E3: ML | F3: CĐBR | G3: CNTT | H3: IP | I3: TD | J3: CĐ | K3: HT | L3: Tổng (Movitel) | M3: Tổng (Có ví) | N3: Tỷ trọng (%) | O3: VT | P3: ML | Q3: CĐBR | R3: CNTT | S3: IP | T3: TD | U3: CĐ | V3: HT | W3: Tổng (Movitel) | X3: Tổng (Có ví) | Y3: Tỷ trọng (%) | Z3: VT | AA3: ML | AB3: CĐBR | AC3: CNTT | AD3: IP | AE3: TD | AF3: CĐ | AG3: HT | AH3: Tổng | AI3: Tỷ trọng (%) | AJ3: 4G | AK3: 5G | AL3: CĐBR | AM3: Truyền hình | AN3: DC | AO3: Cloud | AP3: CNTT
A4: * | B4: Tổng | D4: =SUBTOTAL(9,D6:D33) -> 41.358286 | E4: =SUBTOTAL(9,E6:E33) -> 8.95001 | F4: =SUBTOTAL(9,F6:F33) -> 1.2385273 | G4: =SUBTOTAL(9,G6:G33) -> 18.305994 | H4: =SUBTOTAL(9,H6:H33) -> 11.033791 | I4: =SUBTOTAL(9,I6:I33) -> 10.692601 | J4: =SUBTOTAL(9,J6:J33) -> 8.6180833 | K4: =SUBTOTAL(9,K6:K33) -> 10.606754 | L4: =SUBTOTAL(9,L6:L33) -> 110.80405 | M4: =SUBTOTAL(9,M6:M34) -> 123.35528 | O4: =SUBTOTAL(9,O6:O33) -> 26.886814 | P4: =SUBTOTAL(9,P6:P33) -> 0 | Q4: =SUBTOTAL(9,Q6:Q33) -> 0.56333736 | R4: =SUBTOTAL(9,R6:R33) -> 22.441326 | S4: =SUBTOTAL(9,S6:S33) -> 10.616615 | T4: =SUBTOTAL(9,T6:T33) -> 8.0845519 | U4: =SUBTOTAL(9,U6:U33) -> 15.425907 | V4: =SUBTOTAL(9,V6:V33) -> 6.1510614 | W4: =SUBTOTAL(9,W6:W33) -> 90.169613 | X4: =SUBTOTAL(9,X6:X34) -> 101.02088 | Z4: =SUBTOTAL(9,Z6:Z33) -> 68.2451 | AA4: =SUBTOTAL(9,AA6:AA33) -> 8.95001 | AB4: =SUBTOTAL(9,AB6:AB33) -> 1.8018647 | AC4: =SUBTOTAL(9,AC6:AC33) -> 40.74732 | AD4: =SUBTOTAL(9,AD6:AD33) -> 21.650407 | AE4: =SUBTOTAL(9,AE6:AE33) -> 18.777153 | AF4: =SUBTOTAL(9,AF6:AF33) -> 24.04399 | AG4: =SUBTOTAL(9,AG6:AG33) -> 16.757815 | AH4: =SUBTOTAL(9,AH6:AH33) -> 200.97366 | AI4: =AH4/$AH$4 -> 1 | AJ4: =AH10*AJ10+AH12*AJ12+AH21*AJ21+AH24*AJ24+AH25*AJ25+(Z30+AA30+AD30+AF30)*AJ30+(Z31+AA31+AD31+AF31)*AJ31+(Z32+AA32+AD32+AF32)*AJ32+AH33*AJ33 -> 175.28548 | AK4: =AK7*AH7 -> 0 | AL4: =AH8*AL8+AH16*AL16+AH17*AL17+AH19*AL19+AB30*AL30+AB31*AL31+AB32*AL32+AH33*AL33 -> 2.8912809 | AM4: =AH18*AM18+AH21*AM21+AB30*AM30+AB31*AM31 -> 0.1356972 | AN4: =AH21*AN21 -> 1.910828 | AO4: =AH9*AO9+AH20*AO20 -> 0.86982688 | AP4: =AH23*AP23+AH9*AP9+AC30*AP30+AC31*AP31 -> 8.9408041
B5: Tỷ trọng theo mảng | D5: =D4/$L$4 -> 0.37325609 | E5: =E4/$L$4 -> 0.080773313 | F5: =F4/$L$4 -> 0.011177636 | G5: =G4/$L$4 -> 0.16521052 | H5: =H4/$L$4 -> 0.099579318 | I5: =I4/$L$4 -> 0.096500099 | J5: =J4/$L$4 -> 0.077777694 | K5: =K4/$L$4 -> 0.095725329 | ... M5: =M4/$L$4 -> 1.1132741 | O5: =O4/$X$4 -> 0.26615107 | P5: =P4/$X$4 -> 0 | Q5: =Q4/$X$4 -> 0.005576445 | R5: =R4/$X$4 -> 0.22214543 | S5: =S4/$X$4 -> 0.10509328 | T5: =T4/$X$4 -> 0.080028526 | U5: =U4/$X$4 -> 0.15270019 | V5: =V4/$X$4 -> 0.060889012 | ... X5: =X4/$X$4 -> 1 | Z5: =Z4/$AH$4 -> 0.33957236 | AA5: =AA4/$AH$4 -> 0.044533249 | AB5: =AB4/$AH$4 -> 0.0089656757 | AC5: =AC4/$AH$4 -> 0.20274955 | AD5: =AD4/$AH$4 -> 0.10772758 | AE5: =AE4/$AH$4 -> 0.093430917 | AF5: =AF4/$AH$4 -> 0.11963752 | AG5: =AG4/$AH$4 -> 0.083383142 | AH5: =AH4/$AH$4 -> 1
A6: I | B6: Công nghệ mới triển khai diện rộng cho kinh doanh | D6: =SUBTOTAL(9,D7:D10) -> 0 | E6: =SUBTOTAL(9,E7:E10) -> 0 | F6: =SUBTOTAL(9,F7:F10) -> 0 | G6: =SUBTOTAL(9,G7:G10) -> 0.836372 | H6: =SUBTOTAL(9,H7:H10) -> 0 | I6: =SUBTOTAL(9,I7:I10) -> 0 | J6: =SUBTOTAL(9,J7:J10) -> 0 | K6: =SUBTOTAL(9,K7:K10) -> 0 | ... M6: =SUBTOTAL(9,M7:M10) -> 0.836372 | N6: =L6/$L$4 -> 0.0075482081 | O6: =SUBTOTAL(9,O7:O10) -> 0 | P6: =SUBTOTAL(9,P7:P10) -> 0 | Q6: =SUBTOTAL(9,Q7:Q10) -> 0 | R6: =SUBTOTAL(9,R7:R10) -> 0.836372 | S6: =SUBTOTAL(9,S7:S10) -> 0 | T6: =SUBTOTAL(9,T7:T10) -> 0 | U6: =SUBTOTAL(9,U7:U10) -> 0 | V6: =SUBTOTAL(9,V7:V10) -> 0 | ... X6: =SUBTOTAL(9,X7:X10) -> 0.836372 | Y6: =W6/$W$4 -> 0.0092755416 | Z6: =SUBTOTAL(9,Z7:Z9) -> 0 | AA6: =SUBTOTAL(9,AA7:AA9) -> 0 | AB6: =SUBTOTAL(9,AB7:AB9) -> 0 | AC6: =SUBTOTAL(9,AC7:AC9) -> 1.672744 | AD6: =SUBTOTAL(9,AD7:AD9) -> 0 | AE6: =SUBTOTAL(9,AE7:AE9) -> 0 | AF6: =SUBTOTAL(9,AF7:AF9) -> 0 | AG6: =SUBTOTAL(9,AG7:AG9) -> 0 | AH6: =SUBTOTAL(9,AH7:AH10) -> 1.672744 | AI6: =AH6/$AH$4 -> 0.0083232002
A7: 1 | B7: Mạng 5G | C7: 5G | D7: =SUMIFS('PL1.1 ML2027-2028'!$G:$G,'PL1.1 ML2027-2028'!$J:$J,'TH theo dich vu'!$D$3,'PL1.1 ML2027-2028'!$K:$K,'TH theo dich vu'!C7)/$D$1 -> 0 | E7: =SUMIFS('PL1.1 ML2027-2028'!$G:$G,'PL1.1 ML2027-2028'!$J:$J,'TH theo dich vu'!$E$3,'PL1.1 ML2027-2028'!$K:$K,'TH theo dich vu'!C7)/$D$1 -> 0 | F7: =SUMIFS('PL1.1 ML2027-2028'!$G:$G,'PL1.1 ML2027-2028'!$J:$J,'TH theo dich vu'!$F$3,'PL1.1 ML2027-2028'!$K:$K,'TH theo dich vu'!C7)/$D$1 -> 0 | G7: =SUMIFS('PL1.1 ML2027-2028'!$G:$G,'PL1.1 ML2027-2028'!$J:$J,'TH theo dich vu'!$G$3,'PL1.1 ML2027-2028'!$K:$K,'TH theo dich vu'!C7)/$D$1 -> 0 | H7: =SUMIFS('PL1.1 ML2027-2028'!$G:$G,'PL1.1 ML2027-2028'!$J:$J,"TD",'PL1.1 ML2027-2028'!$M:$M,"IP",'PL1.1 ML2027-2028'!$K:$K,'TH theo dich vu'!C7)/$D$1 -> 0 | I7: =SUMIFS('PL1.1 ML2027-2028'!$G:$G,'PL1.1 ML2027-2028'!$J:$J,"TD",'PL1.1 ML2027-2028'!$M:$M,"Mạng cáp",'PL1.1 ML2027-2028'!$K:$K,'TH theo dich vu'!C7)/$D$1 -> 0 | J7: =SUMIFS('PL1.1 ML2027-2028'!$G:$G,'PL1.1 ML2027-2028'!$J:$J,'TH theo dich vu'!$J$3,'PL1.1 ML2027-2028'!$K:$K,'TH theo dich vu'!C7)/$D$1 -> 0 | K7: =SUMIFS('PL1.1 ML2027-2028'!$G:$G,'PL1.1 ML2027-2028'!$J:$J,'TH theo dich vu'!K$3,'PL1.1 ML2027-2028'!$K:$K,'TH theo dich vu'!C7)/$D$1 -> 0 | L7: =SUM(D7:K7) -> 0 | M7: =SUM(D7:K7) -> 0 | N7: =L7/$L$4 -> 0 | O7: =SUMIFS('PL1.1 ML2027-2028'!$H:$H,'PL1.1 ML2027-2028'!$J:$J,'TH theo dich vu'!O$3,'PL1.1 ML2027-2028'!$K:$K,'TH theo dich vu'!$C7)/$D$1 -> 0 | P7: =SUMIFS('PL1.1 ML2027-2028'!$H:$H,'PL1.1 ML2027-2028'!$J:$J,'TH theo dich vu'!P$3,'PL1.1 ML2027-2028'!$K:$K,'TH theo dich vu'!$C7)/$D$1 -> 0 | Q7: =SUMIFS('PL1.1 ML2027-2028'!$H:$H,'PL1.1 ML2027-2028'!$J:$J,'TH theo dich vu'!Q$3,'PL1.1 ML2027-2028'!$K:$K,'TH theo dich vu'!$C7)/$D$1 -> 0 | R7: =SUMIFS('PL1.1 ML2027-2028'!$H:$H,'PL1.1 ML2027-2028'!$J:$J,'TH theo dich vu'!R$3,'PL1.1 ML2027-2028'!$K:$K,'TH theo dich vu'!$C7)/$D$1 -> 0 | S7: =SUMIFS('PL1.1 ML2027-2028'!$H:$H,'PL1.1 ML2027-2028'!$J:$J,"TD",'PL1.1 ML2027-2028'!$M:$M,"IP",'PL1.1 ML2027-2028'!$K:$K,'TH theo dich vu'!C7)/$D$1 -> 0 | T7: =SUMIFS('PL1.1 ML2027-2028'!$H:$H,'PL1.1 ML2027-2028'!$J:$J,"TD",'PL1.1 ML2027-2028'!$M:$M,"Mạng cáp",'PL1.1 ML2027-2028'!$K:$K,'TH theo dich vu'!C7)/$D$1 -> 0 | U7: =SUMIFS('PL1.1 ML2027-2028'!$H:$H,'PL1.1 ML2027-2028'!$J:$J,'TH theo dich vu'!U$3,'PL1.1 ML2027-2028'!$K:$K,'TH theo dich vu'!$C7)/$D$1 -> 0 | V7: =SUMIFS('PL1.1 ML2027-2028'!$H:$H,'PL1.1 ML2027-2028'!$J:$J,'TH theo dich vu'!V$3,'PL1.1 ML2027-2028'!$K:$K,'TH theo dich vu'!$C7)/$D$1 -> 0 | W7: =SUM(O7:V7) -> 0 | X7: =SUM(O7:V7) -> 0 | Z7: =D7+O7 -> 0 | AA7: =E7+P7 -> 0 | AB7: =F7+Q7 -> 0 | AC7: =G7+R7 -> 0 | AD7: =H7+S7 -> 0 | AE7: =I7+T7 -> 0 | AF7: =J7+U7 -> 0 | AG7: =K7+V7 -> 0 | AH7: =SUM(Z7:AG7) -> 0 | AI7: =AH7/$AH$4 -> 0 | AK7: 1
A8: 2 | B8: XGSPON | C8: XGSPON | D8: =SUMIFS('PL1.1 ML2027-2028'!$G:$G,'PL1.1 ML2027-2028'!$J:$J,'TH theo dich vu'!$D$3,'PL1.1 ML2027-2028'!$K:$K,'TH theo dich vu'!C8)/$D$1 -> 0 | E8: =SUMIFS('PL1.1 ML2027-2028'!$G:$G,'PL1.1 ML2027-2028'!$J:$J,'TH theo dich vu'!$E$3,'PL1.1 ML2027-2028'!$K:$K,'TH theo dich vu'!C8)/$D$1 -> 0 | F8: =SUMIFS('PL1.1 ML2027-2028'!$G:$G,'PL1.1 ML2027-2028'!$J:$J,'TH theo dich vu'!$F$3,'PL1.1 ML2027-2028'!$K:$K,'TH theo dich vu'!C8)/$D$1 -> 0 | G8: =SUMIFS('PL1.1 ML2027-2028'!$G:$G,'PL1.1 ML2027-2028'!$J:$J,'TH theo dich vu'!$G$3,'PL1.1 ML2027-2028'!$K:$K,'TH theo dich vu'!C8)/$D$1 * 0.43287 -> 0 | H8: =SUMIFS('PL1.1 ML2027-2028'!$G:$G,'PL1.1 ML2027-2028'!$J:$J,"TD",'PL1.1 ML2027-2028'!$M:$M,"IP",'PL1.1 ML2027-2028'!$K:$K,'TH theo dich vu'!C8)/$D$1 -> 0 | I8: =SUMIFS('PL1.1 ML2027-2028'!$G:$G,'PL1.1 ML2027-2028'!$J:$J,"TD",'PL1.1 ML2027-2028'!$M:$M,"Mạng cáp",'PL1.1 ML2027-2028'!$K:$K,'TH theo dich vu'!C8)/$D$1 -> 0 | J8: =SUMIFS('PL1.1 ML2027-2028'!$G:$G,'PL1.1 ML2027-2028'!$J:$J,'TH theo dich vu'!$J$3,'PL1.1 ML2027-2028'!$K:$K,'TH theo dich vu'!C8)/$D$1 -> 0 | K8: =SUMIFS('PL1.1 ML2027-2028'!$G:$G,'PL1.1 ML2027-2028'!$J:$J,'TH theo dich vu'!K$3,'PL1.1 ML2027-2028'!$K:$K,'TH theo dich vu'!C8)/$D$1 -> 0 | L8: =SUM(D8:K8) -> 0 | M8: =SUM(D8:K8) -> 0 | N8: =L8/$L$4 -> 0 | O8: =SUMIFS('PL1.1 ML2027-2028'!$H:$H,'PL1.1 ML2027-2028'!$J:$J,'TH theo dich vu'!O$3,'PL1.1 ML2027-2028'!$K:$K,'TH theo dich vu'!$C8)/$D$1 -> 0 | P8: =SUMIFS('PL1.1 ML2027-2028'!$H:$H,'PL1.1 ML2027-2028'!$J:$J,'TH theo dich vu'!P$3,'PL1.1 ML2027-2028'!$K:$K,'TH theo dich vu'!$C8)/$D$1 -> 0 | Q8: =SUMIFS('PL1.1 ML2027-2028'!$H:$H,'PL1.1 ML2027-2028'!$J:$J,'TH theo dich vu'!Q$3,'PL1.1 ML2027-2028'!$K:$K,'TH theo dich vu'!$C8)/$D$1 -> 0 | R8: =SUMIFS('PL1.1 ML2027-2028'!$H:$H,'PL1.1 ML2027-2028'!$J:$J,'TH theo dich vu'!R$3,'PL1.1 ML2027-2028'!$K:$K,'TH theo dich vu'!$C8)/$D$1 -> 0 | S8: =SUMIFS('PL1.1 ML2027-2028'!$H:$H,'PL1.1 ML2027-2028'!$J:$J,"TD",'PL1.1 ML2027-2028'!$M:$M,"IP",'PL1.1 ML2027-2028'!$K:$K,'TH theo dich vu'!C8)/$D$1 -> 0 | T8: =SUMIFS('PL1.1 ML2027-2028'!$H:$H,'PL1.1 ML2027-2028'!$J:$J,"TD",'PL1.1 ML2027-2028'!$M:$M,"Mạng cáp",'PL1.1 ML2027-2028'!$K:$K,'TH theo dich vu'!C8)/$D$1 -> 0 | U8: =SUMIFS('PL1.1 ML2027-2028'!$H:$H,'PL1.1 ML2027-2028'!$J:$J,'TH theo dich vu'!U$3,'PL1.1 ML2027-2028'!$K:$K,'TH theo dich vu'!$C8)/$D$1 -> 0 | V8: =SUMIFS('PL1.1 ML2027-2028'!$H:$H,'PL1.1 ML2027-2028'!$J:$J,'TH theo dich vu'!V$3,'PL1.1 ML2027-2028'!$K:$K,'TH theo dich vu'!$C8)/$D$1 -> 0 | W8: =SUM(O8:V8) -> 0 | X8: =SUM(O8:V8) -> 0 | Z8: =D8+O8 -> 0 | AA8: =E8+P8 -> 0 | AB8: =F8+Q8 -> 0 | AC8: =G8+R8 -> 0 | AD8: =H8+S8 -> 0 | AE8: =I8+T8 -> 0 | AF8: =J8+U8 -> 0 | AG8: =K8+V8 -> 0 | AH8: =SUM(Z8:AG8) -> 0 | AI8: =AH8/$AH$4 -> 0 | AL8: 1
A9: 3 | B9: AI/GPU | C9: AI/GPU | D9: =SUMIFS('PL1.1 ML2027-2028'!$G:$G,'PL1.1 ML2027-2028'!$J:$J,'TH theo dich vu'!$D$3,'PL1.1 ML2027-2028'!$K:$K,'TH theo dich vu'!C9)/$D$1 -> 0 | E9: =SUMIFS('PL1.1 ML2027-2028'!$G:$G,'PL1.1 ML2027-2028'!$J:$J,'TH theo dich vu'!$E$3,'PL1.1 ML2027-2028'!$K:$K,'TH theo dich vu'!C9)/$D$1 -> 0 | F9: =SUMIFS('PL1.1 ML2027-2028'!$G:$G,'PL1.1 ML2027-2028'!$J:$J,'TH theo dich vu'!$F$3,'PL1.1 ML2027-2028'!$K:$K,'TH theo dich vu'!C9)/$D$1 -> 0 | G9: =SUMIFS('PL1.1 ML2027-2028'!$G:$G,'PL1.1 ML2027-2028'!$J:$J,'TH theo dich vu'!G$3,'PL1.1 ML2027-2028'!$K:$K,'TH theo dich vu'!$C9)/$D$1 -> 0.836372 | H9: =SUMIFS('PL1.1 ML2027-2028'!$G:$G,'PL1.1 ML2027-2028'!$J:$J,"TD",'PL1.1 ML2027-2028'!$M:$M,"IP",'PL1.1 ML2027-2028'!$K:$K,'TH theo dich vu'!C9)/$D$1 -> 0 | I9: =SUMIFS('PL1.1 ML2027-2028'!$G:$G,'PL1.1 ML2027-2028'!$J:$J,"TD",'PL1.1 ML2027-2028'!$M:$M,"Mạng cáp",'PL1.1 ML2027-2028'!$K:$K,'TH theo dich vu'!C9)/$D$1 -> 0 | J9: =SUMIFS('PL1.1 ML2027-2028'!$G:$G,'PL1.1 ML2027-2028'!$J:$J,'TH theo dich vu'!$J$3,'PL1.1 ML2027-2028'!$K:$K,'TH theo dich vu'!C9)/$D$1 -> 0 | K9: =SUMIFS('PL1.1 ML2027-2028'!$G:$G,'PL1.1 ML2027-2028'!$J:$J,'TH theo dich vu'!K$3,'PL1.1 ML2027-2028'!$K:$K,'TH theo dich vu'!C9)/$D$1 -> 0 | L9: =SUM(D9:K9) -> 0.836372 | M9: =SUM(D9:K9) -> 0.836372 | N9: =L9/$L$4 -> 0.0075482081 | O9: =SUMIFS('PL1.1 ML2027-2028'!$H:$H,'PL1.1 ML2027-2028'!$J:$J,'TH theo dich vu'!O$3,'PL1.1 ML2027-2028'!$K:$K,'TH theo dich vu'!$C9)/$D$1 -> 0 | P9: =SUMIFS('PL1.1 ML2027-2028'!$H:$H,'PL1.1 ML2027-2028'!$J:$J,'TH theo dich vu'!P$3,'PL1.1 ML2027-2028'!$K:$K,'TH theo dich vu'!$C9)/$D$1 -> 0 | Q9: =SUMIFS('PL1.1 ML2027-2028'!$H:$H,'PL1.1 ML2027-2028'!$J:$J,'TH theo dich vu'!Q$3,'PL1.1 ML2027-2028'!$K:$K,'TH theo dich vu'!$C9)/$D$1 -> 0 | R9: =SUMIFS('PL1.1 ML2027-2028'!$H:$H,'PL1.1 ML2027-2028'!$J:$J,'TH theo dich vu'!R$3,'PL1.1 ML2027-2028'!$K:$K,'TH theo dich vu'!$C9)/$D$1 -> 0.836372 | S9: =SUMIFS('PL1.1 ML2027-2028'!$H:$H,'PL1.1 ML2027-2028'!$J:$J,"TD",'PL1.1 ML2027-2028'!$M:$M,"IP",'PL1.1 ML2027-2028'!$K:$K,'TH theo dich vu'!C9)/$D$1 -> 0 | T9: =SUMIFS('PL1.1 ML2027-2028'!$H:$H,'PL1.1 ML2027-2028'!$J:$J,"TD",'PL1.1 ML2027-2028'!$M:$M,"Mạng cáp",'PL1.1 ML2027-2028'!$K:$K,'TH theo dich vu'!C9)/$D$1 -> 0 | U9: =SUMIFS('PL1.1 ML2027-2028'!$H:$H,'PL1.1 ML2027-2028'!$J:$J,'TH theo dich vu'!U$3,'PL1.1 ML2027-2028'!$K:$K,'TH theo dich vu'!$C9)/$D$1 -> 0 | V9: =SUMIFS('PL1.1 ML2027-2028'!$H:$H,'PL1.1 ML2027-2028'!$J:$J,'TH theo dich vu'!V$3,'PL1.1 ML2027-2028'!$K:$K,'TH theo dich vu'!$C9)/$D$1 -> 0 | W9: =SUM(O9:V9) -> 0.836372 | X9: =SUM(O9:V9) -> 0.836372 | Z9: =D9+O9 -> 0 | AA9: =E9+P9 -> 0 | AB9: =F9+Q9 -> 0 | AC9: =G9+R9 -> 1.672744 | AD9: =H9+S9 -> 0 | AE9: =I9+T9 -> 0 | AF9: =J9+U9 -> 0 | AG9: =K9+V9 -> 0 | AH9: =SUM(Z9:AG9) -> 1.672744 | AI9: =AH9/$AH$4 -> 0.0083232002 | AO9: 0.52 | AP9: 0.48
A10: 4 | B10: Private Mobile Network | C10: PMN | D10: =SUMIFS('PL1.1 ML2027-2028'!$G:$G,'PL1.1 ML2027-2028'!$J:$J,'TH theo dich vu'!$D$3,'PL1.1 ML2027-2028'!$K:$K,'TH theo dich vu'!C10)/$D$1 -> 0 | E10: =SUMIFS('PL1.1 ML2027-2028'!$G:$G,'PL1.1 ML2027-2028'!$J:$J,'TH theo dich vu'!$E$3,'PL1.1 ML2027-2028'!$K:$K,'TH theo dich vu'!C10)/$D$1 -> 0 | F10: =SUMIFS('PL1.1 ML2027-2028'!$G:$G,'PL1.1 ML2027-2028'!$J:$J,'TH theo dich vu'!$F$3,'PL1.1 ML2027-2028'!$K:$K,'TH theo dich vu'!C10)/$D$1 -> 0 | G10: =SUMIFS('PL1.1 ML2027-2028'!$G:$G,'PL1.1 ML2027-2028'!$J:$J,'TH theo dich vu'!$G$3,'PL1.1 ML2027-2028'!$K:$K,'TH theo dich vu'!C10)/$D$1 -> 0 | H10: =SUMIFS('PL1.1 ML2027-2028'!$G:$G,'PL1.1 ML2027-2028'!$J:$J,"TD",'PL1.1 ML2027-2028'!$M:$M,"IP",'PL1.1 ML2027-2028'!$K:$K,'TH theo dich vu'!C10)/$D$1 -> 0 | I10: =SUMIFS('PL1.1 ML2027-2028'!$G:$G,'PL1.1 ML2027-2028'!$J:$J,"TD",'PL1.1 ML2027-2028'!$M:$M,"Mạng cáp",'PL1.1 ML2027-2028'!$K:$K,'TH theo dich vu'!C10)/$D$1 -> 0 | J10: =SUMIFS('PL1.1 ML2027-2028'!$G:$G,'PL1.1 ML2027-2028'!$J:$J,'TH theo dich vu'!$J$3,'PL1.1 ML2027-2028'!$K:$K,'TH theo dich vu'!C10)/$D$1 -> 0 | K10: =SUMIFS('PL1.1 ML2027-2028'!$G:$G,'PL1.1 ML2027-2028'!$J:$J,'TH theo dich vu'!K$3,'PL1.1 ML2027-2028'!$K:$K,'TH theo dich vu'!C10)/$D$1 -> 0 | L10: =SUM(D10:K10) -> 0 | M10: =SUM(D10:K10) -> 0 | N10: =L10/$L$4 -> 0 | O10: =SUMIFS('PL1.1 ML2027-2028'!$H:$H,'PL1.1 ML2027-2028'!$J:$J,'TH theo dich vu'!O$3,'PL1.1 ML2027-2028'!$K:$K,'TH theo dich vu'!$C10)/$D$1 -> 0 | P10: =SUMIFS('PL1.1 ML2027-2028'!$H:$H,'PL1.1 ML2027-2028'!$J:$J,'TH theo dich vu'!P$3,'PL1.1 ML2027-2028'!$K:$K,'TH theo dich vu'!$C10)/$D$1 -> 0 | Q10: =SUMIFS('PL1.1 ML2027-2028'!$H:$H,'PL1.1 ML2027-2028'!$J:$J,'TH theo dich vu'!Q$3,'PL1.1 ML2027-2028'!$K:$K,'TH theo dich vu'!$C10)/$D$1 -> 0 | R10: =SUMIFS('PL1.1 ML2027-2028'!$H:$H,'PL1.1 ML2027-2028'!$J:$J,'TH theo dich vu'!R$3,'PL1.1 ML2027-2028'!$K:$K,'TH theo dich vu'!$C10)/$D$1 -> 0 | S10: =SUMIFS('PL1.1 ML2027-2028'!$H:$H,'PL1.1 ML2027-2028'!$J:$J,"TD",'PL1.1 ML2027-2028'!$M:$M,"IP",'PL1.1 ML2027-2028'!$K:$K,'TH theo dich vu'!C10)/$D$1 -> 0 | T10: =SUMIFS('PL1.1 ML2027-2028'!$H:$H,'PL1.1 ML2027-2028'!$J:$J,"TD",'PL1.1 ML2027-2028'!$M:$M,"Mạng cáp",'PL1.1 ML2027-2028'!$K:$K,'TH theo dich vu'!C10)/$D$1 -> 0 | U10: =SUMIFS('PL1.1 ML2027-2028'!$H:$H,'PL1.1 ML2027-2028'!$J:$J,'TH theo dich vu'!U$3,'PL1.1 ML2027-2028'!$K:$K,'TH theo dich vu'!$C10)/$D$1 -> 0 | V10: =SUMIFS('PL1.1 ML2027-2028'!$H:$H,'PL1.1 ML2027-2028'!$J:$J,'TH theo dich vu'!V$3,'PL1.1 ML2027-2028'!$K:$K,'TH theo dich vu'!$C10)/$D$1 -> 0 | W10: =SUM(O10:V10) -> 0 | X10: =SUM(O10:V10) -> 0 | Z10: =D10+O10 -> 0 | AA10: =E10+P10 -> 0 | AB10: =F10+Q10 -> 0 | AC10: =G10+R10 -> 0 | AD10: =H10+S10 -> 0 | AE10: =I10+T10 -> 0 | AF10: =J10+U10 -> 0 | AG10: =K10+V10 -> 0 | AH10: =SUM(Z10:AG10) -> 0 | AI10: =AH10/$AH$4 -> 0 | AJ10: 1
A11: II | B11: Mở rộng mạng lưới hiện tại cho kinh doanh | D11: =SUBTOTAL(9,D12:D28) -> 39.611989 | E11: =SUBTOTAL(9,E12:E28) -> 2.98235 | F11: =SUBTOTAL(9,F12:F28) -> 1.0754468 | G11: =SUBTOTAL(9,G12:G28) -> 15.582282 | H11: =SUBTOTAL(9,H12:H28) -> 8.4989447 | I11: =SUBTOTAL(9,I12:I28) -> 5.43998 | J11: =SUBTOTAL(9,J12:J28) -> 5.8563325 | K11: =SUBTOTAL(9,K12:K28) -> 10.606754 | L11: =SUBTOTAL(9,L13:L28) -> 89.654079 | M11: =SUBTOTAL(9,M13:M28) -> 89.654079 | N11: =L11/$L$4 -> 0.80912279 | O11: =SUBTOTAL(9,O12:O25) -> 23.890997 | P11: =SUBTOTAL(9,P12:P25) -> 0 | Q11: =SUBTOTAL(9,Q12:Q25) -> 0.43173884 | R11: =SUBTOTAL(9,R12:R25) -> 17.900934 | S11: =SUBTOTAL(9,S12:S28) -> 4.87838 | T11: =SUBTOTAL(9,T12:T28) -> 2.3974304 | U11: =SUBTOTAL(9,U12:U25) -> 5.1952654 | V11: =SUBTOTAL(9,V12:V28) -> 6.1510614 | W11: =SUBTOTAL(9,W13:W28) -> 60.845808 | X11: =SUBTOTAL(9,X13:X28) -> 60.845808 | Y11: =W11/$W$4 -> 0.67479282 | Z11: =SUBTOTAL(9,Z12:Z32) -> 68.2451 | AA11: =SUBTOTAL(9,AA12:AA32) -> 8.95001 | AB11: =SUBTOTAL(9,AB12:AB32) -> 1.8018647 | AC11: =SUBTOTAL(9,AC12:AC32) -> 39.074576 | AD11: =SUBTOTAL(9,AD12:AD32) -> 21.650407 | AE11: =SUBTOTAL(9,AE12:AE32) -> 18.777153 | AF11: =SUBTOTAL(9,AF12:AF32) -> 24.04399 | AG11: =SUBTOTAL(9,AG12:AG32) -> 16.757815 | AH11: =SUBTOTAL(9,AH12:AH25) -> 150.49989 | AI11: =AH11/$AH$4 -> 0.74885379
A12: 1 | B12: Mạng 2/3/4G | D12: =SUBTOTAL(9,D13:D14) -> 39.611989 | E12: =SUBTOTAL(9,E13:E14) -> 2.98235 | F12: =SUBTOTAL(9,F13:F14) -> 0 | G12: =SUBTOTAL(9,G13:G14) -> 0 | H12: =SUBTOTAL(9,H13:H14) -> 6.3373152 | I12: =SUBTOTAL(9,I13:I14) -> 4.5213812 | J12: =SUBTOTAL(9,J13:J14) -> 5.8563325 | K12: =SUBTOTAL(9,K13:K14) -> 10.606754 | ... M12: =SUBTOTAL(9,M13:M14) -> 69.916122 | N12: =L12/$L$4 -> 0.63098889 | O12: =SUBTOTAL(9,O13:O14) -> 23.890997 | P12: =SUBTOTAL(9,P13:P14) -> 0 | Q12: =SUBTOTAL(9,Q13:Q14) -> 0 | R12: =SUBTOTAL(9,R13:R14) -> 0 | S12: =SUBTOTAL(9,S13:S14) -> 4.5843471 | T12: =SUBTOTAL(9,T13:T14) -> 2.2535846 | U12: =SUBTOTAL(9,U13:U14) -> 5.1952654 | V12: =SUBTOTAL(9,V13:V14) -> 6.1510614 | ... X12: =SUBTOTAL(9,X13:X14) -> 42.075256 | Y12: =W12/$W$4 -> 0.46662345 | Z12: =SUBTOTAL(9,Z13:Z14) -> 63.502987 | AA12: =SUBTOTAL(9,AA13:AA14) -> 2.98235 | AB12: =SUBTOTAL(9,AB13:AB14) -> 0 | AC12: =SUBTOTAL(9,AC13:AC14) -> 0 | AD12: =SUBTOTAL(9,AD13:AD14) -> 10.921662 | AE12: =SUBTOTAL(9,AE13:AE14) -> 6.7749658 | AF12: =SUBTOTAL(9,AF13:AF14) -> 11.051598 | AG12: =SUBTOTAL(9,AG13:AG14) -> 16.757815 | AH12: =SUBTOTAL(9,AH13:AH14) -> 111.99138 | AI12: =AH12/$AH$4 -> 0.55724406 | AJ12: 1
A13: - | B13: 2/3/4G vùng phủ | C13: VPDĐ | D13: =SUMIFS('PL1.1 ML2027-2028'!$G:$G,'PL1.1 ML2027-2028'!$J:$J,'TH theo dich vu'!$D$3,'PL1.1 ML2027-2028'!$K:$K,'TH theo dich vu'!C13)/$D$1 -> 4.178882 | E13: =SUMIFS('PL1.1 ML2027-2028'!$G:$G,'PL1.1 ML2027-2028'!$J:$J,'TH theo dich vu'!$E$3,'PL1.1 ML2027-2028'!$K:$K,'TH theo dich vu'!C13)/$D$1 -> 0 | F13: =SUMIFS('PL1.1 ML2027-2028'!$G:$G,'PL1.1 ML2027-2028'!$J:$J,'TH theo dich vu'!$F$3,'PL1.1 ML2027-2028'!$K:$K,'TH theo dich vu'!C13)/$D$1 -> 0 | G13: =SUMIFS('PL1.1 ML2027-2028'!$G:$G,'PL1.1 ML2027-2028'!$J:$J,'TH theo dich vu'!$G$3,'PL1.1 ML2027-2028'!$K:$K,'TH theo dich vu'!C13)/$D$1 -> 0 | H13: =SUMIFS('PL1.1 ML2027-2028'!$G:$G,'PL1.1 ML2027-2028'!$J:$J,"TD",'PL1.1 ML2027-2028'!$M:$M,"IP",'PL1.1 ML2027-2028'!$K:$K,'TH theo dich vu'!C13)/$D$1 -> 0.47038034 | I13: =SUMIFS('PL1.1 ML2027-2028'!$G:$G,'PL1.1 ML2027-2028'!$J:$J,"TD",'PL1.1 ML2027-2028'!$M:$M,"Mạng cáp",'PL1.1 ML2027-2028'!$K:$K,'TH theo dich vu'!C13)/$D$1 -> 0.79282 | J13: =SUMIFS('PL1.1 ML2027-2028'!$G:$G,'PL1.1 ML2027-2028'!$J:$J,'TH theo dich vu'!$J$3,'PL1.1 ML2027-2028'!$K:$K,'TH theo dich vu'!C13)/$D$1 -> 4.3349205 | K13: =SUMIFS('PL1.1 ML2027-2028'!$G:$G,'PL1.1 ML2027-2028'!$J:$J,'TH theo dich vu'!K$3,'PL1.1 ML2027-2028'!$K:$K,'TH theo dich vu'!C13)/$D$1 -> 6.8656099 | L13: =SUM(D13:K13) -> 16.642613 | M13: =SUM(D13:K13) -> 16.642613 | N13: =L13/$L$4 -> 0.1501986 | O13: =SUMIFS('PL1.1 ML2027-2028'!$H:$H,'PL1.1 ML2027-2028'!$J:$J,'TH theo dich vu'!O$3,'PL1.1 ML2027-2028'!$K:$K,'TH theo dich vu'!$C13)/$D$1 -> 3.876778 | P13: =SUMIFS('PL1.1 ML2027-2028'!$H:$H,'PL1.1 ML2027-2028'!$J:$J,'TH theo dich vu'!P$3,'PL1.1 ML2027-2028'!$K:$K,'TH theo dich vu'!$C13)/$D$1 -> 0 | Q13: =SUMIFS('PL1.1 ML2027-2028'!$H:$H,'PL1.1 ML2027-2028'!$J:$J,'TH theo dich vu'!Q$3,'PL1.1 ML2027-2028'!$K:$K,'TH theo dich vu'!$C13)/$D$1 -> 0 | R13: =SUMIFS('PL1.1 ML2027-2028'!$H:$H,'PL1.1 ML2027-2028'!$J:$J,'TH theo dich vu'!R$3,'PL1.1 ML2027-2028'!$K:$K,'TH theo dich vu'!$C13)/$D$1 -> 0 | S13: =SUMIFS('PL1.1 ML2027-2028'!$H:$H,'PL1.1 ML2027-2028'!$J:$J,"TD",'PL1.1 ML2027-2028'!$M:$M,"IP",'PL1.1 ML2027-2028'!$K:$K,'TH theo dich vu'!C13)/$D$1 -> 0.57228616 | T13: =SUMIFS('PL1.1 ML2027-2028'!$H:$H,'PL1.1 ML2027-2028'!$J:$J,"TD",'PL1.1 ML2027-2028'!$M:$M,"Mạng cáp",'PL1.1 ML2027-2028'!$K:$K,'TH theo dich vu'!C13)/$D$1 -> 0.8756884 | U13: =SUMIFS('PL1.1 ML2027-2028'!$H:$H,'PL1.1 ML2027-2028'!$J:$J,'TH theo dich vu'!U$3,'PL1.1 ML2027-2028'!$K:$K,'TH theo dich vu'!$C13)/$D$1 -> 4.62254 | V13: =SUMIFS('PL1.1 ML2027-2028'!$H:$H,'PL1.1 ML2027-2028'!$J:$J,'TH theo dich vu'!V$3,'PL1.1 ML2027-2028'!$K:$K,'TH theo dich vu'!$C13)/$D$1 -> 5.855102 | W13: =SUM(O13:V13) -> 15.802395 | X13: =SUM(O13:V13) -> 15.802395 | Z13: =D13+O13 -> 8.05566 | AA13: =E13+P13 -> 0 | AB13: =F13+Q13 -> 0 | AC13: =G13+R13 -> 0 | AD13: =H13+S13 -> 1.0426665 | AE13: =I13+T13 -> 1.6685084 | AF13: =J13+U13 -> 8.9574605 | AG13: =K13+V13 -> 12.720712 | AH13: =SUM(Z13:AG13) -> 32.445007 | AI13: =AH13/$AH$4 -> 0.1614391
A14: - | B14: 2/3/4G dung lượng | C14: DLDĐ | D14: =SUMIFS('PL1.1 ML2027-2028'!$G:$G,'PL1.1 ML2027-2028'!$J:$J,'TH theo dich vu'!$D$3,'PL1.1 ML2027-2028'!$K:$K,'TH theo dich vu'!C14)/$D$1 -> 35.433107 | E14: =SUMIFS('PL1.1 ML2027-2028'!$G:$G,'PL1.1 ML2027-2028'!$J:$J,'TH theo dich vu'!$E$3,'PL1.1 ML2027-2028'!$K:$K,'TH theo dich vu'!C14)/$D$1 -> 2.98235 | F14: =SUMIFS('PL1.1 ML2027-2028'!$G:$G,'PL1.1 ML2027-2028'!$J:$J,'TH theo dich vu'!$F$3,'PL1.1 ML2027-2028'!$K:$K,'TH theo dich vu'!C14)/$D$1 -> 0 | G14: =SUMIFS('PL1.1 ML2027-2028'!$G:$G,'PL1.1 ML2027-2028'!$J:$J,'TH theo dich vu'!$G$3,'PL1.1 ML2027-2028'!$K:$K,'TH theo dich vu'!C14)/$D$1 -> 0 | H14: =(SUMIFS('PL1.1 ML2027-2028'!$G:$G,'PL1.1 ML2027-2028'!$J:$J,"TD",'PL1.1 ML2027-2028'!$M:$M,"IP",'PL1.1 ML2027-2028'!$K:$K,'TH theo dich vu'!C27)/$D$1+SUMIFS('PL1.1 ML2027-2028'!$G:$G,'PL1.1 ML2027-2028'!$J:$J,"TD",'PL1.1 ML2027-2028'!$M:$M,"IP",'PL1.1 ML2027-2028'!$K:$K,'TH theo dich vu'!C28)/$D$1+SUMIFS('PL1.1 ML2027-2028'!$G:$G,'PL1.1 ML2027-2028'!$J:$J,"TD",'PL1.1 ML2027-2028'!$M:$M,"IP",'PL1.1 ML2027-2028'!$K:$K,'TH theo dich vu'!C14)/$D$1+SUMIFS('PL1.1 ML2027-2028'!$G:$G,'PL1.1 ML2027-2028'!$J:$J,"TD",'PL1.1 ML2027-2028'!$M:$M,"IP",'PL1.1 ML2027-2028'!$K:$K,'TH theo dich vu'!C13)/$D$1)*0.94-H13 -> 5.8669349 | I14: =(SUMIFS('PL1.1 ML2027-2028'!$G:$G,'PL1.1 ML2027-2028'!$J:$J,"TD",'PL1.1 ML2027-2028'!$M:$M,"Mạng cáp",'PL1.1 ML2027-2028'!$K:$K,'TH theo dich vu'!C27)/$D$1+SUMIFS('PL1.1 ML2027-2028'!$G:$G,'PL1.1 ML2027-2028'!$J:$J,"TD",'PL1.1 ML2027-2028'!$M:$M,"Mạng cáp",'PL1.1 ML2027-2028'!$K:$K,'TH theo dich vu'!C28)/$D$1+SUMIFS('PL1.1 ML2027-2028'!$G:$G,'PL1.1 ML2027-2028'!$J:$J,"TD",'PL1.1 ML2027-2028'!$M:$M,"Mạng cáp",'PL1.1 ML2027-2028'!$K:$K,'TH theo dich vu'!C14)/$D$1+SUMIFS('PL1.1 ML2027-2028'!$G:$G,'PL1.1 ML2027-2028'!$J:$J,"TD",'PL1.1 ML2027-2028'!$M:$M,"Mạng cáp",'PL1.1 ML2027-2028'!$K:$K,'TH theo dich vu'!C13)/$D$1)*0.94-I13 -> 3.7285612 | J14: =SUMIFS('PL1.1 ML2027-2028'!$G:$G,'PL1.1 ML2027-2028'!$J:$J,'TH theo dich vu'!$J$3,'PL1.1 ML2027-2028'!$K:$K,'TH theo dich vu'!C14)/$D$1 -> 1.521412 | K14: =SUMIFS('PL1.1 ML2027-2028'!$G:$G,'PL1.1 ML2027-2028'!$J:$J,'TH theo dich vu'!K$3,'PL1.1 ML2027-2028'!$K:$K,'TH theo dich vu'!C14)/$D$1 -> 3.7411439 | L14: =SUM(D14:K14) -> 53.273509 | M14: =SUM(D14:K14) -> 53.273509 | N14: =L14/$L$4 -> 0.48079029 | O14: =SUMIFS('PL1.1 ML2027-2028'!$H:$H,'PL1.1 ML2027-2028'!$J:$J,'TH theo dich vu'!O$3,'PL1.1 ML2027-2028'!$K:$K,'TH theo dich vu'!$C14)/$D$1 -> 20.014219 | P14: =SUMIFS('PL1.1 ML2027-2028'!$H:$H,'PL1.1 ML2027-2028'!$J:$J,'TH theo dich vu'!P$3,'PL1.1 ML2027-2028'!$K:$K,'TH theo dich vu'!$C14)/$D$1 -> 0 | Q14: =SUMIFS('PL1.1 ML2027-2028'!$H:$H,'PL1.1 ML2027-2028'!$J:$J,'TH theo dich vu'!Q$3,'PL1.1 ML2027-2028'!$K:$K,'TH theo dich vu'!$C14)/$D$1 -> 0 | R14: =SUMIFS('PL1.1 ML2027-2028'!$H:$H,'PL1.1 ML2027-2028'!$J:$J,'TH theo dich vu'!R$3,'PL1.1 ML2027-2028'!$K:$K,'TH theo dich vu'!$C14)/$D$1 -> 0 | S14: =(SUMIFS('PL1.1 ML2027-2028'!$H:$H,'PL1.1 ML2027-2028'!$J:$J,"TD",'PL1.1 ML2027-2028'!$M:$M,"IP",'PL1.1 ML2027-2028'!$K:$K,'TH theo dich vu'!C27)/$D$1+SUMIFS('PL1.1 ML2027-2028'!$H:$H,'PL1.1 ML2027-2028'!$J:$J,"TD",'PL1.1 ML2027-2028'!$M:$M,"IP",'PL1.1 ML2027-2028'!$K:$K,'TH theo dich vu'!C28)/$D$1+SUMIFS('PL1.1 ML2027-2028'!$H:$H,'PL1.1 ML2027-2028'!$J:$J,"TD",'PL1.1 ML2027-2028'!$M:$M,"IP",'PL1.1 ML2027-2028'!$K:$K,'TH theo dich vu'!C14)/$D$1+SUMIFS('PL1.1 ML2027-2028'!$H:$H,'PL1.1 ML2027-2028'!$J:$J,"TD",'PL1.1 ML2027-2028'!$M:$M,"IP",'PL1.1 ML2027-2028'!$K:$K,'TH theo dich vu'!C13)/$D$1)*0.94-S13 -> 4.012061 | T14: =(SUMIFS('PL1.1 ML2027-2028'!$H:$H,'PL1.1 ML2027-2028'!$J:$J,"TD",'PL1.1 ML2027-2028'!$M:$M,"Mạng cáp",'PL1.1 ML2027-2028'!$K:$K,'TH theo dich vu'!C27)/$D$1+SUMIFS('PL1.1 ML2027-2028'!$H:$H,'PL1.1 ML2027-2028'!$J:$J,"TD",'PL1.1 ML2027-2028'!$M:$M,"Mạng cáp",'PL1.1 ML2027-2028'!$K:$K,'TH theo dich vu'!C28)/$D$1+SUMIFS('PL1.1 ML2027-2028'!$H:$H,'PL1.1 ML2027-2028'!$J:$J,"TD",'PL1.1 ML2027-2028'!$M:$M,"Mạng cáp",'PL1.1 ML2027-2028'!$K:$K,'TH theo dich vu'!C14)/$D$1+SUMIFS('PL1.1 ML2027-2028'!$H:$H,'PL1.1 ML2027-2028'!$J:$J,"TD",'PL1.1 ML2027-2028'!$M:$M,"Mạng cáp",'PL1.1 ML2027-2028'!$K:$K,'TH theo dich vu'!C13)/$D$1)*0.94-T13 -> 1.3778962 | U14: =SUMIFS('PL1.1 ML2027-2028'!$H:$H,'PL1.1 ML2027-2028'!$J:$J,'TH theo dich vu'!U$3,'PL1.1 ML2027-2028'!$K:$K,'TH theo dich vu'!$C14)/$D$1 -> 0.5727254 | V14: =SUMIFS('PL1.1 ML2027-2028'!$H:$H,'PL1.1 ML2027-2028'!$J:$J,'TH theo dich vu'!V$3,'PL1.1 ML2027-2028'!$K:$K,'TH theo dich vu'!$C14)/$D$1 -> 0.29595936 | W14: =SUM(O14:V14) -> 26.272861 | X14: =SUM(O14:V14) -> 26.272861 | Z14: =D14+O14 -> 55.447327 | AA14: =E14+P14 -> 2.98235 | AB14: =F14+Q14 -> 0 | AC14: =G14+R14 -> 0 | AD14: =H14+S14 -> 9.8789959 | AE14: =I14+T14 -> 5.1064574 | AF14: =J14+U14 -> 2.0941374 | AG14: =K14+V14 -> 4.0371033 | AH14: =SUM(Z14:AG14) -> 79.546371 | AI14: =AH14/$AH$4 -> 0.39580496
A15: 2 | B15: Mạng BRCĐ&TH | D15: =SUBTOTAL(9,D16:D19) -> 0 | E15: =SUBTOTAL(9,E16:E19) -> 0 | F15: =SUBTOTAL(9,F16:F19) -> 1.0754468 | G15: =SUBTOTAL(9,G16:G19) -> 0 | H15: =SUBTOTAL(9,H16:H19) -> 0.40450948 | I15: =SUBTOTAL(9,I16:I19) -> 0.2885988 | J15: =SUBTOTAL(9,J16:J19) -> 0 | K15: =SUBTOTAL(9,K16:K19) -> 0 | ... M15: =SUBTOTAL(9,M16:M19) -> 1.7685551 | N15: =L15/$L$4 -> 0.015961106 | O15: =SUBTOTAL(9,O16:O19) -> 0 | P15: =SUBTOTAL(9,P16:P19) -> 0 | Q15: =SUBTOTAL(9,Q16:Q19) -> 0.43173884 | R15: =SUBTOTAL(9,R16:R19) -> 0 | S15: =SUBTOTAL(9,S16:S19) -> 0.2926179 | T15: =SUBTOTAL(9,T16:T19) -> 0.14384582 | U15: =SUBTOTAL(9,U16:U19) -> 0 | V15: =SUBTOTAL(9,V16:V19) -> 0 | ... X15: =SUBTOTAL(9,X16:X19) -> 0.86820256 | Y15: =W15/$W$4 -> 0.0096285493 | Z15: =SUBTOTAL(9,Z16:Z19) -> 0 | AA15: =SUBTOTAL(9,AA16:AA19) -> 0 | AB15: =SUBTOTAL(9,AB16:AB19) -> 1.5071857 | AC15: =SUBTOTAL(9,AC16:AC19) -> 0 | AD15: =SUBTOTAL(9,AD16:AD19) -> 0.69712738 | AE15: =SUBTOTAL(9,AE16:AE19) -> 0.43244462 | AF15: =SUBTOTAL(9,AF16:AF19) -> 0 | AG15: =SUBTOTAL(9,AG16:AG19) -> 0 | AH15: =SUBTOTAL(9,AH16:AH19) -> 2.6367577 | AI15: =AH15/$AH$4 -> 0.013119917
A16: - | B16: Vùng phủ GPON | C16: VPGPON | D16: =SUMIFS('PL1.1 ML2027-2028'!$G:$G,'PL1.1 ML2027-2028'!$J:$J,'TH theo dich vu'!$D$3,'PL1.1 ML2027-2028'!$K:$K,'TH theo dich vu'!C16)/$D$1 -> 0 | E16: =SUMIFS('PL1.1 ML2027-2028'!$G:$G,'PL1.1 ML2027-2028'!$J:$J,'TH theo dich vu'!$E$3,'PL1.1 ML2027-2028'!$K:$K,'TH theo dich vu'!C16)/$D$1 -> 0 | F16: =SUMIFS('PL1.1 ML2027-2028'!$G:$G,'PL1.1 ML2027-2028'!$J:$J,'TH theo dich vu'!$F$3,'PL1.1 ML2027-2028'!$K:$K,'TH theo dich vu'!C16)/$D$1 -> 0.77179484 | G16: =SUMIFS('PL1.1 ML2027-2028'!$G:$G,'PL1.1 ML2027-2028'!$J:$J,'TH theo dich vu'!$G$3,'PL1.1 ML2027-2028'!$K:$K,'TH theo dich vu'!C16)/$D$1 -> 0 | H16: =SUMIFS('PL1.1 ML2027-2028'!$G:$G,'PL1.1 ML2027-2028'!$J:$J,"TD",'PL1.1 ML2027-2028'!$M:$M,"IP",'PL1.1 ML2027-2028'!$K:$K,'TH theo dich vu'!C16)/$D$1 -> 0 | I16: =SUMIFS('PL1.1 ML2027-2028'!$G:$G,'PL1.1 ML2027-2028'!$J:$J,"TD",'PL1.1 ML2027-2028'!$M:$M,"Mạng cáp",'PL1.1 ML2027-2028'!$K:$K,'TH theo dich vu'!C16)/$D$1 -> 0 | J16: =SUMIFS('PL1.1 ML2027-2028'!$G:$G,'PL1.1 ML2027-2028'!$J:$J,'TH theo dich vu'!$J$3,'PL1.1 ML2027-2028'!$K:$K,'TH theo dich vu'!C16)/$D$1 -> 0 | K16: =SUMIFS('PL1.1 ML2027-2028'!$G:$G,'PL1.1 ML2027-2028'!$J:$J,'TH theo dich vu'!K$3,'PL1.1 ML2027-2028'!$K:$K,'TH theo dich vu'!C16)/$D$1 -> 0 | L16: =SUM(D16:K16) -> 0.77179484 | M16: =SUM(D16:K16) -> 0.77179484 | N16: =L16/$L$4 -> 0.006965403 | O16: =SUMIFS('PL1.1 ML2027-2028'!$H:$H,'PL1.1 ML2027-2028'!$J:$J,'TH theo dich vu'!O$3,'PL1.1 ML2027-2028'!$K:$K,'TH theo dich vu'!$C16)/$D$1 -> 0 | P16: =SUMIFS('PL1.1 ML2027-2028'!$H:$H,'PL1.1 ML2027-2028'!$J:$J,'TH theo dich vu'!P$3,'PL1.1 ML2027-2028'!$K:$K,'TH theo dich vu'!$C16)/$D$1 -> 0 | Q16: =SUMIFS('PL1.1 ML2027-2028'!$H:$H,'PL1.1 ML2027-2028'!$J:$J,'TH theo dich vu'!Q$3,'PL1.1 ML2027-2028'!$K:$K,'TH theo dich vu'!$C16)/$D$1 -> 0.17173884 | R16: =SUMIFS('PL1.1 ML2027-2028'!$H:$H,'PL1.1 ML2027-2028'!$J:$J,'TH theo dich vu'!R$3,'PL1.1 ML2027-2028'!$K:$K,'TH theo dich vu'!$C16)/$D$1 -> 0 | S16: =SUMIFS('PL1.1 ML2027-2028'!$H:$H,'PL1.1 ML2027-2028'!$J:$J,"TD",'PL1.1 ML2027-2028'!$M:$M,"IP",'PL1.1 ML2027-2028'!$K:$K,'TH theo dich vu'!C16)/$D$1 -> 0 | T16: =SUMIFS('PL1.1 ML2027-2028'!$H:$H,'PL1.1 ML2027-2028'!$J:$J,"TD",'PL1.1 ML2027-2028'!$M:$M,"Mạng cáp",'PL1.1 ML2027-2028'!$K:$K,'TH theo dich vu'!C16)/$D$1 -> 0 | U16: =SUMIFS('PL1.1 ML2027-2028'!$H:$H,'PL1.1 ML2027-2028'!$J:$J,'TH theo dich vu'!U$3,'PL1.1 ML2027-2028'!$K:$K,'TH theo dich vu'!$C16)/$D$1 -> 0 | V16: =SUMIFS('PL1.1 ML2027-2028'!$H:$H,'PL1.1 ML2027-2028'!$J:$J,'TH theo dich vu'!V$3,'PL1.1 ML2027-2028'!$K:$K,'TH theo dich vu'!$C16)/$D$1 -> 0 | W16: =SUM(O16:V16) -> 0.17173884 | X16: =SUM(O16:V16) -> 0.17173884 | Z16: =D16+O16 -> 0 | AA16: =E16+P16 -> 0 | AB16: =F16+Q16 -> 0.94353368 | AC16: =G16+R16 -> 0 | AD16: =H16+S16 -> 0 | AE16: =I16+T16 -> 0 | AF16: =J16+U16 -> 0 | AG16: =K16+V16 -> 0 | AH16: =SUM(Z16:AG16) -> 0.94353368 | AI16: =AH16/$AH$4 -> 0.0046948126 | AL16: 1
A17: - | B17: Dung lượng Internet | C17: DLGPON | D17: =SUMIFS('PL1.1 ML2027-2028'!$G:$G,'PL1.1 ML2027-2028'!$J:$J,'TH theo dich vu'!$D$3,'PL1.1 ML2027-2028'!$K:$K,'TH theo dich vu'!C17)/$D$1 -> 0 | E17: =SUMIFS('PL1.1 ML2027-2028'!$G:$G,'PL1.1 ML2027-2028'!$J:$J,'TH theo dich vu'!$E$3,'PL1.1 ML2027-2028'!$K:$K,'TH theo dich vu'!C17)/$D$1 -> 0 | F17: =SUMIFS('PL1.1 ML2027-2028'!$G:$G,'PL1.1 ML2027-2028'!$J:$J,'TH theo dich vu'!$F$3,'PL1.1 ML2027-2028'!$K:$K,'TH theo dich vu'!C17)/$D$1 -> 0.303652 | G17: =SUMIFS('PL1.1 ML2027-2028'!$G:$G,'PL1.1 ML2027-2028'!$J:$J,'TH theo dich vu'!$G$3,'PL1.1 ML2027-2028'!$K:$K,'TH theo dich vu'!C17)/$D$1 -> 0 | H17: =(SUMIFS('PL1.1 ML2027-2028'!$G:$G,'PL1.1 ML2027-2028'!$J:$J,"TD",'PL1.1 ML2027-2028'!$M:$M,"IP",'PL1.1 ML2027-2028'!$K:$K,'TH theo dich vu'!C27)/$D$1+SUMIFS('PL1.1 ML2027-2028'!$G:$G,'PL1.1 ML2027-2028'!$J:$J,"TD",'PL1.1 ML2027-2028'!$M:$M,"IP",'PL1.1 ML2027-2028'!$K:$K,'TH theo dich vu'!C28)/$D$1+SUMIFS('PL1.1 ML2027-2028'!$G:$G,'PL1.1 ML2027-2028'!$J:$J,"TD",'PL1.1 ML2027-2028'!$M:$M,"IP",'PL1.1 ML2027-2028'!$K:$K,'TH theo dich vu'!C14)/$D$1+SUMIFS('PL1.1 ML2027-2028'!$G:$G,'PL1.1 ML2027-2028'!$J:$J,"TD",'PL1.1 ML2027-2028'!$M:$M,"IP",'PL1.1 ML2027-2028'!$K:$K,'TH theo dich vu'!C13)/$D$1)*0.06 -> 0.40450948 | I17: =(SUMIFS('PL1.1 ML2027-2028'!$G:$G,'PL1.1 ML2027-2028'!$J:$J,"TD",'PL1.1 ML2027-2028'!$M:$M,"Mạng cáp",'PL1.1 ML2027-2028'!$K:$K,'TH theo dich vu'!C27)/$D$1+SUMIFS('PL1.1 ML2027-2028'!$G:$G,'PL1.1 ML2027-2028'!$J:$J,"TD",'PL1.1 ML2027-2028'!$M:$M,"Mạng cáp",'PL1.1 ML2027-2028'!$K:$K,'TH theo dich vu'!C28)/$D$1+SUMIFS('PL1.1 ML2027-2028'!$G:$G,'PL1.1 ML2027-2028'!$J:$J,"TD",'PL1.1 ML2027-2028'!$M:$M,"Mạng cáp",'PL1.1 ML2027-2028'!$K:$K,'TH theo dich vu'!C14)/$D$1+SUMIFS('PL1.1 ML2027-2028'!$G:$G,'PL1.1 ML2027-2028'!$J:$J,"TD",'PL1.1 ML2027-2028'!$M:$M,"Mạng cáp",'PL1.1 ML2027-2028'!$K:$K,'TH theo dich vu'!C13)/$D$1)*0.06 -> 0.2885988 | J17: =SUMIFS('PL1.1 ML2027-2028'!$G:$G,'PL1.1 ML2027-2028'!$J:$J,'TH theo dich vu'!$J$3,'PL1.1 ML2027-2028'!$K:$K,'TH theo dich vu'!C17)/$D$1 -> 0 | K17: =SUMIFS('PL1.1 ML2027-2028'!$G:$G,'PL1.1 ML2027-2028'!$J:$J,'TH theo dich vu'!K$3,'PL1.1 ML2027-2028'!$K:$K,'TH theo dich vu'!C17)/$D$1 -> 0 | L17: =SUM(D17:K17) -> 0.99676028 | M17: =SUM(D17:K17) -> 0.99676028 | N17: =L17/$L$4 -> 0.0089957029 | O17: =SUMIFS('PL1.1 ML2027-2028'!$H:$H,'PL1.1 ML2027-2028'!$J:$J,'TH theo dich vu'!O$3,'PL1.1 ML2027-2028'!$K:$K,'TH theo dich vu'!$C17)/$D$1 -> 0 | P17: =SUMIFS('PL1.1 ML2027-2028'!$H:$H,'PL1.1 ML2027-2028'!$J:$J,'TH theo dich vu'!P$3,'PL1.1 ML2027-2028'!$K:$K,'TH theo dich vu'!$C17)/$D$1 -> 0 | Q17: =SUMIFS('PL1.1 ML2027-2028'!$H:$H,'PL1.1 ML2027-2028'!$J:$J,'TH theo dich vu'!Q$3,'PL1.1 ML2027-2028'!$K:$K,'TH theo dich vu'!$C17)/$D$1 -> 0.26 | R17: =SUMIFS('PL1.1 ML2027-2028'!$H:$H,'PL1.1 ML2027-2028'!$J:$J,'TH theo dich vu'!R$3,'PL1.1 ML2027-2028'!$K:$K,'TH theo dich vu'!$C17)/$D$1 -> 0 | S17: =(SUMIFS('PL1.1 ML2027-2028'!$H:$H,'PL1.1 ML2027-2028'!$J:$J,"TD",'PL1.1 ML2027-2028'!$M:$M,"IP",'PL1.1 ML2027-2028'!$K:$K,'TH theo dich vu'!C27)/$D$1+SUMIFS('PL1.1 ML2027-2028'!$H:$H,'PL1.1 ML2027-2028'!$J:$J,"TD",'PL1.1 ML2027-2028'!$M:$M,"IP",'PL1.1 ML2027-2028'!$K:$K,'TH theo dich vu'!C28)/$D$1+SUMIFS('PL1.1 ML2027-2028'!$H:$H,'PL1.1 ML2027-2028'!$J:$J,"TD",'PL1.1 ML2027-2028'!$M:$M,"IP",'PL1.1 ML2027-2028'!$K:$K,'TH theo dich vu'!C14)/$D$1+SUMIFS('PL1.1 ML2027-2028'!$H:$H,'PL1.1 ML2027-2028'!$J:$J,"TD",'PL1.1 ML2027-2028'!$M:$M,"IP",'PL1.1 ML2027-2028'!$K:$K,'TH theo dich vu'!C13)/$D$1)*0.06 -> 0.2926179 | T17: =(SUMIFS('PL1.1 ML2027-2028'!$H:$H,'PL1.1 ML2027-2028'!$J:$J,"TD",'PL1.1 ML2027-2028'!$M:$M,"Mạng cáp",'PL1.1 ML2027-2028'!$K:$K,'TH theo dich vu'!C27)/$D$1+SUMIFS('PL1.1 ML2027-2028'!$H:$H,'PL1.1 ML2027-2028'!$J:$J,"TD",'PL1.1 ML2027-2028'!$M:$M,"Mạng cáp",'PL1.1 ML2027-2028'!$K:$K,'TH theo dich vu'!C28)/$D$1+SUMIFS('PL1.1 ML2027-2028'!$H:$H,'PL1.1 ML2027-2028'!$J:$J,"TD",'PL1.1 ML2027-2028'!$M:$M,"Mạng cáp",'PL1.1 ML2027-2028'!$K:$K,'TH theo dich vu'!C14)/$D$1+SUMIFS('PL1.1 ML2027-2028'!$H:$H,'PL1.1 ML2027-2028'!$J:$J,"TD",'PL1.1 ML2027-2028'!$M:$M,"Mạng cáp",'PL1.1 ML2027-2028'!$K:$K,'TH theo dich vu'!C13)/$D$1)*0.06 -> 0.14384582 | U17: =SUMIFS('PL1.1 ML2027-2028'!$H:$H,'PL1.1 ML2027-2028'!$J:$J,'TH theo dich vu'!U$3,'PL1.1 ML2027-2028'!$K:$K,'TH theo dich vu'!$C17)/$D$1 -> 0 | V17: =SUMIFS('PL1.1 ML2027-2028'!$H:$H,'PL1.1 ML2027-2028'!$J:$J,'TH theo dich vu'!V$3,'PL1.1 ML2027-2028'!$K:$K,'TH theo dich vu'!$C17)/$D$1 -> 0 | W17: =SUM(O17:V17) -> 0.69646372 | X17: =SUM(O17:V17) -> 0.69646372 | Z17: =D17+O17 -> 0 | AA17: =E17+P17 -> 0 | AB17: =F17+Q17 -> 0.563652 | AC17: =G17+R17 -> 0 | AD17: =H17+S17 -> 0.69712738 | AE17: =I17+T17 -> 0.43244462 | AF17: =J17+U17 -> 0 | AG17: =K17+V17 -> 0 | AH17: =SUM(Z17:AG17) -> 1.693224 | AI17: =AH17/$AH$4 -> 0.0084251041 | AL17: 1
A18: - | B18: Dung lượng Truyền hình | C18: TH | D18: =SUMIFS('PL1.1 ML2027-2028'!$G:$G,'PL1.1 ML2027-2028'!$J:$J,'TH theo dich vu'!$D$3,'PL1.1 ML2027-2028'!$K:$K,'TH theo dich vu'!C18)/$D$1 -> 0 | E18: =SUMIFS('PL1.1 ML2027-2028'!$G:$G,'PL1.1 ML2027-2028'!$J:$J,'TH theo dich vu'!$E$3,'PL1.1 ML2027-2028'!$K:$K,'TH theo dich vu'!C18)/$D$1 -> 0 | F18: =SUMIFS('PL1.1 ML2027-2028'!$G:$G,'PL1.1 ML2027-2028'!$J:$J,'TH theo dich vu'!$F$3,'PL1.1 ML2027-2028'!$K:$K,'TH theo dich vu'!C18)/$D$1 -> 0 | G18: =SUMIFS('PL1.1 ML2027-2028'!$G:$G,'PL1.1 ML2027-2028'!$J:$J,'TH theo dich vu'!$G$3,'PL1.1 ML2027-2028'!$K:$K,'TH theo dich vu'!C18)/$D$1 -> 0 | H18: =SUMIFS('PL1.1 ML2027-2028'!$G:$G,'PL1.1 ML2027-2028'!$J:$J,"TD",'PL1.1 ML2027-2028'!$M:$M,"IP",'PL1.1 ML2027-2028'!$K:$K,'TH theo dich vu'!C18)/$D$1 -> 0 | I18: =SUMIFS('PL1.1 ML2027-2028'!$G:$G,'PL1.1 ML2027-2028'!$J:$J,"TD",'PL1.1 ML2027-2028'!$M:$M,"Mạng cáp",'PL1.1 ML2027-2028'!$K:$K,'TH theo dich vu'!C18)/$D$1 -> 0 | J18: =SUMIFS('PL1.1 ML2027-2028'!$G:$G,'PL1.1 ML2027-2028'!$J:$J,'TH theo dich vu'!$J$3,'PL1.1 ML2027-2028'!$K:$K,'TH theo dich vu'!C18)/$D$1 -> 0 | K18: =SUMIFS('PL1.1 ML2027-2028'!$G:$G,'PL1.1 ML2027-2028'!$J:$J,'TH theo dich vu'!K$3,'PL1.1 ML2027-2028'!$K:$K,'TH theo dich vu'!C18)/$D$1 -> 0 | L18: =SUM(D18:J18) -> 0 | M18: =SUM(D18:K18) -> 0 | N18: =L18/$L$4 -> 0 | O18: =SUMIFS('PL1.1 ML2027-2028'!$H:$H,'PL1.1 ML2027-2028'!$J:$J,'TH theo dich vu'!O$3,'PL1.1 ML2027-2028'!$K:$K,'TH theo dich vu'!$C18)/$D$1 -> 0 | P18: =SUMIFS('PL1.1 ML2027-2028'!$H:$H,'PL1.1 ML2027-2028'!$J:$J,'TH theo dich vu'!P$3,'PL1.1 ML2027-2028'!$K:$K,'TH theo dich vu'!$C18)/$D$1 -> 0 | Q18: =SUMIFS('PL1.1 ML2027-2028'!$H:$H,'PL1.1 ML2027-2028'!$J:$J,'TH theo dich vu'!Q$3,'PL1.1 ML2027-2028'!$K:$K,'TH theo dich vu'!$C18)/$D$1 -> 0 | R18: =SUMIFS('PL1.1 ML2027-2028'!$H:$H,'PL1.1 ML2027-2028'!$J:$J,'TH theo dich vu'!R$3,'PL1.1 ML2027-2028'!$K:$K,'TH theo dich vu'!$C18)/$D$1 -> 0 | S18: =SUMIFS('PL1.1 ML2027-2028'!$H:$H,'PL1.1 ML2027-2028'!$J:$J,"TD",'PL1.1 ML2027-2028'!$M:$M,"IP",'PL1.1 ML2027-2028'!$K:$K,'TH theo dich vu'!C18)/$D$1 -> 0 | T18: =SUMIFS('PL1.1 ML2027-2028'!$H:$H,'PL1.1 ML2027-2028'!$J:$J,"TD",'PL1.1 ML2027-2028'!$M:$M,"Mạng cáp",'PL1.1 ML2027-2028'!$K:$K,'TH theo dich vu'!C18)/$D$1 -> 0 | U18: =SUMIFS('PL1.1 ML2027-2028'!$H:$H,'PL1.1 ML2027-2028'!$J:$J,'TH theo dich vu'!U$3,'PL1.1 ML2027-2028'!$K:$K,'TH theo dich vu'!$C18)/$D$1 -> 0 | V18: =SUMIFS('PL1.1 ML2027-2028'!$H:$H,'PL1.1 ML2027-2028'!$J:$J,'TH theo dich vu'!V$3,'PL1.1 ML2027-2028'!$K:$K,'TH theo dich vu'!$C18)/$D$1 -> 0 | W18: =SUM(O18:U18) -> 0 | X18: =SUM(O18:V18) -> 0 | Z18: =D18+O18 -> 0 | AA18: =E18+P18 -> 0 | AB18: =F18+Q18 -> 0 | AC18: =G18+R18 -> 0 | AD18: =H18+S18 -> 0 | AE18: =I18+T18 -> 0 | AF18: =J18+U18 -> 0 | AG18: =K18+V18 -> 0 | AH18: =SUM(Z18:AG18) -> 0 | AI18: =AH18/$AH$4 -> 0 | AM18: 1
A19: - | B19: Kênh truyền | C19: KT | D19: =SUMIFS('PL1.1 ML2027-2028'!$G:$G,'PL1.1 ML2027-2028'!$J:$J,'TH theo dich vu'!$D$3,'PL1.1 ML2027-2028'!$K:$K,'TH theo dich vu'!C19)/$D$1 -> 0 | E19: =SUMIFS('PL1.1 ML2027-2028'!$G:$G,'PL1.1 ML2027-2028'!$J:$J,'TH theo dich vu'!$E$3,'PL1.1 ML2027-2028'!$K:$K,'TH theo dich vu'!C19)/$D$1 -> 0 | F19: =SUMIFS('PL1.1 ML2027-2028'!$G:$G,'PL1.1 ML2027-2028'!$J:$J,'TH theo dich vu'!$F$3,'PL1.1 ML2027-2028'!$K:$K,'TH theo dich vu'!C19)/$D$1 -> 0 | G19: =SUMIFS('PL1.1 ML2027-2028'!$G:$G,'PL1.1 ML2027-2028'!$J:$J,'TH theo dich vu'!$G$3,'PL1.1 ML2027-2028'!$K:$K,'TH theo dich vu'!C19)/$D$1 -> 0 | H19: =SUMIFS('PL1.1 ML2027-2028'!$G:$G,'PL1.1 ML2027-2028'!$J:$J,"TD",'PL1.1 ML2027-2028'!$M:$M,"IP",'PL1.1 ML2027-2028'!$K:$K,'TH theo dich vu'!C19)/$D$1 -> 0 | I19: =SUMIFS('PL1.1 ML2027-2028'!$G:$G,'PL1.1 ML2027-2028'!$J:$J,"TD",'PL1.1 ML2027-2028'!$M:$M,"Mạng cáp",'PL1.1 ML2027-2028'!$K:$K,'TH theo dich vu'!C19)/$D$1 -> 0 | J19: =SUMIFS('PL1.1 ML2027-2028'!$G:$G,'PL1.1 ML2027-2028'!$J:$J,'TH theo dich vu'!$J$3,'PL1.1 ML2027-2028'!$K:$K,'TH theo dich vu'!C19)/$D$1 -> 0 | K19: =SUMIFS('PL1.1 ML2027-2028'!$G:$G,'PL1.1 ML2027-2028'!$J:$J,'TH theo dich vu'!K$3,'PL1.1 ML2027-2028'!$K:$K,'TH theo dich vu'!C19)/$D$1 -> 0 | L19: =SUM(D19:J19) -> 0 | M19: =SUM(D19:K19) -> 0 | N19: =L19/$L$4 -> 0 | O19: =SUMIFS('PL1.1 ML2027-2028'!$H:$H,'PL1.1 ML2027-2028'!$J:$J,'TH theo dich vu'!O$3,'PL1.1 ML2027-2028'!$K:$K,'TH theo dich vu'!$C19)/$D$1 -> 0 | P19: =SUMIFS('PL1.1 ML2027-2028'!$H:$H,'PL1.1 ML2027-2028'!$J:$J,'TH theo dich vu'!P$3,'PL1.1 ML2027-2028'!$K:$K,'TH theo dich vu'!$C19)/$D$1 -> 0 | Q19: =SUMIFS('PL1.1 ML2027-2028'!$H:$H,'PL1.1 ML2027-2028'!$J:$J,'TH theo dich vu'!Q$3,'PL1.1 ML2027-2028'!$K:$K,'TH theo dich vu'!$C19)/$D$1 -> 0 | R19: =SUMIFS('PL1.1 ML2027-2028'!$H:$H,'PL1.1 ML2027-2028'!$J:$J,'TH theo dich vu'!R$3,'PL1.1 ML2027-2028'!$K:$K,'TH theo dich vu'!$C19)/$D$1 -> 0 | S19: =SUMIFS('PL1.1 ML2027-2028'!$H:$H,'PL1.1 ML2027-2028'!$J:$J,"TD",'PL1.1 ML2027-2028'!$M:$M,"IP",'PL1.1 ML2027-2028'!$K:$K,'TH theo dich vu'!C19)/$D$1 -> 0 | T19: =SUMIFS('PL1.1 ML2027-2028'!$H:$H,'PL1.1 ML2027-2028'!$J:$J,"TD",'PL1.1 ML2027-2028'!$M:$M,"Mạng cáp",'PL1.1 ML2027-2028'!$K:$K,'TH theo dich vu'!C19)/$D$1 -> 0 | U19: =SUMIFS('PL1.1 ML2027-2028'!$H:$H,'PL1.1 ML2027-2028'!$J:$J,'TH theo dich vu'!U$3,'PL1.1 ML2027-2028'!$K:$K,'TH theo dich vu'!$C19)/$D$1 -> 0 | V19: =SUMIFS('PL1.1 ML2027-2028'!$H:$H,'PL1.1 ML2027-2028'!$J:$J,'TH theo dich vu'!V$3,'PL1.1 ML2027-2028'!$K:$K,'TH theo dich vu'!$C19)/$D$1 -> 0 | W19: =SUM(O19:U19) -> 0 | X19: =SUM(O19:V19) -> 0 | Z19: =D19+O19 -> 0 | AA19: =E19+P19 -> 0 | AB19: =F19+Q19 -> 0 | AC19: =G19+R19 -> 0 | AD19: =H19+S19 -> 0 | AE19: =I19+T19 -> 0 | AF19: =J19+U19 -> 0 | AG19: =K19+V19 -> 0 | AH19: =SUM(Z19:AG19) -> 0 | AI19: =AH19/$AH$4 -> 0 | AL19: 1
A20: 3 | B20: Phục vụ kinh doanh Cloud | C20: Cloud_KD | D20: =SUMIFS('PL1.1 ML2027-2028'!$G:$G,'PL1.1 ML2027-2028'!$J:$J,'TH theo dich vu'!$D$3,'PL1.1 ML2027-2028'!$K:$K,'TH theo dich vu'!C20)/$D$1 -> 0 | E20: =SUMIFS('PL1.1 ML2027-2028'!$G:$G,'PL1.1 ML2027-2028'!$J:$J,'TH theo dich vu'!$E$3,'PL1.1 ML2027-2028'!$K:$K,'TH theo dich vu'!C20)/$D$1 -> 0 | F20: =SUMIFS('PL1.1 ML2027-2028'!$G:$G,'PL1.1 ML2027-2028'!$J:$J,'TH theo dich vu'!$F$3,'PL1.1 ML2027-2028'!$K:$K,'TH theo dich vu'!C20)/$D$1 -> 0 | G20: =SUMIFS('PL1.1 ML2027-2028'!$G:$G,'PL1.1 ML2027-2028'!$J:$J,'TH theo dich vu'!$G$3,'PL1.1 ML2027-2028'!$K:$K,'TH theo dich vu'!C20)/$D$1 -> 0 | H20: =SUMIFS('PL1.1 ML2027-2028'!$G:$G,'PL1.1 ML2027-2028'!$J:$J,"TD",'PL1.1 ML2027-2028'!$M:$M,"IP",'PL1.1 ML2027-2028'!$K:$K,'TH theo dich vu'!C20)/$D$1 -> 0 | I20: =SUMIFS('PL1.1 ML2027-2028'!$G:$G,'PL1.1 ML2027-2028'!$J:$J,"TD",'PL1.1 ML2027-2028'!$M:$M,"Mạng cáp",'PL1.1 ML2027-2028'!$K:$K,'TH theo dich vu'!C20)/$D$1 -> 0 | J20: =SUMIFS('PL1.1 ML2027-2028'!$G:$G,'PL1.1 ML2027-2028'!$J:$J,'TH theo dich vu'!$J$3,'PL1.1 ML2027-2028'!$K:$K,'TH theo dich vu'!C20)/$D$1 -> 0 | K20: =SUMIFS('PL1.1 ML2027-2028'!$G:$G,'PL1.1 ML2027-2028'!$J:$J,'TH theo dich vu'!$J$3,'PL1.1 ML2027-2028'!$K:$K,'TH theo dich vu'!D20)/$D$1 -> 0 | L20: =SUM(D20:J20) -> 0 | M20: =SUM(D20:K20) -> 0 | N20: =L20/$L$4 -> 0 | O20: =SUMIFS('PL1.1 ML2027-2028'!$H:$H,'PL1.1 ML2027-2028'!$J:$J,'TH theo dich vu'!O$3,'PL1.1 ML2027-2028'!$K:$K,'TH theo dich vu'!$C20)/$D$1 -> 0 | P20: =SUMIFS('PL1.1 ML2027-2028'!$H:$H,'PL1.1 ML2027-2028'!$J:$J,'TH theo dich vu'!P$3,'PL1.1 ML2027-2028'!$K:$K,'TH theo dich vu'!$C20)/$D$1 -> 0 | Q20: =SUMIFS('PL1.1 ML2027-2028'!$H:$H,'PL1.1 ML2027-2028'!$J:$J,'TH theo dich vu'!Q$3,'PL1.1 ML2027-2028'!$K:$K,'TH theo dich vu'!$C20)/$D$1 -> 0 | R20: =SUMIFS('PL1.1 ML2027-2028'!$H:$H,'PL1.1 ML2027-2028'!$J:$J,'TH theo dich vu'!R$3,'PL1.1 ML2027-2028'!$K:$K,'TH theo dich vu'!$C20)/$D$1 -> 0 | S20: =SUMIFS('PL1.1 ML2027-2028'!$H:$H,'PL1.1 ML2027-2028'!$J:$J,"TD",'PL1.1 ML2027-2028'!$M:$M,"IP",'PL1.1 ML2027-2028'!$K:$K,'TH theo dich vu'!C20)/$D$1 -> 0 | T20: =SUMIFS('PL1.1 ML2027-2028'!$H:$H,'PL1.1 ML2027-2028'!$J:$J,"TD",'PL1.1 ML2027-2028'!$M:$M,"Mạng cáp",'PL1.1 ML2027-2028'!$K:$K,'TH theo dich vu'!C20)/$D$1 -> 0 | U20: =SUMIFS('PL1.1 ML2027-2028'!$H:$H,'PL1.1 ML2027-2028'!$J:$J,'TH theo dich vu'!U$3,'PL1.1 ML2027-2028'!$K:$K,'TH theo dich vu'!$C20)/$D$1 -> 0 | V20: =SUMIFS('PL1.1 ML2027-2028'!$G:$G,'PL1.1 ML2027-2028'!$J:$J,'TH theo dich vu'!$J$3,'PL1.1 ML2027-2028'!$K:$K,'TH theo dich vu'!O20)/$D$1 -> 0 | W20: =SUM(O20:U20) -> 0 | X20: =SUM(O20:V20) -> 0 | Z20: =D20+O20 -> 0 | AA20: =E20+P20 -> 0 | AB20: =F20+Q20 -> 0 | AC20: =G20+R20 -> 0 | AD20: =H20+S20 -> 0 | AE20: =I20+T20 -> 0 | AF20: =J20+U20 -> 0 | AG20: =K20+V20 -> 0 | AH20: =SUM(Z20:AG20) -> 0 | AI20: =AH20/$AH$4 -> 0 | AO20: 1
A21: 4 | B21: Data Center | C21: DC | D21: =SUMIFS('PL1.1 ML2027-2028'!$G:$G,'PL1.1 ML2027-2028'!$J:$J,'TH theo dich vu'!$D$3,'PL1.1 ML2027-2028'!$K:$K,'TH theo dich vu'!C21)/$D$1 -> 0 | E21: =SUMIFS('PL1.1 ML2027-2028'!$G:$G,'PL1.1 ML2027-2028'!$J:$J,'TH theo dich vu'!$E$3,'PL1.1 ML2027-2028'!$K:$K,'TH theo dich vu'!C21)/$D$1 -> 0 | F21: =SUMIFS('PL1.1 ML2027-2028'!$G:$G,'PL1.1 ML2027-2028'!$J:$J,'TH theo dich vu'!$F$3,'PL1.1 ML2027-2028'!$K:$K,'TH theo dich vu'!C21)/$D$1 -> 0 | G21: =SUMIFS('PL1.1 ML2027-2028'!$G:$G,'PL1.1 ML2027-2028'!$J:$J,'TH theo dich vu'!$G$3,'PL1.1 ML2027-2028'!$K:$K,'TH theo dich vu'!C21)/$D$1 -> 0 | H21: =SUMIFS('PL1.1 ML2027-2028'!$G:$G,'PL1.1 ML2027-2028'!$J:$J,"TD",'PL1.1 ML2027-2028'!$M:$M,"IP",'PL1.1 ML2027-2028'!$K:$K,'TH theo dich vu'!C21)/$D$1 -> 1.75712 | I21: =SUMIFS('PL1.1 ML2027-2028'!$G:$G,'PL1.1 ML2027-2028'!$J:$J,"TD",'PL1.1 ML2027-2028'!$M:$M,"Mạng cáp",'PL1.1 ML2027-2028'!$K:$K,'TH theo dich vu'!C21)/$D$1 -> 0.63 | J21: =SUMIFS('PL1.1 ML2027-2028'!$G:$G,'PL1.1 ML2027-2028'!$J:$J,'TH theo dich vu'!$J$3,'PL1.1 ML2027-2028'!$K:$K,'TH theo dich vu'!C21)/$D$1 -> 0 | K21: =SUMIFS('PL1.1 ML2027-2028'!$G:$G,'PL1.1 ML2027-2028'!$J:$J,'TH theo dich vu'!$J$3,'PL1.1 ML2027-2028'!$K:$K,'TH theo dich vu'!D21)/$D$1 -> 0 | L21: =SUM(D21:J21) -> 2.38712 | M21: =SUM(D21:K21) -> 2.38712 | N21: =L21/$L$4 -> 0.021543617 | O21: =SUMIFS('PL1.1 ML2027-2028'!$H:$H,'PL1.1 ML2027-2028'!$J:$J,'TH theo dich vu'!O$3,'PL1.1 ML2027-2028'!$K:$K,'TH theo dich vu'!$C21)/$D$1 -> 0 | P21: =SUMIFS('PL1.1 ML2027-2028'!$H:$H,'PL1.1 ML2027-2028'!$J:$J,'TH theo dich vu'!P$3,'PL1.1 ML2027-2028'!$K:$K,'TH theo dich vu'!$C21)/$D$1 -> 0 | Q21: =SUMIFS('PL1.1 ML2027-2028'!$H:$H,'PL1.1 ML2027-2028'!$J:$J,'TH theo dich vu'!Q$3,'PL1.1 ML2027-2028'!$K:$K,'TH theo dich vu'!$C21)/$D$1 -> 0 | R21: =SUMIFS('PL1.1 ML2027-2028'!$H:$H,'PL1.1 ML2027-2028'!$J:$J,'TH theo dich vu'!R$3,'PL1.1 ML2027-2028'!$K:$K,'TH theo dich vu'!$C21)/$D$1 -> 0 | S21: =SUMIFS('PL1.1 ML2027-2028'!$H:$H,'PL1.1 ML2027-2028'!$J:$J,"TD",'PL1.1 ML2027-2028'!$M:$M,"IP",'PL1.1 ML2027-2028'!$K:$K,'TH theo dich vu'!C21)/$D$1 -> 0.001415 | T21: =SUMIFS('PL1.1 ML2027-2028'!$H:$H,'PL1.1 ML2027-2028'!$J:$J,"TD",'PL1.1 ML2027-2028'!$M:$M,"Mạng cáp",'PL1.1 ML2027-2028'!$K:$K,'TH theo dich vu'!C21)/$D$1 -> 0 | U21: =SUMIFS('PL1.1 ML2027-2028'!$H:$H,'PL1.1 ML2027-2028'!$J:$J,'TH theo dich vu'!U$3,'PL1.1 ML2027-2028'!$K:$K,'TH theo dich vu'!$C21)/$D$1 -> 0 | V21: =SUMIFS('PL1.1 ML2027-2028'!$G:$G,'PL1.1 ML2027-2028'!$J:$J,'TH theo dich vu'!$J$3,'PL1.1 ML2027-2028'!$K:$K,'TH theo dich vu'!O21)/$D$1 -> 0 | W21: =SUM(O21:U21) -> 0.001415 | X21: =SUM(O21:V21) -> 0.001415 | Z21: =D21+O21 -> 0 | AA21: =E21+P21 -> 0 | AB21: =F21+Q21 -> 0 | AC21: =G21+R21 -> 0 | AD21: =H21+S21 -> 1.758535 | AE21: =I21+T21 -> 0.63 | AF21: =J21+U21 -> 0 | AG21: =K21+V21 -> 0 | AH21: =SUM(Z21:AG21) -> 2.388535 | AI21: =AH21/$AH$4 -> 0.011884816 | AJ21: =20%*80% -> 0.16 | AM21: =20%*20% -> 0.04 | AN21: 0.8
A22: 5 | B22: Triển khai hạ tầng CNTT | D22: =SUBTOTAL(9,D23:D25) -> 0 | E22: =SUBTOTAL(9,E23:E25) -> 0 | F22: =SUBTOTAL(9,F23:F25) -> 0 | G22: =SUBTOTAL(9,G23:G25) -> 15.582282 | H22: =SUBTOTAL(9,H23:H25) -> 0 | I22: =SUBTOTAL(9,I23:I25) -> 0 | J22: =SUBTOTAL(9,J23:J25) -> 0 | K22: =SUBTOTAL(9,K23:K25) -> 0 | ... M22: =SUBTOTAL(9,M23:M25) -> 15.582282 | N22: =L22/$L$4 -> 0.14062918 | O22: =SUBTOTAL(9,O23:O25) -> 0 | P22: =SUBTOTAL(9,P23:P25) -> 0 | Q22: =SUBTOTAL(9,Q23:Q25) -> 0 | R22: =SUBTOTAL(9,R23:R25) -> 17.900934 | S22: =SUBTOTAL(9,S23:S25) -> 0 | T22: =SUBTOTAL(9,T23:T25) -> 0 | U22: =SUBTOTAL(9,U23:U25) -> 0 | V22: =SUBTOTAL(9,V23:V25) -> 0 | ... X22: =SUBTOTAL(9,X23:X25) -> 17.900934 | Y22: =W22/$W$4 -> 0.19852513 | Z22: =SUBTOTAL(9,Z23:Z25) -> 0 | AA22: =SUBTOTAL(9,AA23:AA25) -> 0 | AB22: =SUBTOTAL(9,AB23:AB25) -> 0 | AC22: =SUBTOTAL(9,AC23:AC25) -> 33.483216 | AD22: =SUBTOTAL(9,AD23:AD25) -> 0 | AE22: =SUBTOTAL(9,AE23:AE25) -> 0 | AF22: =SUBTOTAL(9,AF23:AF25) -> 0 | AG22: =SUBTOTAL(9,AG23:AG25) -> 0 | AH22: =SUBTOTAL(9,AH23:AH25) -> 33.483216 | AI22: =AH22/$AH$4 -> 0.166605
A23: - | B23: Trực tiếp kinh doanh (ví điện tử) | C23: TTKD | D23: =SUMIFS('PL1.1 ML2027-2028'!$G:$G,'PL1.1 ML2027-2028'!$J:$J,'TH theo dich vu'!$D$3,'PL1.1 ML2027-2028'!$K:$K,'TH theo dich vu'!C23)/$D$1 -> 0 | E23: =SUMIFS('PL1.1 ML2027-2028'!$G:$G,'PL1.1 ML2027-2028'!$J:$J,'TH theo dich vu'!$E$3,'PL1.1 ML2027-2028'!$K:$K,'TH theo dich vu'!C23)/$D$1 -> 0 | F23: =SUMIFS('PL1.1 ML2027-2028'!$G:$G,'PL1.1 ML2027-2028'!$J:$J,'TH theo dich vu'!$F$3,'PL1.1 ML2027-2028'!$K:$K,'TH theo dich vu'!C23)/$D$1 -> 0 | G23: =SUMIFS('PL1.1 ML2027-2028'!$G:$G,'PL1.1 ML2027-2028'!$J:$J,'TH theo dich vu'!$G$3,'PL1.1 ML2027-2028'!$K:$K,'TH theo dich vu'!C23)/$D$1 -> 0.790467 | H23: =SUMIFS('PL1.1 ML2027-2028'!$G:$G,'PL1.1 ML2027-2028'!$J:$J,"TD",'PL1.1 ML2027-2028'!$M:$M,"IP",'PL1.1 ML2027-2028'!$K:$K,'TH theo dich vu'!C23)/$D$1 -> 0 | I23: =SUMIFS('PL1.1 ML2027-2028'!$G:$G,'PL1.1 ML2027-2028'!$J:$J,"TD",'PL1.1 ML2027-2028'!$M:$M,"Mạng cáp",'PL1.1 ML2027-2028'!$K:$K,'TH theo dich vu'!C23)/$D$1 -> 0 | J23: =SUMIFS('PL1.1 ML2027-2028'!$G:$G,'PL1.1 ML2027-2028'!$J:$J,'TH theo dich vu'!$J$3,'PL1.1 ML2027-2028'!$K:$K,'TH theo dich vu'!C23)/$D$1 -> 0 | K23: =SUMIFS('PL1.1 ML2027-2028'!$G:$G,'PL1.1 ML2027-2028'!$J:$J,'TH theo dich vu'!K$3,'PL1.1 ML2027-2028'!$K:$K,'TH theo dich vu'!C23)/$D$1 -> 0 | L23: =SUM(D23:K23) -> 0.790467 | M23: =SUM(D23:K23) -> 0.790467 | N23: =L23/$L$4 -> 0.0071339181 | O23: =SUMIFS('PL1.1 ML2027-2028'!$H:$H,'PL1.1 ML2027-2028'!$J:$J,'TH theo dich vu'!O$3,'PL1.1 ML2027-2028'!$K:$K,'TH theo dich vu'!$C23)/$D$1 -> 0 | P23: =SUMIFS('PL1.1 ML2027-2028'!$H:$H,'PL1.1 ML2027-2028'!$J:$J,'TH theo dich vu'!P$3,'PL1.1 ML2027-2028'!$K:$K,'TH theo dich vu'!$C23)/$D$1 -> 0 | Q23: =SUMIFS('PL1.1 ML2027-2028'!$H:$H,'PL1.1 ML2027-2028'!$J:$J,'TH theo dich vu'!Q$3,'PL1.1 ML2027-2028'!$K:$K,'TH theo dich vu'!$C23)/$D$1 -> 0 | R23: =SUMIFS('PL1.1 ML2027-2028'!$H:$H,'PL1.1 ML2027-2028'!$J:$J,'TH theo dich vu'!R$3,'PL1.1 ML2027-2028'!$K:$K,'TH theo dich vu'!$C23)/$D$1 -> 1.75606 | S23: =SUMIFS('PL1.1 ML2027-2028'!$H:$H,'PL1.1 ML2027-2028'!$J:$J,"TD",'PL1.1 ML2027-2028'!$M:$M,"IP",'PL1.1 ML2027-2028'!$K:$K,'TH theo dich vu'!C23)/$D$1 -> 0 | T23: =SUMIFS('PL1.1 ML2027-2028'!$H:$H,'PL1.1 ML2027-2028'!$J:$J,"TD",'PL1.1 ML2027-2028'!$M:$M,"Mạng cáp",'PL1.1 ML2027-2028'!$K:$K,'TH theo dich vu'!C23)/$D$1 -> 0 | U23: =SUMIFS('PL1.1 ML2027-2028'!$H:$H,'PL1.1 ML2027-2028'!$J:$J,'TH theo dich vu'!U$3,'PL1.1 ML2027-2028'!$K:$K,'TH theo dich vu'!$C23)/$D$1 -> 0 | V23: =SUMIFS('PL1.1 ML2027-2028'!$H:$H,'PL1.1 ML2027-2028'!$J:$J,'TH theo dich vu'!V$3,'PL1.1 ML2027-2028'!$K:$K,'TH theo dich vu'!$C23)/$D$1 -> 0 | W23: =SUM(O23:V23) -> 1.75606 | X23: =SUM(O23:V23) -> 1.75606 | Z23: =D23+O23 -> 0 | AA23: =E23+P23 -> 0 | AB23: =F23+Q23 -> 0 | AC23: =G23+R23 -> 2.546527 | AD23: =H23+S23 -> 0 | AE23: =I23+T23 -> 0 | AF23: =J23+U23 -> 0 | AG23: =K23+V23 -> 0 | AH23: =SUM(Z23:AG23) -> 2.546527 | AI23: =AH23/$AH$4 -> 0.012670949 | AP23: 1
A24: - | B24: Hỗ trợ kinh doanh và quản trị | C24: HTKD | D24: =SUMIFS('PL1.1 ML2027-2028'!$G:$G,'PL1.1 ML2027-2028'!$J:$J,'TH theo dich vu'!$D$3,'PL1.1 ML2027-2028'!$K:$K,'TH theo dich vu'!C24)/$D$1 -> 0 | E24: =SUMIFS('PL1.1 ML2027-2028'!$G:$G,'PL1.1 ML2027-2028'!$J:$J,'TH theo dich vu'!$E$3,'PL1.1 ML2027-2028'!$K:$K,'TH theo dich vu'!C24)/$D$1 -> 0 | F24: =SUMIFS('PL1.1 ML2027-2028'!$G:$G,'PL1.1 ML2027-2028'!$J:$J,'TH theo dich vu'!$F$3,'PL1.1 ML2027-2028'!$K:$K,'TH theo dich vu'!C24)/$D$1 -> 0 | G24: =SUMIFS('PL1.1 ML2027-2028'!$G:$G,'PL1.1 ML2027-2028'!$J:$J,'TH theo dich vu'!$G$3,'PL1.1 ML2027-2028'!$K:$K,'TH theo dich vu'!C24)/$D$1 -> 14.533353 | H24: =SUMIFS('PL1.1 ML2027-2028'!$G:$G,'PL1.1 ML2027-2028'!$J:$J,"TD",'PL1.1 ML2027-2028'!$M:$M,"IP",'PL1.1 ML2027-2028'!$K:$K,'TH theo dich vu'!C24)/$D$1 -> 0 | I24: =SUMIFS('PL1.1 ML2027-2028'!$G:$G,'PL1.1 ML2027-2028'!$J:$J,"TD",'PL1.1 ML2027-2028'!$M:$M,"Mạng cáp",'PL1.1 ML2027-2028'!$K:$K,'TH theo dich vu'!C24)/$D$1 -> 0 | J24: =SUMIFS('PL1.1 ML2027-2028'!$G:$G,'PL1.1 ML2027-2028'!$J:$J,'TH theo dich vu'!$J$3,'PL1.1 ML2027-2028'!$K:$K,'TH theo dich vu'!C24)/$D$1 -> 0 | K24: =SUMIFS('PL1.1 ML2027-2028'!$G:$G,'PL1.1 ML2027-2028'!$J:$J,'TH theo dich vu'!K$3,'PL1.1 ML2027-2028'!$K:$K,'TH theo dich vu'!C24)/$D$1 -> 0 | L24: =SUM(D24:K24) -> 14.533353 | M24: =SUM(D24:K24) -> 14.533353 | N24: =L24/$L$4 -> 0.13116266 | O24: =SUMIFS('PL1.1 ML2027-2028'!$H:$H,'PL1.1 ML2027-2028'!$J:$J,'TH theo dich vu'!O$3,'PL1.1 ML2027-2028'!$K:$K,'TH theo dich vu'!$C24)/$D$1 -> 0 | P24: =SUMIFS('PL1.1 ML2027-2028'!$H:$H,'PL1.1 ML2027-2028'!$J:$J,'TH theo dich vu'!P$3,'PL1.1 ML2027-2028'!$K:$K,'TH theo dich vu'!$C24)/$D$1 -> 0 | Q24: =SUMIFS('PL1.1 ML2027-2028'!$H:$H,'PL1.1 ML2027-2028'!$J:$J,'TH theo dich vu'!Q$3,'PL1.1 ML2027-2028'!$K:$K,'TH theo dich vu'!$C24)/$D$1 -> 0 | R24: =SUMIFS('PL1.1 ML2027-2028'!$H:$H,'PL1.1 ML2027-2028'!$J:$J,'TH theo dich vu'!R$3,'PL1.1 ML2027-2028'!$K:$K,'TH theo dich vu'!$C24)/$D$1 -> 16.106412 | S24: =SUMIFS('PL1.1 ML2027-2028'!$H:$H,'PL1.1 ML2027-2028'!$J:$J,"TD",'PL1.1 ML2027-2028'!$M:$M,"IP",'PL1.1 ML2027-2028'!$K:$K,'TH theo dich vu'!C24)/$D$1 -> 0 | T24: =SUMIFS('PL1.1 ML2027-2028'!$H:$H,'PL1.1 ML2027-2028'!$J:$J,"TD",'PL1.1 ML2027-2028'!$M:$M,"Mạng cáp",'PL1.1 ML2027-2028'!$K:$K,'TH theo dich vu'!C24)/$D$1 -> 0 | U24: =SUMIFS('PL1.1 ML2027-2028'!$H:$H,'PL1.1 ML2027-2028'!$J:$J,'TH theo dich vu'!U$3,'PL1.1 ML2027-2028'!$K:$K,'TH theo dich vu'!$C24)/$D$1 -> 0 | V24: =SUMIFS('PL1.1 ML2027-2028'!$H:$H,'PL1.1 ML2027-2028'!$J:$J,'TH theo dich vu'!V$3,'PL1.1 ML2027-2028'!$K:$K,'TH theo dich vu'!$C24)/$D$1 -> 0 | W24: =SUM(O24:V24) -> 16.106412 | X24: =SUM(O24:V24) -> 16.106412 | Z24: =D24+O24 -> 0 | AA24: =E24+P24 -> 0 | AB24: =F24+Q24 -> 0 | AC24: =G24+R24 -> 30.639765 | AD24: =H24+S24 -> 0 | AE24: =I24+T24 -> 0 | AF24: =J24+U24 -> 0 | AG24: =K24+V24 -> 0 | AH24: =SUM(Z24:AG24) -> 30.639765 | AI24: =AH24/$AH$4 -> 0.15245662 | AJ24: 1
