Workbook
Name \p: #REF!
Name __atn1: #REF!
Name __atn10: #REF!
Name __atn2: #REF!
Name __atn3: #REF!
Name __atn4: #REF!
Name __atn5: #REF!
Name __atn6: #REF!
Name __atn7: #REF!
Name __atn8: #REF!
Name __atn9: #REF!
Name __boi1: #REF!
Name __boi2: #REF!
Name __CON1: #REF!
Name __CON2: #REF!
Name __cpd1: #REF!
Name __cpd2: #REF!
Name __deo1: #REF!
Name __deo10: #REF!
Name __deo2: #REF!
Name __deo3: #REF!
Name __deo4: #REF!
Name __deo5: #REF!
Name __deo6: #REF!
Name __deo7: #REF!
Name __deo8: #REF!
Name __deo9: #REF!
Name __lap1: #REF!
Name __lap2: #REF!
Name __nc151: #REF!
Name __NET2: #REF!
Name __SHR1: #REF!
Name __SHR2: #REF!
Name __tax1: #REF!
Name __tax2: #REF!
Name __tax3: #REF!
Name __tax4: #REF!
Name __tct5: #REF!
Name __tg427: #REF!
Name __TH20: #REF!
Name _1: #REF!
Name _1000A01: #REF!
Name _2: #REF!
Name _atn2: #REF!
Name _atn3: #REF!
Name _atn4: #REF!
Name _atn5: #REF!
Name _atn6: #REF!
Name _atn7: #REF!
Name _atn8: #REF!
Name _atn9: #REF!
Name _ATT_REG_DCOM_3G: #REF!
Name _ATT_REG_MI_3G: #REF!
Name _ATT_REG_voice_2G: #REF!
Name _ATT_REG_voice_3G: #REF!
Name _boi1: #REF!
Name _boi2: #REF!
Name _C_Lphi_4ab: #REF!
Name _chk1: #REF!
Name _CON1: #REF!

Sheet PL1.1 ML2027-2028
A1: PHỤ LỤC 1.1: BẢNG TỔNG HỢP CHI TIẾT NHU CẦU ĐẦU TƯ, MUA SẮM THEO QHĐC NĂM 2027-2028 (Ban hành kèm theo Tờ trình số của Tập đoàn CNVTQĐ)
G3: KHÔNG XÓA | J3: KHÔNG XÓA
A4: TT | B4: Nội dung/ hạng mục đầu tư, mua sắm | C4: Đơn vị tính | D4: Khối lượng | F4: Đơn giá dự kiến | G4: Thành tiền dự kiến (VNĐ) | I4: Dự kiến đơn vị đầu tư, mua sắm | J4: Mã mảng | K4: Mã DV | L4: Mã loại
D6: 2027 | E6: 2028 | F6: USD | G6: 2027 | H6: 2028
C7: 6 | F7: 7 | G7: =SUBTOTAL(9,G8:G2687) -> 25295609 | H7: =SUBTOTAL(9,H8:H2687) -> 24867096
B8: TỔNG ĐẦU TƯ VTTB VÀ XÂY LẮP 2027-2028 | G8: =SUBTOTAL(9,G9:G2687) -> 25295609 | H8: =SUBTOTAL(9,H9:H2687) -> 24867096
A9: P1 | B9: TỔNG ĐẦU TƯ VTTB 2027-2028 | G9: =SUBTOTAL(9,G10:G2153) -> 22438647 | H9: =SUBTOTAL(9,H10:H2153) -> 20897953
A10: A | B10: VÔ TUYẾN | G10: =SUBTOTAL(9,G11:G93) -> 6703944.7 | H10: =SUBTOTAL(9,H11:H93) -> 6963516.8
A11: A1 | B11: Mạng 5G | G11: =SUBTOTAL(9,G12:G21) -> 0 | H11: =SUBTOTAL(9,H12:H21) -> 0
A12: 1 | B12: Thiết bị macro 5G
A13: - | B13: Huawei_eNodeB 32T32R Dualband 2600-3500MHz (3AAU 3 sector, 3 cell LTE TDD @20+20+20MHz per 1 sector band 2600MHz and 1 cell NR @100MHz per 1 sector band C), Excluse BBU box. | C13: Trạm | G13: =F13*D13 -> 0 | H13: =F13*E13 -> 0 | J13: VT | K13: 5G | L13: VTTB
A14: - | B14: NodeB Massive MIMO 2.6GHz+3.5GHz | C14: Tủ | G14: =F14*D14 -> 0 | H14: =F14*E14 -> 0 | J14: VT | K14: 5G | L14: VTTB
A15: 2 | B15: Thiết bị RRU 5G
A16: - | B16: RRU 5G triển khai IBD | C16: Chiếc | G16: =F16*D16 -> 0 | H16: =F16*E16 -> 0 | J16: VT | K16: 5G | L16: VTTB
A17: 3 | B17: Thiết bị smallcell 5G
A18: - | B18: Thiết bị vô tuyến 5G 4T4R | C18: Chiếc | G18: =F18*D18 -> 0 | H18: =F18*E18 -> 0 | J18: VT | K18: 5G | L18: VTTB
A19: 4 | B19: Card Baseband
A20: - | B20: Card Baseband cho 5G | C20: Chiếc | G20: =F20*D20 -> 0 | H20: =F20*E20 -> 0 | J20: VT | K20: 5G | L20: VTTB
A21: 5 | B21: Nâng cấp hệ thống Inbuilding lên 5G
A22: A2 | B22: Mạng 2/3/4G | G22: =SUBTOTAL(9,G23:G44) -> 1128228.4 | H22: =SUBTOTAL(9,H23:H44) -> 653733.03
A23: I | B23: Vùng phủ | G23: =SUBTOTAL(9,G24:G44) -> 1128228.4 | H23: =SUBTOTAL(9,H24:H44) -> 653733.03
A24: 1 | B24: Thiết bị 4G | G24: =SUBTOTAL(9,G25:G31) -> 1128228.4 | H24: =SUBTOTAL(9,H25:H31) -> 653733.03
A25: - | B25: Huawei_SRAN Tripband eNodeB 700+800+900MHz (3 RRU 4x120w)(L111@15MHz+L111@10MHz ) 12Trx. Exclude BBU + BB card | C25: Tủ | D25: 11 | F25: 15065.825 | G25: =F25*D25 -> 165724.07 | H25: =F25*E25 -> 0 | J25: VT | K25: VPDĐ | L25: VTTB
A26: - | B26: Huawei_SRAN Tripband eNodeB 700+800+900MHz (3 RRU 4x120w)(L111@15MHz+L111@10MHz , 12TRx, BB card UBBPg2a) + 3 AISG | C26: Tủ | E26: 3 | F26: 18983.05 | G26: =F26*D26 -> 0 | H26: =F26*E26 -> 56949.15 | J26: VT | K26: VPDĐ | L26: VTTB
A27: - | B27: ZTE_SRAN Tripband eNodeB 700+800+900MHz (3 RRU 4x120w)(L111@15MHz+L111@10MHz , 12TRx, excluse BBU + BB card | C27: Tủ | D27: 3 | F27: 12944.888 | G27: =F27*D27 -> 38834.665 | H27: =F27*E27 -> 0 | J27: VT | K27: VPDĐ | L27: VTTB
A28: - | B28: ZTE_SRAN Tripband eNodeB 700+800+900MHz (3 RRU 4x120w)(L111@15MHz+L111@10MHz , 12TRx, BB VBPe3p) | C28: Chiếc | D28: 46 | E28: 30 | F28: 18886.296 | G28: =F28*D28 -> 868769.61 | H28: =F28*E28 -> 566588.88 | J28: VT | K28: VPDĐ | L28: VTTB
A29: - | B29: Anten 4G 8 port 4 port 700-900 + 4P 1800-2600 MHz | C29: Chiếc | D29: 180 | E29: 99 | F29: 305 | G29: =F29*D29 -> 54900 | H29: =F29*E29 -> 30195 | J29: VT | K29: VPDĐ | L29: VTTB
A30: - | B30: Jumper | C30: Chiếc | G30: =F30*D30 -> 0 | H30: =F30*E30 -> 0 | J30: VT | K30: VPDĐ | L30: VTTB
A31: - | B31: Bộ Gá đa năng (gồm 3 gá đơn lẻ và các phụ kiện) | C31: Chiếc | G31: =F31*D31 -> 0 | H31: =F31*E31 -> 0 | J31: VT | K31: VPDĐ | L31: VTTB
A32: 2 | B32: Thiết bị 3G | G32: =SUBTOTAL(9,G33:G38) -> 0 | H32: =SUBTOTAL(9,H33:H39) -> 0
A33: - | B33: NodeB 3G dualband_Cosite | C33: Tủ | G33: =F33*D33 -> 0 | H33: =F33*E33 -> 0 | J33: VT | K33: VPDĐ | L33: VTTB
A34: - | B34: NodeB 3G dualband_New site | C34: Tủ | G34: =F34*D34 -> 0 | H34: =F34*E34 -> 0 | J34: VT | K34: VPDĐ | L34: VTTB
A35: - | B35: Card baseband | C35: Chiếc | G35: =F35*D35 -> 0 | H35: =F35*E35 -> 0 | J35: VT | K35: VPDĐ | L35: VTTB
A36: - | B36: Anten đa băng | C36: Chiếc | G36: =F36*D36 -> 0 | H36: =F36*E36 -> 0 | J36: VT | K36: VPDĐ | L36: VTTB
A37: - | B37: Jumper | C37: Chiếc | G37: =F37*D37 -> 0 | H37: =F37*E37 -> 0 | J37: VT | K37: VPDĐ | L37: VTTB
A38: - | B38: Bộ Gá đa năng (gồm 3 gá đơn lẻ và các phụ kiện) | C38: Chiếc | G38: =F38*D38 -> 0 | H38: =F38*E38 -> 0 | J38: VT | K38: VPDĐ | L38: VTTB
A39: 3 | B39: Thiết bị 2G | G39: =SUBTOTAL(9,G40:G44) -> 0 | H39: =SUBTOTAL(9,H40:H46) -> 0
A40: - | B40: BTS 2G dualband_Cosite | C40: Tủ | G40: =F40*D40 -> 0 | H40: =F40*E40 -> 0 | J40: VT | K40: VPDĐ | L40: VTTB
A41: - | B41: BTS 2G dualband_New site 2G | C41: Tủ | G41: =F41*D41 -> 0 | H41: =F41*E41 -> 0 | J41: VT | K41: VPDĐ | L41: VTTB
A42: - | B42: Anten đa băng | C42: Chiếc | G42: =F42*D42 -> 0 | H42: =F42*E42 -> 0 | J42: VT | K42: VPDĐ | L42: VTTB
...

Sheet TH theo DV
D1: 1000000
A2: STT | B2: Nội dung | C2: Ko xóa | D2: 2027 (triệu USD) | M2: 2028 (triệu USD) | V2: 2027-2028 (triệu USD) | AD2: Tỷ trọng theo dịch vụ
B3: Mảng | C3: Mã DV | D3: VT | E3: ML | F3: CĐBR | G3: CNTT | H3: TD | I3: CĐ | J3: HT | K3: Tổng | L3: Tỷ trọng (%) | M3: VT | N3: ML | O3: CĐBR | P3: CNTT | Q3: TD | R3: CĐ | S3: HT | T3: Tổng | U3: Tỷ trọng (%) | V3: VT | W3: ML | X3: CĐBR | Y3: CNTT | Z3: TD | AA3: CĐ | AB3: Tổng | AC3: Tỷ trọng (%) | AD3: 4G | AE3: 5G | AF3: CĐBR | AG3: Truyền hình | AH3: DC | AI3: Cloud | AJ3: CNTT
A4: * | B4: Tổng | D4: =SUBTOTAL(9,D6:D33) -> 6.7039447 | E4: =SUBTOTAL(9,E6:E33) -> 4.4103298 | F4: =SUBTOTAL(9,F6:F33) -> 0.24886576 | G4: =SUBTOTAL(9,G6:G33) -> 3.143013 | H4: =SUBTOTAL(9,H6:H33) -> 4.2668639 | I4: =SUBTOTAL(9,I6:I33) -> 3.6656298 | J4: =SUBTOTAL(9,J6:J33) -> 2.7723624 | K4: =SUBTOTAL(9,K6:K33) -> 25.211009 | M4: =SUBTOTAL(9,M6:M33) -> 6.9635168 | N4: =SUBTOTAL(9,N6:N33) -> 1.26294 | O4: =SUBTOTAL(9,O6:O33) -> 0.15776484 | P4: =SUBTOTAL(9,P6:P33) -> 6.9118918 | Q4: =SUBTOTAL(9,Q6:Q33) -> 1.9307843 | R4: =SUBTOTAL(9,R6:R33) -> 3.6710549 | S4: =SUBTOTAL(9,S6:S33) -> 3.9691435 | T4: =SUBTOTAL(9,T6:T33) -> 24.867096 | V4: =SUBTOTAL(9,V6:V33) -> 13.667462 | W4: =SUBTOTAL(9,W6:W33) -> 5.6732698 | X4: =SUBTOTAL(9,X6:X33) -> 0.4066306 | Y4: =SUBTOTAL(9,Y6:Y33) -> 10.054905 | Z4: =SUBTOTAL(9,Z6:Z33) -> 6.1976482 | AA4: =SUBTOTAL(9,AA6:AA33) -> 7.3366847 | AB4: =SUBTOTAL(9,AB6:AB33) -> 43.3366 | AC4: =AB4/$AB$4 -> 1 | AD4: =AB10*AD10+AB12*AD12+AB21*AD21+AB24*AD24+AB25*AD25+(V30+W30+Z30+AA30)*AD30+(V31+W31+Z31+AA31)*AD31+(V32+W32+Z32+AA32)*AD32+AB33*AD33 -> 35.751091 | AE4: =AE7*AB7 -> 0.066364 | AF4: =AB8*AF8+AB16*AF16+AB17*AF17+AB19*AF19+X30*AF30+X31*AF31+X32*AF32+AB33*AF33 -> 2.0167546 | AG4: =AB18*AG18+AB21*AG21+X30*AG30+X31*AG31 -> 0.069726597 | AH4: =AB21*AH21 -> 1.3945319 | AI4: =AB9*AI9+AB20*AI20 -> 0.06506552 | AJ4: =AB23*AJ23+AB9*AJ9+Y30*AJ30+Y31*AJ31 -> 3.4639825
B5: Tỷ trọng theo mảng | D5: =D4/$K$4 -> 0.26591338 | E5: =E4/$K$4 -> 0.17493666 | F5: =F4/$K$4 -> 0.0098713128 | G5: =G4/$K$4 -> 0.12466827 | H5: =H4/$K$4 -> 0.16924606 | I5: =I4/$K$4 -> 0.14539798 | J5: =J4/$K$4 -> 0.10996634 | K5: =K4/$K$4 -> 1 | M5: =M4/$T$4 -> 0.28002935 | N5: =N4/$T$4 -> 0.050787594 | O5: =O4/$T$4 -> 0.006344321 | P5: =P4/$T$4 -> 0.27795331 | Q5: =Q4/$T$4 -> 0.07764414 | R5: =R4/$T$4 -> 0.14762701 | S5: =S4/$K$4 -> 0.15743692 | T5: =T4/$T$4 -> 1 | V5: =V4/$AB$4 -> 0.31537919 | W5: =W4/$AB$4 -> 0.13091174 | X5: =X4/$AB$4 -> 0.0093830758 | Y5: =Y4/$AB$4 -> 0.23201878 | Z5: =Z4/$AB$4 -> 0.14301187 | AA5: =AA4/$AB$4 -> 0.16929535 | AB5: =AB4/$AB$4 -> 1
A6: I | B6: Công nghệ mới triển khai diện rộng cho kinh doanh | D6: =SUBTOTAL(9,D7:D10) -> 0 | E6: =SUBTOTAL(9,E7:E10) -> 0 | F6: =SUBTOTAL(9,F7:F10) -> 0 | G6: =SUBTOTAL(9,G7:G10) -> 0.125126 | H6: =SUBTOTAL(9,H7:H10) -> 0.0353 | I6: =SUBTOTAL(9,I7:I10) -> 0 | J6: =SUBTOTAL(9,J7:J10) -> 0 | K6: =SUBTOTAL(9,K7:K10) -> 0.160426 | L6: =K6/$K$4 -> 0.0063633311 | M6: =SUBTOTAL(9,M7:M10) -> 0 | N6: =SUBTOTAL(9,N7:N10) -> 0 | O6: =SUBTOTAL(9,O7:O10) -> 0 | P6: =SUBTOTAL(9,P7:P10) -> 0 | Q6: =SUBTOTAL(9,Q7:Q10) -> 0.031064 | R6: =SUBTOTAL(9,R7:R10) -> 0 | S6: =SUBTOTAL(9,S7:S10) -> 0 | T6: =SUBTOTAL(9,T7:T10) -> 0.031064 | U6: =T6/$T$4 -> 0.0012492009 | V6: =SUBTOTAL(9,V7:V9) -> 0 | W6: =SUBTOTAL(9,W7:W9) -> 0 | X6: =SUBTOTAL(9,X7:X9) -> 0 | Y6: =SUBTOTAL(9,Y7:Y9) -> 0.125126 | Z6: =SUBTOTAL(9,Z7:Z9) -> 0.066364 | AA6: =SUBTOTAL(9,AA7:AA9) -> 0 | AB6: =SUBTOTAL(9,AB7:AB10) -> 0.19149 | AC6: =AB6/$AB$4 -> 0.0044186669
A7: 1 | B7: Mạng 5G | C7: 5G | D7: =SUMIFS('PL1.1 ML2027-2028'!$G:$G,'PL1.1 ML2027-2028'!$J:$J,'TH theo DV'!$D$3,'PL1.1 ML2027-2028'!$K:$K,'TH theo DV'!C7)/$D$1 -> 0 | E7: =SUMIFS('PL1.1 ML2027-2028'!$G:$G,'PL1.1 ML2027-2028'!$J:$J,'TH theo DV'!$E$3,'PL1.1 ML2027-2028'!$K:$K,'TH theo DV'!C7)/$D$1 -> 0 | F7: =SUMIFS('PL1.1 ML2027-2028'!$G:$G,'PL1.1 ML2027-2028'!$J:$J,'TH theo DV'!$F$3,'PL1.1 ML2027-2028'!$K:$K,'TH theo DV'!C7)/$D$1 -> 0 | G7: =SUMIFS('PL1.1 ML2027-2028'!$G:$G,'PL1.1 ML2027-2028'!$J:$J,'TH theo DV'!$G$3,'PL1.1 ML2027-2028'!$K:$K,'TH theo DV'!C7)/$D$1 -> 0 | H7: =SUMIFS('PL1.1 ML2027-2028'!$G:$G,'PL1.1 ML2027-2028'!$J:$J,'TH theo DV'!$H$3,'PL1.1 ML2027-2028'!$K:$K,'TH theo DV'!C7)/$D$1 -> 0.0353 | I7: =SUMIFS('PL1.1 ML2027-2028'!$G:$G,'PL1.1 ML2027-2028'!$J:$J,'TH theo DV'!$I$3,'PL1.1 ML2027-2028'!$K:$K,'TH theo DV'!C7)/$D$1 -> 0 | J7: =SUMIFS('PL1.1 ML2027-2028'!$G:$G,'PL1.1 ML2027-2028'!$J:$J,'TH theo DV'!J$3,'PL1.1 ML2027-2028'!$K:$K,'TH theo DV'!$C7)/$D$1 -> 0 | K7: =SUM(D7:J7) -> 0.0353 | L7: =K7/$K$4 -> 0.0014001819 | M7: =SUMIFS('PL1.1 ML2027-2028'!$H:$H,'PL1.1 ML2027-2028'!$J:$J,'TH theo DV'!M$3,'PL1.1 ML2027-2028'!$K:$K,'TH theo DV'!$C7)/$D$1 -> 0 | N7: =SUMIFS('PL1.1 ML2027-2028'!$H:$H,'PL1.1 ML2027-2028'!$J:$J,'TH theo DV'!N$3,'PL1.1 ML2027-2028'!$K:$K,'TH theo DV'!$C7)/$D$1 -> 0 | O7: =SUMIFS('PL1.1 ML2027-2028'!$H:$H,'PL1.1 ML2027-2028'!$J:$J,'TH theo DV'!O$3,'PL1.1 ML2027-2028'!$K:$K,'TH theo DV'!$C7)/$D$1 -> 0 | P7: =SUMIFS('PL1.1 ML2027-2028'!$H:$H,'PL1.1 ML2027-2028'!$J:$J,'TH theo DV'!P$3,'PL1.1 ML2027-2028'!$K:$K,'TH theo DV'!$C7)/$D$1 -> 0 | Q7: =SUMIFS('PL1.1 ML2027-2028'!$H:$H,'PL1.1 ML2027-2028'!$J:$J,'TH theo DV'!Q$3,'PL1.1 ML2027-2028'!$K:$K,'TH theo DV'!$C7)/$D$1 -> 0.031064 | R7: =SUMIFS('PL1.1 ML2027-2028'!$H:$H,'PL1.1 ML2027-2028'!$J:$J,'TH theo DV'!R$3,'PL1.1 ML2027-2028'!$K:$K,'TH theo DV'!$C7)/$D$1 -> 0 | S7: =SUMIFS('PL1.1 ML2027-2028'!$H:$H,'PL1.1 ML2027-2028'!$J:$J,'TH theo DV'!S$3,'PL1.1 ML2027-2028'!$K:$K,'TH theo DV'!$C7)/$D$1 -> 0 | T7: =SUM(M7:S7) -> 0.031064 | V7: =D7+M7 -> 0 | W7: =E7+N7 -> 0 | X7: =F7+O7 -> 0 | Y7: =G7+P7 -> 0 | Z7: =H7+Q7 -> 0.066364 | AA7: =I7+R7 -> 0 | AB7: =SUM(V7:AA7) -> 0.066364 | AC7: =AB7/$AB$4 -> 0.0015313615 | AE7: 1
A8: 2 | B8: XGSPON | C8: XGSPON | D8: =SUMIFS('PL1.1 ML2027-2028'!$G:$G,'PL1.1 ML2027-2028'!$J:$J,'TH theo DV'!$D$3,'PL1.1 ML2027-2028'!$K:$K,'TH theo DV'!C8)/$D$1 -> 0 | E8: =SUMIFS('PL1.1 ML2027-2028'!$G:$G,'PL1.1 ML2027-2028'!$J:$J,'TH theo DV'!$E$3,'PL1.1 ML2027-2028'!$K:$K,'TH theo DV'!C8)/$D$1 -> 0 | F8: =SUMIFS('PL1.1 ML2027-2028'!$G:$G,'PL1.1 ML2027-2028'!$J:$J,'TH theo DV'!$F$3,'PL1.1 ML2027-2028'!$K:$K,'TH theo DV'!C8)/$D$1 -> 0 | G8: =SUMIFS('PL1.1 ML2027-2028'!$G:$G,'PL1.1 ML2027-2028'!$J:$J,'TH theo DV'!$G$3,'PL1.1 ML2027-2028'!$K:$K,'TH theo DV'!C8)/$D$1 * 0.43287 -> 0 | H8: =SUMIFS('PL1.1 ML2027-2028'!$G:$G,'PL1.1 ML2027-2028'!$J:$J,'TH theo DV'!$H$3,'PL1.1 ML2027-2028'!$K:$K,'TH theo DV'!C8)/$D$1 -> 0 | I8: =SUMIFS('PL1.1 ML2027-2028'!$G:$G,'PL1.1 ML2027-2028'!$J:$J,'TH theo DV'!$I$3,'PL1.1 ML2027-2028'!$K:$K,'TH theo DV'!C8)/$D$1 -> 0 | J8: =SUMIFS('PL1.1 ML2027-2028'!$G:$G,'PL1.1 ML2027-2028'!$J:$J,'TH theo DV'!J$3,'PL1.1 ML2027-2028'!$K:$K,'TH theo DV'!$C8)/$D$1 -> 0 | K8: =SUM(D8:J8) -> 0 | L8: =K8/$K$4 -> 0 | M8: =SUMIFS('PL1.1 ML2027-2028'!$H:$H,'PL1.1 ML2027-2028'!$J:$J,'TH theo DV'!M$3,'PL1.1 ML2027-2028'!$K:$K,'TH theo DV'!$C8)/$D$1 -> 0 | N8: =SUMIFS('PL1.1 ML2027-2028'!$H:$H,'PL1.1 ML2027-2028'!$J:$J,'TH theo DV'!N$3,'PL1.1 ML2027-2028'!$K:$K,'TH theo DV'!$C8)/$D$1 -> 0 | O8: =SUMIFS('PL1.1 ML2027-2028'!$H:$H,'PL1.1 ML2027-2028'!$J:$J,'TH theo DV'!O$3,'PL1.1 ML2027-2028'!$K:$K,'TH theo DV'!$C8)/$D$1 -> 0 | P8: =SUMIFS('PL1.1 ML2027-2028'!$H:$H,'PL1.1 ML2027-2028'!$J:$J,'TH theo DV'!P$3,'PL1.1 ML2027-2028'!$K:$K,'TH theo DV'!$C8)/$D$1 -> 0 | Q8: =SUMIFS('PL1.1 ML2027-2028'!$H:$H,'PL1.1 ML2027-2028'!$J:$J,'TH theo DV'!Q$3,'PL1.1 ML2027-2028'!$K:$K,'TH theo DV'!$C8)/$D$1 -> 0 | R8: =SUMIFS('PL1.1 ML2027-2028'!$H:$H,'PL1.1 ML2027-2028'!$J:$J,'TH theo DV'!R$3,'PL1.1 ML2027-2028'!$K:$K,'TH theo DV'!$C8)/$D$1 -> 0 | S8: =SUMIFS('PL1.1 ML2027-2028'!$H:$H,'PL1.1 ML2027-2028'!$J:$J,'TH theo DV'!S$3,'PL1.1 ML2027-2028'!$K:$K,'TH theo DV'!$C8)/$D$1 -> 0 | T8: =SUM(M8:S8) -> 0 | V8: =D8+M8 -> 0 | W8: =E8+N8 -> 0 | X8: =F8+O8 -> 0 | Y8: =G8+P8 -> 0 | Z8: =H8+Q8 -> 0 | AA8: =I8+R8 -> 0 | AB8: =SUM(V8:AA8) -> 0 | AC8: =AB8/$AB$4 -> 0 | AF8: 1
A9: 3 | B9: AI/GPU | C9: AI/GPU | D9: =SUMIFS('PL1.1 ML2027-2028'!$G:$G,'PL1.1 ML2027-2028'!$J:$J,'TH theo DV'!$D$3,'PL1.1 ML2027-2028'!$K:$K,'TH theo DV'!C9)/$D$1 -> 0 | E9: =SUMIFS('PL1.1 ML2027-2028'!$G:$G,'PL1.1 ML2027-2028'!$J:$J,'TH theo DV'!$E$3,'PL1.1 ML2027-2028'!$K:$K,'TH theo DV'!C9)/$D$1 -> 0 | F9: =SUMIFS('PL1.1 ML2027-2028'!$G:$G,'PL1.1 ML2027-2028'!$J:$J,'TH theo DV'!$F$3,'PL1.1 ML2027-2028'!$K:$K,'TH theo DV'!C9)/$D$1 -> 0 | G9: =SUMIFS('PL1.1 ML2027-2028'!$G:$G,'PL1.1 ML2027-2028'!$J:$J,'TH theo DV'!G$3,'PL1.1 ML2027-2028'!$K:$K,'TH theo DV'!$C9)/$D$1 -> 0.125126 | H9: =SUMIFS('PL1.1 ML2027-2028'!$G:$G,'PL1.1 ML2027-2028'!$J:$J,'TH theo DV'!$H$3,'PL1.1 ML2027-2028'!$K:$K,'TH theo DV'!C9)/$D$1 -> 0 | I9: =SUMIFS('PL1.1 ML2027-2028'!$G:$G,'PL1.1 ML2027-2028'!$J:$J,'TH theo DV'!$I$3,'PL1.1 ML2027-2028'!$K:$K,'TH theo DV'!C9)/$D$1 -> 0 | J9: =SUMIFS('PL1.1 ML2027-2028'!$G:$G,'PL1.1 ML2027-2028'!$J:$J,'TH theo DV'!J$3,'PL1.1 ML2027-2028'!$K:$K,'TH theo DV'!$C9)/$D$1 -> 0 | K9: =SUM(D9:J9) -> 0.125126 | L9: =K9/$K$4 -> 0.0049631492 | M9: =SUMIFS('PL1.1 ML2027-2028'!$H:$H,'PL1.1 ML2027-2028'!$J:$J,'TH theo DV'!M$3,'PL1.1 ML2027-2028'!$K:$K,'TH theo DV'!$C9)/$D$1 -> 0 | N9: =SUMIFS('PL1.1 ML2027-2028'!$H:$H,'PL1.1 ML2027-2028'!$J:$J,'TH theo DV'!N$3,'PL1.1 ML2027-2028'!$K:$K,'TH theo DV'!$C9)/$D$1 -> 0 | O9: =SUMIFS('PL1.1 ML2027-2028'!$H:$H,'PL1.1 ML2027-2028'!$J:$J,'TH theo DV'!O$3,'PL1.1 ML2027-2028'!$K:$K,'TH theo DV'!$C9)/$D$1 -> 0 | P9: =SUMIFS('PL1.1 ML2027-2028'!$H:$H,'PL1.1 ML2027-2028'!$J:$J,'TH theo DV'!P$3,'PL1.1 ML2027-2028'!$K:$K,'TH theo DV'!$C9)/$D$1 -> 0 | Q9: =SUMIFS('PL1.1 ML2027-2028'!$H:$H,'PL1.1 ML2027-2028'!$J:$J,'TH theo DV'!Q$3,'PL1.1 ML2027-2028'!$K:$K,'TH theo DV'!$C9)/$D$1 -> 0 | R9: =SUMIFS('PL1.1 ML2027-2028'!$H:$H,'PL1.1 ML2027-2028'!$J:$J,'TH theo DV'!R$3,'PL1.1 ML2027-2028'!$K:$K,'TH theo DV'!$C9)/$D$1 -> 0 | S9: =SUMIFS('PL1.1 ML2027-2028'!$H:$H,'PL1.1 ML2027-2028'!$J:$J,'TH theo DV'!S$3,'PL1.1 ML2027-2028'!$K:$K,'TH theo DV'!$C9)/$D$1 -> 0 | T9: =SUM(M9:S9) -> 0 | V9: =D9+M9 -> 0 | W9: =E9+N9 -> 0 | X9: =F9+O9 -> 0 | Y9: =G9+P9 -> 0.125126 | Z9: =H9+Q9 -> 0 | AA9: =I9+R9 -> 0 | AB9: =SUM(V9:AA9) -> 0.125126 | AC9: =AB9/$AB$4 -> 0.0028873054 | AI9: 0.52 | AJ9: 0.48
A10: 4 | B10: Private Mobile Network | C10: PMN | D10: =SUMIFS('PL1.1 ML2027-2028'!$G:$G,'PL1.1 ML2027-2028'!$J:$J,'TH theo DV'!$D$3,'PL1.1 ML2027-2028'!$K:$K,'TH theo DV'!C10)/$D$1 -> 0 | E10: =SUMIFS('PL1.1 ML2027-2028'!$G:$G,'PL1.1 ML2027-2028'!$J:$J,'TH theo DV'!$E$3,'PL1.1 ML2027-2028'!$K:$K,'TH theo DV'!C10)/$D$1 -> 0 | F10: =SUMIFS('PL1.1 ML2027-2028'!$G:$G,'PL1.1 ML2027-2028'!$J:$J,'TH theo DV'!$F$3,'PL1.1 ML2027-2028'!$K:$K,'TH theo DV'!C10)/$D$1 -> 0 | G10: =SUMIFS('PL1.1 ML2027-2028'!$G:$G,'PL1.1 ML2027-2028'!$J:$J,'TH theo DV'!$G$3,'PL1.1 ML2027-2028'!$K:$K,'TH theo DV'!C10)/$D$1 -> 0 | H10: =SUMIFS('PL1.1 ML2027-2028'!$G:$G,'PL1.1 ML2027-2028'!$J:$J,'TH theo DV'!$H$3,'PL1.1 ML2027-2028'!$K:$K,'TH theo DV'!C10)/$D$1 -> 0 | I10: =SUMIFS('PL1.1 ML2027-2028'!$G:$G,'PL1.1 ML2027-2028'!$J:$J,'TH theo DV'!$I$3,'PL1.1 ML2027-2028'!$K:$K,'TH theo DV'!C10)/$D$1 -> 0 | J10: =SUMIFS('PL1.1 ML2027-2028'!$G:$G,'PL1.1 ML2027-2028'!$J:$J,'TH theo DV'!J$3,'PL1.1 ML2027-2028'!$K:$K,'TH theo DV'!$C10)/$D$1 -> 0 | K10: =SUM(D10:J10) -> 0 | L10: =K10/$K$4 -> 0 | M10: =SUMIFS('PL1.1 ML2027-2028'!$H:$H,'PL1.1 ML2027-2028'!$J:$J,'TH theo DV'!M$3,'PL1.1 ML2027-2028'!$K:$K,'TH theo DV'!$C10)/$D$1 -> 0 | N10: =SUMIFS('PL1.1 ML2027-2028'!$H:$H,'PL1.1 ML2027-2028'!$J:$J,'TH theo DV'!N$3,'PL1.1 ML2027-2028'!$K:$K,'TH theo DV'!$C10)/$D$1 -> 0 | O10: =SUMIFS('PL1.1 ML2027-2028'!$H:$H,'PL1.1 ML2027-2028'!$J:$J,'TH theo DV'!O$3,'PL1.1 ML2027-2028'!$K:$K,'TH theo DV'!$C10)/$D$1 -> 0 | P10: =SUMIFS('PL1.1 ML2027-2028'!$H:$H,'PL1.1 ML2027-2028'!$J:$J,'TH theo DV'!P$3,'PL1.1 ML2027-2028'!$K:$K,'TH theo DV'!$C10)/$D$1 -> 0 | Q10: =SUMIFS('PL1.1 ML2027-2028'!$H:$H,'PL1.1 ML2027-2028'!$J:$J,'TH theo DV'!Q$3,'PL1.1 ML2027-2028'!$K:$K,'TH theo DV'!$C10)/$D$1 -> 0 | R10: =SUMIFS('PL1.1 ML2027-2028'!$H:$H,'PL1.1 ML2027-2028'!$J:$J,'TH theo DV'!R$3,'PL1.1 ML2027-2028'!$K:$K,'TH theo DV'!$C10)/$D$1 -> 0 | S10: =SUMIFS('PL1.1 ML2027-2028'!$H:$H,'PL1.1 ML2027-2028'!$J:$J,'TH theo DV'!S$3,'PL1.1 ML2027-2028'!$K:$K,'TH theo DV'!$C10)/$D$1 -> 0 | T10: =SUM(M10:S10) -> 0 | V10: =D10+M10 -> 0 | W10: =E10+N10 -> 0 | X10: =F10+O10 -> 0 | Y10: =G10+P10 -> 0 | Z10: =H10+Q10 -> 0 | AA10: =I10+R10 -> 0 | AB10: =SUM(V10:AA10) -> 0 | AC10: =AB10/$AB$4 -> 0 | AD10: 1
A11: II | B11: Mở rộng mạng lưới hiện tại cho kinh doanh | D11: =SUBTOTAL(9,D12:D25) -> 6.1685237 | E11: =SUBTOTAL(9,E12:E25) -> 3.5683679 | F11: =SUBTOTAL(9,F12:F25) -> 0.24886576 | G11: =SUBTOTAL(9,G12:G25) -> 2.084005 | H11: =SUBTOTAL(9,H12:H25) -> 3.6325999 | I11: =SUBTOTAL(9,I12:I25) -> 2.3053437 | J11: =SUBTOTAL(9,J12:J25) -> 2.7723624 | K11: =SUBTOTAL(9,K12:K28) -> 21.021192 | L11: =K11/$K$4 -> 0.83381002 | M11: =SUBTOTAL(9,M12:M25) -> 6.2622168 | N11: =SUBTOTAL(9,N12:N25) -> 0.2919 | O11: =SUBTOTAL(9,O12:O25) -> 0.15776484 | P11: =SUBTOTAL(9,P12:P25) -> 6.6932028 | Q11: =SUBTOTAL(9,Q12:Q25) -> 1.2954203 | R11: =SUBTOTAL(9,R12:R25) -> 1.8311428 | S11: =SUBTOTAL(9,S12:S25) -> 3.9691435 | T11: =SUBTOTAL(9,T12:T28) -> 20.768751 | U11: =T11/$T$4 -> 0.83519004 | V11: =SUBTOTAL(9,V12:V32) -> 13.667462 | W11: =SUBTOTAL(9,W12:W32) -> 5.6732698 | X11: =SUBTOTAL(9,X12:X32) -> 0.4066306 | Y11: =SUBTOTAL(9,Y12:Y32) -> 9.9297788 | Z11: =SUBTOTAL(9,Z12:Z32) -> 6.1312842 | AA11: =SUBTOTAL(9,AA12:AA32) -> 7.3366847 | AB11: =SUBTOTAL(9,AB12:AB25) -> 34.539354 | AC11: =AB11/$AB$4 -> 0.79700193
A12: 1 | B12: Mạng 2/3/4G | D12: =SUBTOTAL(9,D13:D14) -> 6.1685237 | E12: =SUBTOTAL(9,E13:E14) -> 3.5683679 | F12: =SUBTOTAL(9,F13:F14) -> 0 | G12: =SUBTOTAL(9,G13:G14) -> 0 | H12: =SUBTOTAL(9,H13:H14) -> 0.834259 | I12: =SUBTOTAL(9,I13:I14) -> 1.9053437 | J12: =SUBTOTAL(9,J13:J14) -> 2.6355654 | K12: =SUBTOTAL(9,K13:K14) -> 15.11206 | L12: =K12/$K$4 -> 0.59942303 | M12: =SUBTOTAL(9,M13:M14) -> 6.2622168 | N12: =SUBTOTAL(9,N13:N14) -> 0.2919 | O12: =SUBTOTAL(9,O13:O14) -> 0 | P12: =SUBTOTAL(9,P13:P14) -> 0 | Q12: =SUBTOTAL(9,Q13:Q14) -> 1.1404723 | R12: =SUBTOTAL(9,R13:R14) -> 1.8311428 | S12: =SUBTOTAL(9,S13:S14) -> 3.9691435 | T12: =SUBTOTAL(9,T13:T14) -> 13.494876 | U12: =T12/$T$4 -> 0.54267999 | V12: =SUBTOTAL(9,V13:V14) -> 12.430741 | W12: =SUBTOTAL(9,W13:W14) -> 3.8602679 | X12: =SUBTOTAL(9,X13:X14) -> 0 | Y12: =SUBTOTAL(9,Y13:Y14) -> 0 | Z12: =SUBTOTAL(9,Z13:Z14) -> 1.9747313 | AA12: =SUBTOTAL(9,AA13:AA14) -> 3.7364865 | AB12: =SUBTOTAL(9,AB13:AB14) -> 22.002226 | AC12: =AB12/$AB$4 -> 0.50770541 | AD12: 1
A13: - | B13: 2/3/4G vùng phủ | C13: VPDĐ | D13: =SUMIFS('PL1.1 ML2027-2028'!$G:$G,'PL1.1 ML2027-2028'!$J:$J,'TH theo DV'!$D$3,'PL1.1 ML2027-2028'!$K:$K,'TH theo DV'!C13)/$D$1 -> 1.1282284 | E13: =SUMIFS('PL1.1 ML2027-2028'!$G:$G,'PL1.1 ML2027-2028'!$J:$J,'TH theo DV'!$E$3,'PL1.1 ML2027-2028'!$K:$K,'TH theo DV'!C13)/$D$1 -> 0 | F13: =SUMIFS('PL1.1 ML2027-2028'!$G:$G,'PL1.1 ML2027-2028'!$J:$J,'TH theo DV'!$F$3,'PL1.1 ML2027-2028'!$K:$K,'TH theo DV'!C13)/$D$1 -> 0 | G13: =SUMIFS('PL1.1 ML2027-2028'!$G:$G,'PL1.1 ML2027-2028'!$J:$J,'TH theo DV'!$G$3,'PL1.1 ML2027-2028'!$K:$K,'TH theo DV'!C13)/$D$1 -> 0 | H13: =SUMIFS('PL1.1 ML2027-2028'!$G:$G,'PL1.1 ML2027-2028'!$J:$J,'TH theo DV'!H$3,'PL1.1 ML2027-2028'!$K:$K,'TH theo DV'!$C13)/$D$1 -> 0.834259 | I13: =SUMIFS('PL1.1 ML2027-2028'!$G:$G,'PL1.1 ML2027-2028'!$J:$J,'TH theo DV'!$I$3,'PL1.1 ML2027-2028'!$K:$K,'TH theo DV'!C13)/$D$1 -> 1.4700764 | J13: =SUMIFS('PL1.1 ML2027-2028'!$G:$G,'PL1.1 ML2027-2028'!$J:$J,'TH theo DV'!J$3,'PL1.1 ML2027-2028'!$K:$K,'TH theo DV'!$C13)/$D$1 -> 2.2636443 | K13: =SUM(D13:J13) -> 5.6962081 | L13: =K13/$K$4 -> 0.22594129 | M13: =SUMIFS('PL1.1 ML2027-2028'!$H:$H,'PL1.1 ML2027-2028'!$J:$J,'TH theo DV'!M$3,'PL1.1 ML2027-2028'!$K:$K,'TH theo DV'!$C13)/$D$1 -> 0.65373303 | N13: =SUMIFS('PL1.1 ML2027-2028'!$H:$H,'PL1.1 ML2027-2028'!$J:$J,'TH theo DV'!N$3,'PL1.1 ML2027-2028'!$K:$K,'TH theo DV'!$C13)/$D$1 -> 0 | O13: =SUMIFS('PL1.1 ML2027-2028'!$H:$H,'PL1.1 ML2027-2028'!$J:$J,'TH theo DV'!O$3,'PL1.1 ML2027-2028'!$K:$K,'TH theo DV'!$C13)/$D$1 -> 0 | P13: =SUMIFS('PL1.1 ML2027-2028'!$H:$H,'PL1.1 ML2027-2028'!$J:$J,'TH theo DV'!P$3,'PL1.1 ML2027-2028'!$K:$K,'TH theo DV'!$C13)/$D$1 -> 0 | Q13: =SUMIFS('PL1.1 ML2027-2028'!$H:$H,'PL1.1 ML2027-2028'!$J:$J,'TH theo DV'!Q$3,'PL1.1 ML2027-2028'!$K:$K,'TH theo DV'!$C13)/$D$1 -> 1.1404723 | R13: =SUMIFS('PL1.1 ML2027-2028'!$H:$H,'PL1.1 ML2027-2028'!$J:$J,'TH theo DV'!R$3,'PL1.1 ML2027-2028'!$K:$K,'TH theo DV'!$C13)/$D$1 -> 0.9702167 | S13: =SUMIFS('PL1.1 ML2027-2028'!$H:$H,'PL1.1 ML2027-2028'!$J:$J,'TH theo DV'!S$3,'PL1.1 ML2027-2028'!$K:$K,'TH theo DV'!$C13)/$D$1 -> 1.4610112 | T13: =SUM(M13:S13) -> 4.2254333 | V13: =D13+M13 -> 1.7819614 | W13: =E13+N13 -> 0 | X13: =F13+O13 -> 0 | Y13: =G13+P13 -> 0 | Z13: =H13+Q13 -> 1.9747313 | AA13: =I13+R13 -> 2.4402931 | AB13: =SUM(V13:AA13) -> 6.1969858 | AC13: =AB13/$AB$4 -> 0.14299659
A14: - | B14: 2/3/4G dung lượng | C14: DLDĐ | D14: =SUMIFS('PL1.1 ML2027-2028'!$G:$G,'PL1.1 ML2027-2028'!$J:$J,'TH theo DV'!$D$3,'PL1.1 ML2027-2028'!$K:$K,'TH theo DV'!C14)/$D$1 -> 5.0402954 | E14: =SUMIFS('PL1.1 ML2027-2028'!$G:$G,'PL1.1 ML2027-2028'!$J:$J,'TH theo DV'!$E$3,'PL1.1 ML2027-2028'!$K:$K,'TH theo DV'!C14)/$D$1 -> 3.5683679 | F14: =SUMIFS('PL1.1 ML2027-2028'!$G:$G,'PL1.1 ML2027-2028'!$J:$J,'TH theo DV'!$F$3,'PL1.1 ML2027-2028'!$K:$K,'TH theo DV'!C14)/$D$1 -> 0 | G14: =SUMIFS('PL1.1 ML2027-2028'!$G:$G,'PL1.1 ML2027-2028'!$J:$J,'TH theo DV'!$G$3,'PL1.1 ML2027-2028'!$K:$K,'TH theo DV'!C14)/$D$1 -> 0 | H14: =SUMIFS('PL1.1 ML2027-2028'!$G:$G,'PL1.1 ML2027-2028'!$J:$J,'TH theo DV'!H$3,'PL1.1 ML2027-2028'!$K:$K,'TH theo DV'!$C14)/$D$1 -> 0 | I14: =SUMIFS('PL1.1 ML2027-2028'!$G:$G,'PL1.1 ML2027-2028'!$J:$J,'TH theo DV'!$I$3,'PL1.1 ML2027-2028'!$K:$K,'TH theo DV'!C14)/$D$1 -> 0.43526727 | J14: =SUMIFS('PL1.1 ML2027-2028'!$G:$G,'PL1.1 ML2027-2028'!$J:$J,'TH theo DV'!J$3,'PL1.1 ML2027-2028'!$K:$K,'TH theo DV'!$C14)/$D$1 -> 0.37192109 | K14: =SUM(D14:J14) -> 9.4158516 | L14: =K14/$K$4 -> 0.37348174 | M14: =SUMIFS('PL1.1 ML2027-2028'!$H:$H,'PL1.1 ML2027-2028'!$J:$J,'TH theo DV'!M$3,'PL1.1 ML2027-2028'!$K:$K,'TH theo DV'!$C14)/$D$1 -> 5.6084838 | N14: =SUMIFS('PL1.1 ML2027-2028'!$H:$H,'PL1.1 ML2027-2028'!$J:$J,'TH theo DV'!N$3,'PL1.1 ML2027-2028'!$K:$K,'TH theo DV'!$C14)/$D$1 -> 0.2919 | O14: =SUMIFS('PL1.1 ML2027-2028'!$H:$H,'PL1.1 ML2027-2028'!$J:$J,'TH theo DV'!O$3,'PL1.1 ML2027-2028'!$K:$K,'TH theo DV'!$C14)/$D$1 -> 0 | P14: =SUMIFS('PL1.1 ML2027-2028'!$H:$H,'PL1.1 ML2027-2028'!$J:$J,'TH theo DV'!P$3,'PL1.1 ML2027-2028'!$K:$K,'TH theo DV'!$C14)/$D$1 -> 0 | Q14: =SUMIFS('PL1.1 ML2027-2028'!$H:$H,'PL1.1 ML2027-2028'!$J:$J,'TH theo DV'!Q$3,'PL1.1 ML2027-2028'!$K:$K,'TH theo DV'!$C14)/$D$1 -> 0 | R14: =SUMIFS('PL1.1 ML2027-2028'!$H:$H,'PL1.1 ML2027-2028'!$J:$J,'TH theo DV'!R$3,'PL1.1 ML2027-2028'!$K:$K,'TH theo DV'!$C14)/$D$1 -> 0.86092614 | S14: =SUMIFS('PL1.1 ML2027-2028'!$H:$H,'PL1.1 ML2027-2028'!$J:$J,'TH theo DV'!S$3,'PL1.1 ML2027-2028'!$K:$K,'TH theo DV'!$C14)/$D$1 -> 2.5081323 | T14: =SUM(M14:S14) -> 9.2694422 | V14: =D14+M14 -> 10.648779 | W14: =E14+N14 -> 3.8602679 | X14: =F14+O14 -> 0 | Y14: =G14+P14 -> 0 | Z14: =H14+Q14 -> 0 | AA14: =I14+R14 -> 1.2961934 | AB14: =SUM(V14:AA14) -> 15.80524 | AC14: =AB14/$AB$4 -> 0.36470883
A15: 2 | B15: Mạng BRCĐ&TH | D15: =SUBTOTAL(9,D16:D19) -> 0 | E15: =SUBTOTAL(9,E16:E19) -> 0 | F15: =SUBTOTAL(9,F16:F19) -> 0.24886576 | G15: =SUBTOTAL(9,G16:G19) -> 0 | H15: =SUBTOTAL(9,H16:H19) -> 1.51789 | I15: =SUBTOTAL(9,I16:I19) -> 0 | J15: =SUBTOTAL(9,J16:J19) -> 0 | K15: =SUBTOTAL(9,K16:K19) -> 1.7667558 | L15: =K15/$K$4 -> 0.07007874 | M15: =SUBTOTAL(9,M16:M19) -> 0 | N15: =SUBTOTAL(9,N16:N19) -> 0 | O15: =SUBTOTAL(9,O16:O19) -> 0.15776484 | P15: =SUBTOTAL(9,P16:P19) -> 0 | Q15: =SUBTOTAL(9,Q16:Q19) -> 0.092234 | R15: =SUBTOTAL(9,R16:R19) -> 0 | S15: =SUBTOTAL(9,S16:S19) -> 0 | T15: =SUBTOTAL(9,T16:T19) -> 0.24999884 | U15: =T15/$T$4 -> 0.010053399 | V15: =SUBTOTAL(9,V16:V19) -> 0 | W15: =SUBTOTAL(9,W16:W19) -> 0 | X15: =SUBTOTAL(9,X16:X19) -> 0.4066306 | Y15: =SUBTOTAL(9,Y16:Y19) -> 0 | Z15: =SUBTOTAL(9,Z16:Z19) -> 1.610124 | AA15: =SUBTOTAL(9,AA16:AA19) -> 0 | AB15: =SUBTOTAL(9,AB16:AB19) -> 2.0167546 | AC15: =AB15/$AB$4 -> 0.046536983
A16: - | B16: Vùng phủ GPON | C16: VPGPON | D16: =SUMIFS('PL1.1 ML2027-2028'!$G:$G,'PL1.1 ML2027-2028'!$J:$J,'TH theo DV'!$D$3,'PL1.1 ML2027-2028'!$K:$K,'TH theo DV'!C16)/$D$1 -> 0 | E16: =SUMIFS('PL1.1 ML2027-2028'!$G:$G,'PL1.1 ML2027-2028'!$J:$J,'TH theo DV'!$E$3,'PL1.1 ML2027-2028'!$K:$K,'TH theo DV'!C16)/$D$1 -> 0 | F16: =SUMIFS('PL1.1 ML2027-2028'!$G:$G,'PL1.1 ML2027-2028'!$J:$J,'TH theo DV'!$F$3,'PL1.1 ML2027-2028'!$K:$K,'TH theo DV'!C16)/$D$1 -> 0 | G16: =SUMIFS('PL1.1 ML2027-2028'!$G:$G,'PL1.1 ML2027-2028'!$J:$J,'TH theo DV'!$G$3,'PL1.1 ML2027-2028'!$K:$K,'TH theo DV'!C16)/$D$1 -> 0 | H16: =SUMIFS('PL1.1 ML2027-2028'!$G:$G,'PL1.1 ML2027-2028'!$J:$J,'TH theo DV'!$H$3,'PL1.1 ML2027-2028'!$K:$K,'TH theo DV'!C16)/$D$1 -> 0 | I16: =SUMIFS('PL1.1 ML2027-2028'!$G:$G,'PL1.1 ML2027-2028'!$J:$J,'TH theo DV'!$I$3,'PL1.1 ML2027-2028'!$K:$K,'TH theo DV'!C16)/$D$1 -> 0 | J16: =SUMIFS('PL1.1 ML2027-2028'!$G:$G,'PL1.1 ML2027-2028'!$J:$J,'TH theo DV'!J$3,'PL1.1 ML2027-2028'!$K:$K,'TH theo DV'!$C16)/$D$1 -> 0 | K16: =SUM(D16:J16) -> 0 | L16: =K16/$K$4 -> 0 | M16: =SUMIFS('PL1.1 ML2027-2028'!$H:$H,'PL1.1 ML2027-2028'!$J:$J,'TH theo DV'!M$3,'PL1.1 ML2027-2028'!$K:$K,'TH theo DV'!$C16)/$D$1 -> 0 | N16: =SUMIFS('PL1.1 ML2027-2028'!$H:$H,'PL1.1 ML2027-2028'!$J:$J,'TH theo DV'!N$3,'PL1.1 ML2027-2028'!$K:$K,'TH theo DV'!$C16)/$D$1 -> 0 | O16: =SUMIFS('PL1.1 ML2027-2028'!$H:$H,'PL1.1 ML2027-2028'!$J:$J,'TH theo DV'!O$3,'PL1.1 ML2027-2028'!$K:$K,'TH theo DV'!$C16)/$D$1 -> 0 | P16: =SUMIFS('PL1.1 ML2027-2028'!$H:$H,'PL1.1 ML2027-2028'!$J:$J,'TH theo DV'!P$3,'PL1.1 ML2027-2028'!$K:$K,'TH theo DV'!$C16)/$D$1 -> 0 | Q16: =SUMIFS('PL1.1 ML2027-2028'!$H:$H,'PL1.1 ML2027-2028'!$J:$J,'TH theo DV'!Q$3,'PL1.1 ML2027-2028'!$K:$K,'TH theo DV'!$C16)/$D$1 -> 0 | R16: =SUMIFS('PL1.1 ML2027-2028'!$H:$H,'PL1.1 ML2027-2028'!$J:$J,'TH theo DV'!R$3,'PL1.1 ML2027-2028'!$K:$K,'TH theo DV'!$C16)/$D$1 -> 0 | S16: =SUMIFS('PL1.1 ML2027-2028'!$H:$H,'PL1.1 ML2027-2028'!$J:$J,'TH theo DV'!S$3,'PL1.1 ML2027-2028'!$K:$K,'TH theo DV'!$C16)/$D$1 -> 0 | T16: =SUM(M16:S16) -> 0 | V16: =D16+M16 -> 0 | W16: =E16+N16 -> 0 | X16: =F16+O16 -> 0 | Y16: =G16+P16 -> 0 | Z16: =H16+Q16 -> 0 | AA16: =I16+R16 -> 0 | AB16: =SUM(V16:AA16) -> 0 | AC16: =AB16/$AB$4 -> 0 | AF16: 1
A17: - | B17: Dung lượng Internet | C17: DLGPON | D17: =SUMIFS('PL1.1 ML2027-2028'!$G:$G,'PL1.1 ML2027-2028'!$J:$J,'TH theo DV'!$D$3,'PL1.1 ML2027-2028'!$K:$K,'TH theo DV'!C17)/$D$1 -> 0 | E17: =SUMIFS('PL1.1 ML2027-2028'!$G:$G,'PL1.1 ML2027-2028'!$J:$J,'TH theo DV'!$E$3,'PL1.1 ML2027-2028'!$K:$K,'TH theo DV'!C17)/$D$1 -> 0 | F17: =SUMIFS('PL1.1 ML2027-2028'!$G:$G,'PL1.1 ML2027-2028'!$J:$J,'TH theo DV'!$F$3,'PL1.1 ML2027-2028'!$K:$K,'TH theo DV'!C17)/$D$1 -> 0 | G17: =SUMIFS('PL1.1 ML2027-2028'!$G:$G,'PL1.1 ML2027-2028'!$J:$J,'TH theo DV'!$G$3,'PL1.1 ML2027-2028'!$K:$K,'TH theo DV'!C17)/$D$1 -> 0 | H17: =SUMIFS('PL1.1 ML2027-2028'!$G:$G,'PL1.1 ML2027-2028'!$J:$J,'TH theo DV'!$H$3,'PL1.1 ML2027-2028'!$K:$K,'TH theo DV'!C17)/$D$1 -> 1.51789 | I17: =SUMIFS('PL1.1 ML2027-2028'!$G:$G,'PL1.1 ML2027-2028'!$J:$J,'TH theo DV'!$I$3,'PL1.1 ML2027-2028'!$K:$K,'TH theo DV'!C17)/$D$1 -> 0 | J17: =SUMIFS('PL1.1 ML2027-2028'!$G:$G,'PL1.1 ML2027-2028'!$J:$J,'TH theo DV'!J$3,'PL1.1 ML2027-2028'!$K:$K,'TH theo DV'!$C17)/$D$1 -> 0 | K17: =SUM(D17:J17) -> 1.51789 | L17: =K17/$K$4 -> 0.060207427 | M17: =SUMIFS('PL1.1 ML2027-2028'!$H:$H,'PL1.1 ML2027-2028'!$J:$J,'TH theo DV'!M$3,'PL1.1 ML2027-2028'!$K:$K,'TH theo DV'!$C17)/$D$1 -> 0 | N17: =SUMIFS('PL1.1 ML2027-2028'!$H:$H,'PL1.1 ML2027-2028'!$J:$J,'TH theo DV'!N$3,'PL1.1 ML2027-2028'!$K:$K,'TH theo DV'!$C17)/$D$1 -> 0 | O17: =SUMIFS('PL1.1 ML2027-2028'!$H:$H,'PL1.1 ML2027-2028'!$J:$J,'TH theo DV'!O$3,'PL1.1 ML2027-2028'!$K:$K,'TH theo DV'!$C17)/$D$1 -> 0 | P17: =SUMIFS('PL1.1 ML2027-2028'!$H:$H,'PL1.1 ML2027-2028'!$J:$J,'TH theo DV'!P$3,'PL1.1 ML2027-2028'!$K:$K,'TH theo DV'!$C17)/$D$1 -> 0 | Q17: =SUMIFS('PL1.1 ML2027-2028'!$H:$H,'PL1.1 ML2027-2028'!$J:$J,'TH theo DV'!Q$3,'PL1.1 ML2027-2028'!$K:$K,'TH theo DV'!$C17)/$D$1 -> 0.092234 | R17: =SUMIFS('PL1.1 ML2027-2028'!$H:$H,'PL1.1 ML2027-2028'!$J:$J,'TH theo DV'!R$3,'PL1.1 ML2027-2028'!$K:$K,'TH theo DV'!$C17)/$D$1 -> 0 | S17: =SUMIFS('PL1.1 ML2027-2028'!$H:$H,'PL1.1 ML2027-2028'!$J:$J,'TH theo DV'!S$3,'PL1.1 ML2027-2028'!$K:$K,'TH theo DV'!$C17)/$D$1 -> 0 | T17: =SUM(M17:S17) -> 0.092234 | V17: =D17+M17 -> 0 | W17: =E17+N17 -> 0 | X17: =F17+O17 -> 0 | Y17: =G17+P17 -> 0 | Z17: =H17+Q17 -> 1.610124 | AA17: =I17+R17 -> 0 | AB17: =SUM(V17:AA17) -> 1.610124 | AC17: =AB17/$AB$4 -> 0.037153907 | AF17: 1
A18: - | B18: Dung lượng Truyền hình | C18: TH | D18: =SUMIFS('PL1.1 ML2027-2028'!$G:$G,'PL1.1 ML2027-2028'!$J:$J,'TH theo DV'!$D$3,'PL1.1 ML2027-2028'!$K:$K,'TH theo DV'!C18)/$D$1 -> 0 | E18: =SUMIFS('PL1.1 ML2027-2028'!$G:$G,'PL1.1 ML2027-2028'!$J:$J,'TH theo DV'!$E$3,'PL1.1 ML2027-2028'!$K:$K,'TH theo DV'!C18)/$D$1 -> 0 | F18: =SUMIFS('PL1.1 ML2027-2028'!$G:$G,'PL1.1 ML2027-2028'!$J:$J,'TH theo DV'!$F$3,'PL1.1 ML2027-2028'!$K:$K,'TH theo DV'!C18)/$D$1 -> 0 | G18: =SUMIFS('PL1.1 ML2027-2028'!$G:$G,'PL1.1 ML2027-2028'!$J:$J,'TH theo DV'!$G$3,'PL1.1 ML2027-2028'!$K:$K,'TH theo DV'!C18)/$D$1 -> 0 | H18: =SUMIFS('PL1.1 ML2027-2028'!$G:$G,'PL1.1 ML2027-2028'!$J:$J,'TH theo DV'!$H$3,'PL1.1 ML2027-2028'!$K:$K,'TH theo DV'!C18)/$D$1 -> 0 | I18: =SUMIFS('PL1.1 ML2027-2028'!$G:$G,'PL1.1 ML2027-2028'!$J:$J,'TH theo DV'!$I$3,'PL1.1 ML2027-2028'!$K:$K,'TH theo DV'!C18)/$D$1 -> 0 | J18: =SUMIFS('PL1.1 ML2027-2028'!$G:$G,'PL1.1 ML2027-2028'!$J:$J,'TH theo DV'!J$3,'PL1.1 ML2027-2028'!$K:$K,'TH theo DV'!$C18)/$D$1 -> 0 | K18: =SUM(D18:J18) -> 0 | L18: =K18/$K$4 -> 0 | M18: =SUMIFS('PL1.1 ML2027-2028'!$H:$H,'PL1.1 ML2027-2028'!$J:$J,'TH theo DV'!M$3,'PL1.1 ML2027-2028'!$K:$K,'TH theo DV'!$C18)/$D$1 -> 0 | N18: =SUMIFS('PL1.1 ML2027-2028'!$H:$H,'PL1.1 ML2027-2028'!$J:$J,'TH theo DV'!N$3,'PL1.1 ML2027-2028'!$K:$K,'TH theo DV'!$C18)/$D$1 -> 0 | O18: =SUMIFS('PL1.1 ML2027-2028'!$H:$H,'PL1.1 ML2027-2028'!$J:$J,'TH theo DV'!O$3,'PL1.1 ML2027-2028'!$K:$K,'TH theo DV'!$C18)/$D$1 -> 0 | P18: =SUMIFS('PL1.1 ML2027-2028'!$H:$H,'PL1.1 ML2027-2028'!$J:$J,'TH theo DV'!P$3,'PL1.1 ML2027-2028'!$K:$K,'TH theo DV'!$C18)/$D$1 -> 0 | Q18: =SUMIFS('PL1.1 ML2027-2028'!$H:$H,'PL1.1 ML2027-2028'!$J:$J,'TH theo DV'!Q$3,'PL1.1 ML2027-2028'!$K:$K,'TH theo DV'!$C18)/$D$1 -> 0 | R18: =SUMIFS('PL1.1 ML2027-2028'!$H:$H,'PL1.1 ML2027-2028'!$J:$J,'TH theo DV'!R$3,'PL1.1 ML2027-2028'!$K:$K,'TH theo DV'!$C18)/$D$1 -> 0 | S18: =SUMIFS('PL1.1 ML2027-2028'!$H:$H,'PL1.1 ML2027-2028'!$J:$J,'TH theo DV'!S$3,'PL1.1 ML2027-2028'!$K:$K,'TH theo DV'!$C18)/$D$1 -> 0 | T18: =SUM(M18:S18) -> 0 | V18: =D18+M18 -> 0 | W18: =E18+N18 -> 0 | X18: =F18+O18 -> 0 | Y18: =G18+P18 -> 0 | Z18: =H18+Q18 -> 0 | AA18: =I18+R18 -> 0 | AB18: =SUM(V18:AA18) -> 0 | AC18: =AB18/$AB$4 -> 0 | AG18: 1
A19: - | B19: Kênh truyền | C19: KT | D19: =SUMIFS('PL1.1 ML2027-2028'!$G:$G,'PL1.1 ML2027-2028'!$J:$J,'TH theo DV'!$D$3,'PL1.1 ML2027-2028'!$K:$K,'TH theo DV'!C19)/$D$1 -> 0 | E19: =SUMIFS('PL1.1 ML2027-2028'!$G:$G,'PL1.1 ML2027-2028'!$J:$J,'TH theo DV'!$E$3,'PL1.1 ML2027-2028'!$K:$K,'TH theo DV'!C19)/$D$1 -> 0 | F19: =SUMIFS('PL1.1 ML2027-2028'!$G:$G,'PL1.1 ML2027-2028'!$J:$J,'TH theo DV'!$F$3,'PL1.1 ML2027-2028'!$K:$K,'TH theo DV'!C19)/$D$1 -> 0.24886576 | G19: =SUMIFS('PL1.1 ML2027-2028'!$G:$G,'PL1.1 ML2027-2028'!$J:$J,'TH theo DV'!$G$3,'PL1.1 ML2027-2028'!$K:$K,'TH theo DV'!C19)/$D$1 -> 0 | H19: =SUMIFS('PL1.1 ML2027-2028'!$G:$G,'PL1.1 ML2027-2028'!$J:$J,'TH theo DV'!$H$3,'PL1.1 ML2027-2028'!$K:$K,'TH theo DV'!C19)/$D$1 -> 0 | I19: =SUMIFS('PL1.1 ML2027-2028'!$G:$G,'PL1.1 ML2027-2028'!$J:$J,'TH theo DV'!$I$3,'PL1.1 ML2027-2028'!$K:$K,'TH theo DV'!C19)/$D$1 -> 0 | J19: =SUMIFS('PL1.1 ML2027-2028'!$G:$G,'PL1.1 ML2027-2028'!$J:$J,'TH theo DV'!J$3,'PL1.1 ML2027-2028'!$K:$K,'TH theo DV'!$C19)/$D$1 -> 0 | K19: =SUM(D19:J19) -> 0.24886576 | L19: =K19/$K$4 -> 0.0098713128 | M19: =SUMIFS('PL1.1 ML2027-2028'!$H:$H,'PL1.1 ML2027-2028'!$J:$J,'TH theo DV'!M$3,'PL1.1 ML2027-2028'!$K:$K,'TH theo DV'!$C19)/$D$1 -> 0 | N19: =SUMIFS('PL1.1 ML2027-2028'!$H:$H,'PL1.1 ML2027-2028'!$J:$J,'TH theo DV'!N$3,'PL1.1 ML2027-2028'!$K:$K,'TH theo DV'!$C19)/$D$1 -> 0 | O19: =SUMIFS('PL1.1 ML2027-2028'!$H:$H,'PL1.1 ML2027-2028'!$J:$J,'TH theo DV'!O$3,'PL1.1 ML2027-2028'!$K:$K,'TH theo DV'!$C19)/$D$1 -> 0.15776484 | P19: =SUMIFS('PL1.1 ML2027-2028'!$H:$H,'PL1.1 ML2027-2028'!$J:$J,'TH theo DV'!P$3,'PL1.1 ML2027-2028'!$K:$K,'TH theo DV'!$C19)/$D$1 -> 0 | Q19: =SUMIFS('PL1.1 ML2027-2028'!$H:$H,'PL1.1 ML2027-2028'!$J:$J,'TH theo DV'!Q$3,'PL1.1 ML2027-2028'!$K:$K,'TH theo DV'!$C19)/$D$1 -> 0 | R19: =SUMIFS('PL1.1 ML2027-2028'!$H:$H,'PL1.1 ML2027-2028'!$J:$J,'TH theo DV'!R$3,'PL1.1 ML2027-2028'!$K:$K,'TH theo DV'!$C19)/$D$1 -> 0 | S19: =SUMIFS('PL1.1 ML2027-2028'!$H:$H,'PL1.1 ML2027-2028'!$J:$J,'TH theo DV'!S$3,'PL1.1 ML2027-2028'!$K:$K,'TH theo DV'!$C19)/$D$1 -> 0 | T19: =SUM(M19:S19) -> 0.15776484 | V19: =D19+M19 -> 0 | W19: =E19+N19 -> 0 | X19: =F19+O19 -> 0.4066306 | Y19: =G19+P19 -> 0 | Z19: =H19+Q19 -> 0 | AA19: =I19+R19 -> 0 | AB19: =SUM(V19:AA19) -> 0.4066306 | AC19: =AB19/$AB$4 -> 0.0093830758 | AF19: 1
A20: 3 | B20: Phục vụ kinh doanh Cloud | C20: Cloud_KD | D20: =SUMIFS('PL1.1 ML2027-2028'!$G:$G,'PL1.1 ML2027-2028'!$J:$J,'TH theo DV'!$D$3,'PL1.1 ML2027-2028'!$K:$K,'TH theo DV'!C20)/$D$1 -> 0 | E20: =SUMIFS('PL1.1 ML2027-2028'!$G:$G,'PL1.1 ML2027-2028'!$J:$J,'TH theo DV'!$E$3,'PL1.1 ML2027-2028'!$K:$K,'TH theo DV'!C20)/$D$1 -> 0 | F20: =SUMIFS('PL1.1 ML2027-2028'!$G:$G,'PL1.1 ML2027-2028'!$J:$J,'TH theo DV'!$F$3,'PL1.1 ML2027-2028'!$K:$K,'TH theo DV'!C20)/$D$1 -> 0 | G20: =SUMIFS('PL1.1 ML2027-2028'!$G:$G,'PL1.1 ML2027-2028'!$J:$J,'TH theo DV'!$G$3,'PL1.1 ML2027-2028'!$K:$K,'TH theo DV'!C20)/$D$1 -> 0 | H20: =SUMIFS('PL1.1 ML2027-2028'!$G:$G,'PL1.1 ML2027-2028'!$J:$J,'TH theo DV'!$H$3,'PL1.1 ML2027-2028'!$K:$K,'TH theo DV'!C20)/$D$1 -> 0 | I20: =SUMIFS('PL1.1 ML2027-2028'!$G:$G,'PL1.1 ML2027-2028'!$J:$J,'TH theo DV'!$I$3,'PL1.1 ML2027-2028'!$K:$K,'TH theo DV'!C20)/$D$1 -> 0 | J20: =SUMIFS('PL1.1 ML2027-2028'!$G:$G,'PL1.1 ML2027-2028'!$J:$J,'TH theo DV'!J$3,'PL1.1 ML2027-2028'!$K:$K,'TH theo DV'!$C20)/$D$1 -> 0 | K20: =SUM(D20:J20) -> 0 | L20: =K20/$K$4 -> 0 | M20: =SUMIFS('PL1.1 ML2027-2028'!$H:$H,'PL1.1 ML2027-2028'!$J:$J,'TH theo DV'!M$3,'PL1.1 ML2027-2028'!$K:$K,'TH theo DV'!$C20)/$D$1 -> 0 | N20: =SUMIFS('PL1.1 ML2027-2028'!$H:$H,'PL1.1 ML2027-2028'!$J:$J,'TH theo DV'!N$3,'PL1.1 ML2027-2028'!$K:$K,'TH theo DV'!$C20)/$D$1 -> 0 | O20: =SUMIFS('PL1.1 ML2027-2028'!$H:$H,'PL1.1 ML2027-2028'!$J:$J,'TH theo DV'!O$3,'PL1.1 ML2027-2028'!$K:$K,'TH theo DV'!$C20)/$D$1 -> 0 | P20: =SUMIFS('PL1.1 ML2027-2028'!$H:$H,'PL1.1 ML2027-2028'!$J:$J,'TH theo DV'!P$3,'PL1.1 ML2027-2028'!$K:$K,'TH theo DV'!$C20)/$D$1 -> 0 | Q20: =SUMIFS('PL1.1 ML2027-2028'!$H:$H,'PL1.1 ML2027-2028'!$J:$J,'TH theo DV'!Q$3,'PL1.1 ML2027-2028'!$K:$K,'TH theo DV'!$C20)/$D$1 -> 0 | R20: =SUMIFS('PL1.1 ML2027-2028'!$H:$H,'PL1.1 ML2027-2028'!$J:$J,'TH theo DV'!R$3,'PL1.1 ML2027-2028'!$K:$K,'TH theo DV'!$C20)/$D$1 -> 0 | S20: =SUMIFS('PL1.1 ML2027-2028'!$H:$H,'PL1.1 ML2027-2028'!$J:$J,'TH theo DV'!S$3,'PL1.1 ML2027-2028'!$K:$K,'TH theo DV'!$C20)/$D$1 -> 0 | T20: =SUM(M20:S20) -> 0 | V20: =D20+M20 -> 0 | W20: =E20+N20 -> 0 | X20: =F20+O20 -> 0 | Y20: =G20+P20 -> 0 | Z20: =H20+Q20 -> 0 | AA20: =I20+R20 -> 0 | AB20: =SUM(V20:AA20) -> 0 | AC20: =AB20/$AB$4 -> 0 | AI20: 1
A21: 4 | B21: Data Center | C21: DC | D21: =SUMIFS('PL1.1 ML2027-2028'!$G:$G,'PL1.1 ML2027-2028'!$J:$J,'TH theo DV'!$D$3,'PL1.1 ML2027-2028'!$K:$K,'TH theo DV'!C21)/$D$1 -> 0 | E21: =SUMIFS('PL1.1 ML2027-2028'!$G:$G,'PL1.1 ML2027-2028'!$J:$J,'TH theo DV'!$E$3,'PL1.1 ML2027-2028'!$K:$K,'TH theo DV'!C21)/$D$1 -> 0 | F21: =SUMIFS('PL1.1 ML2027-2028'!$G:$G,'PL1.1 ML2027-2028'!$J:$J,'TH theo DV'!$F$3,'PL1.1 ML2027-2028'!$K:$K,'TH theo DV'!C21)/$D$1 -> 0 | G21: =SUMIFS('PL1.1 ML2027-2028'!$G:$G,'PL1.1 ML2027-2028'!$J:$J,'TH theo DV'!$G$3,'PL1.1 ML2027-2028'!$K:$K,'TH theo DV'!C21)/$D$1 -> 0 | H21: =SUMIFS('PL1.1 ML2027-2028'!$G:$G,'PL1.1 ML2027-2028'!$J:$J,'TH theo DV'!$H$3,'PL1.1 ML2027-2028'!$K:$K,'TH theo DV'!C21)/$D$1 -> 1.2804509 | I21: =SUMIFS('PL1.1 ML2027-2028'!$G:$G,'PL1.1 ML2027-2028'!$J:$J,'TH theo DV'!$I$3,'PL1.1 ML2027-2028'!$K:$K,'TH theo DV'!C21)/$D$1 -> 0.4 | J21: =SUMIFS('PL1.1 ML2027-2028'!$G:$G,'PL1.1 ML2027-2028'!$J:$J,'TH theo DV'!J$3,'PL1.1 ML2027-2028'!$K:$K,'TH theo DV'!$C21)/$D$1 -> 0.136797 | K21: =SUM(D21:J21) -> 1.8172479 | L21: =K21/$K$4 -> 0.072081522 | M21: =SUMIFS('PL1.1 ML2027-2028'!$H:$H,'PL1.1 ML2027-2028'!$J:$J,'TH theo DV'!M$3,'PL1.1 ML2027-2028'!$K:$K,'TH theo DV'!$C21)/$D$1 -> 0 | N21: =SUMIFS('PL1.1 ML2027-2028'!$H:$H,'PL1.1 ML2027-2028'!$J:$J,'TH theo DV'!N$3,'PL1.1 ML2027-2028'!$K:$K,'TH theo DV'!$C21)/$D$1 -> 0 | O21: =SUMIFS('PL1.1 ML2027-2028'!$H:$H,'PL1.1 ML2027-2028'!$J:$J,'TH theo DV'!O$3,'PL1.1 ML2027-2028'!$K:$K,'TH theo DV'!$C21)/$D$1 -> 0 | P21: =SUMIFS('PL1.1 ML2027-2028'!$H:$H,'PL1.1 ML2027-2028'!$J:$J,'TH theo DV'!P$3,'PL1.1 ML2027-2028'!$K:$K,'TH theo DV'!$C21)/$D$1 -> 0 | Q21: =SUMIFS('PL1.1 ML2027-2028'!$H:$H,'PL1.1 ML2027-2028'!$J:$J,'TH theo DV'!Q$3,'PL1.1 ML2027-2028'!$K:$K,'TH theo DV'!$C21)/$D$1 -> 0.062714 | R21: =SUMIFS('PL1.1 ML2027-2028'!$H:$H,'PL1.1 ML2027-2028'!$J:$J,'TH theo DV'!R$3,'PL1.1 ML2027-2028'!$K:$K,'TH theo DV'!$C21)/$D$1 -> 0 | S21: =SUMIFS('PL1.1 ML2027-2028'!$H:$H,'PL1.1 ML2027-2028'!$J:$J,'TH theo DV'!S$3,'PL1.1 ML2027-2028'!$K:$K,'TH theo DV'!$C21)/$D$1 -> 0 | T21: =SUM(M21:S21) -> 0.062714 | V21: =D21+M21 -> 0 | W21: =E21+N21 -> 0 | X21: =F21+O21 -> 0 | Y21: =G21+P21 -> 0 | Z21: =H21+Q21 -> 1.3431649 | AA21: =I21+R21 -> 0.4 | AB21: =SUM(V21:AA21) -> 1.7431649 | AC21: =AB21/$AB$4 -> 0.040223851 | AD21: =20%*80% -> 0.16 | AG21: =20%*20% -> 0.04 | AH21: 0.8
A22: 5 | B22: Triển khai hạ tầng CNTT | D22: =SUBTOTAL(9,D23:D25) -> 0 | E22: =SUBTOTAL(9,E23:E25) -> 0 | F22: =SUBTOTAL(9,F23:F25) -> 0 | G22: =SUBTOTAL(9,G23:G25) -> 2.084005 | H22: =SUBTOTAL(9,H23:H25) -> 0 | I22: =SUBTOTAL(9,I23:I25) -> 0 | J22: =SUBTOTAL(9,J23:J25) -> 0 | K22: =SUBTOTAL(9,K23:K25) -> 2.084005 | L22: =K22/$K$4 -> 0.082662498 | M22: =SUBTOTAL(9,M23:M25) -> 0 | N22: =SUBTOTAL(9,N23:N25) -> 0 | O22: =SUBTOTAL(9,O23:O25) -> 0 | P22: =SUBTOTAL(9,P23:P25) -> 6.6932028 | Q22: =SUBTOTAL(9,Q23:Q25) -> 0 | R22: =SUBTOTAL(9,R23:R25) -> 0 | S22: =SUBTOTAL(9,S23:S25) -> 0 | T22: =SUBTOTAL(9,T23:T25) -> 6.6932028 | U22: =T22/$T$4 -> 0.269159 | V22: =SUBTOTAL(9,V23:V25) -> 0 | W22: =SUBTOTAL(9,W23:W25) -> 0 | X22: =SUBTOTAL(9,X23:X25) -> 0 | Y22: =SUBTOTAL(9,Y23:Y25) -> 8.7772078 | Z22: =SUBTOTAL(9,Z23:Z25) -> 0 | AA22: =SUBTOTAL(9,AA23:AA25) -> 0 | AB22: =SUBTOTAL(9,AB23:AB25) -> 8.7772078 | AC22: =AB22/$AB$4 -> 0.20253568
A23: - | B23: Trực tiếp kinh doanh (ví) | C23: TTKD | D23: =SUMIFS('PL1.1 ML2027-2028'!$G:$G,'PL1.1 ML2027-2028'!$J:$J,'TH theo DV'!$D$3,'PL1.1 ML2027-2028'!$K:$K,'TH theo DV'!C23)/$D$1 -> 0 | E23: =SUMIFS('PL1.1 ML2027-2028'!$G:$G,'PL1.1 ML2027-2028'!$J:$J,'TH theo DV'!$E$3,'PL1.1 ML2027-2028'!$K:$K,'TH theo DV'!C23)/$D$1 -> 0 | F23: =SUMIFS('PL1.1 ML2027-2028'!$G:$G,'PL1.1 ML2027-2028'!$J:$J,'TH theo DV'!$F$3,'PL1.1 ML2027-2028'!$K:$K,'TH theo DV'!C23)/$D$1 -> 0 | G23: =SUMIFS('PL1.1 ML2027-2028'!$G:$G,'PL1.1 ML2027-2028'!$J:$J,'TH theo DV'!$G$3,'PL1.1 ML2027-2028'!$K:$K,'TH theo DV'!C23)/$D$1 -> 0.390336 | H23: =SUMIFS('PL1.1 ML2027-2028'!$G:$G,'PL1.1 ML2027-2028'!$J:$J,'TH theo DV'!$H$3,'PL1.1 ML2027-2028'!$K:$K,'TH theo DV'!C23)/$D$1 -> 0 | I23: =SUMIFS('PL1.1 ML2027-2028'!$G:$G,'PL1.1 ML2027-2028'!$J:$J,'TH theo DV'!$I$3,'PL1.1 ML2027-2028'!$K:$K,'TH theo DV'!C23)/$D$1 -> 0 | J23: =SUMIFS('PL1.1 ML2027-2028'!$G:$G,'PL1.1 ML2027-2028'!$J:$J,'TH theo DV'!J$3,'PL1.1 ML2027-2028'!$K:$K,'TH theo DV'!$C23)/$D$1 -> 0 | K23: =SUM(D23:J23) -> 0.390336 | L23: =K23/$K$4 -> 0.01548276 | M23: =SUMIFS('PL1.1 ML2027-2028'!$H:$H,'PL1.1 ML2027-2028'!$J:$J,'TH theo DV'!M$3,'PL1.1 ML2027-2028'!$K:$K,'TH theo DV'!$C23)/$D$1 -> 0 | N23: =SUMIFS('PL1.1 ML2027-2028'!$H:$H,'PL1.1 ML2027-2028'!$J:$J,'TH theo DV'!N$3,'PL1.1 ML2027-2028'!$K:$K,'TH theo DV'!$C23)/$D$1 -> 0 | O23: =SUMIFS('PL1.1 ML2027-2028'!$H:$H,'PL1.1 ML2027-2028'!$J:$J,'TH theo DV'!O$3,'PL1.1 ML2027-2028'!$K:$K,'TH theo DV'!$C23)/$D$1 -> 0 | P23: =SUMIFS('PL1.1 ML2027-2028'!$H:$H,'PL1.1 ML2027-2028'!$J:$J,'TH theo DV'!P$3,'PL1.1 ML2027-2028'!$K:$K,'TH theo DV'!$C23)/$D$1 -> 1.861015 | Q23: =SUMIFS('PL1.1 ML2027-2028'!$H:$H,'PL1.1 ML2027-2028'!$J:$J,'TH theo DV'!Q$3,'PL1.1 ML2027-2028'!$K:$K,'TH theo DV'!$C23)/$D$1 -> 0 | R23: =SUMIFS('PL1.1 ML2027-2028'!$H:$H,'PL1.1 ML2027-2028'!$J:$J,'TH theo DV'!R$3,'PL1.1 ML2027-2028'!$K:$K,'TH theo DV'!$C23)/$D$1 -> 0 | S23: =SUMIFS('PL1.1 ML2027-2028'!$H:$H,'PL1.1 ML2027-2028'!$J:$J,'TH theo DV'!S$3,'PL1.1 ML2027-2028'!$K:$K,'TH theo DV'!$C23)/$D$1 -> 0 | T23: =SUM(M23:S23) -> 1.861015 | V23: =D23+M23 -> 0 | W23: =E23+N23 -> 0 | X23: =F23+O23 -> 0 | Y23: =G23+P23 -> 2.251351 | Z23: =H23+Q23 -> 0 | AA23: =I23+R23 -> 0 | AB23: =SUM(V23:AA23) -> 2.251351 | AC23: =AB23/$AB$4 -> 0.051950338 | AJ23: 1
A24: - | B24: Hỗ trợ kinh doanh và quản trị | C24: HTKD | D24: =SUMIFS('PL1.1 ML2027-2028'!$G:$G,'PL1.1 ML2027-2028'!$J:$J,'TH theo DV'!$D$3,'PL1.1 ML2027-2028'!$K:$K,'TH theo DV'!C24)/$D$1 -> 0 | E24: =SUMIFS('PL1.1 ML2027-2028'!$G:$G,'PL1.1 ML2027-2028'!$J:$J,'TH theo DV'!$E$3,'PL1.1 ML2027-2028'!$K:$K,'TH theo DV'!C24)/$D$1 -> 0 | F24: =SUMIFS('PL1.1 ML2027-2028'!$G:$G,'PL1.1 ML2027-2028'!$J:$J,'TH theo DV'!$F$3,'PL1.1 ML2027-2028'!$K:$K,'TH theo DV'!C24)/$D$1 -> 0 | G24: =SUMIFS('PL1.1 ML2027-2028'!$G:$G,'PL1.1 ML2027-2028'!$J:$J,'TH theo DV'!$G$3,'PL1.1 ML2027-2028'!$K:$K,'TH theo DV'!C24)/$D$1 -> 1.693669 | H24: =SUMIFS('PL1.1 ML2027-2028'!$G:$G,'PL1.1 ML2027-2028'!$J:$J,'TH theo DV'!$H$3,'PL1.1 ML2027-2028'!$K:$K,'TH theo DV'!C24)/$D$1 -> 0 | I24: =SUMIFS('PL1.1 ML2027-2028'!$G:$G,'PL1.1 ML2027-2028'!$J:$J,'TH theo DV'!$I$3,'PL1.1 ML2027-2028'!$K:$K,'TH theo DV'!C24)/$D$1 -> 0 | J24: =SUMIFS('PL1.1 ML2027-2028'!$G:$G,'PL1.1 ML2027-2028'!$J:$J,'TH theo DV'!J$3,'PL1.1 ML2027-2028'!$K:$K,'TH theo DV'!$C24)/$D$1 -> 0 | K24: =SUM(D24:J24) -> 1.693669 | L24: =K24/$K$4 -> 0.067179738 | M24: =SUMIFS('PL1.1 ML2027-2028'!$H:$H,'PL1.1 ML2027-2028'!$J:$J,'TH theo DV'!M$3,'PL1.1 ML2027-2028'!$K:$K,'TH theo DV'!$C24)/$D$1 -> 0 | N24: =SUMIFS('PL1.1 ML2027-2028'!$H:$H,'PL1.1 ML2027-2028'!$J:$J,'TH theo DV'!N$3,'PL1.1 ML2027-2028'!$K:$K,'TH theo DV'!$C24)/$D$1 -> 0 | O24: =SUMIFS('PL1.1 ML2027-2028'!$H:$H,'PL1.1 ML2027-2028'!$J:$J,'TH theo DV'!O$3,'PL1.1 ML2027-2028'!$K:$K,'TH theo DV'!$C24)/$D$1 -> 0 | P24: =SUMIFS('PL1.1 ML2027-2028'!$H:$H,'PL1.1 ML2027-2028'!$J:$J,'TH theo DV'!P$3,'PL1.1 ML2027-2028'!$K:$K,'TH theo DV'!$C24)/$D$1 -> 4.8321878 | Q24: =SUMIFS('PL1.1 ML2027-2028'!$H:$H,'PL1.1 ML2027-2028'!$J:$J,'TH theo DV'!Q$3,'PL1.1 ML2027-2028'!$K:$K,'TH theo DV'!$C24)/$D$1 -> 0 | R24: =SUMIFS('PL1.1 ML2027-2028'!$H:$H,'PL1.1 ML2027-2028'!$J:$J,'TH theo DV'!R$3,'PL1.1 ML2027-2028'!$K:$K,'TH theo DV'!$C24)/$D$1 -> 0 | S24: =SUMIFS('PL1.1 ML2027-2028'!$H:$H,'PL1.1 ML2027-2028'!$J:$J,'TH theo DV'!S$3,'PL1.1 ML2027-2028'!$K:$K,'TH theo DV'!$C24)/$D$1 -> 0 | T24: =SUM(M24:S24) -> 4.8321878 | V24: =D24+M24 -> 0 | W24: =E24+N24 -> 0 | X24: =F24+O24 -> 0 | Y24: =G24+P24 -> 6.5258568 | Z24: =H24+Q24 -> 0 | AA24: =I24+R24 -> 0 | AB24: =SUM(V24:AA24) -> 6.5258568 | AC24: =AB24/$AB$4 -> 0.15058534 | AD24: 1
A25: - | B25: ATTT | C25: ATTT | D25: =SUMIFS('PL1.1 ML2027-2028'!$G:$G,'PL1.1 ML2027-2028'!$J:$J,'TH theo DV'!$D$3,'PL1.1 ML2027-2028'!$K:$K,'TH theo DV'!C25)/$D$1 -> 0 | E25: =SUMIFS('PL1.1 ML2027-2028'!$G:$G,'PL1.1 ML2027-2028'!$J:$J,'TH theo DV'!$E$3,'PL1.1 ML2027-2028'!$K:$K,'TH theo DV'!C25)/$D$1 -> 0 | F25: =SUMIFS('PL1.1 ML2027-2028'!$G:$G,'PL1.1 ML2027-2028'!$J:$J,'TH theo DV'!$F$3,'PL1.1 ML2027-2028'!$K:$K,'TH theo DV'!C25)/$D$1 -> 0 | G25: =SUMIFS('PL1.1 ML2027-2028'!$G:$G,'PL1.1 ML2027-2028'!$J:$J,'TH theo DV'!$G$3,'PL1.1 ML2027-2028'!$K:$K,'TH theo DV'!C25)/$D$1 -> 0 | H25: =SUMIFS('PL1.1 ML2027-2028'!$G:$G,'PL1.1 ML2027-2028'!$J:$J,'TH theo DV'!$H$3,'PL1.1 ML2027-2028'!$K:$K,'TH theo DV'!C25)/$D$1 -> 0 | I25: =SUMIFS('PL1.1 ML2027-2028'!$G:$G,'PL1.1 ML2027-2028'!$J:$J,'TH theo DV'!$I$3,'PL1.1 ML2027-2028'!$K:$K,'TH theo DV'!C25)/$D$1 -> 0 | J25: =SUMIFS('PL1.1 ML2027-2028'!$G:$G,'PL1.1 ML2027-2028'!$J:$J,'TH theo DV'!J$3,'PL1.1 ML2027-2028'!$K:$K,'TH theo DV'!$C25)/$D$1 -> 0 | K25: =SUM(D25:J25) -> 0 | L25: =K25/$K$4 -> 0 | M25: =SUMIFS('PL1.1 ML2027-2028'!$H:$H,'PL1.1 ML2027-2028'!$J:$J,'TH theo DV'!M$3,'PL1.1 ML2027-2028'!$K:$K,'TH theo DV'!$C25)/$D$1 -> 0 | N25: =SUMIFS('PL1.1 ML2027-2028'!$H:$H,'PL1.1 ML2027-2028'!$J:$J,'TH theo DV'!N$3,'PL1.1 ML2027-2028'!$K:$K,'TH theo DV'!$C25)/$D$1 -> 0 | O25: =SUMIFS('PL1.1 ML2027-2028'!$H:$H,'PL1.1 ML2027-2028'!$J:$J,'TH theo DV'!O$3,'PL1.1 ML2027-2028'!$K:$K,'TH theo DV'!$C25)/$D$1 -> 0 | P25: =SUMIFS('PL1.1 ML2027-2028'!$H:$H,'PL1.1 ML2027-2028'!$J:$J,'TH theo DV'!P$3,'PL1.1 ML2027-2028'!$K:$K,'TH theo DV'!$C25)/$D$1 -> 0 | Q25: =SUMIFS('PL1.1 ML2027-2028'!$H:$H,'PL1.1 ML2027-2028'!$J:$J,'TH theo DV'!Q$3,'PL1.1 ML2027-2028'!$K:$K,'TH theo DV'!$C25)/$D$1 -> 0 | R25: =SUMIFS('PL1.1 ML2027-2028'!$H:$H,'PL1.1 ML2027-2028'!$J:$J,'TH theo DV'!R$3,'PL1.1 ML2027-2028'!$K:$K,'TH theo DV'!$C25)/$D$1 -> 0 | S25: =SUMIFS('PL1.1 ML2027-2028'!$H:$H,'PL1.1 ML2027-2028'!$J:$J,'TH theo DV'!S$3,'PL1.1 ML2027-2028'!$K:$K,'TH theo DV'!$C25)/$D$1 -> 0 | T25: =SUM(M25:S25) -> 0 | V25: =D25+M25 -> 0 | W25: =E25+N25 -> 0 | X25: =F25+O25 -> 0 | Y25: =G25+P25 -> 0 | Z25: =H25+Q25 -> 0 | AA25: =I25+R25 -> 0 | AB25: =SUM(V25:AA25) -> 0 | AC25: =AB25/$AB$4 -> 0 | AD25: 1
A26: 5 | B26: Mạng truyền dẫn | D26: =SUBTOTAL(9,D27:D29) -> 0 | E26: =SUBTOTAL(9,E27:E29) -> 0 | F26: =SUBTOTAL(9,F27:F29) -> 0 | G26: =SUBTOTAL(9,G27:G29) -> 0 | H26: =SUBTOTAL(9,H27:H28) -> 0.241124 | I26: =SUBTOTAL(9,I27:I29) -> 0 | J26: =SUBTOTAL(9,J27:J29) -> 0 | K26: =SUBTOTAL(9,K27:K28) -> 0.241124 | L26: =K26/$K$4 -> 0.0095642343 | M26: =SUBTOTAL(9,M27:M29) -> 0 | N26: =SUBTOTAL(9,N27:N29) -> 0 | O26: =SUBTOTAL(9,O27:O29) -> 0 | P26: =SUBTOTAL(9,P27:P29) -> 0 | Q26: =SUBTOTAL(9,Q27:Q29) -> 0.26796 | R26: =SUBTOTAL(9,R27:R29) -> 0 | S26: =SUBTOTAL(9,S27:S29) -> 0 | T26: =SUBTOTAL(9,T27:T29) -> 0.26796 | U26: =T26/$T$4 -> 0.010775685 | V26: =SUBTOTAL(9,V27:V29) -> 0 | W26: =SUBTOTAL(9,W27:W29) -> 0 | X26: =SUBTOTAL(9,X27:X29) -> 0 | Y26: =SUBTOTAL(9,Y27:Y29) -> 0 | Z26: =SUBTOTAL(9,Z27:Z29) -> 0.509084 | AA26: =SUBTOTAL(9,AA27:AA29) -> 0 | AB26: =SUBTOTAL(9,AB27:AB29) -> 0.509084 | AC26: =AB26/$AB$4 -> 0.011747207
A27: - | B27: Dung lượng Metro | C27: DLMETRO | D27: =SUMIFS('PL1.1 ML2027-2028'!$G:$G,'PL1.1 ML2027-2028'!$J:$J,'TH theo DV'!$D$3,'PL1.1 ML2027-2028'!$K:$K,'TH theo DV'!C27)/$D$1 -> 0 | E27: =SUMIFS('PL1.1 ML2027-2028'!$G:$G,'PL1.1 ML2027-2028'!$J:$J,'TH theo DV'!$E$3,'PL1.1 ML2027-2028'!$K:$K,'TH theo DV'!C27)/$D$1 -> 0 | F27: =SUMIFS('PL1.1 ML2027-2028'!$G:$G,'PL1.1 ML2027-2028'!$J:$J,'TH theo DV'!$F$3,'PL1.1 ML2027-2028'!$K:$K,'TH theo DV'!C27)/$D$1 -> 0 | G27: =SUMIFS('PL1.1 ML2027-2028'!$G:$G,'PL1.1 ML2027-2028'!$J:$J,'TH theo DV'!$G$3,'PL1.1 ML2027-2028'!$K:$K,'TH theo DV'!C27)/$D$1 -> 0 | H27: =SUMIFS('PL1.1 ML2027-2028'!$G:$G,'PL1.1 ML2027-2028'!$J:$J,'TH theo DV'!$H$3,'PL1.1 ML2027-2028'!$K:$K,'TH theo DV'!C27)/$D$1 -> 0.01346 | I27: =SUMIFS('PL1.1 ML2027-2028'!$G:$G,'PL1.1 ML2027-2028'!$J:$J,'TH theo DV'!$I$3,'PL1.1 ML2027-2028'!$K:$K,'TH theo DV'!C27)/$D$1 -> 0 | J27: =SUMIFS('PL1.1 ML2027-2028'!$G:$G,'PL1.1 ML2027-2028'!$J:$J,'TH theo DV'!J$3,'PL1.1 ML2027-2028'!$K:$K,'TH theo DV'!$C27)/$D$1 -> 0 | K27: =SUM(D27:J27) -> 0.01346 | L27: =K27/$K$4 -> 0.00053389374 | M27: =SUMIFS('PL1.1 ML2027-2028'!$H:$H,'PL1.1 ML2027-2028'!$J:$J,'TH theo DV'!M$3,'PL1.1 ML2027-2028'!$K:$K,'TH theo DV'!$C27)/$D$1 -> 0 | N27: =SUMIFS('PL1.1 ML2027-2028'!$H:$H,'PL1.1 ML2027-2028'!$J:$J,'TH theo DV'!N$3,'PL1.1 ML2027-2028'!$K:$K,'TH theo DV'!$C27)/$D$1 -> 0 | O27: =SUMIFS('PL1.1 ML2027-2028'!$H:$H,'PL1.1 ML2027-2028'!$J:$J,'TH theo DV'!O$3,'PL1.1 ML2027-2028'!$K:$K,'TH theo DV'!$C27)/$D$1 -> 0 | P27: =SUMIFS('PL1.1 ML2027-2028'!$H:$H,'PL1.1 ML2027-2028'!$J:$J,'TH theo DV'!P$3,'PL1.1 ML2027-2028'!$K:$K,'TH theo DV'!$C27)/$D$1 -> 0 | Q27: =SUMIFS('PL1.1 ML2027-2028'!$H:$H,'PL1.1 ML2027-2028'!$J:$J,'TH theo DV'!Q$3,'PL1.1 ML2027-2028'!$K:$K,'TH theo DV'!$C27)/$D$1 -> 0.01764 | R27: =SUMIFS('PL1.1 ML2027-2028'!$H:$H,'PL1.1 ML2027-2028'!$J:$J,'TH theo DV'!R$3,'PL1.1 ML2027-2028'!$K:$K,'TH theo DV'!$C27)/$D$1 -> 0 | S27: =SUMIFS('PL1.1 ML2027-2028'!$H:$H,'PL1.1 ML2027-2028'!$J:$J,'TH theo DV'!S$3,'PL1.1 ML2027-2028'!$K:$K,'TH theo DV'!$C27)/$D$1 -> 0 | T27: =SUM(M27:S27) -> 0.01764 | V27: =D27+M27 -> 0 | W27: =E27+N27 -> 0 | X27: =F27+O27 -> 0 | Y27: =G27+P27 -> 0 | Z27: =H27+Q27 -> 0.0311 | AA27: =I27+R27 -> 0 | AB27: =SUM(V27:AA27) -> 0.0311 | AC27: =AB27/$AB$4 -> 0.00071763821 | AJ27: 1
A28: - | B28: Dung lượng IPBN | C28: DLIPBN | D28: =SUMIFS('PL1.1 ML2027-2028'!$G:$G,'PL1.1 ML2027-2028'!$J:$J,'TH theo DV'!$D$3,'PL1.1 ML2027-2028'!$K:$K,'TH theo DV'!C28)/$D$1 -> 0 | E28: =SUMIFS('PL1.1 ML2027-2028'!$G:$G,'PL1.1 ML2027-2028'!$J:$J,'TH theo DV'!$E$3,'PL1.1 ML2027-2028'!$K:$K,'TH theo DV'!C28)/$D$1 -> 0 | F28: =SUMIFS('PL1.1 ML2027-2028'!$G:$G,'PL1.1 ML2027-2028'!$J:$J,'TH theo DV'!$F$3,'PL1.1 ML2027-2028'!$K:$K,'TH theo DV'!C28)/$D$1 -> 0 | G28: =SUMIFS('PL1.1 ML2027-2028'!$G:$G,'PL1.1 ML2027-2028'!$J:$J,'TH theo DV'!$G$3,'PL1.1 ML2027-2028'!$K:$K,'TH theo DV'!C28)/$D$1 -> 0 | H28: =SUMIFS('PL1.1 ML2027-2028'!$G:$G,'PL1.1 ML2027-2028'!$J:$J,'TH theo DV'!$H$3,'PL1.1 ML2027-2028'!$K:$K,'TH theo DV'!C28)/$D$1 -> 0.227664 | I28: =SUMIFS('PL1.1 ML2027-2028'!$G:$G,'PL1.1 ML2027-2028'!$J:$J,'TH theo DV'!$I$3,'PL1.1 ML2027-2028'!$K:$K,'TH theo DV'!C28)/$D$1 -> 0 | J28: =SUMIFS('PL1.1 ML2027-2028'!$G:$G,'PL1.1 ML2027-2028'!$J:$J,'TH theo DV'!J$3,'PL1.1 ML2027-2028'!$K:$K,'TH theo DV'!$C28)/$D$1 -> 0 | K28: =SUM(D28:J28) -> 0.227664 | L28: =K28/$K$4 -> 0.0090303405 | M28: =SUMIFS('PL1.1 ML2027-2028'!$H:$H,'PL1.1 ML2027-2028'!$J:$J,'TH theo DV'!M$3,'PL1.1 ML2027-2028'!$K:$K,'TH theo DV'!$C28)/$D$1 -> 0 | N28: =SUMIFS('PL1.1 ML2027-2028'!$H:$H,'PL1.1 ML2027-2028'!$J:$J,'TH theo DV'!N$3,'PL1.1 ML2027-2028'!$K:$K,'TH theo DV'!$C28)/$D$1 -> 0 | O28: =SUMIFS('PL1.1 ML2027-2028'!$H:$H,'PL1.1 ML2027-2028'!$J:$J,'TH theo DV'!O$3,'PL1.1 ML2027-2028'!$K:$K,'TH theo DV'!$C28)/$D$1 -> 0 | P28: =SUMIFS('PL1.1 ML2027-2028'!$H:$H,'PL1.1 ML2027-2028'!$J:$J,'TH theo DV'!P$3,'PL1.1 ML2027-2028'!$K:$K,'TH theo DV'!$C28)/$D$1 -> 0 | Q28: =SUMIFS('PL1.1 ML2027-2028'!$H:$H,'PL1.1 ML2027-2028'!$J:$J,'TH theo DV'!Q$3,'PL1.1 ML2027-2028'!$K:$K,'TH theo DV'!$C28)/$D$1 -> 0.25032 | R28: =SUMIFS('PL1.1 ML2027-2028'!$H:$H,'PL1.1 ML2027-2028'!$J:$J,'TH theo DV'!R$3,'PL1.1 ML2027-2028'!$K:$K,'TH theo DV'!$C28)/$D$1 -> 0 | S28: =SUMIFS('PL1.1 ML2027-2028'!$H:$H,'PL1.1 ML2027-2028'!$J:$J,'TH theo DV'!S$3,'PL1.1 ML2027-2028'!$K:$K,'TH theo DV'!$C28)/$D$1 -> 0 | T28: =SUM(M28:S28) -> 0.25032 | V28: =D28+M28 -> 0 | W28: =E28+N28 -> 0 | X28: =F28+O28 -> 0 | Y28: =G28+P28 -> 0 | Z28: =H28+Q28 -> 0.477984 | AA28: =I28+R28 -> 0 | AB28: =SUM(V28:AA28) -> 0.477984 | AC28: =AB28/$AB$4 -> 0.011029569 | AD28: 1
A29: III | B29: Đảm bảo VHKT, kiên cố, bền vững trong thiên tai | D29: =SUBTOTAL(9,D30:D33) -> 0.535421 | E29: =SUBTOTAL(9,E30:E33) -> 0.84196192 | F29: =SUBTOTAL(9,F30:F33) -> 0 | G29: =SUBTOTAL(9,G30:G33) -> 0.933882 | H29: =SUBTOTAL(9,H30:H33) -> 0.35784 | I29: =SUBTOTAL(9,I30:I33) -> 1.3602861 | J29: =SUBTOTAL(9,J30:J33) -> 0 | K29: =SUBTOTAL(9,K30:K33) -> 4.029391 | L29: =K29/$K$4 -> 0.15982664 | M29: =SUBTOTAL(9,M30:M33) -> 0.7013 | N29: =SUBTOTAL(9,N31:N33) -> 0.87104 | O29: =SUBTOTAL(9,O30:O33) -> 0 | P29: =SUBTOTAL(9,P30:P33) -> 0.218689 | Q29: =SUBTOTAL(9,Q30:Q33) -> 0.33634 | R29: =SUBTOTAL(9,R30:R33) -> 1.8399121 | S29: =SUBTOTAL(9,S30:S33) -> 0 | T29: =SUBTOTAL(9,T30:T33) -> 4.0672811 | U29: =T29/$T$4 -> 0.16356076 | V29: =SUBTOTAL(9,V31:V33) -> 0.789121 | W29: =SUBTOTAL(9,W31:W33) -> 1.6130019 | X29: =SUBTOTAL(9,X31:X33) -> 0 | Y29: =SUBTOTAL(9,Y31:Y33) -> 1.152571 | Z29: =SUBTOTAL(9,Z31:Z33) -> 0.4642 | AA29: =SUBTOTAL(9,AA31:AA33) -> 2.727514 | AB29: =SUBTOTAL(9,AB31:AB33) -> 6.7464079 | AC29: =AB29/$AB$4 -> 0.1556746
A30: 1 | B30: Đảm bảo dự phòng ƯCTT | C30: ƯCTT | D30: =SUMIFS('PL1.1 ML2027-2028'!$G:$G,'PL1.1 ML2027-2028'!$J:$J,'TH theo DV'!$D$3,'PL1.1 ML2027-2028'!$K:$K,'TH theo DV'!C30)/$D$1 -> 0.2238 | E30: =SUMIFS('PL1.1 ML2027-2028'!$G:$G,'PL1.1 ML2027-2028'!$J:$J,'TH theo DV'!$E$3,'PL1.1 ML2027-2028'!$K:$K,'TH theo DV'!C30)/$D$1 -> 0.1 | F30: =SUMIFS('PL1.1 ML2027-2028'!$G:$G,'PL1.1 ML2027-2028'!$J:$J,'TH theo DV'!$F$3,'PL1.1 ML2027-2028'!$K:$K,'TH theo DV'!C30)/$D$1 -> 0 | G30: =SUMIFS('PL1.1 ML2027-2028'!$G:$G,'PL1.1 ML2027-2028'!$J:$J,'TH theo DV'!$G$3,'PL1.1 ML2027-2028'!$K:$K,'TH theo DV'!C30)/$D$1 -> 0 | H30: =SUMIFS('PL1.1 ML2027-2028'!$G:$G,'PL1.1 ML2027-2028'!$J:$J,'TH theo DV'!$H$3,'PL1.1 ML2027-2028'!$K:$K,'TH theo DV'!C30)/$D$1 -> 0.12574 | I30: =SUMIFS('PL1.1 ML2027-2028'!$G:$G,'PL1.1 ML2027-2028'!$J:$J,'TH theo DV'!$I$3,'PL1.1 ML2027-2028'!$K:$K,'TH theo DV'!C30)/$D$1 -> 0.2195421 | J30: =SUMIFS('PL1.1 ML2027-2028'!$G:$G,'PL1.1 ML2027-2028'!$J:$J,'TH theo DV'!J$3,'PL1.1 ML2027-2028'!$K:$K,'TH theo DV'!$C30)/$D$1 -> 0 | K30: =SUM(D30:J30) -> 0.6690821 | L30: =K30/$K$4 -> 0.026539283 | M30: =SUMIFS('PL1.1 ML2027-2028'!$H:$H,'PL1.1 ML2027-2028'!$J:$J,'TH theo DV'!M$3,'PL1.1 ML2027-2028'!$K:$K,'TH theo DV'!$C30)/$D$1 -> 0.2238 | N30: =SUMIFS('PL1.1 ML2027-2028'!$H:$H,'PL1.1 ML2027-2028'!$J:$J,'TH theo DV'!N$3,'PL1.1 ML2027-2028'!$K:$K,'TH theo DV'!$C30)/$D$1 -> 0.1 | O30: =SUMIFS('PL1.1 ML2027-2028'!$H:$H,'PL1.1 ML2027-2028'!$J:$J,'TH theo DV'!O$3,'PL1.1 ML2027-2028'!$K:$K,'TH theo DV'!$C30)/$D$1 -> 0 | P30: =SUMIFS('PL1.1 ML2027-2028'!$H:$H,'PL1.1 ML2027-2028'!$J:$J,'TH theo DV'!P$3,'PL1.1 ML2027-2028'!$K:$K,'TH theo DV'!$C30)/$D$1 -> 0 | Q30: =SUMIFS('PL1.1 ML2027-2028'!$H:$H,'PL1.1 ML2027-2028'!$J:$J,'TH theo DV'!Q$3,'PL1.1 ML2027-2028'!$K:$K,'TH theo DV'!$C30)/$D$1 -> 0.10424 | R30: =SUMIFS('PL1.1 ML2027-2028'!$H:$H,'PL1.1 ML2027-2028'!$J:$J,'TH theo DV'!R$3,'PL1.1 ML2027-2028'!$K:$K,'TH theo DV'!$C30)/$D$1 -> 0.2531421 | S30: =SUMIFS('PL1.1 ML2027-2028'!$H:$H,'PL1.1 ML2027-2028'!$J:$J,'TH theo DV'!S$3,'PL1.1 ML2027-2028'!$K:$K,'TH theo DV'!$C30)/$D$1 -> 0 | T30: =SUM(M30:S30) -> 0.6811821 | U30: =T30/$T$4 -> 0.027392909 | V30: =D30+M30 -> 0.4476 | W30: =E30+N30 -> 0.2 | X30: =F30+O30 -> 0 | Y30: =G30+P30 -> 0 | Z30: =H30+Q30 -> 0.22998 | AA30: =I30+R30 -> 0.4726842 | AB30: =SUM(V30:AA30) -> 1.3502642 | AC30: =AB30/$AB$4 -> 0.031157595 | AD30: 1 | AF30: 0.8 | AG30: 0.2 | AJ30: 1
A31: 2 | B31: Đảm bảo VHKT và nâng cao chất lượng mạng | C31: VHKT | D31: =SUMIFS('PL1.1 ML2027-2028'!$G:$G,'PL1.1 ML2027-2028'!$J:$J,'TH theo DV'!$D$3,'PL1.1 ML2027-2028'!$K:$K,'TH theo DV'!C31)/$D$1 -> 0.311621 | E31: =SUMIFS('PL1.1 ML2027-2028'!$G:$G,'PL1.1 ML2027-2028'!$J:$J,'TH theo DV'!$E$3,'PL1.1 ML2027-2028'!$K:$K,'TH theo DV'!C31)/$D$1 -> 0.74196192 | F31: =SUMIFS('PL1.1 ML2027-2028'!$G:$G,'PL1.1 ML2027-2028'!$J:$J,'TH theo DV'!$F$3,'PL1.1 ML2027-2028'!$K:$K,'TH theo DV'!C31)/$D$1 -> 0 | G31: =SUMIFS('PL1.1 ML2027-2028'!$G:$G,'PL1.1 ML2027-2028'!$J:$J,'TH theo DV'!$G$3,'PL1.1 ML2027-2028'!$K:$K,'TH theo DV'!C31)/$D$1 -> 0.933882 | H31: =SUMIFS('PL1.1 ML2027-2028'!$G:$G,'PL1.1 ML2027-2028'!$J:$J,'TH theo DV'!$H$3,'PL1.1 ML2027-2028'!$K:$K,'TH theo DV'!C31)/$D$1 -> 0 | I31: =SUMIFS('PL1.1 ML2027-2028'!$G:$G,'PL1.1 ML2027-2028'!$J:$J,'TH theo DV'!$I$3,'PL1.1 ML2027-2028'!$K:$K,'TH theo DV'!C31)/$D$1 -> 0.22998 | J31: =SUMIFS('PL1.1 ML2027-2028'!$G:$G,'PL1.1 ML2027-2028'!$J:$J,'TH theo DV'!J$3,'PL1.1 ML2027-2028'!$K:$K,'TH theo DV'!$C31)/$D$1 -> 0 | K31: =SUM(D31:J31) -> 2.2174449 | L31: =K31/$K$4 -> 0.08795542 | M31: =SUMIFS('PL1.1 ML2027-2028'!$H:$H,'PL1.1 ML2027-2028'!$J:$J,'TH theo DV'!M$3,'PL1.1 ML2027-2028'!$K:$K,'TH theo DV'!$C31)/$D$1 -> 0.4775 | N31: =SUMIFS('PL1.1 ML2027-2028'!$H:$H,'PL1.1 ML2027-2028'!$J:$J,'TH theo DV'!N$3,'PL1.1 ML2027-2028'!$K:$K,'TH theo DV'!$C31)/$D$1 -> 0.87104 | O31: =SUMIFS('PL1.1 ML2027-2028'!$H:$H,'PL1.1 ML2027-2028'!$J:$J,'TH theo DV'!O$3,'PL1.1 ML2027-2028'!$K:$K,'TH theo DV'!$C31)/$D$1 -> 0 | P31: =SUMIFS('PL1.1 ML2027-2028'!$H:$H,'PL1.1 ML2027-2028'!$J:$J,'TH theo DV'!P$3,'PL1.1 ML2027-2028'!$K:$K,'TH theo DV'!$C31)/$D$1 -> 0.218689 | Q31: =SUMIFS('PL1.1 ML2027-2028'!$H:$H,'PL1.1 ML2027-2028'!$J:$J,'TH theo DV'!Q$3,'PL1.1 ML2027-2028'!$K:$K,'TH theo DV'!$C31)/$D$1 -> 0 | R31: =SUMIFS('PL1.1 ML2027-2028'!$H:$H,'PL1.1 ML2027-2028'!$J:$J,'TH theo DV'!R$3,'PL1.1 ML2027-2028'!$K:$K,'TH theo DV'!$C31)/$D$1 -> 0.05225 | S31: =SUMIFS('PL1.1 ML2027-2028'!$H:$H,'PL1.1 ML2027-2028'!$J:$J,'TH theo DV'!S$3,'PL1.1 ML2027-2028'!$K:$K,'TH theo DV'!$C31)/$D$1 -> 0 | T31: =SUM(M31:S31) -> 1.619479 | U31: =T31/$T$4 -> 0.065125376 | V31: =D31+M31 -> 0.789121 | W31: =E31+N31 -> 1.6130019 | X31: =F31+O31 -> 0 | Y31: =G31+P31 -> 1.152571 | Z31: =H31+Q31 -> 0 | AA31: =I31+R31 -> 0.28223 | AB31: =SUM(V31:AA31) -> 3.8369239 | AC31: =AB31/$AB$4 -> 0.088537724 | AD31: 1 | AF31: 0.8 | AG31: 0.2 | AJ31: 1
