Workbook
Name \p: #REF!
Name \p: #REF!
Name \p: #REF!
Name __atn1: #REF!
Name __atn1: #REF!
Name __atn1: #REF!
Name __atn10: #REF!
Name __atn10: #REF!
Name __atn10: #REF!
Name __atn2: #REF!
Name __atn2: #REF!
Name __atn2: #REF!
Name __atn3: #REF!
Name __atn3: #REF!
Name __atn3: #REF!
Name __atn4: #REF!
Name __atn4: #REF!
Name __atn4: #REF!
Name __atn5: #REF!
Name __atn5: #REF!
Name __atn5: #REF!
Name __atn6: #REF!
Name __atn6: #REF!
Name __atn6: #REF!
Name __atn7: #REF!
Name __atn7: #REF!
Name __atn7: #REF!
Name __atn8: #REF!
Name __atn8: #REF!
Name __atn8: #REF!
Name __atn9: #REF!
Name __atn9: #REF!
Name __atn9: #REF!
Name __boi1: #REF!
Name __boi1: #REF!
Name __boi1: #REF!
Name __boi2: #REF!
Name __boi2: #REF!
Name __boi2: #REF!
Name __CON1: #REF!
Name __CON1: #REF!
Name __CON1: #REF!
Name __CON2: #REF!
Name __CON2: #REF!
Name __CON2: #REF!
Name __cpd1: #REF!
Name __cpd1: #REF!
Name __cpd1: #REF!
Name __cpd2: #REF!
Name __cpd2: #REF!
Name __cpd2: #REF!
Name __deo1: #REF!
Name __deo1: #REF!
Name __deo1: #REF!
Name __deo10: #REF!
Name __deo10: #REF!
Name __deo10: #REF!
Name __deo2: #REF!
Name __deo2: #REF!
Name __deo2: #REF!

Sheet PL1.1 ML2027-2028
A1: PHỤ LỤC 1.1: BẢNG TỔNG HỢP CHI TIẾT NHU CẦU ĐẦU TƯ, MUA SẮM THEO QHĐC NĂM 2027-2028 (Ban hành kèm theo Tờ trình số của Tập đoàn CNVTQĐ) | P1: Ghi chú
G3: KHÔNG XÓA | J3: KHÔNG XÓA
A4: TT | B4: Nội dung/ hạng mục đầu tư, mua sắm | C4: Đơn vị tính | D4: Khối lượng | F4: Đơn giá dự kiến | G4: Thành tiền dự kiến (VNĐ) | I4: Dự kiến đơn vị đầu tư, mua sắm | J4: Mã mảng | K4: Mã DV | L4: Mã loại
D6: 2027 | E6: 2028 | F6: USD | G6: 2027 | H6: 2028
C7: 6 | F7: 7 | G7: =SUBTOTAL(9,G8:G2183) -> 32216367 | H7: =SUBTOTAL(9,H8:H2183) -> 28083744
B8: TỔNG ĐẦU TƯ VTTB VÀ XÂY LẮP 2027-2028 | G8: =SUBTOTAL(9,G9:G2183) -> 32216367 | H8: =SUBTOTAL(9,H9:H2183) -> 28083744
A9: P1 | B9: TỔNG ĐẦU TƯ VTTB 2027-2028 | G9: =SUBTOTAL(9,G10:G1904) -> 29205895 | H9: =SUBTOTAL(9,H10:H1904) -> 24197061
A10: A | B10: VÔ TUYẾN | G10: =SUBTOTAL(9,G11:G92) -> 8220468.4 | H10: =SUBTOTAL(9,H11:H92) -> 7412191.5
A11: A1 | B11: Mạng 5G | G11: =SUBTOTAL(9,G12:G21) -> 0 | H11: =SUBTOTAL(9,H12:H21) -> 0 | P11: Cosite trên 802 vị trí triển khai 4G DL
A12: 1 | B12: Thiết bị macro 5G
A13: - | B13: Bộ Gá đa năng (gồm 3 gá đơn lẻ và các phụ kiện) | C13: Bộ | G13: =F13*D13 -> 0 | H13: =F13*E13 -> 0 | J13: VT | K13: 5G | L13: VTTB
A14: - | B14: NodeB Massive MIMO 2.6GHz+3.5GHz | C14: Tủ | G14: =F14*D14 -> 0 | H14: =F14*E14 -> 0 | J14: VT | K14: 5G | L14: VTTB
A15: 2 | B15: Thiết bị RRU 5G
A16: - | B16: RRU 5G triển khai IBD | C16: Chiếc | G16: =F16*D16 -> 0 | H16: =F16*E16 -> 0 | J16: VT | K16: 5G | L16: VTTB
A17: 3 | B17: Thiết bị smallcell 5G
A18: - | B18: Thiết bị vô tuyến 5G 4T4R | C18: Chiếc | G18: =F18*D18 -> 0 | H18: =F18*E18 -> 0 | J18: VT | K18: 5G | L18: VTTB
A19: 4 | B19: Card Baseband
A20: - | B20: Card Baseband cho 5G | C20: Chiếc | G20: =F20*D20 -> 0 | H20: =F20*E20 -> 0 | J20: VT | K20: 5G | L20: VTTB
A21: 5 | B21: Nâng cấp hệ thống Inbuilding lên 5G
A22: A2 | B22: Mạng 2/3/4G | G22: =SUBTOTAL(9,G23:G44) -> 1212469.1 | H22: =SUBTOTAL(9,H23:H44) -> 729620.64
A23: I | B23: Vùng phủ | G23: =SUBTOTAL(9,G24:G44) -> 1212469.1 | H23: =SUBTOTAL(9,H24:H44) -> 729620.64 | P23: Triển khai 208 vị trí triển khai vùng phủ mới cho 4G kết hợp cosite 2G, tổng chi phí dự kiến 3.5M USD
A24: 1 | B24: Thiết bị 4G | G24: =SUBTOTAL(9,G25:G31) -> 1212469.1 | H24: =SUBTOTAL(9,H25:H31) -> 729620.64
A25: - | B25: Huawei_SRAN Tripband eNodeB 700+800+900MHz (3 RRU 4x120w)(L111@15MHz+L111@10MHz ) 12Trx. Exclude BBU + BB card | C25: Tủ | D25: 11 | F25: 16430.5 | G25: =F25*D25 -> 180735.5 | H25: =F25*E25 -> 0 | J25: VT | K25: VPDĐ | L25: VTTB
A26: - | B26: Huawei_SRAN Tripband eNodeB 700+800+900MHz (3 RRU 4x120w)(L111@15MHz+L111@10MHz , 12TRx, BB card UBBPg2a) + 3 AISG | C26: Tủ | E26: 3 | F26: 20190 | G26: =F26*D26 -> 0 | H26: =F26*E26 -> 60570 | J26: VT | K26: VPDĐ | L26: VTTB
A27: - | B27: ZTE_SRAN Tripband eNodeB 700+800+900MHz (3 RRU 4x120w)(L111@15MHz+L111@10MHz , 12TRx, BB VBPe3p) | C27: Tủ | D27: 46 | E27: 30 | F27: 21295.188 | G27: =F27*D27 -> 979578.64 | H27: =F27*E27 -> 638855.64 | J27: VT | K27: VPDĐ | L27: VTTB
A28: - | B28: Diplexer 800-900 | C28: Chiếc | G28: =F28*D28 -> 0 | H28: =F28*E28 -> 0 | J28: VT | K28: VPDĐ | L28: VTTB
A29: - | B29: Anten 4G 8 port 4 port 700-900 + 4P 1800-2600 MHz | C29: Chiếc | D29: 171 | E29: 99 | F29: 305 | G29: =F29*D29 -> 52155 | H29: =F29*E29 -> 30195 | J29: VT | K29: VPDĐ | L29: VTTB
A30: - | B30: Jumper | C30: Chiếc | G30: =F30*D30 -> 0 | H30: =F30*E30 -> 0 | J30: VT | K30: VPDĐ | L30: VTTB
A31: - | B31: Bộ Gá đa năng (gồm 3 gá đơn lẻ và các phụ kiện) | C31: Chiếc | G31: =F31*D31 -> 0 | H31: =F31*E31 -> 0 | J31: VT | K31: VPDĐ | L31: VTTB
A32: 2 | B32: Thiết bị 3G | G32: =SUBTOTAL(9,G33:G39) -> 0 | H32: =SUBTOTAL(9,H33:H39) -> 0
A33: - | B33: NodeB 3G dualband_Cosite | C33: Tủ | G33: =F33*D33 -> 0 | H33: =F33*E33 -> 0 | J33: VT | K33: VPDĐ | L33: VTTB
A34: - | B34: NodeB 3G dualband_New site | C34: Tủ | G34: =F34*D34 -> 0 | H34: =F34*E34 -> 0 | J34: VT | K34: VPDĐ | L34: VTTB
A35: - | B35: Card baseband | C35: Chiếc | G35: =F35*D35 -> 0 | H35: =F35*E35 -> 0 | J35: VT | K35: VPDĐ | L35: VTTB
A36: - | B36: Anten đa băng | C36: Chiếc | G36: =F36*D36 -> 0 | H36: =F36*E36 -> 0 | J36: VT | K36: VPDĐ | L36: VTTB
A37: - | B37: Jumper | C37: Chiếc | G37: =F37*D37 -> 0 | H37: =F37*E37 -> 0 | J37: VT | K37: VPDĐ | L37: VTTB
A38: - | B38: Bộ Gá đa năng (gồm 3 gá đơn lẻ và các phụ kiện) | C38: Chiếc | G38: =F38*D38 -> 0 | H38: =F38*E38 -> 0 | J38: VT | K38: VPDĐ | L38: VTTB
A39: 3 | B39: Thiết bị 2G | G39: =SUBTOTAL(9,G40:G46) -> 0 | H39: =SUBTOTAL(9,H40:H46) -> 0
A40: - | B40: BTS 2G dualband_Cosite | C40: Tủ | G40: =F40*D40 -> 0 | H40: =F40*E40 -> 0 | J40: VT | K40: VPDĐ | L40: VTTB
A41: - | B41: BTS 2G dualband_New site 2G | C41: Tủ | G41: =F41*D41 -> 0 | H41: =F41*E41 -> 0 | J41: VT | K41: VPDĐ | L41: VTTB
A42: - | B42: Anten đa băng | C42: Chiếc | G42: =F42*D42 -> 0 | H42: =F42*E42 -> 0 | J42: VT | K42: VPDĐ | L42: VTTB
...

Sheet TH theo DV_Tổng
D1: 1000000
A2: STT | B2: Nội dung | C2: Ko xóa | D2: 2027 (triệu USD) | N2: 2028 (triệu USD) | X2: Ghi chú | Y2: 2027-2028 (triệu USD) | AI2: Ghi chú
B3: Mảng | C3: Mã DV | D3: VT | E3: ML | F3: CĐBR | G3: CNTT | H3: IP | I3: TD | J3: CĐ | K3: HT | L3: Tổng | M3: Tỷ trọng (%) | N3: VT | O3: ML | P3: CĐBR | Q3: CNTT | R3: IP | S3: TD | T3: CĐ | U3: HT | V3: Tổng | W3: Tỷ trọng (%) | Y3: VT | Z3: ML | AA3: CĐBR | AB3: CNTT | AC3: IP | AD3: TD | AE3: CĐ | AF3: HT | AG3: Tổng | AH3: Tỷ trọng (%)
A4: * | B4: Tổng | D4: =SUBTOTAL(9,D6:D35) -> 8.2204684 | E4: =SUBTOTAL(9,E6:E35) -> 4.9719708 | F4: =SUBTOTAL(9,F6:F35) -> 0.4167082 | G4: =SUBTOTAL(9,G6:G35) -> 5.0310212 | H4: =SUBTOTAL(9,H6:H35) -> 3.741948 | I4: =SUBTOTAL(9,I6:I35) -> 1.4899959 | J4: =SUBTOTAL(9,J6:J35) -> 5.4738318 | K4: =SUBTOTAL(9,K6:K35) -> 2.8569624 | L4: =SUBTOTAL(9,L6:L35) -> 32.202907 | N4: =SUBTOTAL(9,N6:N35) -> 7.4121915 | O4: =SUBTOTAL(9,O6:O35) -> 0.5455 | P4: =SUBTOTAL(9,P6:P35) -> 0.3029988 | Q4: =SUBTOTAL(9,Q6:Q35) -> 9.9714008 | R4: =SUBTOTAL(9,R6:R35) -> 0.69828 | S4: =SUBTOTAL(9,S6:S35) -> 1.5255163 | T4: =SUBTOTAL(9,T6:T35) -> 3.8435129 | U4: =SUBTOTAL(9,U6:U35) -> 3.7843435 | V4: =SUBTOTAL(9,V6:V35) -> 28.083744 | Y4: =SUBTOTAL(9,Y6:Y35) -> 15.63266 | Z4: =SUBTOTAL(9,Z6:Z35) -> 5.5174708 | AA4: =SUBTOTAL(9,AA6:AA35) -> 0.719707 | AB4: =SUBTOTAL(9,AB6:AB35) -> 15.002422 | AC4: =SUBTOTAL(9,AC6:AC35) -> 4.440228 | AD4: =SUBTOTAL(9,AD6:AD35) -> 3.0155122 | AE4: =SUBTOTAL(9,AE6:AE35) -> 9.3173447 | AF4: =SUBTOTAL(9,AF6:AF35) -> 6.6413059 | AG4: =SUBTOTAL(9,AG6:AG35) -> 60.149854 | AH4: =AG4/$AG$4 -> 1
B5: Tỷ trọng theo mảng | D5: =D4/$L$4 -> 0.25527101 | E5: =E4/$L$4 -> 0.15439509 | F5: =F4/$L$4 -> 0.01294008 | G5: =G4/$L$4 -> 0.15622879 | H5: =H4/$L$4 -> 0.11619908 | I5: =I4/$L$4 -> 0.046268989 | J5: =J4/$L$4 -> 0.16997943 | K5: =K4/$L$4 -> 0.088717532 | L5: =L4/$L$4 -> 1 | N5: =N4/$V$4 -> 0.26393174 | O5: =O4/$V$4 -> 0.019424048 | P5: =P4/$V$4 -> 0.010789117 | Q5: =Q4/$V$4 -> 0.35505953 | R5: =R4/$L$4 -> 0.021683757 | S5: =S4/$L$4 -> 0.047372007 | T5: =T4/$V$4 -> 0.13685899 | U5: =U4/$L$4 -> 0.11751559 | V5: =V4/$L$4 -> 0.87208724 | Y5: =Y4/$AG$4 -> 0.25989523 | Z5: =Z4/$AG$4 -> 0.091728748 | AA5: =AA4/$AG$4 -> 0.011965233 | AB5: =AB4/$AG$4 -> 0.24941743 | AC5: =AC4/$AG$4 -> 0.073819432 | AD5: =AD4/$AG$4 -> 0.050133326 | AE5: =AE4/$AG$4 -> 0.1549022 | AF5: =AF4/$AG$4 -> 0.11041267 | AG5: =AG4/$AG$4 -> 1
A6: I | B6: Công nghệ mới triển khai diện rộng cho kinh doanh | D6: =SUBTOTAL(9,D7:D10) -> 0 | E6: =SUBTOTAL(9,E7:E10) -> 0 | F6: =SUBTOTAL(9,F7:F10) -> 0 | G6: =SUBTOTAL(9,G7:G10) -> 0 | H6: =SUBTOTAL(9,H7:H10) -> 0 | I6: =SUBTOTAL(9,I7:I10) -> 0 | J6: =SUBTOTAL(9,J7:J10) -> 0 | K6: =SUBTOTAL(9,K7:K10) -> 0 | L6: =SUBTOTAL(9,L7:L10) -> 0 | M6: =L6/$L$4 -> 0 | N6: =SUBTOTAL(9,N7:N10) -> 0 | O6: =SUBTOTAL(9,O7:O10) -> 0 | P6: =SUBTOTAL(9,P7:P10) -> 0 | Q6: =SUBTOTAL(9,Q7:Q10) -> 0 | R6: =SUBTOTAL(9,R7:R10) -> 0 | S6: =SUBTOTAL(9,S7:S10) -> 0 | T6: =SUBTOTAL(9,T7:T10) -> 0 | U6: =SUBTOTAL(9,U7:U10) -> 0 | V6: =SUBTOTAL(9,V7:V10) -> 0 | W6: =V6/$V$4 -> 0 | Y6: =SUBTOTAL(9,Y7:Y9) -> 0 | Z6: =SUBTOTAL(9,Z7:Z9) -> 0 | AA6: =SUBTOTAL(9,AA7:AA9) -> 0 | AB6: =SUBTOTAL(9,AB7:AB9) -> 0 | AC6: =SUBTOTAL(9,AC7:AC9) -> 0 | AD6: =SUBTOTAL(9,AD7:AD9) -> 0 | AE6: =SUBTOTAL(9,AE7:AE9) -> 0 | AF6: =SUBTOTAL(9,AF7:AF9) -> 0 | AG6: =SUBTOTAL(9,AG7:AG10) -> 0 | AH6: =AG6/$AG$4 -> 0
A7: 1 | B7: Mạng 5G | C7: 5G | D7: =SUMIFS('PL1.1 ML2027-2028'!$G:$G,'PL1.1 ML2027-2028'!$J:$J,'TH theo DV_Tổng'!$D$3,'PL1.1 ML2027-2028'!$K:$K,'TH theo DV_Tổng'!C7)/$D$1 -> 0 | E7: =SUMIFS('PL1.1 ML2027-2028'!$G:$G,'PL1.1 ML2027-2028'!$J:$J,'TH theo DV_Tổng'!$E$3,'PL1.1 ML2027-2028'!$K:$K,'TH theo DV_Tổng'!C7)/$D$1 -> 0 | F7: =SUMIFS('PL1.1 ML2027-2028'!$G:$G,'PL1.1 ML2027-2028'!$J:$J,'TH theo DV_Tổng'!$F$3,'PL1.1 ML2027-2028'!$K:$K,'TH theo DV_Tổng'!C7)/$D$1 -> 0 | G7: =SUMIFS('PL1.1 ML2027-2028'!$G:$G,'PL1.1 ML2027-2028'!$J:$J,'TH theo DV_Tổng'!$G$3,'PL1.1 ML2027-2028'!$K:$K,'TH theo DV_Tổng'!C7)/$D$1 -> 0 | H7: =SUMIFS('PL1.1 ML2027-2028'!$G:$G,'PL1.1 ML2027-2028'!$J:$J,"TD",'PL1.1 ML2027-2028'!$M:$M,"IP",'PL1.1 ML2027-2028'!$K:$K,'TH theo DV_Tổng'!C7)/$D$1 -> 0 | I7: =SUMIFS('PL1.1 ML2027-2028'!$G:$G,'PL1.1 ML2027-2028'!$J:$J,"TD",'PL1.1 ML2027-2028'!$M:$M,"Mạng cáp",'PL1.1 ML2027-2028'!$K:$K,'TH theo DV_Tổng'!C7)/$D$1 -> 0 | J7: =SUMIFS('PL1.1 ML2027-2028'!$G:$G,'PL1.1 ML2027-2028'!$J:$J,'TH theo DV_Tổng'!$J$3,'PL1.1 ML2027-2028'!$K:$K,'TH theo DV_Tổng'!C7)/$D$1 -> 0 | K7: =SUMIFS('PL1.1 ML2027-2028'!$G:$G,'PL1.1 ML2027-2028'!$J:$J,'TH theo DV_Tổng'!K$3,'PL1.1 ML2027-2028'!$K:$K,'TH theo DV_Tổng'!C7)/$D$1 -> 0 | L7: =SUM(D7:K7) -> 0 | M7: =L7/$L$4 -> 0 | N7: =SUMIFS('PL1.1 ML2027-2028'!$H:$H,'PL1.1 ML2027-2028'!$J:$J,'TH theo DV_Tổng'!N$3,'PL1.1 ML2027-2028'!$K:$K,'TH theo DV_Tổng'!$C7)/$D$1 -> 0 | O7: =SUMIFS('PL1.1 ML2027-2028'!$H:$H,'PL1.1 ML2027-2028'!$J:$J,'TH theo DV_Tổng'!O$3,'PL1.1 ML2027-2028'!$K:$K,'TH theo DV_Tổng'!$C7)/$D$1 -> 0 | P7: =SUMIFS('PL1.1 ML2027-2028'!$H:$H,'PL1.1 ML2027-2028'!$J:$J,'TH theo DV_Tổng'!P$3,'PL1.1 ML2027-2028'!$K:$K,'TH theo DV_Tổng'!$C7)/$D$1 -> 0 | Q7: =SUMIFS('PL1.1 ML2027-2028'!$H:$H,'PL1.1 ML2027-2028'!$J:$J,'TH theo DV_Tổng'!Q$3,'PL1.1 ML2027-2028'!$K:$K,'TH theo DV_Tổng'!$C7)/$D$1 -> 0 | R7: =SUMIFS('PL1.1 ML2027-2028'!$H:$H,'PL1.1 ML2027-2028'!$J:$J,"TD",'PL1.1 ML2027-2028'!$M:$M,"IP",'PL1.1 ML2027-2028'!$K:$K,'TH theo DV_Tổng'!C7)/$D$1 -> 0 | S7: =SUMIFS('PL1.1 ML2027-2028'!$H:$H,'PL1.1 ML2027-2028'!$J:$J,"TD",'PL1.1 ML2027-2028'!$M:$M,"Mạng cáp",'PL1.1 ML2027-2028'!$K:$K,'TH theo DV_Tổng'!C7)/$D$1 -> 0 | T7: =SUMIFS('PL1.1 ML2027-2028'!$H:$H,'PL1.1 ML2027-2028'!$J:$J,'TH theo DV_Tổng'!T$3,'PL1.1 ML2027-2028'!$K:$K,'TH theo DV_Tổng'!$C7)/$D$1 -> 0 | U7: =SUMIFS('PL1.1 ML2027-2028'!$H:$H,'PL1.1 ML2027-2028'!$J:$J,'TH theo DV_Tổng'!U$3,'PL1.1 ML2027-2028'!$K:$K,'TH theo DV_Tổng'!$C7)/$D$1 -> 0 | V7: =SUM(N7:U7) -> 0 | X7: Chi phí triển khai 5G tính trong dung lượng 4G. Do triển khai cosite 4G+5G | Y7: =D7+N7 -> 0 | Z7: =E7+O7 -> 0 | AA7: =F7+P7 -> 0 | AB7: =G7+Q7 -> 0 | AC7: =H7+R7 -> 0 | AD7: =I7+S7 -> 0 | AE7: =J7+T7 -> 0 | AF7: =K7+U7 -> 0 | AG7: =SUM(Y7:AF7) -> 0 | AH7: =AG7/$AG$4 -> 0 | AI7: Chi phí triển khai 5G tính trong dung lượng 4G. Do triển khai cosite 4G+5G
A8: 2 | B8: XGSPON | C8: XGSPON | D8: =SUMIFS('PL1.1 ML2027-2028'!$G:$G,'PL1.1 ML2027-2028'!$J:$J,'TH theo DV_Tổng'!$D$3,'PL1.1 ML2027-2028'!$K:$K,'TH theo DV_Tổng'!C8)/$D$1 -> 0 | E8: =SUMIFS('PL1.1 ML2027-2028'!$G:$G,'PL1.1 ML2027-2028'!$J:$J,'TH theo DV_Tổng'!$E$3,'PL1.1 ML2027-2028'!$K:$K,'TH theo DV_Tổng'!C8)/$D$1 -> 0 | F8: =SUMIFS('PL1.1 ML2027-2028'!$G:$G,'PL1.1 ML2027-2028'!$J:$J,'TH theo DV_Tổng'!$F$3,'PL1.1 ML2027-2028'!$K:$K,'TH theo DV_Tổng'!C8)/$D$1 -> 0 | G8: =SUMIFS('PL1.1 ML2027-2028'!$G:$G,'PL1.1 ML2027-2028'!$J:$J,'TH theo DV_Tổng'!$G$3,'PL1.1 ML2027-2028'!$K:$K,'TH theo DV_Tổng'!C8)/$D$1 * 0.43287 -> 0 | H8: =SUMIFS('PL1.1 ML2027-2028'!$G:$G,'PL1.1 ML2027-2028'!$J:$J,"TD",'PL1.1 ML2027-2028'!$M:$M,"IP",'PL1.1 ML2027-2028'!$K:$K,'TH theo DV_Tổng'!C8)/$D$1 -> 0 | I8: =SUMIFS('PL1.1 ML2027-2028'!$G:$G,'PL1.1 ML2027-2028'!$J:$J,"TD",'PL1.1 ML2027-2028'!$M:$M,"Mạng cáp",'PL1.1 ML2027-2028'!$K:$K,'TH theo DV_Tổng'!C8)/$D$1 -> 0 | J8: =SUMIFS('PL1.1 ML2027-2028'!$G:$G,'PL1.1 ML2027-2028'!$J:$J,'TH theo DV_Tổng'!$J$3,'PL1.1 ML2027-2028'!$K:$K,'TH theo DV_Tổng'!C8)/$D$1 -> 0 | K8: =SUMIFS('PL1.1 ML2027-2028'!$G:$G,'PL1.1 ML2027-2028'!$J:$J,'TH theo DV_Tổng'!K$3,'PL1.1 ML2027-2028'!$K:$K,'TH theo DV_Tổng'!C8)/$D$1 -> 0 | L8: =SUM(D8:K8) -> 0 | M8: =L8/$L$4 -> 0 | N8: =SUMIFS('PL1.1 ML2027-2028'!$H:$H,'PL1.1 ML2027-2028'!$J:$J,'TH theo DV_Tổng'!N$3,'PL1.1 ML2027-2028'!$K:$K,'TH theo DV_Tổng'!$C8)/$D$1 -> 0 | O8: =SUMIFS('PL1.1 ML2027-2028'!$H:$H,'PL1.1 ML2027-2028'!$J:$J,'TH theo DV_Tổng'!O$3,'PL1.1 ML2027-2028'!$K:$K,'TH theo DV_Tổng'!$C8)/$D$1 -> 0 | P8: =SUMIFS('PL1.1 ML2027-2028'!$H:$H,'PL1.1 ML2027-2028'!$J:$J,'TH theo DV_Tổng'!P$3,'PL1.1 ML2027-2028'!$K:$K,'TH theo DV_Tổng'!$C8)/$D$1 -> 0 | Q8: =SUMIFS('PL1.1 ML2027-2028'!$H:$H,'PL1.1 ML2027-2028'!$J:$J,'TH theo DV_Tổng'!Q$3,'PL1.1 ML2027-2028'!$K:$K,'TH theo DV_Tổng'!$C8)/$D$1 -> 0 | R8: =SUMIFS('PL1.1 ML2027-2028'!$H:$H,'PL1.1 ML2027-2028'!$J:$J,"TD",'PL1.1 ML2027-2028'!$M:$M,"IP",'PL1.1 ML2027-2028'!$K:$K,'TH theo DV_Tổng'!C8)/$D$1 -> 0 | S8: =SUMIFS('PL1.1 ML2027-2028'!$H:$H,'PL1.1 ML2027-2028'!$J:$J,"TD",'PL1.1 ML2027-2028'!$M:$M,"Mạng cáp",'PL1.1 ML2027-2028'!$K:$K,'TH theo DV_Tổng'!C8)/$D$1 -> 0 | T8: =SUMIFS('PL1.1 ML2027-2028'!$H:$H,'PL1.1 ML2027-2028'!$J:$J,'TH theo DV_Tổng'!T$3,'PL1.1 ML2027-2028'!$K:$K,'TH theo DV_Tổng'!$C8)/$D$1 -> 0 | U8: =SUMIFS('PL1.1 ML2027-2028'!$H:$H,'PL1.1 ML2027-2028'!$J:$J,'TH theo DV_Tổng'!U$3,'PL1.1 ML2027-2028'!$K:$K,'TH theo DV_Tổng'!$C8)/$D$1 -> 0 | V8: =SUM(N8:U8) -> 0 | Y8: =D8+N8 -> 0 | Z8: =E8+O8 -> 0 | AA8: =F8+P8 -> 0 | AB8: =G8+Q8 -> 0 | AC8: =H8+R8 -> 0 | AD8: =I8+S8 -> 0 | AE8: =J8+T8 -> 0 | AF8: =K8+U8 -> 0 | AG8: =SUM(Y8:AF8) -> 0 | AH8: =AG8/$AG$4 -> 0
A9: 3 | B9: AI/GPU | C9: AI/GPU | D9: =SUMIFS('PL1.1 ML2027-2028'!$G:$G,'PL1.1 ML2027-2028'!$J:$J,'TH theo DV_Tổng'!$D$3,'PL1.1 ML2027-2028'!$K:$K,'TH theo DV_Tổng'!C9)/$D$1 -> 0 | E9: =SUMIFS('PL1.1 ML2027-2028'!$G:$G,'PL1.1 ML2027-2028'!$J:$J,'TH theo DV_Tổng'!$E$3,'PL1.1 ML2027-2028'!$K:$K,'TH theo DV_Tổng'!C9)/$D$1 -> 0 | F9: =SUMIFS('PL1.1 ML2027-2028'!$G:$G,'PL1.1 ML2027-2028'!$J:$J,'TH theo DV_Tổng'!$F$3,'PL1.1 ML2027-2028'!$K:$K,'TH theo DV_Tổng'!C9)/$D$1 -> 0 | H9: =SUMIFS('PL1.1 ML2027-2028'!$G:$G,'PL1.1 ML2027-2028'!$J:$J,"TD",'PL1.1 ML2027-2028'!$M:$M,"IP",'PL1.1 ML2027-2028'!$K:$K,'TH theo DV_Tổng'!C9)/$D$1 -> 0 | I9: =SUMIFS('PL1.1 ML2027-2028'!$G:$G,'PL1.1 ML2027-2028'!$J:$J,"TD",'PL1.1 ML2027-2028'!$M:$M,"Mạng cáp",'PL1.1 ML2027-2028'!$K:$K,'TH theo DV_Tổng'!C9)/$D$1 -> 0 | J9: =SUMIFS('PL1.1 ML2027-2028'!$G:$G,'PL1.1 ML2027-2028'!$J:$J,'TH theo DV_Tổng'!$J$3,'PL1.1 ML2027-2028'!$K:$K,'TH theo DV_Tổng'!C9)/$D$1 -> 0 | K9: =SUMIFS('PL1.1 ML2027-2028'!$G:$G,'PL1.1 ML2027-2028'!$J:$J,'TH theo DV_Tổng'!K$3,'PL1.1 ML2027-2028'!$K:$K,'TH theo DV_Tổng'!C9)/$D$1 -> 0 | L9: =SUM(D9:K9) -> 0 | M9: =L9/$L$4 -> 0 | N9: =SUMIFS('PL1.1 ML2027-2028'!$H:$H,'PL1.1 ML2027-2028'!$J:$J,'TH theo DV_Tổng'!N$3,'PL1.1 ML2027-2028'!$K:$K,'TH theo DV_Tổng'!$C9)/$D$1 -> 0 | O9: =SUMIFS('PL1.1 ML2027-2028'!$H:$H,'PL1.1 ML2027-2028'!$J:$J,'TH theo DV_Tổng'!O$3,'PL1.1 ML2027-2028'!$K:$K,'TH theo DV_Tổng'!$C9)/$D$1 -> 0 | P9: =SUMIFS('PL1.1 ML2027-2028'!$H:$H,'PL1.1 ML2027-2028'!$J:$J,'TH theo DV_Tổng'!P$3,'PL1.1 ML2027-2028'!$K:$K,'TH theo DV_Tổng'!$C9)/$D$1 -> 0 | Q9: =SUMIFS('PL1.1 ML2027-2028'!$H:$H,'PL1.1 ML2027-2028'!$J:$J,'TH theo DV_Tổng'!Q$3,'PL1.1 ML2027-2028'!$K:$K,'TH theo DV_Tổng'!$C9)/$D$1 -> 0 | R9: =SUMIFS('PL1.1 ML2027-2028'!$H:$H,'PL1.1 ML2027-2028'!$J:$J,"TD",'PL1.1 ML2027-2028'!$M:$M,"IP",'PL1.1 ML2027-2028'!$K:$K,'TH theo DV_Tổng'!C9)/$D$1 -> 0 | S9: =SUMIFS('PL1.1 ML2027-2028'!$H:$H,'PL1.1 ML2027-2028'!$J:$J,"TD",'PL1.1 ML2027-2028'!$M:$M,"Mạng cáp",'PL1.1 ML2027-2028'!$K:$K,'TH theo DV_Tổng'!C9)/$D$1 -> 0 | T9: =SUMIFS('PL1.1 ML2027-2028'!$H:$H,'PL1.1 ML2027-2028'!$J:$J,'TH theo DV_Tổng'!T$3,'PL1.1 ML2027-2028'!$K:$K,'TH theo DV_Tổng'!$C9)/$D$1 -> 0 | U9: =SUMIFS('PL1.1 ML2027-2028'!$H:$H,'PL1.1 ML2027-2028'!$J:$J,'TH theo DV_Tổng'!U$3,'PL1.1 ML2027-2028'!$K:$K,'TH theo DV_Tổng'!$C9)/$D$1 -> 0 | V9: =SUM(N9:U9) -> 0 | X9: Chi phí triển khai AI/GPU tính trong HT CNTT do phục vụ các bài toán nội bộ | Y9: =D9+N9 -> 0 | Z9: =E9+O9 -> 0 | AA9: =F9+P9 -> 0 | AB9: =G9+Q9 -> 0 | AC9: =H9+R9 -> 0 | AD9: =I9+S9 -> 0 | AE9: =J9+T9 -> 0 | AF9: =K9+U9 -> 0 | AG9: =SUM(Y9:AF9) -> 0 | AH9: =AG9/$AG$4 -> 0 | AI9: Chi phí triển khai AI/GPU tính trong HT CNTT do phục vụ các bài toán nội bộ
A10: 4 | B10: Private Mobile Network | C10: PMN | D10: =SUMIFS('PL1.1 ML2027-2028'!$G:$G,'PL1.1 ML2027-2028'!$J:$J,'TH theo DV_Tổng'!$D$3,'PL1.1 ML2027-2028'!$K:$K,'TH theo DV_Tổng'!C10)/$D$1 -> 0 | E10: =SUMIFS('PL1.1 ML2027-2028'!$G:$G,'PL1.1 ML2027-2028'!$J:$J,'TH theo DV_Tổng'!$E$3,'PL1.1 ML2027-2028'!$K:$K,'TH theo DV_Tổng'!C10)/$D$1 -> 0 | F10: =SUMIFS('PL1.1 ML2027-2028'!$G:$G,'PL1.1 ML2027-2028'!$J:$J,'TH theo DV_Tổng'!$F$3,'PL1.1 ML2027-2028'!$K:$K,'TH theo DV_Tổng'!C10)/$D$1 -> 0 | G10: =SUMIFS('PL1.1 ML2027-2028'!$G:$G,'PL1.1 ML2027-2028'!$J:$J,'TH theo DV_Tổng'!$G$3,'PL1.1 ML2027-2028'!$K:$K,'TH theo DV_Tổng'!C10)/$D$1 -> 0 | H10: =SUMIFS('PL1.1 ML2027-2028'!$G:$G,'PL1.1 ML2027-2028'!$J:$J,"TD",'PL1.1 ML2027-2028'!$M:$M,"IP",'PL1.1 ML2027-2028'!$K:$K,'TH theo DV_Tổng'!C10)/$D$1 -> 0 | I10: =SUMIFS('PL1.1 ML2027-2028'!$G:$G,'PL1.1 ML2027-2028'!$J:$J,"TD",'PL1.1 ML2027-2028'!$M:$M,"Mạng cáp",'PL1.1 ML2027-2028'!$K:$K,'TH theo DV_Tổng'!C10)/$D$1 -> 0 | J10: =SUMIFS('PL1.1 ML2027-2028'!$G:$G,'PL1.1 ML2027-2028'!$J:$J,'TH theo DV_Tổng'!$J$3,'PL1.1 ML2027-2028'!$K:$K,'TH theo DV_Tổng'!C10)/$D$1 -> 0 | K10: =SUMIFS('PL1.1 ML2027-2028'!$G:$G,'PL1.1 ML2027-2028'!$J:$J,'TH theo DV_Tổng'!K$3,'PL1.1 ML2027-2028'!$K:$K,'TH theo DV_Tổng'!C10)/$D$1 -> 0 | L10: =SUM(D10:K10) -> 0 | M10: =L10/$L$4 -> 0 | N10: =SUMIFS('PL1.1 ML2027-2028'!$H:$H,'PL1.1 ML2027-2028'!$J:$J,'TH theo DV_Tổng'!N$3,'PL1.1 ML2027-2028'!$K:$K,'TH theo DV_Tổng'!$C10)/$D$1 -> 0 | O10: =SUMIFS('PL1.1 ML2027-2028'!$H:$H,'PL1.1 ML2027-2028'!$J:$J,'TH theo DV_Tổng'!O$3,'PL1.1 ML2027-2028'!$K:$K,'TH theo DV_Tổng'!$C10)/$D$1 -> 0 | P10: =SUMIFS('PL1.1 ML2027-2028'!$H:$H,'PL1.1 ML2027-2028'!$J:$J,'TH theo DV_Tổng'!P$3,'PL1.1 ML2027-2028'!$K:$K,'TH theo DV_Tổng'!$C10)/$D$1 -> 0 | Q10: =SUMIFS('PL1.1 ML2027-2028'!$H:$H,'PL1.1 ML2027-2028'!$J:$J,'TH theo DV_Tổng'!Q$3,'PL1.1 ML2027-2028'!$K:$K,'TH theo DV_Tổng'!$C10)/$D$1 -> 0 | R10: =SUMIFS('PL1.1 ML2027-2028'!$H:$H,'PL1.1 ML2027-2028'!$J:$J,"TD",'PL1.1 ML2027-2028'!$M:$M,"IP",'PL1.1 ML2027-2028'!$K:$K,'TH theo DV_Tổng'!C10)/$D$1 -> 0 | S10: =SUMIFS('PL1.1 ML2027-2028'!$H:$H,'PL1.1 ML2027-2028'!$J:$J,"TD",'PL1.1 ML2027-2028'!$M:$M,"Mạng cáp",'PL1.1 ML2027-2028'!$K:$K,'TH theo DV_Tổng'!C10)/$D$1 -> 0 | T10: =SUMIFS('PL1.1 ML2027-2028'!$H:$H,'PL1.1 ML2027-2028'!$J:$J,'TH theo DV_Tổng'!T$3,'PL1.1 ML2027-2028'!$K:$K,'TH theo DV_Tổng'!$C10)/$D$1 -> 0 | U10: =SUMIFS('PL1.1 ML2027-2028'!$H:$H,'PL1.1 ML2027-2028'!$J:$J,'TH theo DV_Tổng'!U$3,'PL1.1 ML2027-2028'!$K:$K,'TH theo DV_Tổng'!$C10)/$D$1 -> 0 | V10: =SUM(N10:U10) -> 0 | Y10: =D10+N10 -> 0 | Z10: =E10+O10 -> 0 | AA10: =F10+P10 -> 0 | AB10: =G10+Q10 -> 0 | AC10: =H10+R10 -> 0 | AD10: =I10+S10 -> 0 | AE10: =J10+T10 -> 0 | AF10: =K10+U10 -> 0 | AG10: =SUM(Y10:AF10) -> 0 | AH10: =AG10/$AG$4 -> 0
A11: II | B11: Mở rộng mạng lưới hiện tại cho kinh doanh | D11: =SUBTOTAL(9,D12:D29) -> 7.6113818 | E11: =SUBTOTAL(9,E12:E29) -> 3.4853689 | F11: =SUBTOTAL(9,F12:F29) -> 0.4167082 | G11: =SUBTOTAL(9,G12:G29) -> 3.8280682 | H11: =SUBTOTAL(9,H12:H29) -> 3.741948 | I11: =SUBTOTAL(9,I12:I29) -> 1.1321559 | J11: =SUBTOTAL(9,J12:J29) -> 3.2189877 | K11: =SUBTOTAL(9,K12:K29) -> 2.7723624 | L11: =SUBTOTAL(9,L13:L29) -> 26.206981 | M11: =L11/$L$4 -> 0.81380794 | N11: =SUBTOTAL(9,N12:N25) -> 7.1631049 | O11: =SUBTOTAL(9,O12:O25) -> 0.4455 | P11: =SUBTOTAL(9,P12:P25) -> 0.3029988 | Q11: =SUBTOTAL(9,Q12:Q25) -> 6.7178118 | R11: =SUBTOTAL(9,R12:R29) -> 0.69828 | S11: =SUBTOTAL(9,S12:S29) -> 1.1891763 | T11: =SUBTOTAL(9,T12:T25) -> 2.6670148 | U11: =SUBTOTAL(9,U12:U29) -> 3.7843435 | V11: =SUBTOTAL(9,V13:V29) -> 23.090174 | W11: =V11/$V$4 -> 0.82219003 | Y11: =SUBTOTAL(9,Y12:Y29) -> 14.774487 | Z11: =SUBTOTAL(9,Z12:Z29) -> 3.9308689 | AA11: =SUBTOTAL(9,AA12:AA29) -> 0.719707 | AB11: =SUBTOTAL(9,AB12:AB29) -> 10.667824 | AC11: =SUBTOTAL(9,AC12:AC29) -> 4.440228 | AD11: =SUBTOTAL(9,AD12:AD29) -> 2.3213322 | AE11: =SUBTOTAL(9,AE12:AE29) -> 5.8860025 | AF11: =SUBTOTAL(9,AF12:AF29) -> 6.5567059 | AG11: =SUBTOTAL(9,AG13:AG29) -> 49.160358 | AH11: =AG11/$AG$4 -> 0.81729805
A12: 1 | B12: Mạng 2/3/4G | D12: =SUBTOTAL(9,D13:D14) -> 7.6113818 | E12: =SUBTOTAL(9,E13:E14) -> 3.4853689 | F12: =SUBTOTAL(9,F13:F14) -> 0 | G12: =SUBTOTAL(9,G13:G14) -> 0 | H12: =SUBTOTAL(9,H13:H14) -> 2.5213862 | I12: =SUBTOTAL(9,I13:I14) -> 0.869559 | J12: =SUBTOTAL(9,J13:J14) -> 1.9053437 | K12: =SUBTOTAL(9,K13:K14) -> 2.6355654 | L12: =SUBTOTAL(9,L13:L14) -> 19.028605 | M12: =L12/$L$4 -> 0.59089713 | N12: =SUBTOTAL(9,N13:N14) -> 7.1631049 | O12: =SUBTOTAL(9,O13:O14) -> 0.4455 | P12: =SUBTOTAL(9,P13:P14) -> 0 | Q12: =SUBTOTAL(9,Q13:Q14) -> 0 | R12: =SUBTOTAL(9,R13:R14) -> 0.608448 | S12: =SUBTOTAL(9,S13:S14) -> 1.1872281 | T12: =SUBTOTAL(9,T13:T14) -> 1.8311428 | U12: =SUBTOTAL(9,U13:U14) -> 3.7843435 | V12: =SUBTOTAL(9,V13:V14) -> 15.019767 | W12: =V12/$V$4 -> 0.5348207 | Y12: =SUBTOTAL(9,Y13:Y14) -> 14.774487 | Z12: =SUBTOTAL(9,Z13:Z14) -> 3.9308689 | AA12: =SUBTOTAL(9,AA13:AA14) -> 0 | AB12: =SUBTOTAL(9,AB13:AB14) -> 0 | AC12: =SUBTOTAL(9,AC13:AC14) -> 3.1298342 | AD12: =SUBTOTAL(9,AD13:AD14) -> 2.0567871 | AE12: =SUBTOTAL(9,AE13:AE14) -> 3.7364865 | AF12: =SUBTOTAL(9,AF13:AF14) -> 6.4199089 | AG12: =SUBTOTAL(9,AG13:AG14) -> 34.048372 | AH12: =AG12/$AG$4 -> 0.56605911
A13: - | B13: 2/3/4G vùng phủ | C13: VPDĐ | D13: =SUMIFS('PL1.1 ML2027-2028'!$G:$G,'PL1.1 ML2027-2028'!$J:$J,'TH theo DV_Tổng'!$D$3,'PL1.1 ML2027-2028'!$K:$K,'TH theo DV_Tổng'!C13)/$D$1 -> 1.2124691 | E13: =SUMIFS('PL1.1 ML2027-2028'!$G:$G,'PL1.1 ML2027-2028'!$J:$J,'TH theo DV_Tổng'!$E$3,'PL1.1 ML2027-2028'!$K:$K,'TH theo DV_Tổng'!C13)/$D$1 -> 0 | F13: =SUMIFS('PL1.1 ML2027-2028'!$G:$G,'PL1.1 ML2027-2028'!$J:$J,'TH theo DV_Tổng'!$F$3,'PL1.1 ML2027-2028'!$K:$K,'TH theo DV_Tổng'!C13)/$D$1 -> 0 | G13: =SUMIFS('PL1.1 ML2027-2028'!$G:$G,'PL1.1 ML2027-2028'!$J:$J,'TH theo DV_Tổng'!$G$3,'PL1.1 ML2027-2028'!$K:$K,'TH theo DV_Tổng'!C13)/$D$1 -> 0 | H13: =SUMIFS('PL1.1 ML2027-2028'!$G:$G,'PL1.1 ML2027-2028'!$J:$J,"TD",'PL1.1 ML2027-2028'!$M:$M,"IP",'PL1.1 ML2027-2028'!$K:$K,'TH theo DV_Tổng'!C13)/$D$1 -> 0 | I13: =SUMIFS('PL1.1 ML2027-2028'!$G:$G,'PL1.1 ML2027-2028'!$J:$J,"TD",'PL1.1 ML2027-2028'!$M:$M,"Mạng cáp",'PL1.1 ML2027-2028'!$K:$K,'TH theo DV_Tổng'!C13)/$D$1 -> 0.834259 | J13: =SUMIFS('PL1.1 ML2027-2028'!$G:$G,'PL1.1 ML2027-2028'!$J:$J,'TH theo DV_Tổng'!$J$3,'PL1.1 ML2027-2028'!$K:$K,'TH theo DV_Tổng'!C13)/$D$1 -> 1.4700764 | K13: =SUMIFS('PL1.1 ML2027-2028'!$G:$G,'PL1.1 ML2027-2028'!$J:$J,'TH theo DV_Tổng'!K$3,'PL1.1 ML2027-2028'!$K:$K,'TH theo DV_Tổng'!C13)/$D$1 -> 2.2636443 | L13: =SUM(D13:K13) -> 5.7804489 | M13: =L13/$L$4 -> 0.17950084 | N13: =SUMIFS('PL1.1 ML2027-2028'!$H:$H,'PL1.1 ML2027-2028'!$J:$J,'TH theo DV_Tổng'!N$3,'PL1.1 ML2027-2028'!$K:$K,'TH theo DV_Tổng'!$C13)/$D$1 -> 0.72962064 | O13: =SUMIFS('PL1.1 ML2027-2028'!$H:$H,'PL1.1 ML2027-2028'!$J:$J,'TH theo DV_Tổng'!O$3,'PL1.1 ML2027-2028'!$K:$K,'TH theo DV_Tổng'!$C13)/$D$1 -> 0 | P13: =SUMIFS('PL1.1 ML2027-2028'!$H:$H,'PL1.1 ML2027-2028'!$J:$J,'TH theo DV_Tổng'!P$3,'PL1.1 ML2027-2028'!$K:$K,'TH theo DV_Tổng'!$C13)/$D$1 -> 0 | Q13: =SUMIFS('PL1.1 ML2027-2028'!$H:$H,'PL1.1 ML2027-2028'!$J:$J,'TH theo DV_Tổng'!Q$3,'PL1.1 ML2027-2028'!$K:$K,'TH theo DV_Tổng'!$C13)/$D$1 -> 0 | R13: =SUMIFS('PL1.1 ML2027-2028'!$H:$H,'PL1.1 ML2027-2028'!$J:$J,"TD",'PL1.1 ML2027-2028'!$M:$M,"IP",'PL1.1 ML2027-2028'!$K:$K,'TH theo DV_Tổng'!C13)/$D$1 -> 0 | S13: =SUMIFS('PL1.1 ML2027-2028'!$H:$H,'PL1.1 ML2027-2028'!$J:$J,"TD",'PL1.1 ML2027-2028'!$M:$M,"Mạng cáp",'PL1.1 ML2027-2028'!$K:$K,'TH theo DV_Tổng'!C13)/$D$1 -> 1.1404723 | T13: =SUMIFS('PL1.1 ML2027-2028'!$H:$H,'PL1.1 ML2027-2028'!$J:$J,'TH theo DV_Tổng'!T$3,'PL1.1 ML2027-2028'!$K:$K,'TH theo DV_Tổng'!$C13)/$D$1 -> 0.9702167 | U13: =SUMIFS('PL1.1 ML2027-2028'!$H:$H,'PL1.1 ML2027-2028'!$J:$J,'TH theo DV_Tổng'!U$3,'PL1.1 ML2027-2028'!$K:$K,'TH theo DV_Tổng'!$C13)/$D$1 -> 1.4610112 | V13: =SUM(N13:U13) -> 4.3013209 | Y13: =D13+N13 -> 1.9420898 | Z13: =E13+O13 -> 0 | AA13: =F13+P13 -> 0 | AB13: =G13+Q13 -> 0 | AC13: =H13+R13 -> 0 | AD13: =I13+S13 -> 1.9747313 | AE13: =J13+T13 -> 2.4402931 | AF13: =K13+U13 -> 3.7246555 | AG13: =SUM(Y13:AF13) -> 10.08177 | AH13: =AG13/$AG$4 -> 0.16761088
A14: - | B14: 2/3/4G dung lượng | C14: DLDĐ | D14: =SUMIFS('PL1.1 ML2027-2028'!$G:$G,'PL1.1 ML2027-2028'!$J:$J,'TH theo DV_Tổng'!$D$3,'PL1.1 ML2027-2028'!$K:$K,'TH theo DV_Tổng'!C14)/$D$1 -> 6.3989127 | E14: =SUMIFS('PL1.1 ML2027-2028'!$G:$G,'PL1.1 ML2027-2028'!$J:$J,'TH theo DV_Tổng'!$E$3,'PL1.1 ML2027-2028'!$K:$K,'TH theo DV_Tổng'!C14)/$D$1 -> 3.4853689 | F14: =SUMIFS('PL1.1 ML2027-2028'!$G:$G,'PL1.1 ML2027-2028'!$J:$J,'TH theo DV_Tổng'!$F$3,'PL1.1 ML2027-2028'!$K:$K,'TH theo DV_Tổng'!C14)/$D$1 -> 0 | G14: =SUMIFS('PL1.1 ML2027-2028'!$G:$G,'PL1.1 ML2027-2028'!$J:$J,'TH theo DV_Tổng'!$G$3,'PL1.1 ML2027-2028'!$K:$K,'TH theo DV_Tổng'!C14)/$D$1 -> 0 | H14: =(SUMIFS('PL1.1 ML2027-2028'!$G:$G,'PL1.1 ML2027-2028'!$J:$J,"TD",'PL1.1 ML2027-2028'!$M:$M,"IP",'PL1.1 ML2027-2028'!$K:$K,'TH theo DV_Tổng'!C17)/$D$1+SUMIFS('PL1.1 ML2027-2028'!$G:$G,'PL1.1 ML2027-2028'!$J:$J,"TD",'PL1.1 ML2027-2028'!$M:$M,"IP",'PL1.1 ML2027-2028'!$K:$K,'TH theo DV_Tổng'!C28)/$D$1+SUMIFS('PL1.1 ML2027-2028'!$G:$G,'PL1.1 ML2027-2028'!$J:$J,"TD",'PL1.1 ML2027-2028'!$M:$M,"IP",'PL1.1 ML2027-2028'!$K:$K,'TH theo DV_Tổng'!C29)/$D$1+SUMIFS('PL1.1 ML2027-2028'!$G:$G,'PL1.1 ML2027-2028'!$J:$J,"TD",'PL1.1 ML2027-2028'!$M:$M,"IP",'PL1.1 ML2027-2028'!$K:$K,'TH theo DV_Tổng'!C13)/$D$1+SUMIFS('PL1.1 ML2027-2028'!$G:$G,'PL1.1 ML2027-2028'!$J:$J,"TD",'PL1.1 ML2027-2028'!$M:$M,"IP",'PL1.1 ML2027-2028'!$K:$K,'TH theo DV_Tổng'!C14)/$D$1)*96/100-H13 -> 2.5213862 | I14: =SUMIFS('PL1.1 ML2027-2028'!$G:$G,'PL1.1 ML2027-2028'!$J:$J,"TD",'PL1.1 ML2027-2028'!$M:$M,"Mạng cáp",'PL1.1 ML2027-2028'!$K:$K,'TH theo DV_Tổng'!C14)/$D$1 -> 0.0353 | J14: =SUMIFS('PL1.1 ML2027-2028'!$G:$G,'PL1.1 ML2027-2028'!$J:$J,'TH theo DV_Tổng'!$J$3,'PL1.1 ML2027-2028'!$K:$K,'TH theo DV_Tổng'!C14)/$D$1 -> 0.43526727 | K14: =SUMIFS('PL1.1 ML2027-2028'!$G:$G,'PL1.1 ML2027-2028'!$J:$J,'TH theo DV_Tổng'!K$3,'PL1.1 ML2027-2028'!$K:$K,'TH theo DV_Tổng'!C14)/$D$1 -> 0.37192109 | L14: =SUM(D14:K14) -> 13.248156 | M14: =L14/$L$4 -> 0.41139628 | N14: =SUMIFS('PL1.1 ML2027-2028'!$H:$H,'PL1.1 ML2027-2028'!$J:$J,'TH theo DV_Tổng'!N$3,'PL1.1 ML2027-2028'!$K:$K,'TH theo DV_Tổng'!$C14)/$D$1 -> 6.4334843 | O14: =SUMIFS('PL1.1 ML2027-2028'!$H:$H,'PL1.1 ML2027-2028'!$J:$J,'TH theo DV_Tổng'!O$3,'PL1.1 ML2027-2028'!$K:$K,'TH theo DV_Tổng'!$C14)/$D$1 -> 0.4455 | P14: =SUMIFS('PL1.1 ML2027-2028'!$H:$H,'PL1.1 ML2027-2028'!$J:$J,'TH theo DV_Tổng'!P$3,'PL1.1 ML2027-2028'!$K:$K,'TH theo DV_Tổng'!$C14)/$D$1 -> 0 | Q14: =SUMIFS('PL1.1 ML2027-2028'!$H:$H,'PL1.1 ML2027-2028'!$J:$J,'TH theo DV_Tổng'!Q$3,'PL1.1 ML2027-2028'!$K:$K,'TH theo DV_Tổng'!$C14)/$D$1 -> 0 | R14: =(SUMIFS('PL1.1 ML2027-2028'!$H:$H,'PL1.1 ML2027-2028'!$J:$J,"TD",'PL1.1 ML2027-2028'!$M:$M,"IP",'PL1.1 ML2027-2028'!$K:$K,'TH theo DV_Tổng'!C17)/$D$1+SUMIFS('PL1.1 ML2027-2028'!$H:$H,'PL1.1 ML2027-2028'!$J:$J,"TD",'PL1.1 ML2027-2028'!$M:$M,"IP",'PL1.1 ML2027-2028'!$K:$K,'TH theo DV_Tổng'!C28)+SUMIFS('PL1.1 ML2027-2028'!$H:$H,'PL1.1 ML2027-2028'!$J:$J,"TD",'PL1.1 ML2027-2028'!$M:$M,"IP",'PL1.1 ML2027-2028'!$K:$K,'TH theo DV_Tổng'!C29)/$D$1)*96/100 -> 0.608448 | S14: =(SUMIFS('PL1.1 ML2027-2028'!$H:$H,'PL1.1 ML2027-2028'!$J:$J,"TD",'PL1.1 ML2027-2028'!$M:$M,"Mạng cáp",'PL1.1 ML2027-2028'!$K:$K,'TH theo DV_Tổng'!C14)/$D$1+SUMIFS('PL1.1 ML2027-2028'!$H:$H,'PL1.1 ML2027-2028'!$J:$J,"TD",'PL1.1 ML2027-2028'!$M:$M,"Mạng cáp",'PL1.1 ML2027-2028'!$K:$K,'TH theo DV_Tổng'!C17)/$D$1+SUMIFS('PL1.1 ML2027-2028'!$H:$H,'PL1.1 ML2027-2028'!$J:$J,"TD",'PL1.1 ML2027-2028'!$M:$M,"Mạng cáp",'PL1.1 ML2027-2028'!$K:$K,'TH theo DV_Tổng'!C28)/$D$1+SUMIFS('PL1.1 ML2027-2028'!$H:$H,'PL1.1 ML2027-2028'!$J:$J,"TD",'PL1.1 ML2027-2028'!$M:$M,"Mạng cáp",'PL1.1 ML2027-2028'!$K:$K,'TH theo DV_Tổng'!C29)/$D$1)*0.96 -> 0.04675584 | T14: =SUMIFS('PL1.1 ML2027-2028'!$H:$H,'PL1.1 ML2027-2028'!$J:$J,'TH theo DV_Tổng'!T$3,'PL1.1 ML2027-2028'!$K:$K,'TH theo DV_Tổng'!$C14)/$D$1 -> 0.86092614 | U14: =SUMIFS('PL1.1 ML2027-2028'!$H:$H,'PL1.1 ML2027-2028'!$J:$J,'TH theo DV_Tổng'!U$3,'PL1.1 ML2027-2028'!$K:$K,'TH theo DV_Tổng'!$C14)/$D$1 -> 2.3233323 | V14: =SUM(N14:U14) -> 10.718447 | Y14: =D14+N14 -> 12.832397 | Z14: =E14+O14 -> 3.9308689 | AA14: =F14+P14 -> 0 | AB14: =G14+Q14 -> 0 | AC14: =H14+R14 -> 3.1298342 | AD14: =I14+S14 -> 0.08205584 | AE14: =J14+T14 -> 1.2961934 | AF14: =K14+U14 -> 2.6952534 | AG14: =SUM(Y14:AF14) -> 23.966603 | AH14: =AG14/$AG$4 -> 0.39844823
A15: 2 | B15: Mạng BRCĐ&TH | D15: =SUBTOTAL(9,D16:D19) -> 0 | E15: =SUBTOTAL(9,E16:E19) -> 0 | F15: =SUBTOTAL(9,F16:F19) -> 0.4167082 | G15: =SUBTOTAL(9,G16:G19) -> 0 | H15: =SUBTOTAL(9,H16:H19) -> 0.10505776 | I15: =SUBTOTAL(9,I16:I19) -> 0 | J15: =SUBTOTAL(9,J16:J19) -> 0 | K15: =SUBTOTAL(9,K16:K19) -> 0 | L15: =SUBTOTAL(9,L16:L19) -> 0.52176596 | M15: =L15/$L$4 -> 0.016202449 | N15: =SUBTOTAL(9,N16:N19) -> 0 | O15: =SUBTOTAL(9,O16:O19) -> 0 | P15: =SUBTOTAL(9,P16:P19) -> 0.3029988 | Q15: =SUBTOTAL(9,Q16:Q19) -> 0 | R15: =SUBTOTAL(9,R16:R19) -> 0.025352 | S15: =SUBTOTAL(9,S16:S19) -> 0.00194816 | T15: =SUBTOTAL(9,T16:T19) -> 0 | U15: =SUBTOTAL(9,U16:U19) -> 0 | V15: =SUBTOTAL(9,V16:V19) -> 0.33029896 | W15: =V15/$V$4 -> 0.011761215 | Y15: =SUBTOTAL(9,Y16:Y19) -> 0 | Z15: =SUBTOTAL(9,Z16:Z19) -> 0 | AA15: =SUBTOTAL(9,AA16:AA19) -> 0.719707 | AB15: =SUBTOTAL(9,AB16:AB19) -> 0 | AC15: =SUBTOTAL(9,AC16:AC19) -> 0.13040976 | AD15: =SUBTOTAL(9,AD16:AD19) -> 0.00194816 | AE15: =SUBTOTAL(9,AE16:AE19) -> 0 | AF15: =SUBTOTAL(9,AF16:AF19) -> 0 | AG15: =SUBTOTAL(9,AG16:AG19) -> 0.85206492 | AH15: =AG15/$AG$4 -> 0.014165702
A16: - | B16: Vùng phủ GPON | C16: VPGPON | D16: =SUMIFS('PL1.1 ML2027-2028'!$G:$G,'PL1.1 ML2027-2028'!$J:$J,'TH theo DV_Tổng'!$D$3,'PL1.1 ML2027-2028'!$K:$K,'TH theo DV_Tổng'!C16)/$D$1 -> 0 | E16: =SUMIFS('PL1.1 ML2027-2028'!$G:$G,'PL1.1 ML2027-2028'!$J:$J,'TH theo DV_Tổng'!$E$3,'PL1.1 ML2027-2028'!$K:$K,'TH theo DV_Tổng'!C16)/$D$1 -> 0 | F16: =SUMIFS('PL1.1 ML2027-2028'!$G:$G,'PL1.1 ML2027-2028'!$J:$J,'TH theo DV_Tổng'!$F$3,'PL1.1 ML2027-2028'!$K:$K,'TH theo DV_Tổng'!C16)/$D$1 -> 0 | G16: =SUMIFS('PL1.1 ML2027-2028'!$G:$G,'PL1.1 ML2027-2028'!$J:$J,'TH theo DV_Tổng'!$G$3,'PL1.1 ML2027-2028'!$K:$K,'TH theo DV_Tổng'!C16)/$D$1 -> 0 | H16: =SUMIFS('PL1.1 ML2027-2028'!$G:$G,'PL1.1 ML2027-2028'!$J:$J,"TD",'PL1.1 ML2027-2028'!$M:$M,"IP",'PL1.1 ML2027-2028'!$K:$K,'TH theo DV_Tổng'!C16)/$D$1 -> 0 | I16: =SUMIFS('PL1.1 ML2027-2028'!$G:$G,'PL1.1 ML2027-2028'!$J:$J,"TD",'PL1.1 ML2027-2028'!$M:$M,"Mạng cáp",'PL1.1 ML2027-2028'!$K:$K,'TH theo DV_Tổng'!C16)/$D$1 -> 0 | J16: =SUMIFS('PL1.1 ML2027-2028'!$G:$G,'PL1.1 ML2027-2028'!$J:$J,'TH theo DV_Tổng'!$J$3,'PL1.1 ML2027-2028'!$K:$K,'TH theo DV_Tổng'!C16)/$D$1 -> 0 | K16: =SUMIFS('PL1.1 ML2027-2028'!$G:$G,'PL1.1 ML2027-2028'!$J:$J,'TH theo DV_Tổng'!K$3,'PL1.1 ML2027-2028'!$K:$K,'TH theo DV_Tổng'!C16)/$D$1 -> 0 | L16: =SUM(D16:K16) -> 0 | M16: =L16/$L$4 -> 0 | N16: =SUMIFS('PL1.1 ML2027-2028'!$H:$H,'PL1.1 ML2027-2028'!$J:$J,'TH theo DV_Tổng'!N$3,'PL1.1 ML2027-2028'!$K:$K,'TH theo DV_Tổng'!$C16)/$D$1 -> 0 | O16: =SUMIFS('PL1.1 ML2027-2028'!$H:$H,'PL1.1 ML2027-2028'!$J:$J,'TH theo DV_Tổng'!O$3,'PL1.1 ML2027-2028'!$K:$K,'TH theo DV_Tổng'!$C16)/$D$1 -> 0 | P16: =SUMIFS('PL1.1 ML2027-2028'!$H:$H,'PL1.1 ML2027-2028'!$J:$J,'TH theo DV_Tổng'!P$3,'PL1.1 ML2027-2028'!$K:$K,'TH theo DV_Tổng'!$C16)/$D$1 -> 0 | Q16: =SUMIFS('PL1.1 ML2027-2028'!$H:$H,'PL1.1 ML2027-2028'!$J:$J,'TH theo DV_Tổng'!Q$3,'PL1.1 ML2027-2028'!$K:$K,'TH theo DV_Tổng'!$C16)/$D$1 -> 0 | R16: =SUMIFS('PL1.1 ML2027-2028'!$H:$H,'PL1.1 ML2027-2028'!$J:$J,"TD",'PL1.1 ML2027-2028'!$M:$M,"IP",'PL1.1 ML2027-2028'!$K:$K,'TH theo DV_Tổng'!C16)/$D$1 -> 0 | S16: =SUMIFS('PL1.1 ML2027-2028'!$H:$H,'PL1.1 ML2027-2028'!$J:$J,"TD",'PL1.1 ML2027-2028'!$M:$M,"Mạng cáp",'PL1.1 ML2027-2028'!$K:$K,'TH theo DV_Tổng'!C16)/$D$1 -> 0 | T16: =SUMIFS('PL1.1 ML2027-2028'!$H:$H,'PL1.1 ML2027-2028'!$J:$J,'TH theo DV_Tổng'!T$3,'PL1.1 ML2027-2028'!$K:$K,'TH theo DV_Tổng'!$C16)/$D$1 -> 0 | U16: =SUMIFS('PL1.1 ML2027-2028'!$H:$H,'PL1.1 ML2027-2028'!$J:$J,'TH theo DV_Tổng'!U$3,'PL1.1 ML2027-2028'!$K:$K,'TH theo DV_Tổng'!$C16)/$D$1 -> 0 | V16: =SUM(N16:U16) -> 0 | Y16: =D16+N16 -> 0 | Z16: =E16+O16 -> 0 | AA16: =F16+P16 -> 0 | AB16: =G16+Q16 -> 0 | AC16: =H16+R16 -> 0 | AD16: =I16+S16 -> 0 | AE16: =J16+T16 -> 0 | AF16: =K16+U16 -> 0 | AG16: =SUM(Y16:AF16) -> 0 | AH16: =AG16/$AG$4 -> 0
A17: - | B17: Dung lượng Internet | C17: DLGPON | D17: =SUMIFS('PL1.1 ML2027-2028'!$G:$G,'PL1.1 ML2027-2028'!$J:$J,'TH theo DV_Tổng'!$D$3,'PL1.1 ML2027-2028'!$K:$K,'TH theo DV_Tổng'!C17)/$D$1 -> 0 | E17: =SUMIFS('PL1.1 ML2027-2028'!$G:$G,'PL1.1 ML2027-2028'!$J:$J,'TH theo DV_Tổng'!$E$3,'PL1.1 ML2027-2028'!$K:$K,'TH theo DV_Tổng'!C17)/$D$1 -> 0 | F17: =SUMIFS('PL1.1 ML2027-2028'!$G:$G,'PL1.1 ML2027-2028'!$J:$J,'TH theo DV_Tổng'!$F$3,'PL1.1 ML2027-2028'!$K:$K,'TH theo DV_Tổng'!C17)/$D$1 -> 0 | G17: =SUMIFS('PL1.1 ML2027-2028'!$G:$G,'PL1.1 ML2027-2028'!$J:$J,'TH theo DV_Tổng'!$G$3,'PL1.1 ML2027-2028'!$K:$K,'TH theo DV_Tổng'!C17)/$D$1 -> 0 | H17: =(SUMIFS('PL1.1 ML2027-2028'!$G:$G,'PL1.1 ML2027-2028'!$J:$J,"TD",'PL1.1 ML2027-2028'!$M:$M,"IP",'PL1.1 ML2027-2028'!$K:$K,'TH theo DV_Tổng'!C17)/$D$1+SUMIFS('PL1.1 ML2027-2028'!$G:$G,'PL1.1 ML2027-2028'!$J:$J,"TD",'PL1.1 ML2027-2028'!$M:$M,"IP",'PL1.1 ML2027-2028'!$K:$K,'TH theo DV_Tổng'!C28)+SUMIFS('PL1.1 ML2027-2028'!$G:$G,'PL1.1 ML2027-2028'!$J:$J,"TD",'PL1.1 ML2027-2028'!$M:$M,"IP",'PL1.1 ML2027-2028'!$K:$K,'TH theo DV_Tổng'!C29)/$D$1)*4/100 -> 0.10505776 | I17: =SUMIFS('PL1.1 ML2027-2028'!$G:$G,'PL1.1 ML2027-2028'!$J:$J,"TD",'PL1.1 ML2027-2028'!$M:$M,"Mạng cáp",'PL1.1 ML2027-2028'!$K:$K,'TH theo DV_Tổng'!C17)/$D$1 -> 0 | J17: =SUMIFS('PL1.1 ML2027-2028'!$G:$G,'PL1.1 ML2027-2028'!$J:$J,'TH theo DV_Tổng'!$J$3,'PL1.1 ML2027-2028'!$K:$K,'TH theo DV_Tổng'!C17)/$D$1 -> 0 | K17: =SUMIFS('PL1.1 ML2027-2028'!$G:$G,'PL1.1 ML2027-2028'!$J:$J,'TH theo DV_Tổng'!K$3,'PL1.1 ML2027-2028'!$K:$K,'TH theo DV_Tổng'!C17)/$D$1 -> 0 | L17: =SUM(D17:K17) -> 0.10505776 | M17: =L17/$L$4 -> 0.0032623689 | N17: =SUMIFS('PL1.1 ML2027-2028'!$H:$H,'PL1.1 ML2027-2028'!$J:$J,'TH theo DV_Tổng'!N$3,'PL1.1 ML2027-2028'!$K:$K,'TH theo DV_Tổng'!$C17)/$D$1 -> 0 | O17: =SUMIFS('PL1.1 ML2027-2028'!$H:$H,'PL1.1 ML2027-2028'!$J:$J,'TH theo DV_Tổng'!O$3,'PL1.1 ML2027-2028'!$K:$K,'TH theo DV_Tổng'!$C17)/$D$1 -> 0 | P17: =SUMIFS('PL1.1 ML2027-2028'!$H:$H,'PL1.1 ML2027-2028'!$J:$J,'TH theo DV_Tổng'!P$3,'PL1.1 ML2027-2028'!$K:$K,'TH theo DV_Tổng'!$C17)/$D$1 -> 0 | Q17: =SUMIFS('PL1.1 ML2027-2028'!$H:$H,'PL1.1 ML2027-2028'!$J:$J,'TH theo DV_Tổng'!Q$3,'PL1.1 ML2027-2028'!$K:$K,'TH theo DV_Tổng'!$C17)/$D$1 -> 0 | R17: =(SUMIFS('PL1.1 ML2027-2028'!$H:$H,'PL1.1 ML2027-2028'!$J:$J,"TD",'PL1.1 ML2027-2028'!$M:$M,"IP",'PL1.1 ML2027-2028'!$K:$K,'TH theo DV_Tổng'!C17)/$D$1+SUMIFS('PL1.1 ML2027-2028'!$H:$H,'PL1.1 ML2027-2028'!$J:$J,"TD",'PL1.1 ML2027-2028'!$M:$M,"IP",'PL1.1 ML2027-2028'!$K:$K,'TH theo DV_Tổng'!C28)+SUMIFS('PL1.1 ML2027-2028'!$H:$H,'PL1.1 ML2027-2028'!$J:$J,"TD",'PL1.1 ML2027-2028'!$M:$M,"IP",'PL1.1 ML2027-2028'!$K:$K,'TH theo DV_Tổng'!C29)/$D$1)*4/100 -> 0.025352 | S17: =(SUMIFS('PL1.1 ML2027-2028'!$H:$H,'PL1.1 ML2027-2028'!$J:$J,"TD",'PL1.1 ML2027-2028'!$M:$M,"Mạng cáp",'PL1.1 ML2027-2028'!$K:$K,'TH theo DV_Tổng'!C14)/$D$1+SUMIFS('PL1.1 ML2027-2028'!$H:$H,'PL1.1 ML2027-2028'!$J:$J,"TD",'PL1.1 ML2027-2028'!$M:$M,"Mạng cáp",'PL1.1 ML2027-2028'!$K:$K,'TH theo DV_Tổng'!C17)/$D$1+SUMIFS('PL1.1 ML2027-2028'!$H:$H,'PL1.1 ML2027-2028'!$J:$J,"TD",'PL1.1 ML2027-2028'!$M:$M,"Mạng cáp",'PL1.1 ML2027-2028'!$K:$K,'TH theo DV_Tổng'!C28)/$D$1+SUMIFS('PL1.1 ML2027-2028'!$H:$H,'PL1.1 ML2027-2028'!$J:$J,"TD",'PL1.1 ML2027-2028'!$M:$M,"Mạng cáp",'PL1.1 ML2027-2028'!$K:$K,'TH theo DV_Tổng'!C29)/$D$1)*0.04 -> 0.00194816 | T17: =SUMIFS('PL1.1 ML2027-2028'!$H:$H,'PL1.1 ML2027-2028'!$J:$J,'TH theo DV_Tổng'!T$3,'PL1.1 ML2027-2028'!$K:$K,'TH theo DV_Tổng'!$C17)/$D$1 -> 0 | U17: =SUMIFS('PL1.1 ML2027-2028'!$H:$H,'PL1.1 ML2027-2028'!$J:$J,'TH theo DV_Tổng'!U$3,'PL1.1 ML2027-2028'!$K:$K,'TH theo DV_Tổng'!$C17)/$D$1 -> 0 | V17: =SUM(N17:U17) -> 0.02730016 | Y17: =D17+N17 -> 0 | Z17: =E17+O17 -> 0 | AA17: =F17+P17 -> 0 | AB17: =G17+Q17 -> 0 | AC17: =H17+R17 -> 0.13040976 | AD17: =I17+S17 -> 0.00194816 | AE17: =J17+T17 -> 0 | AF17: =K17+U17 -> 0 | AG17: =SUM(Y17:AF17) -> 0.13235792 | AH17: =AG17/$AG$4 -> 0.0022004695
A18: - | B18: Dung lượng Truyền hình | C18: TH | D18: =SUMIFS('PL1.1 ML2027-2028'!$G:$G,'PL1.1 ML2027-2028'!$J:$J,'TH theo DV_Tổng'!$D$3,'PL1.1 ML2027-2028'!$K:$K,'TH theo DV_Tổng'!C18)/$D$1 -> 0 | E18: =SUMIFS('PL1.1 ML2027-2028'!$G:$G,'PL1.1 ML2027-2028'!$J:$J,'TH theo DV_Tổng'!$E$3,'PL1.1 ML2027-2028'!$K:$K,'TH theo DV_Tổng'!C18)/$D$1 -> 0 | F18: =SUMIFS('PL1.1 ML2027-2028'!$G:$G,'PL1.1 ML2027-2028'!$J:$J,'TH theo DV_Tổng'!$F$3,'PL1.1 ML2027-2028'!$K:$K,'TH theo DV_Tổng'!C18)/$D$1 -> 0 | G18: =SUMIFS('PL1.1 ML2027-2028'!$G:$G,'PL1.1 ML2027-2028'!$J:$J,'TH theo DV_Tổng'!$G$3,'PL1.1 ML2027-2028'!$K:$K,'TH theo DV_Tổng'!C18)/$D$1 -> 0 | H18: =SUMIFS('PL1.1 ML2027-2028'!$G:$G,'PL1.1 ML2027-2028'!$J:$J,"TD",'PL1.1 ML2027-2028'!$M:$M,"IP",'PL1.1 ML2027-2028'!$K:$K,'TH theo DV_Tổng'!C18)/$D$1 -> 0 | I18: =SUMIFS('PL1.1 ML2027-2028'!$G:$G,'PL1.1 ML2027-2028'!$J:$J,"TD",'PL1.1 ML2027-2028'!$M:$M,"Mạng cáp",'PL1.1 ML2027-2028'!$K:$K,'TH theo DV_Tổng'!C18)/$D$1 -> 0 | J18: =SUMIFS('PL1.1 ML2027-2028'!$G:$G,'PL1.1 ML2027-2028'!$J:$J,'TH theo DV_Tổng'!$J$3,'PL1.1 ML2027-2028'!$K:$K,'TH theo DV_Tổng'!C18)/$D$1 -> 0 | K18: =SUMIFS('PL1.1 ML2027-2028'!$G:$G,'PL1.1 ML2027-2028'!$J:$J,'TH theo DV_Tổng'!K$3,'PL1.1 ML2027-2028'!$K:$K,'TH theo DV_Tổng'!C18)/$D$1 -> 0 | L18: =SUM(D18:K18) -> 0 | M18: =L18/$L$4 -> 0 | N18: =SUMIFS('PL1.1 ML2027-2028'!$H:$H,'PL1.1 ML2027-2028'!$J:$J,'TH theo DV_Tổng'!N$3,'PL1.1 ML2027-2028'!$K:$K,'TH theo DV_Tổng'!$C18)/$D$1 -> 0 | O18: =SUMIFS('PL1.1 ML2027-2028'!$H:$H,'PL1.1 ML2027-2028'!$J:$J,'TH theo DV_Tổng'!O$3,'PL1.1 ML2027-2028'!$K:$K,'TH theo DV_Tổng'!$C18)/$D$1 -> 0 | P18: =SUMIFS('PL1.1 ML2027-2028'!$H:$H,'PL1.1 ML2027-2028'!$J:$J,'TH theo DV_Tổng'!P$3,'PL1.1 ML2027-2028'!$K:$K,'TH theo DV_Tổng'!$C18)/$D$1 -> 0 | Q18: =SUMIFS('PL1.1 ML2027-2028'!$H:$H,'PL1.1 ML2027-2028'!$J:$J,'TH theo DV_Tổng'!Q$3,'PL1.1 ML2027-2028'!$K:$K,'TH theo DV_Tổng'!$C18)/$D$1 -> 0 | R18: =SUMIFS('PL1.1 ML2027-2028'!$H:$H,'PL1.1 ML2027-2028'!$J:$J,"TD",'PL1.1 ML2027-2028'!$M:$M,"IP",'PL1.1 ML2027-2028'!$K:$K,'TH theo DV_Tổng'!C18)/$D$1 -> 0 | S18: =SUMIFS('PL1.1 ML2027-2028'!$H:$H,'PL1.1 ML2027-2028'!$J:$J,"TD",'PL1.1 ML2027-2028'!$M:$M,"Mạng cáp",'PL1.1 ML2027-2028'!$K:$K,'TH theo DV_Tổng'!C18)/$D$1 -> 0 | T18: =SUMIFS('PL1.1 ML2027-2028'!$H:$H,'PL1.1 ML2027-2028'!$J:$J,'TH theo DV_Tổng'!T$3,'PL1.1 ML2027-2028'!$K:$K,'TH theo DV_Tổng'!$C18)/$D$1 -> 0 | U18: =SUMIFS('PL1.1 ML2027-2028'!$H:$H,'PL1.1 ML2027-2028'!$J:$J,'TH theo DV_Tổng'!U$3,'PL1.1 ML2027-2028'!$K:$K,'TH theo DV_Tổng'!$C18)/$D$1 -> 0 | V18: =SUM(N18:T18) -> 0 | Y18: =D18+N18 -> 0 | Z18: =E18+O18 -> 0 | AA18: =F18+P18 -> 0 | AB18: =G18+Q18 -> 0 | AC18: =H18+R18 -> 0 | AD18: =I18+S18 -> 0 | AE18: =J18+T18 -> 0 | AF18: =K18+U18 -> 0 | AG18: =SUM(Y18:AE18) -> 0 | AH18: =AG18/$AG$4 -> 0
A19: - | B19: Kênh truyền | C19: KT | D19: =SUMIFS('PL1.1 ML2027-2028'!$G:$G,'PL1.1 ML2027-2028'!$J:$J,'TH theo DV_Tổng'!$D$3,'PL1.1 ML2027-2028'!$K:$K,'TH theo DV_Tổng'!C19)/$D$1 -> 0 | E19: =SUMIFS('PL1.1 ML2027-2028'!$G:$G,'PL1.1 ML2027-2028'!$J:$J,'TH theo DV_Tổng'!$E$3,'PL1.1 ML2027-2028'!$K:$K,'TH theo DV_Tổng'!C19)/$D$1 -> 0 | F19: =SUMIFS('PL1.1 ML2027-2028'!$G:$G,'PL1.1 ML2027-2028'!$J:$J,'TH theo DV_Tổng'!$F$3,'PL1.1 ML2027-2028'!$K:$K,'TH theo DV_Tổng'!C19)/$D$1 -> 0.4167082 | G19: =SUMIFS('PL1.1 ML2027-2028'!$G:$G,'PL1.1 ML2027-2028'!$J:$J,'TH theo DV_Tổng'!$G$3,'PL1.1 ML2027-2028'!$K:$K,'TH theo DV_Tổng'!C19)/$D$1 -> 0 | H19: =SUMIFS('PL1.1 ML2027-2028'!$G:$G,'PL1.1 ML2027-2028'!$J:$J,"TD",'PL1.1 ML2027-2028'!$M:$M,"IP",'PL1.1 ML2027-2028'!$K:$K,'TH theo DV_Tổng'!C19)/$D$1 -> 0 | I19: =SUMIFS('PL1.1 ML2027-2028'!$G:$G,'PL1.1 ML2027-2028'!$J:$J,"TD",'PL1.1 ML2027-2028'!$M:$M,"Mạng cáp",'PL1.1 ML2027-2028'!$K:$K,'TH theo DV_Tổng'!C19)/$D$1 -> 0 | J19: =SUMIFS('PL1.1 ML2027-2028'!$G:$G,'PL1.1 ML2027-2028'!$J:$J,'TH theo DV_Tổng'!$J$3,'PL1.1 ML2027-2028'!$K:$K,'TH theo DV_Tổng'!C19)/$D$1 -> 0 | K19: =SUMIFS('PL1.1 ML2027-2028'!$G:$G,'PL1.1 ML2027-2028'!$J:$J,'TH theo DV_Tổng'!K$3,'PL1.1 ML2027-2028'!$K:$K,'TH theo DV_Tổng'!C19)/$D$1 -> 0 | L19: =SUM(D19:K19) -> 0.4167082 | M19: =L19/$L$4 -> 0.01294008 | N19: =SUMIFS('PL1.1 ML2027-2028'!$H:$H,'PL1.1 ML2027-2028'!$J:$J,'TH theo DV_Tổng'!N$3,'PL1.1 ML2027-2028'!$K:$K,'TH theo DV_Tổng'!$C19)/$D$1 -> 0 | O19: =SUMIFS('PL1.1 ML2027-2028'!$H:$H,'PL1.1 ML2027-2028'!$J:$J,'TH theo DV_Tổng'!O$3,'PL1.1 ML2027-2028'!$K:$K,'TH theo DV_Tổng'!$C19)/$D$1 -> 0 | P19: =SUMIFS('PL1.1 ML2027-2028'!$H:$H,'PL1.1 ML2027-2028'!$J:$J,'TH theo DV_Tổng'!P$3,'PL1.1 ML2027-2028'!$K:$K,'TH theo DV_Tổng'!$C19)/$D$1 -> 0.3029988 | Q19: =SUMIFS('PL1.1 ML2027-2028'!$H:$H,'PL1.1 ML2027-2028'!$J:$J,'TH theo DV_Tổng'!Q$3,'PL1.1 ML2027-2028'!$K:$K,'TH theo DV_Tổng'!$C19)/$D$1 -> 0 | R19: =SUMIFS('PL1.1 ML2027-2028'!$H:$H,'PL1.1 ML2027-2028'!$J:$J,"TD",'PL1.1 ML2027-2028'!$M:$M,"IP",'PL1.1 ML2027-2028'!$K:$K,'TH theo DV_Tổng'!C19)/$D$1 -> 0 | S19: =SUMIFS('PL1.1 ML2027-2028'!$H:$H,'PL1.1 ML2027-2028'!$J:$J,"TD",'PL1.1 ML2027-2028'!$M:$M,"Mạng cáp",'PL1.1 ML2027-2028'!$K:$K,'TH theo DV_Tổng'!C19)/$D$1 -> 0 | T19: =SUMIFS('PL1.1 ML2027-2028'!$H:$H,'PL1.1 ML2027-2028'!$J:$J,'TH theo DV_Tổng'!T$3,'PL1.1 ML2027-2028'!$K:$K,'TH theo DV_Tổng'!$C19)/$D$1 -> 0 | U19: =SUMIFS('PL1.1 ML2027-2028'!$H:$H,'PL1.1 ML2027-2028'!$J:$J,'TH theo DV_Tổng'!U$3,'PL1.1 ML2027-2028'!$K:$K,'TH theo DV_Tổng'!$C19)/$D$1 -> 0 | V19: =SUM(N19:T19) -> 0.3029988 | Y19: =D19+N19 -> 0 | Z19: =E19+O19 -> 0 | AA19: =F19+P19 -> 0.719707 | AB19: =G19+Q19 -> 0 | AC19: =H19+R19 -> 0 | AD19: =I19+S19 -> 0 | AE19: =J19+T19 -> 0 | AF19: =K19+U19 -> 0 | AG19: =SUM(Y19:AE19) -> 0.719707 | AH19: =AG19/$AG$4 -> 0.011965233
A20: 3 | B20: Phục vụ kinh doanh Cloud | C20: Cloud_KD | D20: =SUMIFS('PL1.1 ML2027-2028'!$G:$G,'PL1.1 ML2027-2028'!$J:$J,'TH theo DV_Tổng'!$D$3,'PL1.1 ML2027-2028'!$K:$K,'TH theo DV_Tổng'!C20)/$D$1 -> 0 | E20: =SUMIFS('PL1.1 ML2027-2028'!$G:$G,'PL1.1 ML2027-2028'!$J:$J,'TH theo DV_Tổng'!$E$3,'PL1.1 ML2027-2028'!$K:$K,'TH theo DV_Tổng'!C20)/$D$1 -> 0 | F20: =SUMIFS('PL1.1 ML2027-2028'!$G:$G,'PL1.1 ML2027-2028'!$J:$J,'TH theo DV_Tổng'!$F$3,'PL1.1 ML2027-2028'!$K:$K,'TH theo DV_Tổng'!C20)/$D$1 -> 0 | G20: =SUMIFS('PL1.1 ML2027-2028'!$G:$G,'PL1.1 ML2027-2028'!$J:$J,'TH theo DV_Tổng'!$G$3,'PL1.1 ML2027-2028'!$K:$K,'TH theo DV_Tổng'!C20)/$D$1 -> 0 | H20: =SUMIFS('PL1.1 ML2027-2028'!$G:$G,'PL1.1 ML2027-2028'!$J:$J,"TD",'PL1.1 ML2027-2028'!$M:$M,"IP",'PL1.1 ML2027-2028'!$K:$K,'TH theo DV_Tổng'!C20)/$D$1 -> 0 | I20: =SUMIFS('PL1.1 ML2027-2028'!$G:$G,'PL1.1 ML2027-2028'!$J:$J,"TD",'PL1.1 ML2027-2028'!$M:$M,"Mạng cáp",'PL1.1 ML2027-2028'!$K:$K,'TH theo DV_Tổng'!C20)/$D$1 -> 0 | J20: =SUMIFS('PL1.1 ML2027-2028'!$G:$G,'PL1.1 ML2027-2028'!$J:$J,'TH theo DV_Tổng'!$J$3,'PL1.1 ML2027-2028'!$K:$K,'TH theo DV_Tổng'!C20)/$D$1 -> 0 | K20: =SUMIFS('PL1.1 ML2027-2028'!$G:$G,'PL1.1 ML2027-2028'!$J:$J,'TH theo DV_Tổng'!$J$3,'PL1.1 ML2027-2028'!$K:$K,'TH theo DV_Tổng'!D20)/$D$1 -> 0 | L20: =SUM(D20:K20) -> 0 | M20: =L20/$L$4 -> 0 | N20: =SUMIFS('PL1.1 ML2027-2028'!$H:$H,'PL1.1 ML2027-2028'!$J:$J,'TH theo DV_Tổng'!N$3,'PL1.1 ML2027-2028'!$K:$K,'TH theo DV_Tổng'!$C20)/$D$1 -> 0 | O20: =SUMIFS('PL1.1 ML2027-2028'!$H:$H,'PL1.1 ML2027-2028'!$J:$J,'TH theo DV_Tổng'!O$3,'PL1.1 ML2027-2028'!$K:$K,'TH theo DV_Tổng'!$C20)/$D$1 -> 0 | P20: =SUMIFS('PL1.1 ML2027-2028'!$H:$H,'PL1.1 ML2027-2028'!$J:$J,'TH theo DV_Tổng'!P$3,'PL1.1 ML2027-2028'!$K:$K,'TH theo DV_Tổng'!$C20)/$D$1 -> 0 | Q20: =SUMIFS('PL1.1 ML2027-2028'!$H:$H,'PL1.1 ML2027-2028'!$J:$J,'TH theo DV_Tổng'!Q$3,'PL1.1 ML2027-2028'!$K:$K,'TH theo DV_Tổng'!$C20)/$D$1 -> 0 | R20: =SUMIFS('PL1.1 ML2027-2028'!$H:$H,'PL1.1 ML2027-2028'!$J:$J,"TD",'PL1.1 ML2027-2028'!$M:$M,"IP",'PL1.1 ML2027-2028'!$K:$K,'TH theo DV_Tổng'!C20)/$D$1 -> 0 | S20: =SUMIFS('PL1.1 ML2027-2028'!$H:$H,'PL1.1 ML2027-2028'!$J:$J,"TD",'PL1.1 ML2027-2028'!$M:$M,"Mạng cáp",'PL1.1 ML2027-2028'!$K:$K,'TH theo DV_Tổng'!C20)/$D$1 -> 0 | T20: =SUMIFS('PL1.1 ML2027-2028'!$H:$H,'PL1.1 ML2027-2028'!$J:$J,'TH theo DV_Tổng'!T$3,'PL1.1 ML2027-2028'!$K:$K,'TH theo DV_Tổng'!$C20)/$D$1 -> 0 | U20: =SUMIFS('PL1.1 ML2027-2028'!$G:$G,'PL1.1 ML2027-2028'!$J:$J,'TH theo DV_Tổng'!$J$3,'PL1.1 ML2027-2028'!$K:$K,'TH theo DV_Tổng'!N20)/$D$1 -> 0 | V20: =SUM(N20:T20) -> 0 | Y20: =D20+N20 -> 0 | Z20: =E20+O20 -> 0 | AA20: =F20+P20 -> 0 | AB20: =G20+Q20 -> 0 | AC20: =H20+R20 -> 0 | AD20: =I20+S20 -> 0 | AE20: =J20+T20 -> 0 | AF20: =K20+U20 -> 0 | AG20: =SUM(Y20:AE20) -> 0 | AH20: =AG20/$AG$4 -> 0
A21: 4 | B21: Data Center | C21: DC | D21: =SUMIFS('PL1.1 ML2027-2028'!$G:$G,'PL1.1 ML2027-2028'!$J:$J,'TH theo DV_Tổng'!$D$3,'PL1.1 ML2027-2028'!$K:$K,'TH theo DV_Tổng'!C21)/$D$1 -> 0 | E21: =SUMIFS('PL1.1 ML2027-2028'!$G:$G,'PL1.1 ML2027-2028'!$J:$J,'TH theo DV_Tổng'!$E$3,'PL1.1 ML2027-2028'!$K:$K,'TH theo DV_Tổng'!C21)/$D$1 -> 0 | F21: =SUMIFS('PL1.1 ML2027-2028'!$G:$G,'PL1.1 ML2027-2028'!$J:$J,'TH theo DV_Tổng'!$F$3,'PL1.1 ML2027-2028'!$K:$K,'TH theo DV_Tổng'!C21)/$D$1 -> 0 | G21: =SUMIFS('PL1.1 ML2027-2028'!$G:$G,'PL1.1 ML2027-2028'!$J:$J,'TH theo DV_Tổng'!$G$3,'PL1.1 ML2027-2028'!$K:$K,'TH theo DV_Tổng'!C21)/$D$1 -> 0 | H21: =SUMIFS('PL1.1 ML2027-2028'!$G:$G,'PL1.1 ML2027-2028'!$J:$J,"TD",'PL1.1 ML2027-2028'!$M:$M,"IP",'PL1.1 ML2027-2028'!$K:$K,'TH theo DV_Tổng'!C21)/$D$1 -> 1.115504 | I21: =SUMIFS('PL1.1 ML2027-2028'!$G:$G,'PL1.1 ML2027-2028'!$J:$J,"TD",'PL1.1 ML2027-2028'!$M:$M,"Mạng cáp",'PL1.1 ML2027-2028'!$K:$K,'TH theo DV_Tổng'!C21)/$D$1 -> 0.26259693 | J21: =SUMIFS('PL1.1 ML2027-2028'!$G:$G,'PL1.1 ML2027-2028'!$J:$J,'TH theo DV_Tổng'!$J$3,'PL1.1 ML2027-2028'!$K:$K,'TH theo DV_Tổng'!C21)/$D$1 -> 1.313644 | K21: =SUMIFS('PL1.1 ML2027-2028'!$G:$G,'PL1.1 ML2027-2028'!$J:$J,'TH theo DV_Tổng'!$K$3,'PL1.1 ML2027-2028'!$K:$K,'TH theo DV_Tổng'!C21)/$D$1 -> 0.136797 | L21: =SUM(D21:K21) -> 2.8285419 | M21: =L21/$L$4 -> 0.087834988 | N21: =SUMIFS('PL1.1 ML2027-2028'!$H:$H,'PL1.1 ML2027-2028'!$J:$J,'TH theo DV_Tổng'!N$3,'PL1.1 ML2027-2028'!$K:$K,'TH theo DV_Tổng'!$C21)/$D$1 -> 0 | O21: =SUMIFS('PL1.1 ML2027-2028'!$H:$H,'PL1.1 ML2027-2028'!$J:$J,'TH theo DV_Tổng'!O$3,'PL1.1 ML2027-2028'!$K:$K,'TH theo DV_Tổng'!$C21)/$D$1 -> 0 | P21: =SUMIFS('PL1.1 ML2027-2028'!$H:$H,'PL1.1 ML2027-2028'!$J:$J,'TH theo DV_Tổng'!P$3,'PL1.1 ML2027-2028'!$K:$K,'TH theo DV_Tổng'!$C21)/$D$1 -> 0 | Q21: =SUMIFS('PL1.1 ML2027-2028'!$H:$H,'PL1.1 ML2027-2028'!$J:$J,'TH theo DV_Tổng'!Q$3,'PL1.1 ML2027-2028'!$K:$K,'TH theo DV_Tổng'!$C21)/$D$1 -> 0 | R21: =SUMIFS('PL1.1 ML2027-2028'!$H:$H,'PL1.1 ML2027-2028'!$J:$J,"TD",'PL1.1 ML2027-2028'!$M:$M,"IP",'PL1.1 ML2027-2028'!$K:$K,'TH theo DV_Tổng'!C21)/$D$1 -> 0.06448 | S21: =SUMIFS('PL1.1 ML2027-2028'!$H:$H,'PL1.1 ML2027-2028'!$J:$J,"TD",'PL1.1 ML2027-2028'!$M:$M,"Mạng cáp",'PL1.1 ML2027-2028'!$K:$K,'TH theo DV_Tổng'!C21)/$D$1 -> 0 | T21: =SUMIFS('PL1.1 ML2027-2028'!$H:$H,'PL1.1 ML2027-2028'!$J:$J,'TH theo DV_Tổng'!T$3,'PL1.1 ML2027-2028'!$K:$K,'TH theo DV_Tổng'!$C21)/$D$1 -> 0.835872 | U21: =SUMIFS('PL1.1 ML2027-2028'!$G:$G,'PL1.1 ML2027-2028'!$J:$J,'TH theo DV_Tổng'!$J$3,'PL1.1 ML2027-2028'!$K:$K,'TH theo DV_Tổng'!N21)/$D$1 -> 0 | V21: =SUM(N21:T21) -> 0.900352 | Y21: =D21+N21 -> 0 | Z21: =E21+O21 -> 0 | AA21: =F21+P21 -> 0 | AB21: =G21+Q21 -> 0 | AC21: =H21+R21 -> 1.179984 | AD21: =I21+S21 -> 0.26259693 | AE21: =J21+T21 -> 2.149516 | AF21: =K21+U21 -> 0.136797 | AG21: =SUM(Y21:AE21) -> 3.5920969 | AH21: =AG21/$AG$4 -> 0.05971913
A22: 5 | B22: Triển khai hạ tầng CNTT | D22: =SUBTOTAL(9,D23:D26) -> 0 | E22: =SUBTOTAL(9,E23:E26) -> 0 | F22: =SUBTOTAL(9,F23:F26) -> 0 | G22: =SUBTOTAL(9,G23:G26) -> 3.8280682 | H22: =SUBTOTAL(9,H23:H26) -> 0 | I22: =SUBTOTAL(9,I23:I26) -> 0 | J22: =SUBTOTAL(9,J23:J26) -> 0 | K22: =SUBTOTAL(9,K23:K26) -> 0 | L22: =SUBTOTAL(9,L23:L26) -> 3.8280682 | M22: =L22/$L$4 -> 0.11887337 | N22: =SUBTOTAL(9,N23:N26) -> 0 | O22: =SUBTOTAL(9,O23:O26) -> 0 | P22: =SUBTOTAL(9,P23:P26) -> 0 | Q22: =SUBTOTAL(9,Q23:Q26) -> 6.8397558 | R22: =SUBTOTAL(9,R23:R26) -> 0 | S22: =SUBTOTAL(9,S23:S26) -> 0 | T22: =SUBTOTAL(9,T23:T26) -> 0 | U22: =SUBTOTAL(9,U23:U26) -> 0 | V22: =SUBTOTAL(9,V23:V25) -> 6.7178118 | W22: =V22/$V$4 -> 0.23920642 | Y22: =SUBTOTAL(9,Y23:Y26) -> 0 | Z22: =SUBTOTAL(9,Z23:Z26) -> 0 | AA22: =SUBTOTAL(9,AA23:AA26) -> 0 | AB22: =SUBTOTAL(9,AB23:AB26) -> 10.667824 | AC22: =SUBTOTAL(9,AC23:AC26) -> 0 | AD22: =SUBTOTAL(9,AD23:AD26) -> 0 | AE22: =SUBTOTAL(9,AE23:AE26) -> 0 | AF22: =SUBTOTAL(9,AF23:AF26) -> 0 | AG22: =SUBTOTAL(9,AG23:AG26) -> 10.667824 | AH22: =AG22/$AG$4 -> 0.17735411
A23: - | B23: Trực tiếp kinh doanh | C23: TTKD | D23: =SUMIFS('PL1.1 ML2027-2028'!$G:$G,'PL1.1 ML2027-2028'!$J:$J,'TH theo DV_Tổng'!$D$3,'PL1.1 ML2027-2028'!$K:$K,'TH theo DV_Tổng'!C23)/$D$1 -> 0 | E23: =SUMIFS('PL1.1 ML2027-2028'!$G:$G,'PL1.1 ML2027-2028'!$J:$J,'TH theo DV_Tổng'!$E$3,'PL1.1 ML2027-2028'!$K:$K,'TH theo DV_Tổng'!C23)/$D$1 -> 0 | F23: =SUMIFS('PL1.1 ML2027-2028'!$G:$G,'PL1.1 ML2027-2028'!$J:$J,'TH theo DV_Tổng'!$F$3,'PL1.1 ML2027-2028'!$K:$K,'TH theo DV_Tổng'!C23)/$D$1 -> 0 | G23: =SUMIFS('PL1.1 ML2027-2028'!$G:$G,'PL1.1 ML2027-2028'!$J:$J,'TH theo DV_Tổng'!$G$3,'PL1.1 ML2027-2028'!$K:$K,'TH theo DV_Tổng'!C23)/$D$1 -> 0.093843 | H23: =SUMIFS('PL1.1 ML2027-2028'!$G:$G,'PL1.1 ML2027-2028'!$J:$J,"TD",'PL1.1 ML2027-2028'!$M:$M,"IP",'PL1.1 ML2027-2028'!$K:$K,'TH theo DV_Tổng'!C23)/$D$1 -> 0 | I23: =SUMIFS('PL1.1 ML2027-2028'!$G:$G,'PL1.1 ML2027-2028'!$J:$J,"TD",'PL1.1 ML2027-2028'!$M:$M,"Mạng cáp",'PL1.1 ML2027-2028'!$K:$K,'TH theo DV_Tổng'!C23)/$D$1 -> 0 | J23: =SUMIFS('PL1.1 ML2027-2028'!$G:$G,'PL1.1 ML2027-2028'!$J:$J,'TH theo DV_Tổng'!$J$3,'PL1.1 ML2027-2028'!$K:$K,'TH theo DV_Tổng'!C23)/$D$1 -> 0 | K23: =SUMIFS('PL1.1 ML2027-2028'!$G:$G,'PL1.1 ML2027-2028'!$J:$J,'TH theo DV_Tổng'!K$3,'PL1.1 ML2027-2028'!$K:$K,'TH theo DV_Tổng'!C23)/$D$1 -> 0 | L23: =SUM(D23:K23) -> 0.093843 | M23: =L23/$L$4 -> 0.0029141158 | N23: =SUMIFS('PL1.1 ML2027-2028'!$H:$H,'PL1.1 ML2027-2028'!$J:$J,'TH theo DV_Tổng'!N$3,'PL1.1 ML2027-2028'!$K:$K,'TH theo DV_Tổng'!$C23)/$D$1 -> 0 | O23: =SUMIFS('PL1.1 ML2027-2028'!$H:$H,'PL1.1 ML2027-2028'!$J:$J,'TH theo DV_Tổng'!O$3,'PL1.1 ML2027-2028'!$K:$K,'TH theo DV_Tổng'!$C23)/$D$1 -> 0 | P23: =SUMIFS('PL1.1 ML2027-2028'!$H:$H,'PL1.1 ML2027-2028'!$J:$J,'TH theo DV_Tổng'!P$3,'PL1.1 ML2027-2028'!$K:$K,'TH theo DV_Tổng'!$C23)/$D$1 -> 0 | Q23: =SUMIFS('PL1.1 ML2027-2028'!$H:$H,'PL1.1 ML2027-2028'!$J:$J,'TH theo DV_Tổng'!Q$3,'PL1.1 ML2027-2028'!$K:$K,'TH theo DV_Tổng'!$C23)/$D$1 -> 0 | R23: =SUMIFS('PL1.1 ML2027-2028'!$H:$H,'PL1.1 ML2027-2028'!$J:$J,"TD",'PL1.1 ML2027-2028'!$M:$M,"IP",'PL1.1 ML2027-2028'!$K:$K,'TH theo DV_Tổng'!C23)/$D$1 -> 0 | S23: =SUMIFS('PL1.1 ML2027-2028'!$H:$H,'PL1.1 ML2027-2028'!$J:$J,"TD",'PL1.1 ML2027-2028'!$M:$M,"Mạng cáp",'PL1.1 ML2027-2028'!$K:$K,'TH theo DV_Tổng'!C23)/$D$1 -> 0 | T23: =SUMIFS('PL1.1 ML2027-2028'!$H:$H,'PL1.1 ML2027-2028'!$J:$J,'TH theo DV_Tổng'!T$3,'PL1.1 ML2027-2028'!$K:$K,'TH theo DV_Tổng'!$C23)/$D$1 -> 0 | U23: =SUMIFS('PL1.1 ML2027-2028'!$H:$H,'PL1.1 ML2027-2028'!$J:$J,'TH theo DV_Tổng'!U$3,'PL1.1 ML2027-2028'!$K:$K,'TH theo DV_Tổng'!$C23)/$D$1 -> 0 | V23: =SUM(N23:U23) -> 0 | Y23: =D23+N23 -> 0 | Z23: =E23+O23 -> 0 | AA23: =F23+P23 -> 0 | AB23: =G23+Q23 -> 0.093843 | AC23: =H23+R23 -> 0 | AD23: =I23+S23 -> 0 | AE23: =J23+T23 -> 0 | AF23: =K23+U23 -> 0 | AG23: =SUM(Y23:AF23) -> 0.093843 | AH23: =AG23/$AG$4 -> 0.0015601534
A24: - | B24: Hỗ trợ kinh doanh và quản trị | C24: HTKD | D24: =SUMIFS('PL1.1 ML2027-2028'!$G:$G,'PL1.1 ML2027-2028'!$J:$J,'TH theo DV_Tổng'!$D$3,'PL1.1 ML2027-2028'!$K:$K,'TH theo DV_Tổng'!C24)/$D$1 -> 0 | E24: =SUMIFS('PL1.1 ML2027-2028'!$G:$G,'PL1.1 ML2027-2028'!$J:$J,'TH theo DV_Tổng'!$E$3,'PL1.1 ML2027-2028'!$K:$K,'TH theo DV_Tổng'!C24)/$D$1 -> 0 | F24: =SUMIFS('PL1.1 ML2027-2028'!$G:$G,'PL1.1 ML2027-2028'!$J:$J,'TH theo DV_Tổng'!$F$3,'PL1.1 ML2027-2028'!$K:$K,'TH theo DV_Tổng'!C24)/$D$1 -> 0 | G24: =SUMIFS('PL1.1 ML2027-2028'!$G:$G,'PL1.1 ML2027-2028'!$J:$J,'TH theo DV_Tổng'!$G$3,'PL1.1 ML2027-2028'!$K:$K,'TH theo DV_Tổng'!C24)/$D$1+SUMIFS('PL1.1 ML2027-2028'!$G:$G,'PL1.1 ML2027-2028'!$J:$J,'TH theo DV_Tổng'!G$3,'PL1.1 ML2027-2028'!$K:$K,"AI/GPU")/$D$1 -> 3.1325822 | H24: =SUMIFS('PL1.1 ML2027-2028'!$G:$G,'PL1.1 ML2027-2028'!$J:$J,"TD",'PL1.1 ML2027-2028'!$M:$M,"IP",'PL1.1 ML2027-2028'!$K:$K,'TH theo DV_Tổng'!C24)/$D$1 -> 0 | I24: =SUMIFS('PL1.1 ML2027-2028'!$G:$G,'PL1.1 ML2027-2028'!$J:$J,"TD",'PL1.1 ML2027-2028'!$M:$M,"Mạng cáp",'PL1.1 ML2027-2028'!$K:$K,'TH theo DV_Tổng'!C24)/$D$1 -> 0 | J24: =SUMIFS('PL1.1 ML2027-2028'!$G:$G,'PL1.1 ML2027-2028'!$J:$J,'TH theo DV_Tổng'!$J$3,'PL1.1 ML2027-2028'!$K:$K,'TH theo DV_Tổng'!C24)/$D$1 -> 0 | K24: =SUMIFS('PL1.1 ML2027-2028'!$G:$G,'PL1.1 ML2027-2028'!$J:$J,'TH theo DV_Tổng'!K$3,'PL1.1 ML2027-2028'!$K:$K,'TH theo DV_Tổng'!C24)/$D$1 -> 0 | L24: =SUM(D24:K24) -> 3.1325822 | M24: =L24/$L$4 -> 0.09727638 | N24: =SUMIFS('PL1.1 ML2027-2028'!$H:$H,'PL1.1 ML2027-2028'!$J:$J,'TH theo DV_Tổng'!N$3,'PL1.1 ML2027-2028'!$K:$K,'TH theo DV_Tổng'!$C24)/$D$1 -> 0 | O24: =SUMIFS('PL1.1 ML2027-2028'!$H:$H,'PL1.1 ML2027-2028'!$J:$J,'TH theo DV_Tổng'!O$3,'PL1.1 ML2027-2028'!$K:$K,'TH theo DV_Tổng'!$C24)/$D$1 -> 0 | P24: =SUMIFS('PL1.1 ML2027-2028'!$H:$H,'PL1.1 ML2027-2028'!$J:$J,'TH theo DV_Tổng'!P$3,'PL1.1 ML2027-2028'!$K:$K,'TH theo DV_Tổng'!$C24)/$D$1 -> 0 | Q24: =SUMIFS('PL1.1 ML2027-2028'!$H:$H,'PL1.1 ML2027-2028'!$J:$J,'TH theo DV_Tổng'!Q$3,'PL1.1 ML2027-2028'!$K:$K,'TH theo DV_Tổng'!$C24)/$D$1 -> 6.0409278 | R24: =SUMIFS('PL1.1 ML2027-2028'!$H:$H,'PL1.1 ML2027-2028'!$J:$J,"TD",'PL1.1 ML2027-2028'!$M:$M,"IP",'PL1.1 ML2027-2028'!$K:$K,'TH theo DV_Tổng'!C24)/$D$1 -> 0 | S24: =SUMIFS('PL1.1 ML2027-2028'!$H:$H,'PL1.1 ML2027-2028'!$J:$J,"TD",'PL1.1 ML2027-2028'!$M:$M,"Mạng cáp",'PL1.1 ML2027-2028'!$K:$K,'TH theo DV_Tổng'!C24)/$D$1 -> 0 | T24: =SUMIFS('PL1.1 ML2027-2028'!$H:$H,'PL1.1 ML2027-2028'!$J:$J,'TH theo DV_Tổng'!T$3,'PL1.1 ML2027-2028'!$K:$K,'TH theo DV_Tổng'!$C24)/$D$1 -> 0 | U24: =SUMIFS('PL1.1 ML2027-2028'!$H:$H,'PL1.1 ML2027-2028'!$J:$J,'TH theo DV_Tổng'!U$3,'PL1.1 ML2027-2028'!$K:$K,'TH theo DV_Tổng'!$C24)/$D$1 -> 0 | V24: =SUM(N24:U24) -> 6.0409278 | Y24: =D24+N24 -> 0 | Z24: =E24+O24 -> 0 | AA24: =F24+P24 -> 0 | AB24: =G24+Q24 -> 9.17351 | AC24: =H24+R24 -> 0 | AD24: =I24+S24 -> 0 | AE24: =J24+T24 -> 0 | AF24: =K24+U24 -> 0 | AG24: =SUM(Y24:AF24) -> 9.17351 | AH24: =AG24/$AG$4 -> 0.15251093
A25: - | B25: ATTT | C25: ATTT | D25: =SUMIFS('PL1.1 ML2027-2028'!$G:$G,'PL1.1 ML2027-2028'!$J:$J,'TH theo DV_Tổng'!$D$3,'PL1.1 ML2027-2028'!$K:$K,'TH theo DV_Tổng'!C25)/$D$1 -> 0 | E25: =SUMIFS('PL1.1 ML2027-2028'!$G:$G,'PL1.1 ML2027-2028'!$J:$J,'TH theo DV_Tổng'!$E$3,'PL1.1 ML2027-2028'!$K:$K,'TH theo DV_Tổng'!C25)/$D$1 -> 0 | F25: =SUMIFS('PL1.1 ML2027-2028'!$G:$G,'PL1.1 ML2027-2028'!$J:$J,'TH theo DV_Tổng'!$F$3,'PL1.1 ML2027-2028'!$K:$K,'TH theo DV_Tổng'!C25)/$D$1 -> 0 | G25: =SUMIFS('PL1.1 ML2027-2028'!$G:$G,'PL1.1 ML2027-2028'!$J:$J,'TH theo DV_Tổng'!$G$3,'PL1.1 ML2027-2028'!$K:$K,'TH theo DV_Tổng'!C25)/$D$1 -> 0.390384 | H25: =SUMIFS('PL1.1 ML2027-2028'!$G:$G,'PL1.1 ML2027-2028'!$J:$J,"TD",'PL1.1 ML2027-2028'!$M:$M,"IP",'PL1.1 ML2027-2028'!$K:$K,'TH theo DV_Tổng'!C25)/$D$1 -> 0 | I25: =SUMIFS('PL1.1 ML2027-2028'!$G:$G,'PL1.1 ML2027-2028'!$J:$J,"TD",'PL1.1 ML2027-2028'!$M:$M,"Mạng cáp",'PL1.1 ML2027-2028'!$K:$K,'TH theo DV_Tổng'!C25)/$D$1 -> 0 | J25: =SUMIFS('PL1.1 ML2027-2028'!$G:$G,'PL1.1 ML2027-2028'!$J:$J,'TH theo DV_Tổng'!$J$3,'PL1.1 ML2027-2028'!$K:$K,'TH theo DV_Tổng'!C25)/$D$1 -> 0 | K25: =SUMIFS('PL1.1 ML2027-2028'!$G:$G,'PL1.1 ML2027-2028'!$J:$J,'TH theo DV_Tổng'!K$3,'PL1.1 ML2027-2028'!$K:$K,'TH theo DV_Tổng'!C25)/$D$1 -> 0 | L25: =SUM(D25:K25) -> 0.390384 | M25: =L25/$L$4 -> 0.012122632 | N25: =SUMIFS('PL1.1 ML2027-2028'!$H:$H,'PL1.1 ML2027-2028'!$J:$J,'TH theo DV_Tổng'!N$3,'PL1.1 ML2027-2028'!$K:$K,'TH theo DV_Tổng'!$C25)/$D$1 -> 0 | O25: =SUMIFS('PL1.1 ML2027-2028'!$H:$H,'PL1.1 ML2027-2028'!$J:$J,'TH theo DV_Tổng'!O$3,'PL1.1 ML2027-2028'!$K:$K,'TH theo DV_Tổng'!$C25)/$D$1 -> 0 | P25: =SUMIFS('PL1.1 ML2027-2028'!$H:$H,'PL1.1 ML2027-2028'!$J:$J,'TH theo DV_Tổng'!P$3,'PL1.1 ML2027-2028'!$K:$K,'TH theo DV_Tổng'!$C25)/$D$1 -> 0 | Q25: =SUMIFS('PL1.1 ML2027-2028'!$H:$H,'PL1.1 ML2027-2028'!$J:$J,'TH theo DV_Tổng'!Q$3,'PL1.1 ML2027-2028'!$K:$K,'TH theo DV_Tổng'!$C25)/$D$1 -> 0.676884 | R25: =SUMIFS('PL1.1 ML2027-2028'!$H:$H,'PL1.1 ML2027-2028'!$J:$J,"TD",'PL1.1 ML2027-2028'!$M:$M,"IP",'PL1.1 ML2027-2028'!$K:$K,'TH theo DV_Tổng'!C25)/$D$1 -> 0 | S25: =SUMIFS('PL1.1 ML2027-2028'!$H:$H,'PL1.1 ML2027-2028'!$J:$J,"TD",'PL1.1 ML2027-2028'!$M:$M,"Mạng cáp",'PL1.1 ML2027-2028'!$K:$K,'TH theo DV_Tổng'!C25)/$D$1 -> 0 | T25: =SUMIFS('PL1.1 ML2027-2028'!$H:$H,'PL1.1 ML2027-2028'!$J:$J,'TH theo DV_Tổng'!T$3,'PL1.1 ML2027-2028'!$K:$K,'TH theo DV_Tổng'!$C25)/$D$1 -> 0 | U25: =SUMIFS('PL1.1 ML2027-2028'!$H:$H,'PL1.1 ML2027-2028'!$J:$J,'TH theo DV_Tổng'!U$3,'PL1.1 ML2027-2028'!$K:$K,'TH theo DV_Tổng'!$C25)/$D$1 -> 0 | V25: =SUM(N25:T25) -> 0.676884 | Y25: =D25+N25 -> 0 | Z25: =E25+O25 -> 0 | AA25: =F25+P25 -> 0 | AB25: =G25+Q25 -> 1.067268 | AC25: =H25+R25 -> 0 | AD25: =I25+S25 -> 0 | AE25: =J25+T25 -> 0 | AF25: =K25+U25 -> 0 | AG25: =SUM(Y25:AE25) -> 1.067268 | AH25: =AG25/$AG$4 -> 0.017743485
