Workbook
Name \p: #REF!
Name __atn1: #REF!
Name __atn10: #REF!
Name __atn2: #REF!
Name __atn3: #REF!
Name __atn4: #REF!
Name __atn5: #REF!
Name __atn6: #REF!
Name __atn7: #REF!
Name __atn8: #REF!
Name __atn9: #REF!
Name __boi1: #REF!
Name __boi2: #REF!
Name __CON1: #REF!
Name __CON2: #REF!
Name __cpd1: #REF!
Name __cpd2: #REF!
Name __deo1: #REF!
Name __deo10: #REF!
Name __deo2: #REF!
Name __deo3: #REF!
Name __deo4: #REF!
Name __deo5: #REF!
Name __deo6: #REF!
Name __deo7: #REF!
Name __deo8: #REF!
Name __deo9: #REF!
Name __lap1: #REF!
Name __lap2: #REF!
Name __nc151: #REF!
Name __NET2: #REF!
Name __SHR1: #REF!
Name __SHR2: #REF!
Name __tax1: #REF!
Name __tax2: #REF!
Name __tax3: #REF!
Name __tax4: #REF!
Name __tct5: #REF!
Name __tg427: #REF!
Name __TH20: #REF!
Name _1: #REF!
Name _1000A01: #REF!
Name _2: #REF!
Name _atn2: #REF!
Name _atn3: #REF!
Name _atn4: #REF!
Name _atn5: #REF!
Name _atn6: #REF!
Name _atn7: #REF!
Name _atn8: #REF!
Name _atn9: #REF!
Name _ATT_REG_DCOM_3G: #REF!
Name _ATT_REG_MI_3G: #REF!
Name _ATT_REG_voice_2G: #REF!
Name _ATT_REG_voice_3G: #REF!
Name _boi1: #REF!
Name _boi2: #REF!
Name _C_Lphi_4ab: #REF!
Name _chk1: #REF!
Name _CON1: #REF!

Sheet PL1.1 ML2027-2028
A1: PHỤ LỤC 1.1: BẢNG TỔNG HỢP CHI TIẾT NHU CẦU ĐẦU TƯ, MUA SẮM THEO QHĐC NĂM 2027-2028 (Ban hành kèm theo Tờ trình số của Tập đoàn CNVTQĐ)
G3: KHÔNG XÓA | J3: KHÔNG XÓA
A4: TT | B4: Nội dung/ hạng mục đầu tư, mua sắm | C4: Đơn vị tính | D4: Khối lượng | F4: Đơn giá dự kiến | G4: Thành tiền dự kiến (VNĐ) | I4: Dự kiến đơn vị đầu tư, mua sắm | J4: Mã mảng | K4: Mã DV | L4: Mã loại
D6: 2027 | E6: 2028 | F6: USD | G6: 2027 | H6: 2028
C7: 6 | F7: 7 | G7: =SUBTOTAL(9,G8:G10) -> 0 | H7: =SUBTOTAL(9,H8:H10) -> 0
B8: TỔNG ĐẦU TƯ VTTB VÀ XÂY LẮP 2027-2028 | G8: =SUBTOTAL(9,G9:G16) -> 0 | H8: =SUBTOTAL(9,H9:H16) -> 0
A9: P1 | B9: TỔNG ĐẦU TƯ VTTB 2027-2028 | G9: =SUBTOTAL(9,G10:G15) -> 0 | H9: =SUBTOTAL(9,H10:H15) -> 0
A10: A | B10: VÔ TUYẾN | G10: =SUBTOTAL(9,#REF!) -> #REF! | H10: =SUBTOTAL(9,#REF!) -> #REF!
A11: B | B11: MẠNG LÕI | G11: =SUBTOTAL(9,#REF!) -> #REF! | H11: =SUBTOTAL(9,#REF!) -> #REF!
A12: C | B12: CĐBR | G12: =SUBTOTAL(9,#REF!) -> #REF! | H12: =SUBTOTAL(9,#REF!) -> #REF!
A13: D | B13: CNTT+VÍ | G13: =SUBTOTAL(9,#REF!) -> #REF! | H13: =SUBTOTAL(9,#REF!) -> #REF!
A14: F | B14: TRUYỀN DẪN | G14: =SUBTOTAL(9,#REF!) -> #REF! | H14: =SUBTOTAL(9,#REF!) -> #REF!
A15: F | B15: CƠ ĐIỆN | G15: =SUBTOTAL(9,#REF!) -> #REF! | H15: =SUBTOTAL(9,#REF!) -> #REF!
A16: P2 | B16: TRIỂN KHAI HẠ TẦNG | G16: =SUBTOTAL(9,#REF!) -> #REF! | H16: =SUBTOTAL(9,#REF!) -> #REF!

Sheet TH theo DV
D1: 1000000
A2: STT | B2: Nội dung | C2: Ko xóa | D2: 2027 (triệu USD) | N2: 2028 (triệu USD) | X2: 2027-2028 (triệu USD)
B3: Mảng | C3: Mã DV | D3: VT | E3: ML | F3: CĐBR | G3: CNTT | H3: TD | I3: IP | J3: CĐ | K3: HT | L3: Tổng | M3: Tỷ trọng (%) | N3: VT | O3: ML | P3: CĐBR | Q3: CNTT | R3: TD | S3: IP | T3: CĐ | U3: HT | V3: Tổng | W3: Tỷ trọng (%) | X3: VT | Y3: ML | Z3: CĐBR | AA3: CNTT | AB3: TD | AC3: IP | AD3: CĐ | AE3: Tổng | AF3: Tỷ trọng (%)
A4: * | B4: Tổng | D4: =SUBTOTAL(9,D6:D30) -> 0 | E4: =SUBTOTAL(9,E6:E30) -> 0 | F4: =SUBTOTAL(9,F6:F30) -> 0 | G4: =SUBTOTAL(9,G6:G31) -> 0 | H4: =SUBTOTAL(9,H6:H30) -> 0 | I4: =SUBTOTAL(9,I6:I30) -> 0 | J4: =SUBTOTAL(9,J6:J30) -> 0 | K4: =SUBTOTAL(9,K6:K30) -> 0 | L4: =SUBTOTAL(9,L6:L31) -> 0 | N4: =SUBTOTAL(9,N6:N30) -> 0 | O4: =SUBTOTAL(9,O6:O30) -> 0 | P4: =SUBTOTAL(9,P6:P30) -> 0 | Q4: =SUBTOTAL(9,Q6:Q31) -> 0 | R4: =SUBTOTAL(9,R6:R30) -> 0 | S4: =SUBTOTAL(9,S6:S30) -> 0 | T4: =SUBTOTAL(9,T6:T30) -> 0 | U4: =SUBTOTAL(9,U6:U30) -> 0 | V4: =SUBTOTAL(9,V6:V30) -> 0 | X4: =SUBTOTAL(9,X6:X30) -> 0 | Y4: =SUBTOTAL(9,Y6:Y30) -> 0 | Z4: =SUBTOTAL(9,Z6:Z30) -> 0 | AA4: =SUBTOTAL(9,AA6:AA30) -> 0 | AB4: =SUBTOTAL(9,AB6:AB30) -> 0 | AC4: =SUBTOTAL(9,AC6:AC30) -> 0 | AD4: =SUBTOTAL(9,AD6:AD30) -> 0 | AE4: =SUBTOTAL(9,AE6:AE30) -> 0 | AF4: =AE4/$AE$4 -> #DIV/0!
B5: Tỷ trọng theo mảng | D5: =D4/$L$4 -> #DIV/0! | E5: =E4/$L$4 -> #DIV/0! | F5: =F4/$L$4 -> #DIV/0! | G5: =G4/$L$4 -> #DIV/0! | H5: =H4/$L$4 -> #DIV/0! | I5: =I4/$L$4 -> #DIV/0! | J5: =J4/$L$4 -> #DIV/0! | K5: =K4/$L$4 -> #DIV/0! | L5: =L4/$L$4 -> #DIV/0! | N5: =N4/$V$4 -> #DIV/0! | O5: =O4/$V$4 -> #DIV/0! | P5: =P4/$V$4 -> #DIV/0! | Q5: =Q4/$V$4 -> #DIV/0! | R5: =R4/$V$4 -> #DIV/0! | S5: =S4/$V$4 -> #DIV/0! | T5: =T4/$V$4 -> #DIV/0! | U5: =U4/$L$4 -> #DIV/0! | V5: =V4/$V$4 -> #DIV/0! | X5: =X4/$AE$4 -> #DIV/0! | Y5: =Y4/$AE$4 -> #DIV/0! | Z5: =Z4/$AE$4 -> #DIV/0! | AA5: =AA4/$AE$4 -> #DIV/0! | AB5: =AB4/$AE$4 -> #DIV/0! | AC5: =AC4/$AE$4 -> #DIV/0! | AD5: =AD4/$AE$4 -> #DIV/0! | AE5: =AE4/$AE$4 -> #DIV/0!
A6: I | B6: Công nghệ mới triển khai diện rộng cho kinh doanh | D6: =SUBTOTAL(9,D7:D10) -> 0 | E6: =SUBTOTAL(9,E7:E10) -> 0 | F6: =SUBTOTAL(9,F7:F10) -> 0 | G6: =SUBTOTAL(9,G7:G10) -> 0 | H6: =SUBTOTAL(9,H7:H10) -> 0 | I6: =SUBTOTAL(9,I7:I10) -> 0 | J6: =SUBTOTAL(9,J7:J10) -> 0 | K6: =SUBTOTAL(9,K7:K10) -> 0 | L6: =SUBTOTAL(9,L7:L10) -> 0 | M6: =L6/$L$4 -> #DIV/0! | N6: =SUBTOTAL(9,N7:N10) -> 0 | O6: =SUBTOTAL(9,O7:O10) -> 0 | P6: =SUBTOTAL(9,P7:P10) -> 0 | Q6: =SUBTOTAL(9,Q7:Q10) -> 0 | R6: =SUBTOTAL(9,R7:R10) -> 0 | T6: =SUBTOTAL(9,T7:T10) -> 0 | U6: =SUBTOTAL(9,U7:U10) -> 0 | V6: =SUBTOTAL(9,V7:V10) -> 0 | W6: =V6/$V$4 -> #DIV/0! | X6: =SUBTOTAL(9,X7:X9) -> 0 | Y6: =SUBTOTAL(9,Y7:Y9) -> 0 | Z6: =SUBTOTAL(9,Z7:Z9) -> 0 | AA6: =SUBTOTAL(9,AA7:AA9) -> 0 | AB6: =SUBTOTAL(9,AB7:AB9) -> 0 | AC6: =SUBTOTAL(9,AC7:AC9) -> 0 | AD6: =SUBTOTAL(9,AD7:AD9) -> 0 | AE6: =SUBTOTAL(9,AE7:AE10) -> 0 | AF6: =AE6/$AE$4 -> #DIV/0!
A7: 1 | B7: Mạng 5G | C7: 5G | D7: =SUMIFS('PL1.1 ML2027-2028'!$G:$G,'PL1.1 ML2027-2028'!$J:$J,'TH theo DV'!$D$3,'PL1.1 ML2027-2028'!$K:$K,'TH theo DV'!C7)/$D$1 -> 0 | E7: =SUMIFS('PL1.1 ML2027-2028'!$G:$G,'PL1.1 ML2027-2028'!$J:$J,'TH theo DV'!$E$3,'PL1.1 ML2027-2028'!$K:$K,'TH theo DV'!C7)/$D$1 -> 0 | F7: =SUMIFS('PL1.1 ML2027-2028'!$G:$G,'PL1.1 ML2027-2028'!$J:$J,'TH theo DV'!$F$3,'PL1.1 ML2027-2028'!$K:$K,'TH theo DV'!C7)/$D$1 -> 0 | G7: =SUMIFS('PL1.1 ML2027-2028'!$G:$G,'PL1.1 ML2027-2028'!$J:$J,'TH theo DV'!$G$3,'PL1.1 ML2027-2028'!$K:$K,'TH theo DV'!C7)/$D$1 -> 0 | H7: =SUMIFS('PL1.1 ML2027-2028'!$G:$G,'PL1.1 ML2027-2028'!$J:$J,'TH theo DV'!$H$3,'PL1.1 ML2027-2028'!$K:$K,'TH theo DV'!C7)/$D$1 -> 0 | I7: =SUMIFS('PL1.1 ML2027-2028'!$G:$G,'PL1.1 ML2027-2028'!$J:$J,I$3,'PL1.1 ML2027-2028'!$K:$K,C7)/$D$1 -> 0 | J7: =SUMIFS('PL1.1 ML2027-2028'!$G:$G,'PL1.1 ML2027-2028'!$J:$J,'TH theo DV'!$J$3,'PL1.1 ML2027-2028'!$K:$K,'TH theo DV'!C7)/$D$1 -> 0 | K7: =SUMIFS('PL1.1 ML2027-2028'!$G:$G,'PL1.1 ML2027-2028'!$J:$J,'TH theo DV'!K$3,'PL1.1 ML2027-2028'!$K:$K,'TH theo DV'!$C7)/$D$1 -> 0 | L7: =SUM(D7:K7) -> 0 | M7: =L7/$L$4 -> #DIV/0! | N7: =SUMIFS('PL1.1 ML2027-2028'!$H:$H,'PL1.1 ML2027-2028'!$J:$J,'TH theo DV'!N$3,'PL1.1 ML2027-2028'!$K:$K,'TH theo DV'!$C7)/$D$1 -> 0 | O7: =SUMIFS('PL1.1 ML2027-2028'!$H:$H,'PL1.1 ML2027-2028'!$J:$J,'TH theo DV'!O$3,'PL1.1 ML2027-2028'!$K:$K,'TH theo DV'!$C7)/$D$1 -> 0 | P7: =SUMIFS('PL1.1 ML2027-2028'!$H:$H,'PL1.1 ML2027-2028'!$J:$J,'TH theo DV'!P$3,'PL1.1 ML2027-2028'!$K:$K,'TH theo DV'!$C7)/$D$1 -> 0 | Q7: =SUMIFS('PL1.1 ML2027-2028'!$H:$H,'PL1.1 ML2027-2028'!$J:$J,'TH theo DV'!Q$3,'PL1.1 ML2027-2028'!$K:$K,'TH theo DV'!$C7)/$D$1 -> 0 | R7: =SUMIFS('PL1.1 ML2027-2028'!$H:$H,'PL1.1 ML2027-2028'!$J:$J,'TH theo DV'!R$3,'PL1.1 ML2027-2028'!$K:$K,'TH theo DV'!$C7)/$D$1 -> 0 | S7: =SUMIFS('PL1.1 ML2027-2028'!$H:$H,'PL1.1 ML2027-2028'!$J:$J,'TH theo DV'!S$3,'PL1.1 ML2027-2028'!$K:$K,'TH theo DV'!$C7)/$D$1 -> 0 | T7: =SUMIFS('PL1.1 ML2027-2028'!$H:$H,'PL1.1 ML2027-2028'!$J:$J,'TH theo DV'!T$3,'PL1.1 ML2027-2028'!$K:$K,'TH theo DV'!$C7)/$D$1 -> 0 | U7: =SUMIFS('PL1.1 ML2027-2028'!$H:$H,'PL1.1 ML2027-2028'!$J:$J,'TH theo DV'!U$3,'PL1.1 ML2027-2028'!$K:$K,'TH theo DV'!$C7)/$D$1 -> 0 | V7: =SUM(N7:U7) -> 0 | X7: =D7+N7 -> 0 | Y7: =E7+O7 -> 0 | Z7: =F7+P7 -> 0 | AA7: =G7+Q7 -> 0 | AB7: =H7+R7 -> 0 | AC7: =I7+S7 -> 0 | AD7: =J7+T7 -> 0 | AE7: =SUM(X7:AD7) -> 0 | AF7: =AE7/$AE$4 -> #DIV/0!
A8: 2 | B8: XGSPON | C8: XGSPON | D8: =SUMIFS('PL1.1 ML2027-2028'!$G:$G,'PL1.1 ML2027-2028'!$J:$J,'TH theo DV'!$D$3,'PL1.1 ML2027-2028'!$K:$K,'TH theo DV'!C8)/$D$1 -> 0 | E8: =SUMIFS('PL1.1 ML2027-2028'!$G:$G,'PL1.1 ML2027-2028'!$J:$J,'TH theo DV'!$E$3,'PL1.1 ML2027-2028'!$K:$K,'TH theo DV'!C8)/$D$1 -> 0 | F8: =SUMIFS('PL1.1 ML2027-2028'!$G:$G,'PL1.1 ML2027-2028'!$J:$J,'TH theo DV'!$F$3,'PL1.1 ML2027-2028'!$K:$K,'TH theo DV'!C8)/$D$1 -> 0 | G8: =SUMIFS('PL1.1 ML2027-2028'!$G:$G,'PL1.1 ML2027-2028'!$J:$J,'TH theo DV'!$G$3,'PL1.1 ML2027-2028'!$K:$K,'TH theo DV'!C8)/$D$1 -> 0 | H8: =SUMIFS('PL1.1 ML2027-2028'!$G:$G,'PL1.1 ML2027-2028'!$J:$J,'TH theo DV'!$H$3,'PL1.1 ML2027-2028'!$K:$K,'TH theo DV'!C8)/$D$1 -> 0 | I8: =SUMIFS('PL1.1 ML2027-2028'!$G:$G,'PL1.1 ML2027-2028'!$J:$J,I$3,'PL1.1 ML2027-2028'!$K:$K,C8)/$D$1 -> 0 | J8: =SUMIFS('PL1.1 ML2027-2028'!$G:$G,'PL1.1 ML2027-2028'!$J:$J,'TH theo DV'!$J$3,'PL1.1 ML2027-2028'!$K:$K,'TH theo DV'!C8)/$D$1 -> 0 | K8: =SUMIFS('PL1.1 ML2027-2028'!$G:$G,'PL1.1 ML2027-2028'!$J:$J,'TH theo DV'!K$3,'PL1.1 ML2027-2028'!$K:$K,'TH theo DV'!$C8)/$D$1 -> 0 | L8: =SUM(D8:K8) -> 0 | M8: =L8/$L$4 -> #DIV/0! | N8: =SUMIFS('PL1.1 ML2027-2028'!$H:$H,'PL1.1 ML2027-2028'!$J:$J,'TH theo DV'!N$3,'PL1.1 ML2027-2028'!$K:$K,'TH theo DV'!$C8)/$D$1 -> 0 | O8: =SUMIFS('PL1.1 ML2027-2028'!$H:$H,'PL1.1 ML2027-2028'!$J:$J,'TH theo DV'!O$3,'PL1.1 ML2027-2028'!$K:$K,'TH theo DV'!$C8)/$D$1 -> 0 | P8: =SUMIFS('PL1.1 ML2027-2028'!$H:$H,'PL1.1 ML2027-2028'!$J:$J,'TH theo DV'!P$3,'PL1.1 ML2027-2028'!$K:$K,'TH theo DV'!$C8)/$D$1 -> 0 | Q8: =SUMIFS('PL1.1 ML2027-2028'!$H:$H,'PL1.1 ML2027-2028'!$J:$J,'TH theo DV'!Q$3,'PL1.1 ML2027-2028'!$K:$K,'TH theo DV'!$C8)/$D$1 -> 0 | R8: =SUMIFS('PL1.1 ML2027-2028'!$H:$H,'PL1.1 ML2027-2028'!$J:$J,'TH theo DV'!R$3,'PL1.1 ML2027-2028'!$K:$K,'TH theo DV'!$C8)/$D$1 -> 0 | S8: =SUMIFS('PL1.1 ML2027-2028'!$H:$H,'PL1.1 ML2027-2028'!$J:$J,'TH theo DV'!S$3,'PL1.1 ML2027-2028'!$K:$K,'TH theo DV'!$C8)/$D$1 -> 0 | T8: =SUMIFS('PL1.1 ML2027-2028'!$H:$H,'PL1.1 ML2027-2028'!$J:$J,'TH theo DV'!T$3,'PL1.1 ML2027-2028'!$K:$K,'TH theo DV'!$C8)/$D$1 -> 0 | U8: =SUMIFS('PL1.1 ML2027-2028'!$H:$H,'PL1.1 ML2027-2028'!$J:$J,'TH theo DV'!U$3,'PL1.1 ML2027-2028'!$K:$K,'TH theo DV'!$C8)/$D$1 -> 0 | V8: =SUM(N8:U8) -> 0 | X8: =D8+N8 -> 0 | Y8: =E8+O8 -> 0 | Z8: =F8+P8 -> 0 | AA8: =G8+Q8 -> 0 | AB8: =H8+R8 -> 0 | AC8: =I8+S8 -> 0 | AD8: =J8+T8 -> 0 | AE8: =SUM(X8:AD8) -> 0 | AF8: =AE8/$AE$4 -> #DIV/0!
A9: 3 | B9: AI/GPU | C9: AI/GPU | D9: =SUMIFS('PL1.1 ML2027-2028'!$G:$G,'PL1.1 ML2027-2028'!$J:$J,'TH theo DV'!$D$3,'PL1.1 ML2027-2028'!$K:$K,'TH theo DV'!C9)/$D$1 -> 0 | E9: =SUMIFS('PL1.1 ML2027-2028'!$G:$G,'PL1.1 ML2027-2028'!$J:$J,'TH theo DV'!$E$3,'PL1.1 ML2027-2028'!$K:$K,'TH theo DV'!C9)/$D$1 -> 0 | F9: =SUMIFS('PL1.1 ML2027-2028'!$G:$G,'PL1.1 ML2027-2028'!$J:$J,'TH theo DV'!$F$3,'PL1.1 ML2027-2028'!$K:$K,'TH theo DV'!C9)/$D$1 -> 0 | G9: =SUMIFS('PL1.1 ML2027-2028'!$G:$G,'PL1.1 ML2027-2028'!$J:$J,'TH theo DV'!G$3,'PL1.1 ML2027-2028'!$K:$K,'TH theo DV'!$C9)/$D$1 -> 0 | H9: =SUMIFS('PL1.1 ML2027-2028'!$G:$G,'PL1.1 ML2027-2028'!$J:$J,'TH theo DV'!$H$3,'PL1.1 ML2027-2028'!$K:$K,'TH theo DV'!C9)/$D$1 -> 0 | I9: =SUMIFS('PL1.1 ML2027-2028'!$G:$G,'PL1.1 ML2027-2028'!$J:$J,I$3,'PL1.1 ML2027-2028'!$K:$K,C9)/$D$1 -> 0 | J9: =SUMIFS('PL1.1 ML2027-2028'!$G:$G,'PL1.1 ML2027-2028'!$J:$J,'TH theo DV'!$J$3,'PL1.1 ML2027-2028'!$K:$K,'TH theo DV'!C9)/$D$1 -> 0 | K9: =SUMIFS('PL1.1 ML2027-2028'!$G:$G,'PL1.1 ML2027-2028'!$J:$J,'TH theo DV'!K$3,'PL1.1 ML2027-2028'!$K:$K,'TH theo DV'!$C9)/$D$1 -> 0 | L9: =SUM(D9:K9) -> 0 | M9: =L9/$L$4 -> #DIV/0! | N9: =SUMIFS('PL1.1 ML2027-2028'!$H:$H,'PL1.1 ML2027-2028'!$J:$J,'TH theo DV'!N$3,'PL1.1 ML2027-2028'!$K:$K,'TH theo DV'!$C9)/$D$1 -> 0 | O9: =SUMIFS('PL1.1 ML2027-2028'!$H:$H,'PL1.1 ML2027-2028'!$J:$J,'TH theo DV'!O$3,'PL1.1 ML2027-2028'!$K:$K,'TH theo DV'!$C9)/$D$1 -> 0 | P9: =SUMIFS('PL1.1 ML2027-2028'!$H:$H,'PL1.1 ML2027-2028'!$J:$J,'TH theo DV'!P$3,'PL1.1 ML2027-2028'!$K:$K,'TH theo DV'!$C9)/$D$1 -> 0 | Q9: =SUMIFS('PL1.1 ML2027-2028'!$H:$H,'PL1.1 ML2027-2028'!$J:$J,'TH theo DV'!Q$3,'PL1.1 ML2027-2028'!$K:$K,'TH theo DV'!$C9)/$D$1 -> 0 | R9: =SUMIFS('PL1.1 ML2027-2028'!$H:$H,'PL1.1 ML2027-2028'!$J:$J,'TH theo DV'!R$3,'PL1.1 ML2027-2028'!$K:$K,'TH theo DV'!$C9)/$D$1 -> 0 | S9: =SUMIFS('PL1.1 ML2027-2028'!$H:$H,'PL1.1 ML2027-2028'!$J:$J,'TH theo DV'!S$3,'PL1.1 ML2027-2028'!$K:$K,'TH theo DV'!$C9)/$D$1 -> 0 | T9: =SUMIFS('PL1.1 ML2027-2028'!$H:$H,'PL1.1 ML2027-2028'!$J:$J,'TH theo DV'!T$3,'PL1.1 ML2027-2028'!$K:$K,'TH theo DV'!$C9)/$D$1 -> 0 | U9: =SUMIFS('PL1.1 ML2027-2028'!$H:$H,'PL1.1 ML2027-2028'!$J:$J,'TH theo DV'!U$3,'PL1.1 ML2027-2028'!$K:$K,'TH theo DV'!$C9)/$D$1 -> 0 | V9: =SUM(N9:U9) -> 0 | X9: =D9+N9 -> 0 | Y9: =E9+O9 -> 0 | Z9: =F9+P9 -> 0 | AA9: =G9+Q9 -> 0 | AB9: =H9+R9 -> 0 | AC9: =I9+S9 -> 0 | AD9: =J9+T9 -> 0 | AE9: =SUM(X9:AD9) -> 0 | AF9: =AE9/$AE$4 -> #DIV/0!
A10: 4 | B10: Private Mobile Network | C10: PMN | D10: =SUMIFS('PL1.1 ML2027-2028'!$G:$G,'PL1.1 ML2027-2028'!$J:$J,'TH theo DV'!$D$3,'PL1.1 ML2027-2028'!$K:$K,'TH theo DV'!C10)/$D$1 -> 0 | E10: =SUMIFS('PL1.1 ML2027-2028'!$G:$G,'PL1.1 ML2027-2028'!$J:$J,'TH theo DV'!$E$3,'PL1.1 ML2027-2028'!$K:$K,'TH theo DV'!C10)/$D$1 -> 0 | F10: =SUMIFS('PL1.1 ML2027-2028'!$G:$G,'PL1.1 ML2027-2028'!$J:$J,'TH theo DV'!$F$3,'PL1.1 ML2027-2028'!$K:$K,'TH theo DV'!C10)/$D$1 -> 0 | G10: =SUMIFS('PL1.1 ML2027-2028'!$G:$G,'PL1.1 ML2027-2028'!$J:$J,'TH theo DV'!$G$3,'PL1.1 ML2027-2028'!$K:$K,'TH theo DV'!C10)/$D$1 -> 0 | H10: =SUMIFS('PL1.1 ML2027-2028'!$G:$G,'PL1.1 ML2027-2028'!$J:$J,'TH theo DV'!$H$3,'PL1.1 ML2027-2028'!$K:$K,'TH theo DV'!C10)/$D$1 -> 0 | I10: =SUMIFS('PL1.1 ML2027-2028'!$G:$G,'PL1.1 ML2027-2028'!$J:$J,I$3,'PL1.1 ML2027-2028'!$K:$K,C10)/$D$1 -> 0 | J10: =SUMIFS('PL1.1 ML2027-2028'!$G:$G,'PL1.1 ML2027-2028'!$J:$J,'TH theo DV'!$J$3,'PL1.1 ML2027-2028'!$K:$K,'TH theo DV'!C10)/$D$1 -> 0 | K10: =SUMIFS('PL1.1 ML2027-2028'!$G:$G,'PL1.1 ML2027-2028'!$J:$J,'TH theo DV'!K$3,'PL1.1 ML2027-2028'!$K:$K,'TH theo DV'!$C10)/$D$1 -> 0 | L10: =SUM(D10:K10) -> 0 | M10: =L10/$L$4 -> #DIV/0! | N10: =SUMIFS('PL1.1 ML2027-2028'!$H:$H,'PL1.1 ML2027-2028'!$J:$J,'TH theo DV'!N$3,'PL1.1 ML2027-2028'!$K:$K,'TH theo DV'!$C10)/$D$1 -> 0 | O10: =SUMIFS('PL1.1 ML2027-2028'!$H:$H,'PL1.1 ML2027-2028'!$J:$J,'TH theo DV'!O$3,'PL1.1 ML2027-2028'!$K:$K,'TH theo DV'!$C10)/$D$1 -> 0 | P10: =SUMIFS('PL1.1 ML2027-2028'!$H:$H,'PL1.1 ML2027-2028'!$J:$J,'TH theo DV'!P$3,'PL1.1 ML2027-2028'!$K:$K,'TH theo DV'!$C10)/$D$1 -> 0 | Q10: =SUMIFS('PL1.1 ML2027-2028'!$H:$H,'PL1.1 ML2027-2028'!$J:$J,'TH theo DV'!Q$3,'PL1.1 ML2027-2028'!$K:$K,'TH theo DV'!$C10)/$D$1 -> 0 | R10: =SUMIFS('PL1.1 ML2027-2028'!$H:$H,'PL1.1 ML2027-2028'!$J:$J,'TH theo DV'!R$3,'PL1.1 ML2027-2028'!$K:$K,'TH theo DV'!$C10)/$D$1 -> 0 | S10: =SUMIFS('PL1.1 ML2027-2028'!$H:$H,'PL1.1 ML2027-2028'!$J:$J,'TH theo DV'!S$3,'PL1.1 ML2027-2028'!$K:$K,'TH theo DV'!$C10)/$D$1 -> 0 | T10: =SUMIFS('PL1.1 ML2027-2028'!$H:$H,'PL1.1 ML2027-2028'!$J:$J,'TH theo DV'!T$3,'PL1.1 ML2027-2028'!$K:$K,'TH theo DV'!$C10)/$D$1 -> 0 | U10: =SUMIFS('PL1.1 ML2027-2028'!$H:$H,'PL1.1 ML2027-2028'!$J:$J,'TH theo DV'!U$3,'PL1.1 ML2027-2028'!$K:$K,'TH theo DV'!$C10)/$D$1 -> 0 | V10: =SUM(N10:U10) -> 0 | X10: =D10+N10 -> 0 | Y10: =E10+O10 -> 0 | Z10: =F10+P10 -> 0 | AA10: =G10+Q10 -> 0 | AB10: =H10+R10 -> 0 | AC10: =I10+S10 -> 0 | AD10: =J10+T10 -> 0 | AE10: =SUM(X10:AD10) -> 0 | AF10: =AE10/$AE$4 -> #DIV/0!
A11: II | B11: Mở rộng mạng lưới hiện tại cho kinh doanh | D11: =SUBTOTAL(9,D12:D25) -> 0 | E11: =SUBTOTAL(9,E12:E25) -> 0 | F11: =SUBTOTAL(9,F12:F25) -> 0 | G11: =SUBTOTAL(9,G12:G25) -> 0 | H11: =SUBTOTAL(9,H12:H25) -> 0 | J11: =SUBTOTAL(9,J12:J25) -> 0 | K11: =SUBTOTAL(9,K12:K25) -> 0 | L11: =SUBTOTAL(9,L12:L25) -> 0 | M11: =L11/$L$4 -> #DIV/0! | N11: =SUBTOTAL(9,N12:N25) -> 0 | O11: =SUBTOTAL(9,O12:O25) -> 0 | P11: =SUBTOTAL(9,P12:P25) -> 0 | Q11: =SUBTOTAL(9,Q12:Q25) -> 0 | R11: =SUBTOTAL(9,R12:R25) -> 0 | S11: =SUBTOTAL(9,S12:S25) -> 0 | T11: =SUBTOTAL(9,T12:T25) -> 0 | U11: =SUBTOTAL(9,U12:U25) -> 0 | V11: =SUBTOTAL(9,V12:V25) -> 0 | W11: =V11/$V$4 -> #DIV/0! | X11: =SUBTOTAL(9,X12:X29) -> 0 | Y11: =SUBTOTAL(9,Y12:Y29) -> 0 | Z11: =SUBTOTAL(9,Z12:Z29) -> 0 | AA11: =SUBTOTAL(9,AA12:AA29) -> 0 | AB11: =SUBTOTAL(9,AB12:AB29) -> 0 | AC11: =SUBTOTAL(9,AC12:AC29) -> 0 | AD11: =SUBTOTAL(9,AD12:AD29) -> 0 | AE11: =SUBTOTAL(9,AE12:AE25) -> 0 | AF11: =AE11/$AE$4 -> #DIV/0!
A12: 1 | B12: Mạng 2/3/4G | D12: =SUBTOTAL(9,D13:D14) -> 0 | E12: =SUBTOTAL(9,E13:E14) -> 0 | F12: =SUBTOTAL(9,F13:F14) -> 0 | G12: =SUBTOTAL(9,G13:G14) -> 0 | H12: =SUBTOTAL(9,H13:H14) -> 0 | I12: =SUBTOTAL(9,I13:I14) -> 0 | J12: =SUBTOTAL(9,J13:J14) -> 0 | K12: =SUBTOTAL(9,K13:K14) -> 0 | L12: =SUBTOTAL(9,L13:L14) -> 0 | M12: =L12/$L$4 -> #DIV/0! | N12: =SUBTOTAL(9,N13:N14) -> 0 | O12: =SUBTOTAL(9,O13:O14) -> 0 | P12: =SUBTOTAL(9,P13:P14) -> 0 | Q12: =SUBTOTAL(9,Q13:Q14) -> 0 | R12: =SUBTOTAL(9,R13:R14) -> 0 | S12: =SUBTOTAL(9,S13:S14) -> 0 | T12: =SUBTOTAL(9,T13:T14) -> 0 | U12: =SUBTOTAL(9,U13:U14) -> 0 | V12: =SUBTOTAL(9,V13:V14) -> 0 | W12: =V12/$V$4 -> #DIV/0! | X12: =SUBTOTAL(9,X13:X14) -> 0 | Y12: =SUBTOTAL(9,Y13:Y14) -> 0 | Z12: =SUBTOTAL(9,Z13:Z14) -> 0 | AA12: =SUBTOTAL(9,AA13:AA14) -> 0 | AB12: =SUBTOTAL(9,AB13:AB14) -> 0 | AC12: =SUBTOTAL(9,AC13:AC14) -> 0 | AD12: =SUBTOTAL(9,AD13:AD14) -> 0 | AE12: =SUBTOTAL(9,AE13:AE14) -> 0 | AF12: =AE12/$AE$4 -> #DIV/0!
A13: - | B13: 2/3/4G vùng phủ | C13: VPDĐ | D13: =SUMIFS('PL1.1 ML2027-2028'!$G:$G,'PL1.1 ML2027-2028'!$J:$J,'TH theo DV'!$D$3,'PL1.1 ML2027-2028'!$K:$K,'TH theo DV'!C13)/$D$1 -> 0 | E13: =SUMIFS('PL1.1 ML2027-2028'!$G:$G,'PL1.1 ML2027-2028'!$J:$J,'TH theo DV'!$E$3,'PL1.1 ML2027-2028'!$K:$K,'TH theo DV'!C13)/$D$1 -> 0 | F13: =SUMIFS('PL1.1 ML2027-2028'!$G:$G,'PL1.1 ML2027-2028'!$J:$J,'TH theo DV'!$F$3,'PL1.1 ML2027-2028'!$K:$K,'TH theo DV'!C13)/$D$1 -> 0 | G13: =SUMIFS('PL1.1 ML2027-2028'!$G:$G,'PL1.1 ML2027-2028'!$J:$J,'TH theo DV'!$G$3,'PL1.1 ML2027-2028'!$K:$K,'TH theo DV'!C13)/$D$1 -> 0 | H13: =SUMIFS('PL1.1 ML2027-2028'!$G:$G,'PL1.1 ML2027-2028'!$J:$J,'TH theo DV'!H$3,'PL1.1 ML2027-2028'!$K:$K,'TH theo DV'!$C13)/$D$1 -> 0 | I13: =SUMIFS('PL1.1 ML2027-2028'!$G:$G,'PL1.1 ML2027-2028'!$J:$J,I$3,'PL1.1 ML2027-2028'!$K:$K,C13)/$D$1 -> 0 | J13: =SUMIFS('PL1.1 ML2027-2028'!$G:$G,'PL1.1 ML2027-2028'!$J:$J,'TH theo DV'!$J$3,'PL1.1 ML2027-2028'!$K:$K,'TH theo DV'!C13)/$D$1 -> 0 | K13: =SUMIFS('PL1.1 ML2027-2028'!$G:$G,'PL1.1 ML2027-2028'!$J:$J,'TH theo DV'!K$3,'PL1.1 ML2027-2028'!$K:$K,'TH theo DV'!$C13)/$D$1 -> 0 | L13: =SUM(D13:K13) -> 0 | M13: =L13/$L$4 -> #DIV/0! | N13: =SUMIFS('PL1.1 ML2027-2028'!$H:$H,'PL1.1 ML2027-2028'!$J:$J,'TH theo DV'!N$3,'PL1.1 ML2027-2028'!$K:$K,'TH theo DV'!$C13)/$D$1 -> 0 | O13: =SUMIFS('PL1.1 ML2027-2028'!$H:$H,'PL1.1 ML2027-2028'!$J:$J,'TH theo DV'!O$3,'PL1.1 ML2027-2028'!$K:$K,'TH theo DV'!$C13)/$D$1 -> 0 | P13: =SUMIFS('PL1.1 ML2027-2028'!$H:$H,'PL1.1 ML2027-2028'!$J:$J,'TH theo DV'!P$3,'PL1.1 ML2027-2028'!$K:$K,'TH theo DV'!$C13)/$D$1 -> 0 | Q13: =SUMIFS('PL1.1 ML2027-2028'!$H:$H,'PL1.1 ML2027-2028'!$J:$J,'TH theo DV'!Q$3,'PL1.1 ML2027-2028'!$K:$K,'TH theo DV'!$C13)/$D$1 -> 0 | R13: =SUMIFS('PL1.1 ML2027-2028'!$H:$H,'PL1.1 ML2027-2028'!$J:$J,'TH theo DV'!R$3,'PL1.1 ML2027-2028'!$K:$K,'TH theo DV'!$C13)/$D$1 -> 0 | S13: =SUMIFS('PL1.1 ML2027-2028'!$H:$H,'PL1.1 ML2027-2028'!$J:$J,'TH theo DV'!S$3,'PL1.1 ML2027-2028'!$K:$K,'TH theo DV'!$C13)/$D$1 -> 0 | T13: =SUMIFS('PL1.1 ML2027-2028'!$H:$H,'PL1.1 ML2027-2028'!$J:$J,'TH theo DV'!T$3,'PL1.1 ML2027-2028'!$K:$K,'TH theo DV'!$C13)/$D$1 -> 0 | U13: =SUMIFS('PL1.1 ML2027-2028'!$H:$H,'PL1.1 ML2027-2028'!$J:$J,'TH theo DV'!U$3,'PL1.1 ML2027-2028'!$K:$K,'TH theo DV'!$C13)/$D$1 -> 0 | V13: =SUM(N13:U13) -> 0 | X13: =D13+N13 -> 0 | Y13: =E13+O13 -> 0 | Z13: =F13+P13 -> 0 | AA13: =G13+Q13 -> 0 | AB13: =H13+R13 -> 0 | AC13: =I13+S13 -> 0 | AD13: =J13+T13 -> 0 | AE13: =SUM(X13:AD13) -> 0 | AF13: =AE13/$AE$4 -> #DIV/0!
A14: - | B14: 2/3/4G dung lượng | C14: DLDĐ | D14: =SUMIFS('PL1.1 ML2027-2028'!$G:$G,'PL1.1 ML2027-2028'!$J:$J,'TH theo DV'!$D$3,'PL1.1 ML2027-2028'!$K:$K,'TH theo DV'!C14)/$D$1 -> 0 | E14: =SUMIFS('PL1.1 ML2027-2028'!$G:$G,'PL1.1 ML2027-2028'!$J:$J,'TH theo DV'!$E$3,'PL1.1 ML2027-2028'!$K:$K,'TH theo DV'!C14)/$D$1 -> 0 | F14: =SUMIFS('PL1.1 ML2027-2028'!$G:$G,'PL1.1 ML2027-2028'!$J:$J,'TH theo DV'!$F$3,'PL1.1 ML2027-2028'!$K:$K,'TH theo DV'!C14)/$D$1 -> 0 | G14: =SUMIFS('PL1.1 ML2027-2028'!$G:$G,'PL1.1 ML2027-2028'!$J:$J,'TH theo DV'!$G$3,'PL1.1 ML2027-2028'!$K:$K,'TH theo DV'!C14)/$D$1 -> 0 | H14: =SUMIFS('PL1.1 ML2027-2028'!$G:$G,'PL1.1 ML2027-2028'!$J:$J,'TH theo DV'!H$3,'PL1.1 ML2027-2028'!$K:$K,'TH theo DV'!$C14)/$D$1 -> 0 | I14: =SUMIFS('PL1.1 ML2027-2028'!$G:$G,'PL1.1 ML2027-2028'!$J:$J,I$3,'PL1.1 ML2027-2028'!$K:$K,C14)/$D$1+SUMIFS('PL1.1 ML2027-2028'!$G:$G,'PL1.1 ML2027-2028'!$J:$J,I$3,'PL1.1 ML2027-2028'!$K:$K,C14)/$D$1 -> 0 | J14: =SUMIFS('PL1.1 ML2027-2028'!$G:$G,'PL1.1 ML2027-2028'!$J:$J,'TH theo DV'!$J$3,'PL1.1 ML2027-2028'!$K:$K,'TH theo DV'!C14)/$D$1 -> 0 | K14: =SUMIFS('PL1.1 ML2027-2028'!$G:$G,'PL1.1 ML2027-2028'!$J:$J,'TH theo DV'!K$3,'PL1.1 ML2027-2028'!$K:$K,'TH theo DV'!$C14)/$D$1 -> 0 | L14: =SUM(D14:K14) -> 0 | M14: =L14/$L$4 -> #DIV/0! | N14: =SUMIFS('PL1.1 ML2027-2028'!$H:$H,'PL1.1 ML2027-2028'!$J:$J,'TH theo DV'!N$3,'PL1.1 ML2027-2028'!$K:$K,'TH theo DV'!$C14)/$D$1 -> 0 | O14: =SUMIFS('PL1.1 ML2027-2028'!$H:$H,'PL1.1 ML2027-2028'!$J:$J,'TH theo DV'!O$3,'PL1.1 ML2027-2028'!$K:$K,'TH theo DV'!$C14)/$D$1 -> 0 | P14: =SUMIFS('PL1.1 ML2027-2028'!$H:$H,'PL1.1 ML2027-2028'!$J:$J,'TH theo DV'!P$3,'PL1.1 ML2027-2028'!$K:$K,'TH theo DV'!$C14)/$D$1 -> 0 | Q14: =SUMIFS('PL1.1 ML2027-2028'!$H:$H,'PL1.1 ML2027-2028'!$J:$J,'TH theo DV'!Q$3,'PL1.1 ML2027-2028'!$K:$K,'TH theo DV'!$C14)/$D$1 -> 0 | R14: =SUMIFS('PL1.1 ML2027-2028'!$H:$H,'PL1.1 ML2027-2028'!$J:$J,'TH theo DV'!R$3,'PL1.1 ML2027-2028'!$K:$K,'TH theo DV'!$C14)/$D$1 -> 0 | S14: =SUMIFS('PL1.1 ML2027-2028'!$H:$H,'PL1.1 ML2027-2028'!$J:$J,'TH theo DV'!S$3,'PL1.1 ML2027-2028'!$K:$K,'TH theo DV'!$C14)/$D$1 -> 0 | T14: =SUMIFS('PL1.1 ML2027-2028'!$H:$H,'PL1.1 ML2027-2028'!$J:$J,'TH theo DV'!T$3,'PL1.1 ML2027-2028'!$K:$K,'TH theo DV'!$C14)/$D$1 -> 0 | U14: =SUMIFS('PL1.1 ML2027-2028'!$H:$H,'PL1.1 ML2027-2028'!$J:$J,'TH theo DV'!U$3,'PL1.1 ML2027-2028'!$K:$K,'TH theo DV'!$C14)/$D$1 -> 0 | V14: =SUM(N14:U14) -> 0 | X14: =D14+N14 -> 0 | Y14: =E14+O14 -> 0 | Z14: =F14+P14 -> 0 | AA14: =G14+Q14 -> 0 | AB14: =H14+R14 -> 0 | AC14: =I14+S14 -> 0 | AD14: =J14+T14 -> 0 | AE14: =SUM(X14:AD14) -> 0 | AF14: =AE14/$AE$4 -> #DIV/0!
A15: 2 | B15: Mạng BRCĐ&TH | D15: =SUBTOTAL(9,D16:D19) -> 0 | E15: =SUBTOTAL(9,E16:E19) -> 0 | F15: =SUBTOTAL(9,F16:F19) -> 0 | G15: =SUBTOTAL(9,G16:G19) -> 0 | H15: =SUBTOTAL(9,H16:H19) -> 0 | I15: =SUBTOTAL(9,I16:I19) -> 0 | J15: =SUBTOTAL(9,J16:J19) -> 0 | K15: =SUBTOTAL(9,K16:K19) -> 0 | L15: =SUBTOTAL(9,L16:L19) -> 0 | M15: =L15/$L$4 -> #DIV/0! | N15: =SUBTOTAL(9,N16:N19) -> 0 | O15: =SUBTOTAL(9,O16:O19) -> 0 | P15: =SUBTOTAL(9,P16:P19) -> 0 | Q15: =SUBTOTAL(9,Q16:Q19) -> 0 | R15: =SUBTOTAL(9,R16:R19) -> 0 | S15: =SUBTOTAL(9,S16:S19) -> 0 | T15: =SUBTOTAL(9,T16:T19) -> 0 | U15: =SUBTOTAL(9,U16:U19) -> 0 | V15: =SUBTOTAL(9,V16:V19) -> 0 | W15: =V15/$V$4 -> #DIV/0! | X15: =SUBTOTAL(9,X16:X19) -> 0 | Y15: =SUBTOTAL(9,Y16:Y19) -> 0 | Z15: =SUBTOTAL(9,Z16:Z19) -> 0 | AA15: =SUBTOTAL(9,AA16:AA19) -> 0 | AB15: =SUBTOTAL(9,AB16:AB19) -> 0 | AC15: =SUBTOTAL(9,AC16:AC19) -> 0 | AD15: =SUBTOTAL(9,AD16:AD19) -> 0 | AE15: =SUBTOTAL(9,AE16:AE19) -> 0 | AF15: =AE15/$AE$4 -> #DIV/0!
A16: - | B16: Vùng phủ GPON | C16: VPGPON | D16: =SUMIFS('PL1.1 ML2027-2028'!$G:$G,'PL1.1 ML2027-2028'!$J:$J,'TH theo DV'!$D$3,'PL1.1 ML2027-2028'!$K:$K,'TH theo DV'!C16)/$D$1 -> 0 | E16: =SUMIFS('PL1.1 ML2027-2028'!$G:$G,'PL1.1 ML2027-2028'!$J:$J,'TH theo DV'!$E$3,'PL1.1 ML2027-2028'!$K:$K,'TH theo DV'!C16)/$D$1 -> 0 | F16: =SUMIFS('PL1.1 ML2027-2028'!$G:$G,'PL1.1 ML2027-2028'!$J:$J,'TH theo DV'!$F$3,'PL1.1 ML2027-2028'!$K:$K,'TH theo DV'!C16)/$D$1 -> 0 | G16: =SUMIFS('PL1.1 ML2027-2028'!$G:$G,'PL1.1 ML2027-2028'!$J:$J,'TH theo DV'!$G$3,'PL1.1 ML2027-2028'!$K:$K,'TH theo DV'!C16)/$D$1 -> 0 | H16: =SUMIFS('PL1.1 ML2027-2028'!$G:$G,'PL1.1 ML2027-2028'!$J:$J,'TH theo DV'!$H$3,'PL1.1 ML2027-2028'!$K:$K,'TH theo DV'!C16)/$D$1 -> 0 | I16: =SUMIFS('PL1.1 ML2027-2028'!$G:$G,'PL1.1 ML2027-2028'!$J:$J,I$3,'PL1.1 ML2027-2028'!$K:$K,C16)/$D$1 -> 0 | J16: =SUMIFS('PL1.1 ML2027-2028'!$G:$G,'PL1.1 ML2027-2028'!$J:$J,'TH theo DV'!$J$3,'PL1.1 ML2027-2028'!$K:$K,'TH theo DV'!C16)/$D$1 -> 0 | K16: =SUMIFS('PL1.1 ML2027-2028'!$G:$G,'PL1.1 ML2027-2028'!$J:$J,'TH theo DV'!K$3,'PL1.1 ML2027-2028'!$K:$K,'TH theo DV'!$C16)/$D$1 -> 0 | L16: =SUM(D16:K16) -> 0 | M16: =L16/$L$4 -> #DIV/0! | N16: =SUMIFS('PL1.1 ML2027-2028'!$H:$H,'PL1.1 ML2027-2028'!$J:$J,'TH theo DV'!N$3,'PL1.1 ML2027-2028'!$K:$K,'TH theo DV'!$C16)/$D$1 -> 0 | O16: =SUMIFS('PL1.1 ML2027-2028'!$H:$H,'PL1.1 ML2027-2028'!$J:$J,'TH theo DV'!O$3,'PL1.1 ML2027-2028'!$K:$K,'TH theo DV'!$C16)/$D$1 -> 0 | P16: =SUMIFS('PL1.1 ML2027-2028'!$H:$H,'PL1.1 ML2027-2028'!$J:$J,'TH theo DV'!P$3,'PL1.1 ML2027-2028'!$K:$K,'TH theo DV'!$C16)/$D$1 -> 0 | Q16: =SUMIFS('PL1.1 ML2027-2028'!$H:$H,'PL1.1 ML2027-2028'!$J:$J,'TH theo DV'!Q$3,'PL1.1 ML2027-2028'!$K:$K,'TH theo DV'!$C16)/$D$1 -> 0 | R16: =SUMIFS('PL1.1 ML2027-2028'!$H:$H,'PL1.1 ML2027-2028'!$J:$J,'TH theo DV'!R$3,'PL1.1 ML2027-2028'!$K:$K,'TH theo DV'!$C16)/$D$1 -> 0 | S16: =SUMIFS('PL1.1 ML2027-2028'!$H:$H,'PL1.1 ML2027-2028'!$J:$J,'TH theo DV'!S$3,'PL1.1 ML2027-2028'!$K:$K,'TH theo DV'!$C16)/$D$1 -> 0 | T16: =SUMIFS('PL1.1 ML2027-2028'!$H:$H,'PL1.1 ML2027-2028'!$J:$J,'TH theo DV'!T$3,'PL1.1 ML2027-2028'!$K:$K,'TH theo DV'!$C16)/$D$1 -> 0 | U16: =SUMIFS('PL1.1 ML2027-2028'!$H:$H,'PL1.1 ML2027-2028'!$J:$J,'TH theo DV'!U$3,'PL1.1 ML2027-2028'!$K:$K,'TH theo DV'!$C16)/$D$1 -> 0 | V16: =SUM(N16:U16) -> 0 | X16: =D16+N16 -> 0 | Y16: =E16+O16 -> 0 | Z16: =F16+P16 -> 0 | AA16: =G16+Q16 -> 0 | AB16: =H16+R16 -> 0 | AC16: =I16+S16 -> 0 | AD16: =J16+T16 -> 0 | AE16: =SUM(X16:AD16) -> 0 | AF16: =AE16/$AE$4 -> #DIV/0!
A17: - | B17: Dung lượng Internet | C17: DLGPON | D17: =SUMIFS('PL1.1 ML2027-2028'!$G:$G,'PL1.1 ML2027-2028'!$J:$J,'TH theo DV'!$D$3,'PL1.1 ML2027-2028'!$K:$K,'TH theo DV'!C17)/$D$1 -> 0 | E17: =SUMIFS('PL1.1 ML2027-2028'!$G:$G,'PL1.1 ML2027-2028'!$J:$J,'TH theo DV'!$E$3,'PL1.1 ML2027-2028'!$K:$K,'TH theo DV'!C17)/$D$1 -> 0 | F17: =SUMIFS('PL1.1 ML2027-2028'!$G:$G,'PL1.1 ML2027-2028'!$J:$J,'TH theo DV'!$F$3,'PL1.1 ML2027-2028'!$K:$K,'TH theo DV'!C17)/$D$1 -> 0 | G17: =SUMIFS('PL1.1 ML2027-2028'!$G:$G,'PL1.1 ML2027-2028'!$J:$J,'TH theo DV'!$G$3,'PL1.1 ML2027-2028'!$K:$K,'TH theo DV'!C17)/$D$1 -> 0 | H17: =SUMIFS('PL1.1 ML2027-2028'!$G:$G,'PL1.1 ML2027-2028'!$J:$J,'TH theo DV'!$H$3,'PL1.1 ML2027-2028'!$K:$K,'TH theo DV'!C17)/$D$1 -> 0 | I17: =SUMIFS('PL1.1 ML2027-2028'!$G:$G,'PL1.1 ML2027-2028'!$J:$J,I$3,'PL1.1 ML2027-2028'!$K:$K,C17)/$D$1 -> 0 | J17: =SUMIFS('PL1.1 ML2027-2028'!$G:$G,'PL1.1 ML2027-2028'!$J:$J,'TH theo DV'!$J$3,'PL1.1 ML2027-2028'!$K:$K,'TH theo DV'!C17)/$D$1 -> 0 | K17: =SUMIFS('PL1.1 ML2027-2028'!$G:$G,'PL1.1 ML2027-2028'!$J:$J,'TH theo DV'!K$3,'PL1.1 ML2027-2028'!$K:$K,'TH theo DV'!$C17)/$D$1 -> 0 | L17: =SUM(D17:K17) -> 0 | M17: =L17/$L$4 -> #DIV/0! | N17: =SUMIFS('PL1.1 ML2027-2028'!$H:$H,'PL1.1 ML2027-2028'!$J:$J,'TH theo DV'!N$3,'PL1.1 ML2027-2028'!$K:$K,'TH theo DV'!$C17)/$D$1 -> 0 | O17: =SUMIFS('PL1.1 ML2027-2028'!$H:$H,'PL1.1 ML2027-2028'!$J:$J,'TH theo DV'!O$3,'PL1.1 ML2027-2028'!$K:$K,'TH theo DV'!$C17)/$D$1 -> 0 | P17: =SUMIFS('PL1.1 ML2027-2028'!$H:$H,'PL1.1 ML2027-2028'!$J:$J,'TH theo DV'!P$3,'PL1.1 ML2027-2028'!$K:$K,'TH theo DV'!$C17)/$D$1 -> 0 | Q17: =SUMIFS('PL1.1 ML2027-2028'!$H:$H,'PL1.1 ML2027-2028'!$J:$J,'TH theo DV'!Q$3,'PL1.1 ML2027-2028'!$K:$K,'TH theo DV'!$C17)/$D$1 -> 0 | R17: =SUMIFS('PL1.1 ML2027-2028'!$H:$H,'PL1.1 ML2027-2028'!$J:$J,'TH theo DV'!R$3,'PL1.1 ML2027-2028'!$K:$K,'TH theo DV'!$C17)/$D$1 -> 0 | S17: =SUMIFS('PL1.1 ML2027-2028'!$H:$H,'PL1.1 ML2027-2028'!$J:$J,'TH theo DV'!S$3,'PL1.1 ML2027-2028'!$K:$K,'TH theo DV'!$C17)/$D$1 -> 0 | T17: =SUMIFS('PL1.1 ML2027-2028'!$H:$H,'PL1.1 ML2027-2028'!$J:$J,'TH theo DV'!T$3,'PL1.1 ML2027-2028'!$K:$K,'TH theo DV'!$C17)/$D$1 -> 0 | U17: =SUMIFS('PL1.1 ML2027-2028'!$H:$H,'PL1.1 ML2027-2028'!$J:$J,'TH theo DV'!U$3,'PL1.1 ML2027-2028'!$K:$K,'TH theo DV'!$C17)/$D$1 -> 0 | V17: =SUM(N17:U17) -> 0 | X17: =D17+N17 -> 0 | Y17: =E17+O17 -> 0 | Z17: =F17+P17 -> 0 | AA17: =G17+Q17 -> 0 | AB17: =H17+R17 -> 0 | AC17: =I17+S17 -> 0 | AD17: =J17+T17 -> 0 | AE17: =SUM(X17:AD17) -> 0 | AF17: =AE17/$AE$4 -> #DIV/0!
A18: - | B18: Dung lượng Truyền hình | C18: TH | D18: =SUMIFS('PL1.1 ML2027-2028'!$G:$G,'PL1.1 ML2027-2028'!$J:$J,'TH theo DV'!$D$3,'PL1.1 ML2027-2028'!$K:$K,'TH theo DV'!C18)/$D$1 -> 0 | E18: =SUMIFS('PL1.1 ML2027-2028'!$G:$G,'PL1.1 ML2027-2028'!$J:$J,'TH theo DV'!$E$3,'PL1.1 ML2027-2028'!$K:$K,'TH theo DV'!C18)/$D$1 -> 0 | F18: =SUMIFS('PL1.1 ML2027-2028'!$G:$G,'PL1.1 ML2027-2028'!$J:$J,'TH theo DV'!$F$3,'PL1.1 ML2027-2028'!$K:$K,'TH theo DV'!C18)/$D$1 -> 0 | G18: =SUMIFS('PL1.1 ML2027-2028'!$G:$G,'PL1.1 ML2027-2028'!$J:$J,'TH theo DV'!$G$3,'PL1.1 ML2027-2028'!$K:$K,'TH theo DV'!C18)/$D$1 -> 0 | H18: =SUMIFS('PL1.1 ML2027-2028'!$G:$G,'PL1.1 ML2027-2028'!$J:$J,'TH theo DV'!$H$3,'PL1.1 ML2027-2028'!$K:$K,'TH theo DV'!C18)/$D$1 -> 0 | I18: =SUMIFS('PL1.1 ML2027-2028'!$G:$G,'PL1.1 ML2027-2028'!$J:$J,I$3,'PL1.1 ML2027-2028'!$K:$K,C18)/$D$1 -> 0 | J18: =SUMIFS('PL1.1 ML2027-2028'!$G:$G,'PL1.1 ML2027-2028'!$J:$J,'TH theo DV'!$J$3,'PL1.1 ML2027-2028'!$K:$K,'TH theo DV'!C18)/$D$1 -> 0 | K18: =SUMIFS('PL1.1 ML2027-2028'!$G:$G,'PL1.1 ML2027-2028'!$J:$J,'TH theo DV'!K$3,'PL1.1 ML2027-2028'!$K:$K,'TH theo DV'!$C18)/$D$1 -> 0 | L18: =SUM(D18:K18) -> 0 | M18: =L18/$L$4 -> #DIV/0! | N18: =SUMIFS('PL1.1 ML2027-2028'!$H:$H,'PL1.1 ML2027-2028'!$J:$J,'TH theo DV'!N$3,'PL1.1 ML2027-2028'!$K:$K,'TH theo DV'!$C18)/$D$1 -> 0 | O18: =SUMIFS('PL1.1 ML2027-2028'!$H:$H,'PL1.1 ML2027-2028'!$J:$J,'TH theo DV'!O$3,'PL1.1 ML2027-2028'!$K:$K,'TH theo DV'!$C18)/$D$1 -> 0 | P18: =SUMIFS('PL1.1 ML2027-2028'!$H:$H,'PL1.1 ML2027-2028'!$J:$J,'TH theo DV'!P$3,'PL1.1 ML2027-2028'!$K:$K,'TH theo DV'!$C18)/$D$1 -> 0 | Q18: =SUMIFS('PL1.1 ML2027-2028'!$H:$H,'PL1.1 ML2027-2028'!$J:$J,'TH theo DV'!Q$3,'PL1.1 ML2027-2028'!$K:$K,'TH theo DV'!$C18)/$D$1 -> 0 | R18: =SUMIFS('PL1.1 ML2027-2028'!$H:$H,'PL1.1 ML2027-2028'!$J:$J,'TH theo DV'!R$3,'PL1.1 ML2027-2028'!$K:$K,'TH theo DV'!$C18)/$D$1 -> 0 | S18: =SUMIFS('PL1.1 ML2027-2028'!$H:$H,'PL1.1 ML2027-2028'!$J:$J,'TH theo DV'!S$3,'PL1.1 ML2027-2028'!$K:$K,'TH theo DV'!$C18)/$D$1 -> 0 | T18: =SUMIFS('PL1.1 ML2027-2028'!$H:$H,'PL1.1 ML2027-2028'!$J:$J,'TH theo DV'!T$3,'PL1.1 ML2027-2028'!$K:$K,'TH theo DV'!$C18)/$D$1 -> 0 | U18: =SUMIFS('PL1.1 ML2027-2028'!$H:$H,'PL1.1 ML2027-2028'!$J:$J,'TH theo DV'!U$3,'PL1.1 ML2027-2028'!$K:$K,'TH theo DV'!$C18)/$D$1 -> 0 | V18: =SUM(N18:U18) -> 0 | X18: =D18+N18 -> 0 | Y18: =E18+O18 -> 0 | Z18: =F18+P18 -> 0 | AA18: =G18+Q18 -> 0 | AB18: =H18+R18 -> 0 | AC18: =I18+S18 -> 0 | AD18: =J18+T18 -> 0 | AE18: =SUM(X18:AD18) -> 0 | AF18: =AE18/$AE$4 -> #DIV/0!
A19: - | B19: Kênh truyền | C19: KT | D19: =SUMIFS('PL1.1 ML2027-2028'!$G:$G,'PL1.1 ML2027-2028'!$J:$J,'TH theo DV'!$D$3,'PL1.1 ML2027-2028'!$K:$K,'TH theo DV'!C19)/$D$1 -> 0 | E19: =SUMIFS('PL1.1 ML2027-2028'!$G:$G,'PL1.1 ML2027-2028'!$J:$J,'TH theo DV'!$E$3,'PL1.1 ML2027-2028'!$K:$K,'TH theo DV'!C19)/$D$1 -> 0 | F19: =SUMIFS('PL1.1 ML2027-2028'!$G:$G,'PL1.1 ML2027-2028'!$J:$J,'TH theo DV'!$F$3,'PL1.1 ML2027-2028'!$K:$K,'TH theo DV'!C19)/$D$1 -> 0 | G19: =SUMIFS('PL1.1 ML2027-2028'!$G:$G,'PL1.1 ML2027-2028'!$J:$J,'TH theo DV'!$G$3,'PL1.1 ML2027-2028'!$K:$K,'TH theo DV'!C19)/$D$1 -> 0 | H19: =SUMIFS('PL1.1 ML2027-2028'!$G:$G,'PL1.1 ML2027-2028'!$J:$J,'TH theo DV'!$H$3,'PL1.1 ML2027-2028'!$K:$K,'TH theo DV'!C19)/$D$1 -> 0 | I19: =SUMIFS('PL1.1 ML2027-2028'!$G:$G,'PL1.1 ML2027-2028'!$J:$J,I$3,'PL1.1 ML2027-2028'!$K:$K,C19)/$D$1 -> 0 | J19: =SUMIFS('PL1.1 ML2027-2028'!$G:$G,'PL1.1 ML2027-2028'!$J:$J,'TH theo DV'!$J$3,'PL1.1 ML2027-2028'!$K:$K,'TH theo DV'!C19)/$D$1 -> 0 | K19: =SUMIFS('PL1.1 ML2027-2028'!$G:$G,'PL1.1 ML2027-2028'!$J:$J,'TH theo DV'!K$3,'PL1.1 ML2027-2028'!$K:$K,'TH theo DV'!$C19)/$D$1 -> 0 | L19: =SUM(D19:K19) -> 0 | M19: =L19/$L$4 -> #DIV/0! | N19: =SUMIFS('PL1.1 ML2027-2028'!$H:$H,'PL1.1 ML2027-2028'!$J:$J,'TH theo DV'!N$3,'PL1.1 ML2027-2028'!$K:$K,'TH theo DV'!$C19)/$D$1 -> 0 | O19: =SUMIFS('PL1.1 ML2027-2028'!$H:$H,'PL1.1 ML2027-2028'!$J:$J,'TH theo DV'!O$3,'PL1.1 ML2027-2028'!$K:$K,'TH theo DV'!$C19)/$D$1 -> 0 | P19: =SUMIFS('PL1.1 ML2027-2028'!$H:$H,'PL1.1 ML2027-2028'!$J:$J,'TH theo DV'!P$3,'PL1.1 ML2027-2028'!$K:$K,'TH theo DV'!$C19)/$D$1 -> 0 | Q19: =SUMIFS('PL1.1 ML2027-2028'!$H:$H,'PL1.1 ML2027-2028'!$J:$J,'TH theo DV'!Q$3,'PL1.1 ML2027-2028'!$K:$K,'TH theo DV'!$C19)/$D$1 -> 0 | R19: =SUMIFS('PL1.1 ML2027-2028'!$H:$H,'PL1.1 ML2027-2028'!$J:$J,'TH theo DV'!R$3,'PL1.1 ML2027-2028'!$K:$K,'TH theo DV'!$C19)/$D$1 -> 0 | S19: =SUMIFS('PL1.1 ML2027-2028'!$H:$H,'PL1.1 ML2027-2028'!$J:$J,'TH theo DV'!S$3,'PL1.1 ML2027-2028'!$K:$K,'TH theo DV'!$C19)/$D$1 -> 0 | T19: =SUMIFS('PL1.1 ML2027-2028'!$H:$H,'PL1.1 ML2027-2028'!$J:$J,'TH theo DV'!T$3,'PL1.1 ML2027-2028'!$K:$K,'TH theo DV'!$C19)/$D$1 -> 0 | U19: =SUMIFS('PL1.1 ML2027-2028'!$H:$H,'PL1.1 ML2027-2028'!$J:$J,'TH theo DV'!U$3,'PL1.1 ML2027-2028'!$K:$K,'TH theo DV'!$C19)/$D$1 -> 0 | V19: =SUM(N19:U19) -> 0 | X19: =D19+N19 -> 0 | Y19: =E19+O19 -> 0 | Z19: =F19+P19 -> 0 | AA19: =G19+Q19 -> 0 | AB19: =H19+R19 -> 0 | AC19: =I19+S19 -> 0 | AD19: =J19+T19 -> 0 | AE19: =SUM(X19:AD19) -> 0 | AF19: =AE19/$AE$4 -> #DIV/0!
A20: 3 | B20: Phục vụ kinh doanh Cloud | C20: Cloud_KD | D20: =SUMIFS('PL1.1 ML2027-2028'!$G:$G,'PL1.1 ML2027-2028'!$J:$J,'TH theo DV'!$D$3,'PL1.1 ML2027-2028'!$K:$K,'TH theo DV'!C20)/$D$1 -> 0 | E20: =SUMIFS('PL1.1 ML2027-2028'!$G:$G,'PL1.1 ML2027-2028'!$J:$J,'TH theo DV'!$E$3,'PL1.1 ML2027-2028'!$K:$K,'TH theo DV'!C20)/$D$1 -> 0 | F20: =SUMIFS('PL1.1 ML2027-2028'!$G:$G,'PL1.1 ML2027-2028'!$J:$J,'TH theo DV'!$F$3,'PL1.1 ML2027-2028'!$K:$K,'TH theo DV'!C20)/$D$1 -> 0 | G20: =SUMIFS('PL1.1 ML2027-2028'!$G:$G,'PL1.1 ML2027-2028'!$J:$J,'TH theo DV'!$G$3,'PL1.1 ML2027-2028'!$K:$K,'TH theo DV'!C20)/$D$1 -> 0 | H20: =SUMIFS('PL1.1 ML2027-2028'!$G:$G,'PL1.1 ML2027-2028'!$J:$J,'TH theo DV'!$H$3,'PL1.1 ML2027-2028'!$K:$K,'TH theo DV'!C20)/$D$1 -> 0 | I20: =SUMIFS('PL1.1 ML2027-2028'!$G:$G,'PL1.1 ML2027-2028'!$J:$J,I$3,'PL1.1 ML2027-2028'!$K:$K,C20)/$D$1 -> 0 | J20: =SUMIFS('PL1.1 ML2027-2028'!$G:$G,'PL1.1 ML2027-2028'!$J:$J,'TH theo DV'!$J$3,'PL1.1 ML2027-2028'!$K:$K,'TH theo DV'!C20)/$D$1 -> 0 | K20: =SUMIFS('PL1.1 ML2027-2028'!$G:$G,'PL1.1 ML2027-2028'!$J:$J,'TH theo DV'!K$3,'PL1.1 ML2027-2028'!$K:$K,'TH theo DV'!$C20)/$D$1 -> 0 | L20: =SUM(D20:K20) -> 0 | M20: =L20/$L$4 -> #DIV/0! | N20: =SUMIFS('PL1.1 ML2027-2028'!$H:$H,'PL1.1 ML2027-2028'!$J:$J,'TH theo DV'!N$3,'PL1.1 ML2027-2028'!$K:$K,'TH theo DV'!$C20)/$D$1 -> 0 | O20: =SUMIFS('PL1.1 ML2027-2028'!$H:$H,'PL1.1 ML2027-2028'!$J:$J,'TH theo DV'!O$3,'PL1.1 ML2027-2028'!$K:$K,'TH theo DV'!$C20)/$D$1 -> 0 | P20: =SUMIFS('PL1.1 ML2027-2028'!$H:$H,'PL1.1 ML2027-2028'!$J:$J,'TH theo DV'!P$3,'PL1.1 ML2027-2028'!$K:$K,'TH theo DV'!$C20)/$D$1 -> 0 | Q20: =SUMIFS('PL1.1 ML2027-2028'!$H:$H,'PL1.1 ML2027-2028'!$J:$J,'TH theo DV'!Q$3,'PL1.1 ML2027-2028'!$K:$K,'TH theo DV'!$C20)/$D$1 -> 0 | R20: =SUMIFS('PL1.1 ML2027-2028'!$H:$H,'PL1.1 ML2027-2028'!$J:$J,'TH theo DV'!R$3,'PL1.1 ML2027-2028'!$K:$K,'TH theo DV'!$C20)/$D$1 -> 0 | S20: =SUMIFS('PL1.1 ML2027-2028'!$H:$H,'PL1.1 ML2027-2028'!$J:$J,'TH theo DV'!S$3,'PL1.1 ML2027-2028'!$K:$K,'TH theo DV'!$C20)/$D$1 -> 0 | T20: =SUMIFS('PL1.1 ML2027-2028'!$H:$H,'PL1.1 ML2027-2028'!$J:$J,'TH theo DV'!T$3,'PL1.1 ML2027-2028'!$K:$K,'TH theo DV'!$C20)/$D$1 -> 0 | U20: =SUMIFS('PL1.1 ML2027-2028'!$H:$H,'PL1.1 ML2027-2028'!$J:$J,'TH theo DV'!U$3,'PL1.1 ML2027-2028'!$K:$K,'TH theo DV'!$C20)/$D$1 -> 0 | V20: =SUM(N20:U20) -> 0 | X20: =D20+N20 -> 0 | Y20: =E20+O20 -> 0 | Z20: =F20+P20 -> 0 | AA20: =G20+Q20 -> 0 | AB20: =H20+R20 -> 0 | AC20: =I20+S20 -> 0 | AD20: =J20+T20 -> 0 | AE20: =SUM(X20:AD20) -> 0 | AF20: =AE20/$AE$4 -> #DIV/0!
A21: 4 | B21: Data Center | C21: DC | D21: =SUMIFS('PL1.1 ML2027-2028'!$G:$G,'PL1.1 ML2027-2028'!$J:$J,'TH theo DV'!$D$3,'PL1.1 ML2027-2028'!$K:$K,'TH theo DV'!C21)/$D$1 -> 0 | E21: =SUMIFS('PL1.1 ML2027-2028'!$G:$G,'PL1.1 ML2027-2028'!$J:$J,'TH theo DV'!$E$3,'PL1.1 ML2027-2028'!$K:$K,'TH theo DV'!C21)/$D$1 -> 0 | F21: =SUMIFS('PL1.1 ML2027-2028'!$G:$G,'PL1.1 ML2027-2028'!$J:$J,'TH theo DV'!$F$3,'PL1.1 ML2027-2028'!$K:$K,'TH theo DV'!C21)/$D$1 -> 0 | G21: =SUMIFS('PL1.1 ML2027-2028'!$G:$G,'PL1.1 ML2027-2028'!$J:$J,'TH theo DV'!$G$3,'PL1.1 ML2027-2028'!$K:$K,'TH theo DV'!C21)/$D$1 -> 0 | H21: =SUMIFS('PL1.1 ML2027-2028'!$G:$G,'PL1.1 ML2027-2028'!$J:$J,'TH theo DV'!$H$3,'PL1.1 ML2027-2028'!$K:$K,'TH theo DV'!C21)/$D$1 -> 0 | I21: =SUMIFS('PL1.1 ML2027-2028'!$G:$G,'PL1.1 ML2027-2028'!$J:$J,I$3,'PL1.1 ML2027-2028'!$K:$K,C21)/$D$1 -> 0 | J21: =SUMIFS('PL1.1 ML2027-2028'!$G:$G,'PL1.1 ML2027-2028'!$J:$J,'TH theo DV'!$J$3,'PL1.1 ML2027-2028'!$K:$K,'TH theo DV'!C21)/$D$1 -> 0 | K21: =SUMIFS('PL1.1 ML2027-2028'!$G:$G,'PL1.1 ML2027-2028'!$J:$J,'TH theo DV'!K$3,'PL1.1 ML2027-2028'!$K:$K,'TH theo DV'!$C21)/$D$1 -> 0 | L21: =SUM(D21:K21) -> 0 | M21: =L21/$L$4 -> #DIV/0! | N21: =SUMIFS('PL1.1 ML2027-2028'!$H:$H,'PL1.1 ML2027-2028'!$J:$J,'TH theo DV'!N$3,'PL1.1 ML2027-2028'!$K:$K,'TH theo DV'!$C21)/$D$1 -> 0 | O21: =SUMIFS('PL1.1 ML2027-2028'!$H:$H,'PL1.1 ML2027-2028'!$J:$J,'TH theo DV'!O$3,'PL1.1 ML2027-2028'!$K:$K,'TH theo DV'!$C21)/$D$1 -> 0 | P21: =SUMIFS('PL1.1 ML2027-2028'!$H:$H,'PL1.1 ML2027-2028'!$J:$J,'TH theo DV'!P$3,'PL1.1 ML2027-2028'!$K:$K,'TH theo DV'!$C21)/$D$1 -> 0 | Q21: =SUMIFS('PL1.1 ML2027-2028'!$H:$H,'PL1.1 ML2027-2028'!$J:$J,'TH theo DV'!Q$3,'PL1.1 ML2027-2028'!$K:$K,'TH theo DV'!$C21)/$D$1 -> 0 | R21: =SUMIFS('PL1.1 ML2027-2028'!$H:$H,'PL1.1 ML2027-2028'!$J:$J,'TH theo DV'!R$3,'PL1.1 ML2027-2028'!$K:$K,'TH theo DV'!$C21)/$D$1 -> 0 | S21: =SUMIFS('PL1.1 ML2027-2028'!$H:$H,'PL1.1 ML2027-2028'!$J:$J,'TH theo DV'!S$3,'PL1.1 ML2027-2028'!$K:$K,'TH theo DV'!$C21)/$D$1 -> 0 | T21: =SUMIFS('PL1.1 ML2027-2028'!$H:$H,'PL1.1 ML2027-2028'!$J:$J,'TH theo DV'!T$3,'PL1.1 ML2027-2028'!$K:$K,'TH theo DV'!$C21)/$D$1 -> 0 | U21: =SUMIFS('PL1.1 ML2027-2028'!$H:$H,'PL1.1 ML2027-2028'!$J:$J,'TH theo DV'!U$3,'PL1.1 ML2027-2028'!$K:$K,'TH theo DV'!$C21)/$D$1 -> 0 | V21: =SUM(N21:U21) -> 0 | X21: =D21+N21 -> 0 | Y21: =E21+O21 -> 0 | Z21: =F21+P21 -> 0 | AA21: =G21+Q21 -> 0 | AB21: =H21+R21 -> 0 | AC21: =I21+S21 -> 0 | AD21: =J21+T21 -> 0 | AE21: =SUM(X21:AD21) -> 0 | AF21: =AE21/$AE$4 -> #DIV/0!
A22: 5 | B22: Triển khai hạ tầng CNTT | D22: =SUBTOTAL(9,D23:D25) -> 0 | E22: =SUBTOTAL(9,E23:E25) -> 0 | F22: =SUBTOTAL(9,F23:F25) -> 0 | G22: =SUBTOTAL(9,G23:G25) -> 0 | H22: =SUBTOTAL(9,H23:H25) -> 0 | I22: =SUBTOTAL(9,I23:I25) -> 0 | J22: =SUBTOTAL(9,J23:J25) -> 0 | K22: =SUBTOTAL(9,K23:K25) -> 0 | L22: =SUBTOTAL(9,L23:L25) -> 0 | M22: =L22/$L$4 -> #DIV/0! | N22: =SUBTOTAL(9,N23:N25) -> 0 | O22: =SUBTOTAL(9,O23:O25) -> 0 | P22: =SUBTOTAL(9,P23:P25) -> 0 | Q22: =SUBTOTAL(9,Q23:Q25) -> 0 | R22: =SUBTOTAL(9,R23:R25) -> 0 | S22: =SUBTOTAL(9,S23:S25) -> 0 | T22: =SUBTOTAL(9,T23:T25) -> 0 | U22: =SUBTOTAL(9,U23:U25) -> 0 | V22: =SUBTOTAL(9,V23:V25) -> 0 | W22: =V22/$V$4 -> #DIV/0! | X22: =SUBTOTAL(9,X23:X25) -> 0 | Y22: =SUBTOTAL(9,Y23:Y25) -> 0 | Z22: =SUBTOTAL(9,Z23:Z25) -> 0 | AA22: =SUBTOTAL(9,AA23:AA25) -> 0 | AB22: =SUBTOTAL(9,AB23:AB25) -> 0 | AC22: =SUBTOTAL(9,AC23:AC25) -> 0 | AD22: =SUBTOTAL(9,AD23:AD25) -> 0 | AE22: =SUBTOTAL(9,AE23:AE25) -> 0 | AF22: =AE22/$AE$4 -> #DIV/0!
A23: - | B23: Trực tiếp kinh doanh | C23: TTKD | D23: =SUMIFS('PL1.1 ML2027-2028'!$G:$G,'PL1.1 ML2027-2028'!$J:$J,'TH theo DV'!$D$3,'PL1.1 ML2027-2028'!$K:$K,'TH theo DV'!C23)/$D$1 -> 0 | E23: =SUMIFS('PL1.1 ML2027-2028'!$G:$G,'PL1.1 ML2027-2028'!$J:$J,'TH theo DV'!$E$3,'PL1.1 ML2027-2028'!$K:$K,'TH theo DV'!C23)/$D$1 -> 0 | F23: =SUMIFS('PL1.1 ML2027-2028'!$G:$G,'PL1.1 ML2027-2028'!$J:$J,'TH theo DV'!$F$3,'PL1.1 ML2027-2028'!$K:$K,'TH theo DV'!C23)/$D$1 -> 0 | G23: =SUMIFS('PL1.1 ML2027-2028'!$G:$G,'PL1.1 ML2027-2028'!$J:$J,'TH theo DV'!$G$3,'PL1.1 ML2027-2028'!$K:$K,'TH theo DV'!C23)/$D$1 -> 0 | H23: =SUMIFS('PL1.1 ML2027-2028'!$G:$G,'PL1.1 ML2027-2028'!$J:$J,'TH theo DV'!$H$3,'PL1.1 ML2027-2028'!$K:$K,'TH theo DV'!C23)/$D$1 -> 0 | I23: =SUMIFS('PL1.1 ML2027-2028'!$G:$G,'PL1.1 ML2027-2028'!$J:$J,I$3,'PL1.1 ML2027-2028'!$K:$K,C23)/$D$1 -> 0 | J23: =SUMIFS('PL1.1 ML2027-2028'!$G:$G,'PL1.1 ML2027-2028'!$J:$J,'TH theo DV'!$J$3,'PL1.1 ML2027-2028'!$K:$K,'TH theo DV'!C23)/$D$1 -> 0 | K23: =SUMIFS('PL1.1 ML2027-2028'!$G:$G,'PL1.1 ML2027-2028'!$J:$J,'TH theo DV'!K$3,'PL1.1 ML2027-2028'!$K:$K,'TH theo DV'!$C23)/$D$1 -> 0 | L23: =SUM(D23:K23) -> 0 | M23: =L23/$L$4 -> #DIV/0! | N23: =SUMIFS('PL1.1 ML2027-2028'!$H:$H,'PL1.1 ML2027-2028'!$J:$J,'TH theo DV'!N$3,'PL1.1 ML2027-2028'!$K:$K,'TH theo DV'!$C23)/$D$1 -> 0 | O23: =SUMIFS('PL1.1 ML2027-2028'!$H:$H,'PL1.1 ML2027-2028'!$J:$J,'TH theo DV'!O$3,'PL1.1 ML2027-2028'!$K:$K,'TH theo DV'!$C23)/$D$1 -> 0 | P23: =SUMIFS('PL1.1 ML2027-2028'!$H:$H,'PL1.1 ML2027-2028'!$J:$J,'TH theo DV'!P$3,'PL1.1 ML2027-2028'!$K:$K,'TH theo DV'!$C23)/$D$1 -> 0 | Q23: =SUMIFS('PL1.1 ML2027-2028'!$H:$H,'PL1.1 ML2027-2028'!$J:$J,'TH theo DV'!Q$3,'PL1.1 ML2027-2028'!$K:$K,'TH theo DV'!$C23)/$D$1 -> 0 | R23: =SUMIFS('PL1.1 ML2027-2028'!$H:$H,'PL1.1 ML2027-2028'!$J:$J,'TH theo DV'!R$3,'PL1.1 ML2027-2028'!$K:$K,'TH theo DV'!$C23)/$D$1 -> 0 | S23: =SUMIFS('PL1.1 ML2027-2028'!$H:$H,'PL1.1 ML2027-2028'!$J:$J,'TH theo DV'!S$3,'PL1.1 ML2027-2028'!$K:$K,'TH theo DV'!$C23)/$D$1 -> 0 | T23: =SUMIFS('PL1.1 ML2027-2028'!$H:$H,'PL1.1 ML2027-2028'!$J:$J,'TH theo DV'!T$3,'PL1.1 ML2027-2028'!$K:$K,'TH theo DV'!$C23)/$D$1 -> 0 | U23: =SUMIFS('PL1.1 ML2027-2028'!$H:$H,'PL1.1 ML2027-2028'!$J:$J,'TH theo DV'!U$3,'PL1.1 ML2027-2028'!$K:$K,'TH theo DV'!$C23)/$D$1 -> 0 | V23: =SUM(N23:U23) -> 0 | X23: =D23+N23 -> 0 | Y23: =E23+O23 -> 0 | Z23: =F23+P23 -> 0 | AA23: =G23+Q23 -> 0 | AB23: =H23+R23 -> 0 | AC23: =I23+S23 -> 0 | AD23: =J23+T23 -> 0 | AE23: =SUM(X23:AD23) -> 0 | AF23: =AE23/$AE$4 -> #DIV/0!
A24: - | B24: Hỗ trợ kinh doanh và quản trị | C24: HTKD | D24: =SUMIFS('PL1.1 ML2027-2028'!$G:$G,'PL1.1 ML2027-2028'!$J:$J,'TH theo DV'!$D$3,'PL1.1 ML2027-2028'!$K:$K,'TH theo DV'!C24)/$D$1 -> 0 | E24: =SUMIFS('PL1.1 ML2027-2028'!$G:$G,'PL1.1 ML2027-2028'!$J:$J,'TH theo DV'!$E$3,'PL1.1 ML2027-2028'!$K:$K,'TH theo DV'!C24)/$D$1 -> 0 | F24: =SUMIFS('PL1.1 ML2027-2028'!$G:$G,'PL1.1 ML2027-2028'!$J:$J,'TH theo DV'!$F$3,'PL1.1 ML2027-2028'!$K:$K,'TH theo DV'!C24)/$D$1 -> 0 | G24: =SUMIFS('PL1.1 ML2027-2028'!$G:$G,'PL1.1 ML2027-2028'!$J:$J,'TH theo DV'!$G$3,'PL1.1 ML2027-2028'!$K:$K,'TH theo DV'!C24)/$D$1 -> 0 | H24: =SUMIFS('PL1.1 ML2027-2028'!$G:$G,'PL1.1 ML2027-2028'!$J:$J,'TH theo DV'!$H$3,'PL1.1 ML2027-2028'!$K:$K,'TH theo DV'!C24)/$D$1 -> 0 | I24: =SUMIFS('PL1.1 ML2027-2028'!$G:$G,'PL1.1 ML2027-2028'!$J:$J,I$3,'PL1.1 ML2027-2028'!$K:$K,C24)/$D$1 -> 0 | J24: =SUMIFS('PL1.1 ML2027-2028'!$G:$G,'PL1.1 ML2027-2028'!$J:$J,'TH theo DV'!$J$3,'PL1.1 ML2027-2028'!$K:$K,'TH theo DV'!C24)/$D$1 -> 0 | K24: =SUMIFS('PL1.1 ML2027-2028'!$G:$G,'PL1.1 ML2027-2028'!$J:$J,'TH theo DV'!K$3,'PL1.1 ML2027-2028'!$K:$K,'TH theo DV'!$C24)/$D$1 -> 0 | L24: =SUM(D24:K24) -> 0 | M24: =L24/$L$4 -> #DIV/0! | N24: =SUMIFS('PL1.1 ML2027-2028'!$H:$H,'PL1.1 ML2027-2028'!$J:$J,'TH theo DV'!N$3,'PL1.1 ML2027-2028'!$K:$K,'TH theo DV'!$C24)/$D$1 -> 0 | O24: =SUMIFS('PL1.1 ML2027-2028'!$H:$H,'PL1.1 ML2027-2028'!$J:$J,'TH theo DV'!O$3,'PL1.1 ML2027-2028'!$K:$K,'TH theo DV'!$C24)/$D$1 -> 0 | P24: =SUMIFS('PL1.1 ML2027-2028'!$H:$H,'PL1.1 ML2027-2028'!$J:$J,'TH theo DV'!P$3,'PL1.1 ML2027-2028'!$K:$K,'TH theo DV'!$C24)/$D$1 -> 0 | Q24: =SUMIFS('PL1.1 ML2027-2028'!$H:$H,'PL1.1 ML2027-2028'!$J:$J,'TH theo DV'!Q$3,'PL1.1 ML2027-2028'!$K:$K,'TH theo DV'!$C24)/$D$1 -> 0 | R24: =SUMIFS('PL1.1 ML2027-2028'!$H:$H,'PL1.1 ML2027-2028'!$J:$J,'TH theo DV'!R$3,'PL1.1 ML2027-2028'!$K:$K,'TH theo DV'!$C24)/$D$1 -> 0 | S24: =SUMIFS('PL1.1 ML2027-2028'!$H:$H,'PL1.1 ML2027-2028'!$J:$J,'TH theo DV'!S$3,'PL1.1 ML2027-2028'!$K:$K,'TH theo DV'!$C24)/$D$1 -> 0 | T24: =SUMIFS('PL1.1 ML2027-2028'!$H:$H,'PL1.1 ML2027-2028'!$J:$J,'TH theo DV'!T$3,'PL1.1 ML2027-2028'!$K:$K,'TH theo DV'!$C24)/$D$1 -> 0 | U24: =SUMIFS('PL1.1 ML2027-2028'!$H:$H,'PL1.1 ML2027-2028'!$J:$J,'TH theo DV'!U$3,'PL1.1 ML2027-2028'!$K:$K,'TH theo DV'!$C24)/$D$1 -> 0 | V24: =SUM(N24:U24) -> 0 | X24: =D24+N24 -> 0 | Y24: =E24+O24 -> 0 | Z24: =F24+P24 -> 0 | AA24: =G24+Q24 -> 0 | AB24: =H24+R24 -> 0 | AC24: =I24+S24 -> 0 | AD24: =J24+T24 -> 0 | AE24: =SUM(X24:AD24) -> 0 | AF24: =AE24/$AE$4 -> #DIV/0!
A25: - | B25: Phần mềm | C25: PM | D25: =SUMIFS('PL1.1 ML2027-2028'!$G:$G,'PL1.1 ML2027-2028'!$J:$J,'TH theo DV'!$D$3,'PL1.1 ML2027-2028'!$K:$K,'TH theo DV'!C25)/$D$1 -> 0 | E25: =SUMIFS('PL1.1 ML2027-2028'!$G:$G,'PL1.1 ML2027-2028'!$J:$J,'TH theo DV'!$E$3,'PL1.1 ML2027-2028'!$K:$K,'TH theo DV'!C25)/$D$1 -> 0 | F25: =SUMIFS('PL1.1 ML2027-2028'!$G:$G,'PL1.1 ML2027-2028'!$J:$J,'TH theo DV'!$F$3,'PL1.1 ML2027-2028'!$K:$K,'TH theo DV'!C25)/$D$1 -> 0 | G25: =SUMIFS('PL1.1 ML2027-2028'!$G:$G,'PL1.1 ML2027-2028'!$J:$J,'TH theo DV'!$G$3,'PL1.1 ML2027-2028'!$K:$K,'TH theo DV'!C25)/$D$1 -> 0 | H25: =SUMIFS('PL1.1 ML2027-2028'!$G:$G,'PL1.1 ML2027-2028'!$J:$J,'TH theo DV'!$H$3,'PL1.1 ML2027-2028'!$K:$K,'TH theo DV'!C25)/$D$1 -> 0 | I25: =SUMIFS('PL1.1 ML2027-2028'!$G:$G,'PL1.1 ML2027-2028'!$J:$J,I$3,'PL1.1 ML2027-2028'!$K:$K,C25)/$D$1 -> 0 | J25: =SUMIFS('PL1.1 ML2027-2028'!$G:$G,'PL1.1 ML2027-2028'!$J:$J,'TH theo DV'!$J$3,'PL1.1 ML2027-2028'!$K:$K,'TH theo DV'!C25)/$D$1 -> 0 | K25: =SUMIFS('PL1.1 ML2027-2028'!$G:$G,'PL1.1 ML2027-2028'!$J:$J,'TH theo DV'!K$3,'PL1.1 ML2027-2028'!$K:$K,'TH theo DV'!$C25)/$D$1 -> 0 | L25: =SUM(D25:K25) -> 0 | M25: =L25/$L$4 -> #DIV/0! | N25: =SUMIFS('PL1.1 ML2027-2028'!$H:$H,'PL1.1 ML2027-2028'!$J:$J,'TH theo DV'!N$3,'PL1.1 ML2027-2028'!$K:$K,'TH theo DV'!$C25)/$D$1 -> 0 | O25: =SUMIFS('PL1.1 ML2027-2028'!$H:$H,'PL1.1 ML2027-2028'!$J:$J,'TH theo DV'!O$3,'PL1.1 ML2027-2028'!$K:$K,'TH theo DV'!$C25)/$D$1 -> 0 | P25: =SUMIFS('PL1.1 ML2027-2028'!$H:$H,'PL1.1 ML2027-2028'!$J:$J,'TH theo DV'!P$3,'PL1.1 ML2027-2028'!$K:$K,'TH theo DV'!$C25)/$D$1 -> 0 | Q25: =SUMIFS('PL1.1 ML2027-2028'!$H:$H,'PL1.1 ML2027-2028'!$J:$J,'TH theo DV'!Q$3,'PL1.1 ML2027-2028'!$K:$K,'TH theo DV'!$C25)/$D$1 -> 0 | R25: =SUMIFS('PL1.1 ML2027-2028'!$H:$H,'PL1.1 ML2027-2028'!$J:$J,'TH theo DV'!R$3,'PL1.1 ML2027-2028'!$K:$K,'TH theo DV'!$C25)/$D$1 -> 0 | S25: =SUMIFS('PL1.1 ML2027-2028'!$H:$H,'PL1.1 ML2027-2028'!$J:$J,'TH theo DV'!S$3,'PL1.1 ML2027-2028'!$K:$K,'TH theo DV'!$C25)/$D$1 -> 0 | T25: =SUMIFS('PL1.1 ML2027-2028'!$H:$H,'PL1.1 ML2027-2028'!$J:$J,'TH theo DV'!T$3,'PL1.1 ML2027-2028'!$K:$K,'TH theo DV'!$C25)/$D$1 -> 0 | U25: =SUMIFS('PL1.1 ML2027-2028'!$H:$H,'PL1.1 ML2027-2028'!$J:$J,'TH theo DV'!U$3,'PL1.1 ML2027-2028'!$K:$K,'TH theo DV'!$C25)/$D$1 -> 0 | V25: =SUM(N25:U25) -> 0 | X25: =D25+N25 -> 0 | Y25: =E25+O25 -> 0 | Z25: =F25+P25 -> 0 | AA25: =G25+Q25 -> 0 | AB25: =H25+R25 -> 0 | AC25: =I25+S25 -> 0 | AD25: =J25+T25 -> 0 | AE25: =SUM(X25:AD25) -> 0 | AF25: =AE25/$AE$4 -> #DIV/0!
A26: III | B26: Đảm bảo VHKT, kiên cố, bền vững trong thiên tai | D26: =SUBTOTAL(9,D27:D30) -> 0 | E26: =SUBTOTAL(9,E27:E30) -> 0 | F26: =SUBTOTAL(9,F27:F30) -> 0 | G26: =SUBTOTAL(9,G27:G30) -> 0 | H26: =SUBTOTAL(9,H27:H30) -> 0 | J26: =SUBTOTAL(9,J27:J30) -> 0 | K26: =SUBTOTAL(9,K27:K30) -> 0 | L26: =SUBTOTAL(9,L27:L30) -> 0 | M26: =L26/$L$4 -> #DIV/0! | N26: =SUBTOTAL(9,N27:N30) -> 0 | O26: =SUBTOTAL(9,O28:O30) -> 0 | P26: =SUBTOTAL(9,P27:P30) -> 0 | Q26: =SUBTOTAL(9,Q27:Q30) -> 0 | R26: =SUBTOTAL(9,R27:R30) -> 0 | S26: =SUBTOTAL(9,S27:S30) -> 0 | T26: =SUBTOTAL(9,T27:T30) -> 0 | U26: =SUBTOTAL(9,U27:U30) -> 0 | V26: =SUBTOTAL(9,V27:V30) -> 0 | W26: =V26/$V$4 -> #DIV/0! | X26: =SUBTOTAL(9,X28:X30) -> 0 | Y26: =SUBTOTAL(9,Y28:Y30) -> 0 | Z26: =SUBTOTAL(9,Z28:Z30) -> 0 | AA26: =SUBTOTAL(9,AA28:AA30) -> 0 | AB26: =SUBTOTAL(9,AB28:AB30) -> 0 | AC26: =SUBTOTAL(9,AC28:AC30) -> 0 | AD26: =SUBTOTAL(9,AD28:AD30) -> 0 | AE26: =SUBTOTAL(9,AE28:AE30) -> 0 | AF26: =AE26/$AE$4 -> #DIV/0!
A27: 1 | B27: Đảm bảo dự phòng ƯCTT | C27: ƯCTT | D27: =SUMIFS('PL1.1 ML2027-2028'!$G:$G,'PL1.1 ML2027-2028'!$J:$J,'TH theo DV'!$D$3,'PL1.1 ML2027-2028'!$K:$K,'TH theo DV'!C27)/$D$1 -> 0 | E27: =SUMIFS('PL1.1 ML2027-2028'!$G:$G,'PL1.1 ML2027-2028'!$J:$J,'TH theo DV'!$E$3,'PL1.1 ML2027-2028'!$K:$K,'TH theo DV'!C27)/$D$1 -> 0 | F27: =SUMIFS('PL1.1 ML2027-2028'!$G:$G,'PL1.1 ML2027-2028'!$J:$J,'TH theo DV'!$F$3,'PL1.1 ML2027-2028'!$K:$K,'TH theo DV'!C27)/$D$1 -> 0 | G27: =SUMIFS('PL1.1 ML2027-2028'!$G:$G,'PL1.1 ML2027-2028'!$J:$J,'TH theo DV'!$G$3,'PL1.1 ML2027-2028'!$K:$K,'TH theo DV'!C27)/$D$1 -> 0 | H27: =SUMIFS('PL1.1 ML2027-2028'!$G:$G,'PL1.1 ML2027-2028'!$J:$J,'TH theo DV'!$H$3,'PL1.1 ML2027-2028'!$K:$K,'TH theo DV'!C27)/$D$1 -> 0 | I27: =SUMIFS('PL1.1 ML2027-2028'!$G:$G,'PL1.1 ML2027-2028'!$J:$J,I$3,'PL1.1 ML2027-2028'!$K:$K,C27)/$D$1 -> 0 | J27: =SUMIFS('PL1.1 ML2027-2028'!$G:$G,'PL1.1 ML2027-2028'!$J:$J,'TH theo DV'!$J$3,'PL1.1 ML2027-2028'!$K:$K,'TH theo DV'!C27)/$D$1 -> 0 | K27: =SUMIFS('PL1.1 ML2027-2028'!$G:$G,'PL1.1 ML2027-2028'!$J:$J,'TH theo DV'!K$3,'PL1.1 ML2027-2028'!$K:$K,'TH theo DV'!$C27)/$D$1 -> 0 | L27: =SUM(D27:K27) -> 0 | M27: =L27/$L$4 -> #DIV/0! | N27: =SUMIFS('PL1.1 ML2027-2028'!$H:$H,'PL1.1 ML2027-2028'!$J:$J,'TH theo DV'!N$3,'PL1.1 ML2027-2028'!$K:$K,'TH theo DV'!$C27)/$D$1 -> 0 | O27: =SUMIFS('PL1.1 ML2027-2028'!$H:$H,'PL1.1 ML2027-2028'!$J:$J,'TH theo DV'!O$3,'PL1.1 ML2027-2028'!$K:$K,'TH theo DV'!$C27)/$D$1 -> 0 | P27: =SUMIFS('PL1.1 ML2027-2028'!$H:$H,'PL1.1 ML2027-2028'!$J:$J,'TH theo DV'!P$3,'PL1.1 ML2027-2028'!$K:$K,'TH theo DV'!$C27)/$D$1 -> 0 | Q27: =SUMIFS('PL1.1 ML2027-2028'!$H:$H,'PL1.1 ML2027-2028'!$J:$J,'TH theo DV'!Q$3,'PL1.1 ML2027-2028'!$K:$K,'TH theo DV'!$C27)/$D$1 -> 0 | R27: =SUMIFS('PL1.1 ML2027-2028'!$H:$H,'PL1.1 ML2027-2028'!$J:$J,'TH theo DV'!R$3,'PL1.1 ML2027-2028'!$K:$K,'TH theo DV'!$C27)/$D$1 -> 0 | S27: =SUMIFS('PL1.1 ML2027-2028'!$H:$H,'PL1.1 ML2027-2028'!$J:$J,'TH theo DV'!S$3,'PL1.1 ML2027-2028'!$K:$K,'TH theo DV'!$C27)/$D$1 -> 0 | T27: =SUMIFS('PL1.1 ML2027-2028'!$H:$H,'PL1.1 ML2027-2028'!$J:$J,'TH theo DV'!T$3,'PL1.1 ML2027-2028'!$K:$K,'TH theo DV'!$C27)/$D$1 -> 0 | U27: =SUMIFS('PL1.1 ML2027-2028'!$H:$H,'PL1.1 ML2027-2028'!$J:$J,'TH theo DV'!U$3,'PL1.1 ML2027-2028'!$K:$K,'TH theo DV'!$C27)/$D$1 -> 0 | V27: =SUM(N27:U27) -> 0 | W27: =V27/$V$4 -> #DIV/0! | X27: =D27+N27 -> 0 | Y27: =E27+O27 -> 0 | Z27: =F27+P27 -> 0 | AA27: =G27+Q27 -> 0 | AB27: =H27+R27 -> 0 | AC27: =I27+S27 -> 0 | AD27: =J27+T27 -> 0 | AE27: =SUM(X27:AD27) -> 0 | AF27: =AE27/$AE$4 -> #DIV/0!
A28: 2 | B28: Đảm bảo VHKT và nâng cao chất lượng mạng | C28: VHKT | D28: =SUMIFS('PL1.1 ML2027-2028'!$G:$G,'PL1.1 ML2027-2028'!$J:$J,'TH theo DV'!$D$3,'PL1.1 ML2027-2028'!$K:$K,'TH theo DV'!C28)/$D$1 -> 0 | E28: =SUMIFS('PL1.1 ML2027-2028'!$G:$G,'PL1.1 ML2027-2028'!$J:$J,'TH theo DV'!$E$3,'PL1.1 ML2027-2028'!$K:$K,'TH theo DV'!C28)/$D$1 -> 0 | F28: =SUMIFS('PL1.1 ML2027-2028'!$G:$G,'PL1.1 ML2027-2028'!$J:$J,'TH theo DV'!$F$3,'PL1.1 ML2027-2028'!$K:$K,'TH theo DV'!C28)/$D$1 -> 0 | G28: =SUMIFS('PL1.1 ML2027-2028'!$G:$G,'PL1.1 ML2027-2028'!$J:$J,'TH theo DV'!$G$3,'PL1.1 ML2027-2028'!$K:$K,'TH theo DV'!C28)/$D$1 -> 0 | H28: =SUMIFS('PL1.1 ML2027-2028'!$G:$G,'PL1.1 ML2027-2028'!$J:$J,'TH theo DV'!$H$3,'PL1.1 ML2027-2028'!$K:$K,'TH theo DV'!C28)/$D$1 -> 0 | I28: =SUMIFS('PL1.1 ML2027-2028'!$G:$G,'PL1.1 ML2027-2028'!$J:$J,I$3,'PL1.1 ML2027-2028'!$K:$K,C28)/$D$1 -> 0 | J28: =SUMIFS('PL1.1 ML2027-2028'!$G:$G,'PL1.1 ML2027-2028'!$J:$J,'TH theo DV'!$J$3,'PL1.1 ML2027-2028'!$K:$K,'TH theo DV'!C28)/$D$1 -> 0 | K28: =SUMIFS('PL1.1 ML2027-2028'!$G:$G,'PL1.1 ML2027-2028'!$J:$J,'TH theo DV'!K$3,'PL1.1 ML2027-2028'!$K:$K,'TH theo DV'!$C28)/$D$1 -> 0 | L28: =SUM(D28:K28) -> 0 | M28: =L28/$L$4 -> #DIV/0! | N28: =SUMIFS('PL1.1 ML2027-2028'!$H:$H,'PL1.1 ML2027-2028'!$J:$J,'TH theo DV'!N$3,'PL1.1 ML2027-2028'!$K:$K,'TH theo DV'!$C28)/$D$1 -> 0 | O28: =SUMIFS('PL1.1 ML2027-2028'!$H:$H,'PL1.1 ML2027-2028'!$J:$J,'TH theo DV'!O$3,'PL1.1 ML2027-2028'!$K:$K,'TH theo DV'!$C28)/$D$1 -> 0 | P28: =SUMIFS('PL1.1 ML2027-2028'!$H:$H,'PL1.1 ML2027-2028'!$J:$J,'TH theo DV'!P$3,'PL1.1 ML2027-2028'!$K:$K,'TH theo DV'!$C28)/$D$1 -> 0 | Q28: =SUMIFS('PL1.1 ML2027-2028'!$H:$H,'PL1.1 ML2027-2028'!$J:$J,'TH theo DV'!Q$3,'PL1.1 ML2027-2028'!$K:$K,'TH theo DV'!$C28)/$D$1 -> 0 | R28: =SUMIFS('PL1.1 ML2027-2028'!$H:$H,'PL1.1 ML2027-2028'!$J:$J,'TH theo DV'!R$3,'PL1.1 ML2027-2028'!$K:$K,'TH theo DV'!$C28)/$D$1 -> 0 | S28: =SUMIFS('PL1.1 ML2027-2028'!$H:$H,'PL1.1 ML2027-2028'!$J:$J,'TH theo DV'!S$3,'PL1.1 ML2027-2028'!$K:$K,'TH theo DV'!$C28)/$D$1 -> 0 | T28: =SUMIFS('PL1.1 ML2027-2028'!$H:$H,'PL1.1 ML2027-2028'!$J:$J,'TH theo DV'!T$3,'PL1.1 ML2027-2028'!$K:$K,'TH theo DV'!$C28)/$D$1 -> 0 | U28: =SUMIFS('PL1.1 ML2027-2028'!$H:$H,'PL1.1 ML2027-2028'!$J:$J,'TH theo DV'!U$3,'PL1.1 ML2027-2028'!$K:$K,'TH theo DV'!$C28)/$D$1 -> 0 | V28: =SUM(N28:U28) -> 0 | W28: =V28/$V$4 -> #DIV/0! | X28: =D28+N28 -> 0 | Y28: =E28+O28 -> 0 | Z28: =F28+P28 -> 0 | AA28: =G28+Q28 -> 0 | AB28: =H28+R28 -> 0 | AC28: =I28+S28 -> 0 | AD28: =J28+T28 -> 0 | AE28: =SUM(X28:AD28) -> 0 | AF28: =AE28/$AE$4 -> #DIV/0!
A29: 3 | B29: Củng cố kiên cố thường trình | C29: KCTT | D29: =SUMIFS('PL1.1 ML2027-2028'!$G:$G,'PL1.1 ML2027-2028'!$J:$J,'TH theo DV'!$D$3,'PL1.1 ML2027-2028'!$K:$K,'TH theo DV'!C29)/$D$1 -> 0 | E29: =SUMIFS('PL1.1 ML2027-2028'!$G:$G,'PL1.1 ML2027-2028'!$J:$J,'TH theo DV'!$E$3,'PL1.1 ML2027-2028'!$K:$K,'TH theo DV'!C29)/$D$1 -> 0 | F29: =SUMIFS('PL1.1 ML2027-2028'!$G:$G,'PL1.1 ML2027-2028'!$J:$J,'TH theo DV'!$F$3,'PL1.1 ML2027-2028'!$K:$K,'TH theo DV'!C29)/$D$1 -> 0 | G29: =SUMIFS('PL1.1 ML2027-2028'!$G:$G,'PL1.1 ML2027-2028'!$J:$J,'TH theo DV'!$G$3,'PL1.1 ML2027-2028'!$K:$K,'TH theo DV'!C29)/$D$1 -> 0 | H29: =SUMIFS('PL1.1 ML2027-2028'!$G:$G,'PL1.1 ML2027-2028'!$J:$J,'TH theo DV'!$H$3,'PL1.1 ML2027-2028'!$K:$K,'TH theo DV'!C29)/$D$1 -> 0 | I29: =SUMIFS('PL1.1 ML2027-2028'!$G:$G,'PL1.1 ML2027-2028'!$J:$J,I$3,'PL1.1 ML2027-2028'!$K:$K,C29)/$D$1 -> 0 | J29: =SUMIFS('PL1.1 ML2027-2028'!$G:$G,'PL1.1 ML2027-2028'!$J:$J,'TH theo DV'!$J$3,'PL1.1 ML2027-2028'!$K:$K,'TH theo DV'!C29)/$D$1 -> 0 | K29: =SUMIFS('PL1.1 ML2027-2028'!$G:$G,'PL1.1 ML2027-2028'!$J:$J,'TH theo DV'!K$3,'PL1.1 ML2027-2028'!$K:$K,'TH theo DV'!$C29)/$D$1 -> 0 | L29: =SUM(D29:K29) -> 0 | M29: =L29/$L$4 -> #DIV/0! | N29: =SUMIFS('PL1.1 ML2027-2028'!$H:$H,'PL1.1 ML2027-2028'!$J:$J,'TH theo DV'!N$3,'PL1.1 ML2027-2028'!$K:$K,'TH theo DV'!$C29)/$D$1 -> 0 | O29: =SUMIFS('PL1.1 ML2027-2028'!$H:$H,'PL1.1 ML2027-2028'!$J:$J,'TH theo DV'!O$3,'PL1.1 ML2027-2028'!$K:$K,'TH theo DV'!$C29)/$D$1 -> 0 | P29: =SUMIFS('PL1.1 ML2027-2028'!$H:$H,'PL1.1 ML2027-2028'!$J:$J,'TH theo DV'!P$3,'PL1.1 ML2027-2028'!$K:$K,'TH theo DV'!$C29)/$D$1 -> 0 | Q29: =SUMIFS('PL1.1 ML2027-2028'!$H:$H,'PL1.1 ML2027-2028'!$J:$J,'TH theo DV'!Q$3,'PL1.1 ML2027-2028'!$K:$K,'TH theo DV'!$C29)/$D$1 -> 0 | R29: =SUMIFS('PL1.1 ML2027-2028'!$H:$H,'PL1.1 ML2027-2028'!$J:$J,'TH theo DV'!R$3,'PL1.1 ML2027-2028'!$K:$K,'TH theo DV'!$C29)/$D$1 -> 0 | S29: =SUMIFS('PL1.1 ML2027-2028'!$H:$H,'PL1.1 ML2027-2028'!$J:$J,'TH theo DV'!S$3,'PL1.1 ML2027-2028'!$K:$K,'TH theo DV'!$C29)/$D$1 -> 0 | T29: =SUMIFS('PL1.1 ML2027-2028'!$H:$H,'PL1.1 ML2027-2028'!$J:$J,'TH theo DV'!T$3,'PL1.1 ML2027-2028'!$K:$K,'TH theo DV'!$C29)/$D$1 -> 0 | U29: =SUMIFS('PL1.1 ML2027-2028'!$H:$H,'PL1.1 ML2027-2028'!$J:$J,'TH theo DV'!U$3,'PL1.1 ML2027-2028'!$K:$K,'TH theo DV'!$C29)/$D$1 -> 0 | V29: =SUM(N29:U29) -> 0 | W29: =V29/$V$4 -> #DIV/0! | X29: =D29+N29 -> 0 | Y29: =E29+O29 -> 0 | Z29: =F29+P29 -> 0 | AA29: =G29+Q29 -> 0 | AB29: =H29+R29 -> 0 | AC29: =I29+S29 -> 0 | AD29: =J29+T29 -> 0 | AE29: =SUM(X29:AD29) -> 0 | AF29: =AE29/$AE$4 -> #DIV/0!
A30: 4 | B30: Bền vững mạng lưới trong thiên tai | C30: PCTT | D30: =SUMIFS('PL1.1 ML2027-2028'!$G:$G,'PL1.1 ML2027-2028'!$J:$J,'TH theo DV'!$D$3,'PL1.1 ML2027-2028'!$K:$K,'TH theo DV'!C30)/$D$1 -> 0 | E30: =SUMIFS('PL1.1 ML2027-2028'!$G:$G,'PL1.1 ML2027-2028'!$J:$J,'TH theo DV'!$E$3,'PL1.1 ML2027-2028'!$K:$K,'TH theo DV'!C30)/$D$1 -> 0 | F30: =SUMIFS('PL1.1 ML2027-2028'!$G:$G,'PL1.1 ML2027-2028'!$J:$J,'TH theo DV'!$F$3,'PL1.1 ML2027-2028'!$K:$K,'TH theo DV'!C30)/$D$1 -> 0 | G30: =SUMIFS('PL1.1 ML2027-2028'!$G:$G,'PL1.1 ML2027-2028'!$J:$J,'TH theo DV'!$G$3,'PL1.1 ML2027-2028'!$K:$K,'TH theo DV'!C30)/$D$1 -> 0 | H30: =SUMIFS('PL1.1 ML2027-2028'!$G:$G,'PL1.1 ML2027-2028'!$J:$J,'TH theo DV'!$H$3,'PL1.1 ML2027-2028'!$K:$K,'TH theo DV'!C30)/$D$1 -> 0 | I30: =SUMIFS('PL1.1 ML2027-2028'!$G:$G,'PL1.1 ML2027-2028'!$J:$J,I$3,'PL1.1 ML2027-2028'!$K:$K,C30)/$D$1 -> 0 | J30: =SUMIFS('PL1.1 ML2027-2028'!$G:$G,'PL1.1 ML2027-2028'!$J:$J,'TH theo DV'!$J$3,'PL1.1 ML2027-2028'!$K:$K,'TH theo DV'!C30)/$D$1 -> 0 | K30: =SUMIFS('PL1.1 ML2027-2028'!$G:$G,'PL1.1 ML2027-2028'!$J:$J,'TH theo DV'!$J$3,'PL1.1 ML2027-2028'!$K:$K,'TH theo DV'!D30)/$D$1 -> 0 | L30: =SUM(D30:K30) -> 0 | M30: =L30/$L$4 -> #DIV/0! | N30: =SUMIFS('PL1.1 ML2027-2028'!$H:$H,'PL1.1 ML2027-2028'!$J:$J,'TH theo DV'!N$3,'PL1.1 ML2027-2028'!$K:$K,'TH theo DV'!$C30)/$D$1 -> 0 | O30: =SUMIFS('PL1.1 ML2027-2028'!$H:$H,'PL1.1 ML2027-2028'!$J:$J,'TH theo DV'!O$3,'PL1.1 ML2027-2028'!$K:$K,'TH theo DV'!$C30)/$D$1 -> 0 | P30: =SUMIFS('PL1.1 ML2027-2028'!$H:$H,'PL1.1 ML2027-2028'!$J:$J,'TH theo DV'!P$3,'PL1.1 ML2027-2028'!$K:$K,'TH theo DV'!$C30)/$D$1 -> 0 | Q30: =SUMIFS('PL1.1 ML2027-2028'!$H:$H,'PL1.1 ML2027-2028'!$J:$J,'TH theo DV'!Q$3,'PL1.1 ML2027-2028'!$K:$K,'TH theo DV'!$C30)/$D$1 -> 0 | R30: =SUMIFS('PL1.1 ML2027-2028'!$H:$H,'PL1.1 ML2027-2028'!$J:$J,'TH theo DV'!R$3,'PL1.1 ML2027-2028'!$K:$K,'TH theo DV'!$C30)/$D$1 -> 0 | S30: =SUMIFS('PL1.1 ML2027-2028'!$H:$H,'PL1.1 ML2027-2028'!$J:$J,'TH theo DV'!S$3,'PL1.1 ML2027-2028'!$K:$K,'TH theo DV'!$C30)/$D$1 -> 0 | T30: =SUMIFS('PL1.1 ML2027-2028'!$H:$H,'PL1.1 ML2027-2028'!$J:$J,'TH theo DV'!T$3,'PL1.1 ML2027-2028'!$K:$K,'TH theo DV'!$C30)/$D$1 -> 0 | U30: =SUMIFS('PL1.1 ML2027-2028'!$H:$H,'PL1.1 ML2027-2028'!$J:$J,'TH theo DV'!U$3,'PL1.1 ML2027-2028'!$K:$K,'TH theo DV'!$C30)/$D$1 -> 0 | V30: =SUM(N30:U30) -> 0 | W30: =V30/$V$4 -> #DIV/0! | X30: =D30+N30 -> 0 | Y30: =E30+O30 -> 0 | Z30: =F30+P30 -> 0 | AA30: =G30+Q30 -> 0 | AB30: =H30+R30 -> 0 | AC30: =I30+S30 -> 0 | AD30: =J30+T30 -> 0 | AE30: =SUM(X30:AD30) -> 0 | AF30: =AE30/$AE$4 -> #DIV/0!
A31: IV | B31: Ví điện tử | C31: VI | G31: =SUMIFS('PL1.1 ML2027-2028'!$G:$G,'PL1.1 ML2027-2028'!$K:$K,C31)/$D$1 -> 0 | L31: =SUM(D31:K31) -> 0 | M31: =L31/$L$4 -> #DIV/0! | Q31: =SUMIFS('PL1.1 ML2027-2028'!$H:$H,'PL1.1 ML2027-2028'!$K:$K,C31)/$D$1 -> 0 | V31: =SUM(N31:U31) -> 0 | W31: =V31/$V$4 -> #DIV/0! | X31: =D31+N31 -> 0 | Y31: =E31+O31 -> 0 | Z31: =F31+P31 -> 0 | AA31: =G31+Q31 -> 0 | AB31: =H31+R31 -> 0 | AC31: =I31+S31 -> 0 | AD31: =J31+T31 -> 0 | AE31: =SUM(X31:AD31) -> 0 | AF31: =AE31/$AE$4 -> #DIV/0!

Sheet TH theo Mảng
B1: Phụ lục: TÁCH ĐẦU TƯ THEO TỪNG LĨNH VỰC
B2: I. Vô tuyến
B3: STT | C3: Danh mục | D3: Tổng | E3: 2027 | F3: 2028 | G3: Diễn giải khối lượng đầu tư, kết quả | J3: STT | K3: Danh mục | L3: Đầu tư 5 năm (m$) | R3: Diễn giải khối lượng đầu tư, kết quả
G4: 2027 | H4: 2028 | L4: Tổng | M4: 2026 | N4: 2027 | O4: 2028 | P4: 2029 | Q4: 2030
C5: Tổng | D5: =SUM(E5:F5) -> 0 | E5: =SUBTOTAL(9,E6:E12) -> 0 | F5: =SUBTOTAL(9,F6:F12) -> 0 | K5: Tổng | L5: 38.688275 | M5: 9.2793895 | N5: 11.107721 | O5: 12.109147 | P5: 3.9168276 | Q5: 2.2751894
B6: 1 | C6: Mạng 5G | D6: =SUM(E6:F6) -> 0 | E6: =E7 -> 0 | F6: =F7 -> 0 | J6: 1 | K6: Mạng 5G | L6: 20.853332 | M6: 4.7596894 | N6: 7.0410487 | O6: 6.7361231 | P6: 1.3557937 | Q6: 0.96067687
